Workbook
Name Affectation_de_classe: #REF!
Name Affectation_de_classe: Rules!$C$2:$C$50
Name Assegnazione_della_classe: #REF!
Name Assegnazione_della_classe: Rules!$D$2:$D$50
Name Assegnazione_della_proprieta: #REF!
Name Assegnazione_della_proprieta: Rules!$H$2:$H$50
Name Attribution_de_propriete: #REF!
Name Attribution_de_propriete: Rules!$G$2:$G$50
Name DataType: #REF!
Name DataType: Rules!$I$2:$I$50
Name FAIR_Prinzipien: #REF!
Name FAIR_Prinzipien: Rules!$M$2:$M$50
Name IFC_Data_Type: #REF!
Name IFC_Data_Type: Rules!$J$2:$J$50
Name ISG___Informationssicherheitsgesetz: #REF!
Name ISG___Informationssicherheitsgesetz: Rules!$L$2:$L$50
Name Klassen_Zuordnung: #REF!
Name Klassen_Zuordnung: Rules!$B$2:$B$50
Name Klassifikation: #REF!
Name Klassifikation: Rules!$B$2:$B$50
Name LifecycleStatus: #REF!
Name LifecycleStatus: Rules!$N$2:$N$50
Name Markmals_Klassifikation: #REF!
Name Markmals_Klassifikation: Rules!$F$2:$F$50
Name Merkmals_Zuordnung: #REF!
Name Merkmals_Zuordnung: Rules!$F$2:$F$50
Name Objekt_Einordnung: #REF!
Name Objekt_Einordnung: Rules!$A$2:$A$50
Name Property_Classification: #REF!
Name Property_Classification: Rules!$E$2:$E$50
Name Status: #REF!
Name Status: Rules!$K$2:$K$50

Sheet Impressum
B1: IFMA - Data Template - Flächenmanagment
B3: Dokumenteninformationen
C4: Status | D4: Freigegeben
C5: Version | D5: v1.0.0
C6: Herausgeber | D6: IFMA Schweiz
D7: info@ifma.ch
B9: Mit freundlicher Unterstützung von
D10: Losinger Marazzi AG
D11: POM+
B13: Abgrenzung | D13: Fokus auf Austauschformat IFC 4.3.2.0 (IFC4X3_ADD2)
D14: Andere Formate (z. B. CityGML, gbXML, LandXML) sind kein Bestandteil
D15: Strukturvorlage ist eine methodische Grundlage, kein vollständiges Data Dictionaries
D16: Vollständige Data Dictionariess müssen in Datenbanken realsiert werden
D17: Die Handlungsempfehlung ist keine Implementierungsrichtlinie für Softwareentwicklung
D18: Die Strukturvorlage ist ein Best Practice Beispiel und kann jederzeit an neue Anforderungen angepasst werden. Es wird davon abgeraten, auf der Basis der Strukturvorlage Applikationen oder Tools zu entwickeln.
D19: Keine spezifischen Referenzen/Anbindungen an externe Data Dictionaries
B21: Copyright | D21: Dieses Dokument ist als Creative Commons Attribution-NonCommercial-ShareAlike 4.0 International Lizenz als Namensnennung – nichtkommerziell Weitergabe – unter gleichen Bedingungen lizenziert
D22: Weitere Informationen unter:
D23: Creative Commons
B25: Einschränkung und Handhabung | D25: Dieses Dokument erhebt keinen Anspruch auf Vollständigkeit. Es ist auch keine aus rechtlicher Sicht allgemeingültige Empfehlung oder Leitlinie, sondern soll alle Beteiligten in der Bau- und Immobilienbranche dabei unterstützen, die Abhängigkeit der einzelnen notwendigen Steuerungsinstrumente untereinander zu verstehen und richtig zuzuordnen.

Sheet Anleitung
A1: Anleitung Strukturvorlage Data Dictionaries
B3: Inhaltsverzeichnis
B5: 1 | C5: Handhabung
B6: 2 | C6: Governance
B7: 3 | C7: Header (Kopfzeile)
B8: 4 | C8: Classes (Objekte)
B9: 5 | C9: Properties (Merkmale)
B10: 6 | C10: Values (Werte)
B11: 7 | C11: Documents (Dokument) | G11: Data Template (Datenvorlage)
B12: 8 | C12: GroupOfProperties (Merkmalsgruppen)
B14: Hinweise zur Handhabung
B16: Farbcode zum ausfüllen der Strukturvorlage
B17: D | C17: Kein Farbcode: | H17: Diese Spalten müssen ausgefüllt werden.
H18: Bei sprachabhängigen Texten muss mind. EN und eine Landessprache ausgefüllt werden
C19: Grüner Farbcode: | H19: Dropdownliste: Automatische Übersetzung von EN in DE, FR, IT. Basiert auf der Übersetzung im Reiter "Rules"
C20: Grauer Farbcode: | H20: Zusätzliche Sprachen; falls erforderlich
C21: Blauer Farbcode: | H21: Diese Spalte ist system-generated, d.h. ist im Excl nicht auszufüllen, sondern wird vom Zielsystem (Datenbank) generiert
C22: Roter Farbcode: | H22: Wird automatisch durch das Validierungskript ausgefüllt
C24: A | D24: B | E24: C | F24: D | G24: E
B25: Hinweise zur Handhabung | C25: Erforderlich für Excel | D25: Sprachen | E25: Referenziert / System generiert | F25: Rules | G25: Erforderlich für Validierung
B26: A | C26: Erforderlich für Objektkatalog / Merkmalskatalog / Wertekatalog
C27: Definiert die Mindestanforderungen an einen Katalog. Unterscheidung zwischen yes = erforderlich / optional = bei Bedarf ergänzen / no = nicht notwendig
B28: B | C28: Sprachen
C29: Angabe zur Sprache: mehrsprachig = muss in der für den Katalog führenden Sprache enthalten sein
C30: EN, DE, FR, IT = gibt Sprache zwingend vor / neutral = nicht von Sprache abhängig
B31: C | C31: Regelt die Eingabe der Spalten
C32: Darf nicht vom Ersteller manuell ausgefüllt werden, sondern wird auf eine Quelle referenziert, resp. von eine Datenbank automatisch generiert
C33: referenced = Referenz auf anderen Katalog / system-generated = vom Zielsystem generiert
B34: D | C34: Vordefinierte Regeln
C35: Verweist auf die Dropdownliste in diesem Template
B36: E | C36: Erforderlich für eine automatische Validierung zur technischen Qualitätssicherung
C37: Gibt die Valdierungsregeln an, nach welchen die Spalteninhalte geprüft werden
A39: 2 | B39: Governance
B41: Vorgabe einer minimalen Governance für die verschiedenen Kataloge (gültig für alle Reiter)
B42: Optional können aller Regeln der SN EN ISO 23386 ergänzt werden
B44: A | C44: B | D44: C | E44: D | F44: E | G44: F | H44: G
B45: Governance | C45: Status | D45: Versionsdatum | E45: Herkunft (PROV) | F45: Regeln zur Festlegung von Merkmalen | G45: Regeln zur Festlegung von Merkmalsgruppen | H45: Management-Regeln für die Erstellung und Pflege
B46: B | C46: Vorgeschriebener Status des Merkmals während seines Lebenszyklus gemäss Liste (Enumeration)
B47: C | C47: Datum der Version. Format nach ISO 8601 = YYYY-MM-DDThh:mm:ssTDZ (T = festes Trennzeichen zwischen Datum und Uhrzeit / TDZ = Zeitzonenbezeichnung. Z = UTC, Abweichung zu UTC angeben)
C48: Beispiel: CET Zeit: 15:30 = UTC+2h > Korrekte Angabe: 2026-06-18T15:30+02:00
...

Sheet Header
A1: Data Dictionary — Core Metadata
A2: Field | B2: Value | C2: Requirement | D2: Notes / Maps to
A3: IDENTIFICATION
A4: OrganizationCode | B4: IFMA | C4: user defined name (small or capital letters), max 7 chars | D4: Short org code — lowercase, max 7 chars, appears in all derived IRIs
A5: DictionaryCode | C5: SYSTEM-GENERATED | D5: Generated from DictionaryName (EN)
A6: DictionaryName (EN) | B6: data_template_ifma_areamgmt | C6: REQUIRED | D6: Required authoring title in English — source for DictionaryCode generation
A7: DictionaryName (DE) | B7: data_template_ifma_flaechenmanagment | C7: OPTIONAL | D7: Core authoring title in German — minimal DCAT
A8: DictionaryName (FR) | B8: data_template_ifma_gestiondessurfaces | C8: OPTIONAL | D8: Optional multilingual title support
A9: DictionaryName (IT) | B9: data_template_ifma_gestionedellesuperfic | C9: DictionaryName (IT) | D9: Optional multilingual title support
A10: Description (EN) | B10: The data template "Area Management" specifies a comprehensive, integrated system for the model-based recording, planning, assessment and management of areas, spaces and building volumes throughout a building’s entire life cycle. | C10: REQUIRED WHEN USED | D10: dct:description@en
A11: Beschreibung (DE) | B11: Das Data Template "Flächenmanagement" beschreibt ein durchgängiges, integriertes System zur modellbasierten Erfassung, Planung, Bewertung und Bewirtschaftung von Flächen, Räumen und Gebäudevolumen über den gesamten Lebenszyklus eines Gebäudes. | C11: OPTIONAL | D11: dct:description@de
A12: Description (FR) | B12: Le modèle de données « Gestion des surfaces » décrit un système cohérent et intégré permettant la saisie, la planification, l'évaluation et la gestion, basées sur des modèles, des surfaces, des espaces et des volumes de bâtiments tout au long du cycle de vie d'un bâtiment. | C12: OPTIONAL | D12: dct:description@fr
A13: Descrizione (IT) | B13: Il modello di dati “Gestione delle superfici” descrive un sistema coerente e integrato per la rilevazione, la pianificazione, la valutazione e la gestione basate su modelli di superfici, spazi e volumi edilizi lungo l'intero ciclo di vita di un edificio. | C13: OPTIONAL | D13: dct:description@it
A14: DictionaryVersion | C14: REQUIRED | D14: Semantic versioning: MAJOR.MINOR.PATCH
A15: DictionaryUri | C15: SYSTEM-GENERATED | D15: Derived from OrganizationCode and DictionaryCode; canonical base pattern https://example.com/<OrganizationCode>/<DictionaryCode>
C16: Guide | D16: Private organisations may keep only this tab and delete Dictionary_public.
A17: GOVERNANCE
A18: LifecycleStatus | B18: Candidate | C18: REQUIRED | D18: Governance state used to derive i14y registration status
A20: LEGEND
A21: REQUIRED: | B21: Must be filled before validation/export
A22: OPTIONAL: | B22: Fill if available
A24: LICENSING
A25: License | C25: OPTIONAL | D25: Human-readable license name — dct:license
A26: LicenseUrl | C26: OPTIONAL | D26: Resolvable license URI/URL — dct:license
A28: TECHNICAL ENDPOINTS
A29: SPARQL_Endpoint | C29: OPTIONAL | D29: SPARQL endpoint URL for published graph access
A30: TTL_Download_URL | C30: OPTIONAL | D30: Download URL for Turtle/RDF serialization — dcat:distribution
A31: JSON_Download_URL | C31: OPTIONAL | D31: Download URL for JSON/JSON-LD serialization — dcat:distribution
A32: MoreInfoUrl | C32: OPTIONAL | D32: Landing page / homepage

Sheet Classes
A1: Filter | B1: Hinweise zur Handhabung | C1: Structural categorisation | D1: Domain/Domäne/Domaine/Dominio | E1: System/System/Système/Sistema | F1: Category/Kategorie/Catégorie/Categoria | G1: Classes | H1: GUID/URI | I1: Class-ID | J1: Class-Code | K1: Class-Assignment | L1: Klassen-Zuordnung (DE) | M1: Affectation de classe (FR) | N1: Assegnazione della classe (IT) | O1: Designation (EN) | P1: Bezeichnung (DE) | Q1: Désignation (FR) | R1: Designazione (IT) | S1: Description (EN) | T1: Beschreibung (DE) | U1: Description (FR) | V1: Descrizione (IT) | W1: IFC 4.3.2.0 (IFC4X3_ADD2) | X1: IFC_URI | Y1: IfcObject Entity | Z1: IfcTypeObject Entity | AA1: PredefinedType | AB1: ObjectType | AC1: Governance | AD1: Status | AE1: Version date | AF1: Provenance (PROV) | AG1: RelatedDocuments | AH1: RelatedDocumentName (EN) | AI1: RelatedDocumentItemReference | AK1: User Defined (not part of HE Data Dictionary / not validated by Validator)
B2: Erforderlich für Excel | D2: optional | E2: optional | F2: optional | H2: no | I2: no | J2: yes | K2: yes | O2: yes | P2: yes | Q2: optional | R2: optional | S2: ja | T2: ja | U2: optional | V2: optional | X2: yes | Y2: yes | Z2: yes | AA2: yes | AB2: yes | AD2: yes | AE2: yes | AF2: yes | AH2: optional | AI2: optional
B3: Sprachen | D3: multilingual | E3: multilingual | F3: multilingual | H3: neutral | I3: neutral | J3: neutral | K3: multilingual | L3: DE | M3: FR | N3: IT | O3: EN | P3: DE | Q3: FR | R3: IT | S3: EN | T3: DE | U3: FR | V3: IT | X3: multilingual | Y3: multilingual | Z3: multilingual | AA3: multilingual | AB3: multilingual | AD3: EN | AE3: neutral | AF3: EN | AH3: EN | AI3: multilingual
B4: Referenziert / System generiert | H4: referenced | I4: system-generated | L4: system-generated | M4: system-generated | N4: system-generated | X4: referenced | Y4: referenced | Z4: referenced | AA4: referenced | AB4: referenced | AD4: referenced | AE4: referenced | AF4: referenced | AH4: referenced | AI4: referenced
B5: Dropdown Liste | K5: Rules.Class-Assignment | L5: Rules.Klassen-Zuordnung | M5: Rules.Affectation de classe | N5: Rules.Assegnazione della classe | AD5: Rules.Status
B6: Validierung | D6: user defined | E6: user defined | F6: user defined | H6: not validated. Info: If available system-generated URI / user defined backend reference | I6: system-generated from Designation (EN) | J6: user defined | K6: must match Rules.Class-Assignment | L6: system-generated from Class-Assignment via Rules | M6: system-generated from Class-Assignment via Rules | N6: system-generated from Class-Assignment via Rules | O6: user defined | P6: user defined | Q6: user defined | R6: user defined | S6: user defined | T6: user defined | U6: user defined | V6: user defined | X6: validated against identifiers from https://search.bsdd.buildingsmart.org/uri/buildingsmart/ifc/4.3 | Y6: validated against IFC 4.3 entity identifiers | Z6: validated against IFC 4.3 entity identifiers | AA6: validated against IFC predefined types when applicable | AB6: validated against IFC 4.3 entity identifiers | AD6: must match Rules.Status | AE6: date format 2026-06-18T15:30+02:00 | AF6: user defined | AH6: must match a DocumentName (EN) entry from Documents.DocumentName (EN) | AI6: must match a DocumentItemReference entry from Documents.DocumentItemReference
J7: IFMA_C_31010000 | K7: Spatial structure | L7: Räumliche Struktur | M7: Structure spatiale | N7: Struttura spaziale | O7: Storey | P7: Geschoss | S7: The physical floor level or storey level of a building. | T7: Virtuelles Objekt ohne eigene Darstellung, welches die Geschossinformationen trägt. | X7: https://identifier.buildingsmart.org/uri/buildingsmart/ifc/4.3/class/IfcBuildingStorey | Y7: IfcBuildingStorey | Z7: IfcBuildingStorey | AD7: Preview | AE7: 2026-07-09T10:30+02:00 | AF7: IFMA
J8: IFMA_C_31010001 | K8: Spatial structure | L8: Räumliche Struktur | M8: Structure spatiale | N8: Struttura spaziale | O8: Site area | P8: Grundstückfläche | S8: Site area (plot area according to SIA 416) | T8: Volumenkörper für die Darstellung der Grundstückfläche (GSF gemäss SIA 416:2003 Kap. 1). | X8: https://identifier.buildingsmart.org/uri/buildingsmart/ifc/4.3/class/IfcSpace | Y8: IfcSpace | Z8: IfcSpaceType | AA8: USERDEFINED | AB8: SITE_AREA | AD8: Preview | AE8: 2026-07-09T10:30+02:00 | AF8: IFMA | AH8: SIA 416 - Areas and volumes of buildings
J9: IFMA_C_31010002 | K9: Spatial structure | L9: Räumliche Struktur | M9: Structure spatiale | N9: Struttura spaziale | O9: Surrounding area | P9: Umgebungsfläche | S9: Surrounding area according to SIA 416 | T9: Volumenkörper für die Darstellung einer Umgebungsfläche (UF gemäss SIA 416 Kap.1). Unterteilung in UUF und BUF, sowie auch Einteilung der Nutzungsart "10.1 aussenliegende Fahrzeugabstellfäche" gemäss SIA D 0165 möglich. | X9: https://identifier.buildingsmart.org/uri/buildingsmart/ifc/4.3/class/IfcSpace | Y9: IfcSpace | Z9: IfcSpaceType | AA9: USERDEFINED | AB9: SURROUNDING_AREA | AD9: Preview | AE9: 2026-07-09T10:30+02:00 | AF9: IFMA | AH9: SIA 416 - Areas and volumes of buildings
J10: IFMA_C_31010003 | K10: Spatial structure | L10: Räumliche Struktur | M10: Structure spatiale | N10: Struttura spaziale | O10: Gross floor area | P10: Geschossvolumen | S10: Volumetric representation of gross floor areas and storey volumes according to SIA 416 | T10: Volumenkörper für die Darstellung der Geschossvolumen, Geschossflächen und Aussen-Geschossflächen (GV, GF und AGF gemäss SIA 416:2003 Kap. 2, 3 und 5) sowie Dachflächen. | X10: https://identifier.buildingsmart.org/uri/buildingsmart/ifc/4.3/class/IfcSpaceGFA | Y10: IfcSpace | Z10: IfcSpaceType | AA10: GFA | AD10: Preview | AE10: 2026-07-09T10:30+02:00 | AF10: IFMA | AH10: SIA 416 - Areas and volumes of buildings
J11: IFMA_C_31010004 | K11: Spatial structure | L11: Räumliche Struktur | M11: Structure spatiale | N11: Struttura spaziale | O11: Internal room | P11: Innenraum | S11: Internal spaces (net floor areas according to SIA 416) | T11: Volumenkörper für die Darstellung eines Innenraumes (Nettogeschossflächen NGF mit Unterteilung nach HNF, NNF, VF oder FF gemäss SIA 416:2003 Kap. 2). | X11: https://identifier.buildingsmart.org/uri/buildingsmart/ifc/4.3/class/IfcSpace | Y11: IfcSpace | Z11: IfcSpaceType | AA11: USERDEFINED | AB11: ROOM | AD11: Preview | AE11: 2026-07-09T10:30+02:00 | AF11: IFMA | AH11: SIA 416 - Areas and volumes of buildings
J12: IFMA_C_31010005 | K12: Spatial structure | L12: Räumliche Struktur | M12: Structure spatiale | N12: Struttura spaziale | O12: External room | P12: Aussenraum | S12: External spaces (external net floor areas according to SIA 416) | T12: Volumenkörper für die Darstellung eines Aussenraums (Aussen-Nettogeschossflächen ANGF mit Unterteilung nach ANF, AVF oder AFF gemäss SIA 416:2003 Kap. 3). | X12: https://identifier.buildingsmart.org/uri/buildingsmart/ifc/4.3/class/IfcSpace | Y12: IfcSpace | Z12: IfcSpaceType | AA12: USERDEFINED | AB12: EXTERNAL_ROOM | AD12: Preview | AE12: 2026-07-09T10:30+02:00 | AF12: IFMA | AH12: SIA 416 - Areas and volumes of buildings
J13: IFMA_C_31010006 | K13: Spatial structure | L13: Räumliche Struktur | M13: Structure spatiale | N13: Struttura spaziale | O13: Parking space | P13: Einzelparkplatz | S13: Parking spaces such as car parking spaces, moped parking, bicycle parking, fire service access/parking bays | T13: Volumenkörper für die Darstellung eines einzelnen Parkplatzes wie z.B. Autoparkplatz, Mofa-Parkplatz, Velostellplatz und ggbfs. Feuerwehrstellplatz | X13: https://identifier.buildingsmart.org/uri/buildingsmart/ifc/4.3/class/IfcSpace | Y13: IfcSpace | Z13: IfcSpaceType | AA13: PARKING | AD13: Preview | AE13: 2026-07-09T10:30+02:00 | AF13: IFMA
J14: IFMA_C_31010007 | K14: Spatial structure | L14: Räumliche Struktur | M14: Structure spatiale | N14: Struttura spaziale | O14: Rentable area | P14: Vermietbare Fläche | S14: Geometric representation of lettable area where this differs from net floor areas | T14: Geometrische Darstellung der anrechenbare Fläche einer Miet- oder Verkaufseinheit (vermietbare Fläche VMF gemäss SIA D 0165:2000 Abschnitt 3.1.2). Diese Darstellung erübricht sich wenn die übliche Netto- oder Bruttofläche gemäss SIA 416:2003 angewendet wird. Zuordnung nach Eigenmietfläche EMF, Drittmietfläche DMF und Zuschlagsfläche ZF gemäss SIA D 0165:2000 möglich. | X14: https://identifier.buildingsmart.org/uri/buildingsmart/ifc/4.3/class/IfcSpatialZone | Y14: IfcSpatialZone | Z14: IfcSpatialZoneType | AA14: OCCUPANCY | AD14: Preview | AE14: 2026-07-09T10:30+02:00 | AF14: IFMA
J15: IFMA_C_31010008 | K15: Spatial structure | L15: Räumliche Struktur | M15: Structure spatiale | N15: Struttura spaziale | O15: Usage unit | P15: Nutzungseinheit | S15: Grouping of Spaces and SpatialZones belong to the same Unit | T15: Virtuelles Objekte ohne eigene Darstellung für die Gruppierung von Räumen (Innen und Aussen) und ggbfs. Einzelparkplätze und/oder Vermietbare Flächen, welche zu einer Nutzungseinheit gehören. | X15: https://identifier.buildingsmart.org/uri/buildingsmart/ifc/4.3/class/IfcZone | Y15: IfcZone | Z15: n/a | AB15: USAGE_UNIT | AD15: Preview | AE15: 2026-07-09T10:30+02:00 | AF15: IFMA
J16: IFMA_C_31010009 | K16: Spatial structure | L16: Räumliche Struktur | M16: Structure spatiale | N16: Struttura spaziale | O16: Site | P16: Grundstück | T16: Virtuelles Objekt ohne eigene Darstellung, welches die Grundstück- bzw. Parzellen- oder Baufeldinformationen trägt. | X16: https://identifier.buildingsmart.org/uri/buildingsmart/ifc/4.3/class/IfcSite | Y16: IfcSite | Z16: n/a | AD16: Preview | AE16: 2026-07-09T10:30+02:00 | AF16: IFMA
J17: IFMA_C_31010010 | K17: Spatial structure | L17: Räumliche Struktur | M17: Structure spatiale | N17: Struttura spaziale | O17: Building | P17: Gebäude | T17: Virtuelles Objekt ohne eigene Darstellung, welches die Gebäude- bzw. Bauobjektinformationen trägt. | X17: https://identifier.buildingsmart.org/uri/buildingsmart/ifc/4.3/class/IfcBuilding | Y17: IfcBuilding | Z17: n/a | AD17: Preview | AE17: 2026-07-09T10:30+02:00 | AF17: IFMA

Sheet Properties
A1: Filter | B1: Hinweise zur Handhabung | C1: Properties | D1: GUID/URI | E1: Property-ID | F1: Property-Code | G1: Property-Assignment | H1: Merkmals-Zuordnung (DE) | I1: Attribution de propriété (FR) | J1: Assegnazione della proprietà (IT) | K1: Designation (EN) | L1: Bezeichnung (DE) | M1: Désignation (FR) | N1: Designazione (IT) | O1: Description (EN) | P1: Beschreibung (DE) | Q1: Description (FR) | R1: Descrizione (IT) | S1: DataType (Base Type) | T1: DataType (IFC) | U1: EnumerationDesignation (EN) | V1: IFC 4.3.2.0 (IFC4X3_ADD2) | W1: IFC_URI | X1: IfcPropertySet (Pset) IfcQuantitySet (Qto) | Y1: Units/Einheit/Unité/Unità | Z1: Governance | AA1: Status | AB1: Version date | AC1: Provenance (PROV) | AD1: RelatedDocuments | AE1: RelatedDocumentName (EN) | AF1: RelatedDocumentItemReference | AH1: User Defined (not part of HE Data Dictionary / not validated by Validator)
B2: Erforderlich für Excel | D2: no | E2: no | F2: yes | G2: yes | K2: yes | L2: yes | M2: optional | N2: optional | O2: yes | P2: yes | Q2: optional | R2: optional | S2: yes | T2: yes | U2: yes | W2: yes | X2: yes | Y2: yes | AA2: yes | AB2: yes | AC2: yes | AE2: optional | AF2: optional
B3: Sprachen | D3: neutral | E3: neutral | F3: neutral | G3: neutral | H3: DE | I3: FR | J3: IT | K3: EN | L3: DE | M3: FR | N3: IT | O3: EN | P3: DE | Q3: FR | R3: IT | S3: neutral | T3: neutral | U3: EN | W3: neutral | X3: EN | Y3: neutral | AA3: EN | AB3: neutral | AC3: EN | AE3: EN | AF3: multilingual
B4: Referenziert / System generiert | D4: referenced | E4: system-generated | H4: system-generated | I4: system-generated | J4: system-generated | S4: referenced | T4: referenced | U4: referenced | W4: referenced | X4: referenced | AA4: referenced | AB4: referenced | AC4: referenced | AE4: referenced | AF4: referenced
B5: Dropdown Liste | G5: Rules.Property-Assignment | H5: Rules.Merkmals-Zuordnung | I5: Rules.Attribution de propriété | J5: Rules.Assegnazione della proprietà | S5: Rules.DataType | T5: Rules.IFC Data Type | AA5: Rules.Status
B6: Validierung | D6: not validated. Info: If available system-generated URI / user defined backend reference | E6: system-generated from Designation (EN) | F6: user defined | G6: must match Rules.Property-Assignment | H6: system-generated from Property-Assignment via Rules | I6: system-generated from Property-Assignment via Rules | J6: system-generated from Property-Assignment via Rules | K6: user defined | L6: user defined | M6: user defined | N6: user defined | O6: user defined | P6: user defined | Q6: user defined | R6: user defined | S6: must match Rules.DataType | T6: must match Rules.IFC Data Type | U6: must match a Designation (EN) entry from Values.Designation (EN) | W6: validated against identifiers from https://search.bsdd.buildingsmart.org/uri/buildingsmart/ifc/4.3 | X6: validated against IFC 4.3 property/quantity set identifiers when IFC_URI is present | Y6: user defined | AA6: must match Rules.Status | AB6: date format 2026-06-18T15:30+02:00 | AC6: user defined | AE6: must match a DocumentName (EN) entry from Documents.DocumentName (EN) | AF6: must match a DocumentItemReference entry from Documents.DocumentItemReference
F7: IFMA_P_31020002 | G7: Identification and classification | H7: Identifikation und Klassifikation | I7: Identification et classification | J7: Identificazione e classificazione | K7: Name | L7: Name | O7: Unique room number or floor number according to numbering scheme | P7: Attribut um das Objekt zu benennen. Im Rahmen der räumlichen Struktur ist hier eine eindeutige Nummer zu vergeben (Geschossnummer, Wohnungsnummer, Raumnummer, Türnummer…) | S7: STRING | T7: IfcLabel | W7: https://identifier.buildingsmart.org/uri/buildingsmart/ifc/4.3/prop/Name | AA7: Preview | AB7: 2026-07-09T10:30+02:00 | AC7: IFMA
F8: IFMA_P_31020003 | G8: Identification and classification | H8: Identifikation und Klassifikation | I8: Identification et classification | J8: Identificazione e classificazione | K8: LongName | L8: Langer Name | O8: Designation | P8: Attribut um das Objekt zu bezeichnen. Im Fall von Räumen erscheint hier die Raumbezeichnung. | S8: STRING | T8: IfcLabel | W8: https://identifier.buildingsmart.org/uri/buildingsmart/ifc/4.3/prop/LongName | AA8: Preview | AB8: 2026-07-09T10:30+02:00 | AC8: IFMA
F9: IFMA_P_31020004 | G9: Identification and classification | H9: Identifikation und Klassifikation | I9: Identification et classification | J9: Identificazione e classificazione | K9: SIA_416_2003 | L9: SIA_416_2003 | O9: Classification according to SIA 416:2003 | P9: Klassifizierung gemäss SIA 416:2003 | S9: STRING | T9: IfcLabel | U9: area_type_sia_416_code_enum | AA9: Preview | AB9: 2026-07-09T10:30+02:00 | AC9: IFMA
F10: IFMA_P_31020007 | G10: Identification and classification | H10: Identifikation und Klassifikation | I10: Identification et classification | J10: Identificazione e classificazione | K10: SIA_380_2015 | L10: SIA_380_2015 | M10: SIA_380_2015 | O10: Classification according to SIA 380:2015 | P10: Klassifizierung gemäss SIA 380:2015 | S10: STRING | T10: IfcLabel | U10: room_designation_sia_380_label_enum | AA10: Preview | AB10: 2026-07-09T10:30+02:00 | AC10: IFMA
F11: IFMA_P_31020008 | G11: Identification and classification | H11: Identifikation und Klassifikation | I11: Identification et classification | J11: Identificazione e classificazione | K11: SIA_2024_2021 | L11: SIA_2024_2021 | M11: SIA_2024_2021 | O11: Classification according to SIA 2024:2021 | P11: Klassifizierung gemäss SIA 2024:2021 | S11: STRING | T11: IfcLabel | U11: room_usage_sia_2024_code_enum | AA11: Preview | AB11: 2026-07-09T10:30+02:00 | AC11: IFMA
F12: IFMA_P_31020010 | G12: Identification and classification | H12: Identifikation und Klassifikation | I12: Identification et classification | J12: Identificazione e classificazione | K12: SIA_d0165_2000 | L12: SIA_d0165_2000 | M12: SIA_d0165_2001 | O12: Classification according to SIA D 0165:2000/2001 | P12: Klassifizierung gemäss SIA D 0165:2000/2001 | S12: STRING | T12: IfcLabel | U12: area_type_d0165_code_enum | AA12: Preview | AB12: 2026-07-09T10:30+02:00 | AC12: IFMA
F13: IFMA_P_31020012 | G13: Operating conditions and limits | H13: Betriebsbedingungen und Grenzwerte | I13: Conditions de fonctionnement et limites | J13: Condizioni operative e limiti | K13: RoomUsage | L13: Raumnutzung | O13: Room usage e.g. according to room programme | P13: Raumnutzung z.B. gemäss Raumprogramm | S13: STRING | T13: IfcLabel | AA13: Preview | AB13: 2026-07-09T10:30+02:00 | AC13: IFMA
F14: IFMA_P_31020013 | G14: Operating conditions and limits | H14: Betriebsbedingungen und Grenzwerte | I14: Conditions de fonctionnement et limites | J14: Condizioni operative e limiti | K14: RoomType | L14: Raumtyp | O14: Room type (functional type) e.g. according to room catalogue (room data sheets) | P14: Raumtyp (Funktionstyp) z.B. gemäss Raumkatalog (Raumdatenblätter) | S14: STRING | T14: IfcLabel | AA14: Preview | AB14: 2026-07-09T10:30+02:00 | AC14: IFMA
F15: IFMA_P_31020014 | G15: Identification and classification | H15: Identifikation und Klassifikation | I15: Identification et classification | J15: Identificazione e classificazione | K15: UnitType | L15: Einheitstyp | O15: Unit type, in particular dwelling type (e.g. 3.5-room flat) | P15: Einheitstyp, insb. Wohnungstyp z.B. 3.5-Zi | S15: STRING | T15: IfcLabel | AA15: Preview | AB15: 2026-07-09T10:30+02:00 | AC15: IFMA
F16: IFMA_P_31020015 | G16: Identification and classification | H16: Identifikation und Klassifikation | I16: Identification et classification | J16: Identificazione e classificazione | K16: UnitID | L16: Einheitsnummer | O16: Unique unit number (ID) according to numbering scheme for sale or rental units (e.g. apartment number) | P16: Eindeutige Einheitsnummer (ID) gemäss Nummerierungskonzept für Verkaufs- bzw. Mieteinheiten, z.B. Wohnungsnummer. Sie wird ab den Namen der Nutzungseinheit vererbt. | S16: STRING | T16: IfcLabel | AA16: Preview | AB16: 2026-07-09T10:30+02:00 | AC16: IFMA
F17: IFMA_P_31020016 | G17: Identification and classification | H17: Identifikation und Klassifikation | I17: Identification et classification | J17: Identificazione e classificazione | K17: CAFM_ID | L17: CAFM_ID | O17: Object ID in CAFM-System | P17: Objekt-ID im Betriebssystem | S17: STRING | T17: IfcLabel | AA17: Preview | AB17: 2026-07-09T10:30+02:00 | AC17: IFMA
F18: IFMA_P_31020017 | G18: Identification and classification | H18: Identifikation und Klassifikation | I18: Identification et classification | J18: Identificazione e classificazione | K18: RoomSignalLabel | L18: Raumbeschriftung | O18: Room labelled | P18: Beschriftung vom Raum | S18: STRING | T18: IfcLabel | AA18: Preview | AB18: 2026-07-09T10:30+02:00 | AC18: IFMA
F19: IFMA_P_31020018 | G19: Operating conditions and limits | H19: Betriebsbedingungen und Grenzwerte | I19: Conditions de fonctionnement et limites | J19: Condizioni operative e limiti | K19: CleaningGroup | L19: Reinigungsgruppe | O19: Cleaning group | P19: Reinigungsgruppe | S19: STRING | T19: IfcLabel | AA19: Preview | AB19: 2026-07-09T10:30+02:00 | AC19: IFMA
F20: IFMA_P_31020019 | G20: Physical characteristics | H20: Physikalische Eigenschaften | I20: Caractéristiques physiques | J20: Caratteristiche fisiche | K20: AreaLoad | L20: Flächenlast | O20: Maximum Area load | P20: Maximale Flächenlast nach Nutzungsvereinbarung | S20: REAL | T20: IfcPlanarForceMeasure | Y20: kN/m2 | AA20: Preview | AB20: 2026-07-09T10:30+02:00 | AC20: IFMA
F21: IFMA_P_31020020 | G21: Physical characteristics | H21: Physikalische Eigenschaften | I21: Caractéristiques physiques | J21: Caratteristiche fisiche | K21: PointLoad | L21: Punktlast | O21: Maximum Point load | P21: Maximale Punktlast nach Nutzungsvereinbarung | S21: REAL | T21: IfcForceMeasure | Y21: kN | AA21: Preview | AB21: 2026-07-09T10:30+02:00 | AC21: IFMA
F22: IFMA_P_31020021 | G22: Physical characteristics | H22: Physikalische Eigenschaften | I22: Caractéristiques physiques | J22: Caratteristiche fisiche | K22: EnergyReferenceArea | L22: Energiebezugsfläche | O22: States if the space object accounts for the "Energy Reference Area" | P22: Präzisiert, ob der Volumenkörper zur Energiebezugsfläche gehört. | S22: BOOLEAN | T22: IfcLogical | AA22: Preview | AB22: 2026-07-09T10:30+02:00 | AC22: IFMA
F23: IFMA_P_31020022 | G23: Physical characteristics | H23: Physikalische Eigenschaften | I23: Caractéristiques physiques | J23: Caratteristiche fisiche | K23: WindowsCleaningArea | L23: Fensterfläche | O23: Window area of the room | P23: Fensterfläche im Raum | S23: REAL | T23: IfcAreaMeasure | Y23: m2 | AA23: Preview | AB23: 2026-07-09T10:30+02:00 | AC23: IFMA
F24: IFMA_P_31020023 | G24: Performance characteristics | H24: Leistungs- und Funktionskennwerte | I24: Caractéristiques de performance et de fonctionnement | J24: Caratteristiche prestazionali e funzionali | K24: WindowsOpenable | L24: Fenster öffenbar | O24: States if the Room hast openable windows. | P24: Präzisiert, ob es im Raum öffenbare Fenster gibt. | S24: BOOLEAN | T24: IfcLogical | AA24: Preview | AB24: 2026-07-09T10:30+02:00 | AC24: IFMA
F25: IFMA_P_31020024 | G25: Operating conditions and limits | H25: Betriebsbedingungen und Grenzwerte | I25: Conditions de fonctionnement et limites | J25: Condizioni operative e limiti | K25: Occupant | L25: Raumnutzer | O25: Room occupant | P25: Raumnutzer.in. | S25: STRING | T25: IfcLabel | AA25: Preview | AB25: 2026-07-09T10:30+02:00 | AC25: IFMA
F26: IFMA_P_31020025 | G26: Operating conditions and limits | H26: Betriebsbedingungen und Grenzwerte | I26: Conditions de fonctionnement et limites | J26: Condizioni operative e limiti | K26: Shading | L26: Sonnenschutz | O26: Solar shading | P26: Präzisiert, ob der Raum Sonnenschutz hat. | S26: BOOLEAN | T26: IfcLogical | AA26: Preview | AB26: 2026-07-09T10:30+02:00 | AC26: IFMA
F27: IFMA_P_31020026 | G27: Thermal characteristics | H27: Thermische Kennwerte | I27: Caractéristiques thermiques | J27: Caratteristiche termiche | K27: IsHumidified | L27: Befeuchtet | O27: Humidified | P27: Präzisiert, ob der Raum befeuchtet ist. | S27: BOOLEAN | T27: IfcLogical | AA27: Preview | AB27: 2026-07-09T10:30+02:00 | AC27: IFMA
F28: IFMA_P_31020027 | G28: Thermal characteristics | H28: Thermische Kennwerte | I28: Caractéristiques thermiques | J28: Caratteristiche termiche | K28: IsDehumidified | L28: Entfeuchtet | O28: Dehumidified | P28: Präzisiert, ob der Raum entfeuchtet ist. | S28: BOOLEAN | T28: IfcLogical | AA28: Preview | AB28: 2026-07-09T10:30+02:00 | AC28: IFMA
F29: IFMA_P_31020028 | G29: Operating conditions and limits | H29: Betriebsbedingungen und Grenzwerte | I29: Conditions de fonctionnement et limites | J29: Condizioni operative e limiti | K29: IsRentable | L29: Vermietbarkeit | O29: Letting suitability | P29: Vermietbarkeit | S29: BOOLEAN | T29: IfcLogical | AA29: Preview | AB29: 2026-07-09T10:30+02:00 | AC29: IFMA
D30: https://identifier.buildingsmart.org/uri/buildingsmart/ifc/4.3/prop/IsExternal | F30: IFMA_P_31020029 | G30: Identification and classification | H30: Identifikation und Klassifikation | I30: Identification et classification | J30: Identificazione e classificazione | K30: IsExternal | L30: Aussenraum | O30: Indicates whether the element is intended for outdoor use (TRUE) or not (FALSE). If set to (TRUE), the element is an external element that forms the outer boundary of a building. | P30: Angabe, ob das Element für die Verwendung im Aussenbereich vorgesehen ist (TRUE) oder nicht (FALSE). Bei (TRUE) handelt es sich um ein Aussenelement, das ein Gebäude nach außen abschliesst. | S30: BOOLEAN | T30: IfcBoolean | W30: https://identifier.buildingsmart.org/uri/buildingsmart/ifc/4.3/prop/IsExternal | X30: Pset_SpaceCommon | AA30: Preview | AB30: 2026-07-09T10:30+02:00 | AC30: IFMA
D31: https://identifier.buildingsmart.org/uri/buildingsmart/ifc/4.3/prop/OccupancyType | F31: IFMA_P_31020030 | G31: Operating conditions and limits | H31: Betriebsbedingungen und Grenzwerte | I31: Conditions de fonctionnement et limites | J31: Condizioni operative e limiti | K31: OccupancyType | L31: Nutzungsart | O31: Occupancy type for this object.; It is defined according to the presiding national building code. | P31: Nutzungsart dieses Objekts; sie wird gemäss den geltenden nationalen Bauvorschriften definiert. | S31: STRING | T31: IfcLabel | W31: https://identifier.buildingsmart.org/uri/buildingsmart/ifc/4.3/prop/OccupancyType | X31: Pset_SpaceOccupancyRequirements | AA31: Preview | AB31: 2026-07-09T10:30+02:00 | AC31: IFMA
F32: IFMA_P_31020031 | G32: Geometric characteristics | H32: Geometrische Eigenschaften | I32: Caractéristiques géométriques | J32: Caratteristiche geometriche | K32: MinimumHeadroom | L32: Raumnutzhöhe | O32: Effective clear height | P32: Lichte Höhe | S32: REAL | T32: IfcLengthMeasure | W32: https://identifier.buildingsmart.org/uri/buildingsmart/ifc/4.3/prop/MinimumHeadroom | X32: Pset_SpaceOccupancyRequirements | Y32: m | AA32: Preview | AB32: 2026-07-09T10:30+02:00 | AC32: IFMA
D33: https://identifier.buildingsmart.org/uri/buildingsmart/ifc/4.3/prop/OccupancyNumberPeak | F33: IFMA_P_31020032 | G33: Operating conditions and limits | H33: Betriebsbedingungen und Grenzwerte | I33: Conditions de fonctionnement et limites | J33: Condizioni operative e limiti | K33: OccupancyNumberPeak | L33: Personenbelegung geplant | O33: Maximal number of people required for the activity assigned to this space in peak time. | P33: Maximale Anzahl Personen für die zugewiesene Nutzung dieses Raums in Spitzenzeiten. | S33: INTEGER | T33: IfcInteger | W33: https://identifier.buildingsmart.org/uri/buildingsmart/ifc/4.3/prop/OccupancyNumberPeak | X33: Pset_SpaceOccupancyRequirements | AA33: Preview | AB33: 2026-07-09T10:30+02:00 | AC33: IFMA
D34: https://identifier.buildingsmart.org/uri/buildingsmart/ifc/4.3/prop/OccupancyNumber | F34: IFMA_P_31020033 | G34: Operating conditions and limits | H34: Betriebsbedingungen und Grenzwerte | I34: Conditions de fonctionnement et limites | J34: Condizioni operative e limiti | K34: OccupancyNumber | L34: Personenbelegung ist | O34: Number of people required for the activity assigned to this space. | P34: Anzahl Personen für die zugewiesene Nutzung dieses Raums. | S34: INTEGER | T34: IfcInteger | W34: https://identifier.buildingsmart.org/uri/buildingsmart/ifc/4.3/prop/OccupancyNumber | X34: Pset_SpaceOccupancyRequirements | AA34: Preview | AB34: 2026-07-09T10:30+02:00 | AC34: IFMA
D35: https://identifier.buildingsmart.org/uri/buildingsmart/ifc/4.3/prop/FloorCovering | F35: IFMA_P_31020034 | G35: Material and construction | H35: Material und Aufbau | I35: Matériau et constitution | J35: Materiale e struttura | K35: FloorCovering | L35: Bodenbelag | O35: Label to indicate the material or finish of the space flooring. The label is used for room book information and often displayed in room stamp.The material information is provided in absence of an Covering (type=FLOORING) object with own shape representation and material assignment. In case of inconsistency the material assigned to Covering elements takes precedence. | P35: Kennzeichnung des Materials bzw. der Oberfläche des Bodenbelags im Raum. Die Kennzeichnung wird für Raumbuchinformationen verwendet und häufig im Raumstempel angezeigt. Die Materialinformation wird bereitgestellt, sofern kein Covering-Objekt (Typ=FLOORING) mit eigener Geometrie und Materialzuweisung vorhanden ist. Bei Inkonsistenzen hat die Materialzuweisung der Covering-Elemente Vorrang. | S35: STRING | T35: IfcLabel | W35: https://identifier.buildingsmart.org/uri/buildingsmart/ifc/4.3/prop/FloorCovering | X35: Pset_SpaceCoveringRequirements | AA35: Preview | AB35: 2026-07-09T10:30+02:00 | AC35: IFMA
D36: https://identifier.buildingsmart.org/uri/buildingsmart/ifc/4.3/prop/WallCovering | F36: IFMA_P_31020035 | G36: Manufacturer and product information | H36: Hersteller- und Produktinformationen | I36: Informations sur le fabricant et le produit | J36: Informazioni sul produttore e sul prodotto | K36: WallCovering | L36: Wandbelag | O36: Label to indicate the material or finish of the space cladding. The label is used for room book information and often displayed in room stamp.The material information is provided in absence of an Covering (type=CLADDING) object with own shape representation and material assignment. In case of inconsistency the material assigned to Covering elements takes precedence | P36: Kennzeichnung des Materials bzw. der Oberfläche der Wandbekleidung im Raum. Die Kennzeichnung wird für Raumbuchinformationen verwendet und häufig im Raumstempel angezeigt. Die Materialinformation wird bereitgestellt, sofern kein Covering-Objekt (Typ=CLADDING) mit eigener Geometrie und Materialzuweisung vorhanden ist. Bei Inkonsistenzen hat die Materialzuweisung der Covering-Elemente Vorrang. | S36: STRING | T36: IfcLabel | W36: https://identifier.buildingsmart.org/uri/buildingsmart/ifc/4.3/prop/WallCovering | X36: Pset_SpaceCoveringRequirements | AA36: Preview | AB36: 2026-07-09T10:30+02:00 | AC36: IFMA
D37: https://identifier.buildingsmart.org/uri/buildingsmart/ifc/4.3/prop/CeilingCovering | F37: IFMA_P_31020036 | G37: Material and construction | H37: Material und Aufbau | I37: Matériau et constitution | J37: Materiale e struttura | K37: CeilingCovering | L37: Deckenmaterial | O37: Label to indicate the material or finish of the space ceiling. The label is used for room book information and often displayed in room stamp.The material information is provided in absence of an Covering (type=[[CEILING]]) object with own shape representation and material assignment. In case of inconsistency the material assigned to Covering elements takes precedence. | P37: Kennzeichnung des Materials bzw. der Oberfläche der Raumdecke. Die Kennzeichnung wird für Raumbuchinformationen verwendet und häufig im Raumstempel angezeigt. Die Materialinformation wird bereitgestellt, sofern kein Covering-Objekt (Typ=CEILING) mit eigener Geometrie und Materialzuweisung vorhanden ist. Bei Inkonsistenzen hat die Materialzuweisung der Covering-Elemente Vorrang. | S37: STRING | T37: IfcLabel | W37: https://identifier.buildingsmart.org/uri/buildingsmart/ifc/4.3/prop/CeilingCovering | X37: Pset_SpaceCoveringRequirements | AA37: Preview | AB37: 2026-07-09T10:30+02:00 | AC37: IFMA
D38: https://identifier.buildingsmart.org/uri/buildingsmart/ifc/4.3/prop/NaturalVentilation | F38: IFMA_P_31020037 | G38: Thermal characteristics | H38: Thermische Kennwerte | I38: Caractéristiques thermiques | J38: Caratteristiche termiche | K38: NaturalVentilation | L38: Natürliche Belüftung | O38: Indication whether the space is required to have natural ventilation (TRUE), or not (FALSE). | P38: Angabe, ob für den Raum natürliche Lüftung erforderlich ist (TRUE) oder nicht (FALSE). | S38: BOOLEAN | T38: IfcBoolean | W38: https://identifier.buildingsmart.org/uri/buildingsmart/ifc/4.3/prop/NaturalVentilation | X38: Pset_SpaceHVACDesign | AA38: Preview | AB38: 2026-07-09T10:30+02:00 | AC38: IFMA
D39: https://identifier.buildingsmart.org/uri/buildingsmart/ifc/4.3/prop/NaturalVentilationRate | F39: IFMA_P_31020038 | G39: Hydraulic / flow characteristics | H39: Hydraulische / strömungstechnische Kennwerte | I39: Caractéristiques hydrauliques / d’écoulement | J39: Caratteristiche idrauliche / di flusso | K39: NaturalVentilationRate | L39: Natürliche Luftwechselrate | O39: Indication of the requirement of a particular natural air ventilation rate, given in air changes per hour. | P39: Angabe der erforderlichen natürlichen Luftwechselrate (in Luftwechseln pro Stunde). | S39: REAL | T39: IfcVolumetricFlowRateMeasure | W39: https://identifier.buildingsmart.org/uri/buildingsmart/ifc/4.3/prop/NaturalVentilationRate | X39: Pset_SpaceHVACDesign | Y39: m3/h | AA39: Preview | AB39: 2026-07-09T10:30+02:00 | AC39: IFMA
D40: https://identifier.buildingsmart.org/uri/buildingsmart/ifc/4.3/prop/MechanicalVentilation | F40: IFMA_P_31020039 | G40: Performance characteristics | H40: Leistungs- und Funktionskennwerte | I40: Caractéristiques de performance et de fonctionnement | J40: Caratteristiche prestazionali e funzionali | K40: MechanicalVentilation | L40: Mechanische Belüftung | O40: Indication whether the space is required to have mechanical ventilation (TRUE), or not (FALSE). | P40: Angabe, ob für den Raum mechanische Lüftung erforderlich ist (TRUE) oder nicht (FALSE). | S40: BOOLEAN | T40: IfcBoolean | W40: https://identifier.buildingsmart.org/uri/buildingsmart/ifc/4.3/prop/MechanicalVentilation | X40: Pset_SpaceHVACDesign | AA40: Preview | AB40: 2026-07-09T10:30+02:00 | AC40: IFMA
...

Sheet Values
A1: Filter | B1: Hinweise zur Handhabung | C1: Enumerations | D1: GUID/URI | E1: Enumeration-ID | F1: Enumeration-Code | G1: Designation (EN) | H1: Bezeichnung (DE) | I1: Désignation (FR) | J1: Designazione (IT) | K1: Enumeration (EN) | L1: Werteliste (DE) | M1: Liste de valeurs (FR) | N1: Lista valori (IT) | O1: Units/Einheit/Unité/Unità | P1: Governance | Q1: Status | R1: Version date | S1: Provenance (PROV) | T1: RelatedDocuments | U1: RelatedDocumentName (EN) | V1: RelatedDocumentItemReference | X1: User Defined (not part of HE Data Dictionary / not validated by Validator)
B2: Erforderlich für Excel | D2: no | E2: no | F2: yes | G2: yes | H2: yes | I2: optional | J2: optional | K2: yes | L2: yes | M2: optional | N2: optional | O2: yes | Q2: yes | R2: yes | S2: yes | U2: optional | V2: optional
B3: Sprachen | D3: neutral | E3: EN | F3: neutral | G3: EN | H3: DE | I3: FR | J3: IT | K3: EN | L3: DE | M3: FR | N3: IT | O3: multilingual | Q3: EN | R3: neutral | S3: EN | U3: EN | V3: multilingual
B4: Referenziert / System generiert | D4: system-generated | E4: system-generated | Q4: referenced | R4: referenced | S4: referenced | U4: referenced | V4: referenced
B5: Dropdown Liste | Q5: Rules.Status
B6: Validierung | D6: not validated. Info: If available system-generated URI / user defined backend reference | E6: system-generated from Designation (EN) | F6: user defined | G6: user defined | H6: user defined | I6: user defined | J6: user defined | K6: must use JSON-style list syntax, e.g. ["A", "B", "C"] or ["A", 1.5, "C"] for alphanumeric/numeric values | L6: must use JSON-style list syntax, e.g. ["A", "B", "C"] or ["A", 1.5, "C"] for alphanumeric/numeric values | M6: must use JSON-style list syntax, e.g. ["A", "B", "C"] or ["A", 1.5, "C"] for alphanumeric/numeric values | N6: must use JSON-style list syntax, e.g. ["A", "B", "C"] or ["A", 1.5, "C"] for alphanumeric/numeric values | O6: user defined | Q6: must match Rules.Status | R6: date format 2026-06-18T15:30+02:00 | S6: user defined | U6: must match a DocumentName (EN) entry from Documents.DocumentName (EN) | V6: must match a DocumentItemReference entry from Documents.DocumentItemReference
F7: IFMA_V_31030000 | G7: PredefinedType | H7: Vordefinierter Typ | K7: ["GFA", "PARKING", "SPACE", "OCCUPANCY", "USERDEFINED"] | L7: ["GFA", "PARKING", "SPACE", "OCCUPANCY", "USERDEFINED"] | M7: ["GFA", "PARKING", "SPACE", "OCCUPANCY", "USERDEFINED"] | Q7: Preview | R7: 2026-07-09T10:30+02:00 | S7: IFMA
F8: IFMA_V_31030001 | G8: ObjectType | H8: Objekttyp | K8: ["SITE_AREA", "SURROUNDING_AREA", "ROOM", "EXTERNAL_ROOM", "USAGE_UNIT"] | L8: ["SITE_AREA", "SURROUNDING_AREA", "ROOM", "EXTERNAL_ROOM", "USAGE_UNIT"] | M8: ["SITE_AREA", "SURROUNDING_AREA", "ROOM", "EXTERNAL_ROOM", "USAGE_UNIT"] | Q8: Preview | R8: 2026-07-09T10:30+02:00 | S8: IFMA
F9: IFMA_V_31030004 | G9: Area type SIA 416 code | H9: Flächenart SIA 416 Code | K9: ["1", "1.1", "1.2", "1.2.1", "1.2.2", "2", "2.1", "2.1.1.1", "2.1.1.2", "2.1.3", "3", "3.1", "3.1.1", "3.1.2", "3.1.3", "5", "AIRSPACE"] | L9: ["1_GSF", "1.1_GGF", "1.2_UF", "1.2.1_BUF", "1.2.2_UUF", "2_GF", "2.1_NGF", "2.1.1.1_HNF", "2.1.1.2_NNF", "2.1.2_VF", "2.1.3_FF", "3_AGF", "3.1_ANGF", "3.1.1_ANF", "3.1.2_AVF", "3.1.3_AFF", "5_GV", "LUFTRAUM"] | M9: ["1_ST", "1.1_SB", "1.2_SA", "1.2.1_SAA", "1.2.2_SAN", "2_SP", "2.1.1.1_SUP", "2.1.1.2_SUS", "2.1.2_SD", "2.1.3_SI", "3_SEP", "3.1_SEN", "3.1.1_SEU", "3.1.2_SED", "3.1.3_SEI", "5_VB", "VIDE"] | Q9: Preview | R9: 2026-07-09T10:30+02:00 | S9: IFMA
F10: IFMA_V_31030007 | G10: Room designation SIA 380 label | H10: Raumbezeichnung SIA 380 Bezeichnung | K10: ["1", "2", "3", "4", "5", "6", "7", "8", "9", "10"] | L10: ["HNF1", "HNF2", "HNF3", "HNF4", "HNF5", "HNF6", "NNF7", "FF8", "VF9", "BUF10"] | M10: ["SUP1", "SUP2", "SUP3", "SUP4", "SUP5", "SUP6", "SUS7", "SI8", "SD9", "SAA10"] | Q10: Preview | R10: 2026-07-09T10:30+02:00 | S10: IFMA
F11: IFMA_V_31030008 | G11: Room usage SIA 2024 code | H11: Raumnutzung SIA 2024 Code | K11: ["1.01_HNF1", "1.02_HNF1", "2.01_HNF1", "2.02_HNF2", "3.01_HNF2", "3.02_HNF2", "3.03_HNF2", "3.04_HNF2", "4.01_HNF5", "4.02_HNF5", "4.03_HNF5", "4.04_HNF5", "4.05_HNF5", "5.01_HNF4", "5.02_HNF4", "5.03_HNF4", "6.01_HNF1", "6.02_HNF1", "6.03_HNF3", "6.04_HNF3", "7.01_HNF5", "7.02_HNF5", "7.03_HNF5", "8.01_HNF6", "8.02_HNF6", "8.03_HNF6", "9.01_HNF3", "9.02_HNF3", "9.03_HNF3", "10.01_HNF4", "11.01_HNF5", "11.02_HNF5", "11.03_HNF5", "12.01_VF9", "12.02_VF9", "12.03_VF9", "12.04_NNF7", "12.05_HNF1", "12.06_NNF7", "12.07_NNF7", "12.08_NNF7", "12.09_NNF7", "12.10_NNF7", "12.11_HNF4", "12.12_HNF2"] | L11: ["1.01_Wohnen Mehrfamilienhaus", "1.02_Wohnen Einfamilienhaus", "2.01_Hotelzimmer", "2.02_Empfang, Lobby", "3.01_Einzel-, Gruppenbüro", "3.02_Grossraumbüro", "3.03_Sitzungszimmer", "3.04_Schalterhalle, Empfang", "4.01_Schulzimmer", "4.02_Lehrerzimmer", "4.03_Bibliothek", "4.04_Hörsaal", "4.05_Schulfachraum", "5.01_Lebensmittelverkauf", "5.02_Fachgeschäft", "5.03_Verkauf Möbel, Bau, Garten", "6.01_Restaurant", "6.02_Selbstbedienungsrestaurant", "6.03_Küche zu Restaurant", "6.04_Küche zu Selbstbedienungsrestaurant", "7.01_Vorstellungsraum", "7.02_Mehrzweckhalle", "7.03_Ausstellungshalle", "8.01_Bettenzimmer", "8.02_Stationszimmer", "8.03_Behandlungsraum", "9.01_Produktion (grobe Arbeit)", "9.02_Produktion (feine Arbeit)", "9.03_Laborraum", "10.01_Lagerhalle", "11.01_Turnhalle", "11.02_Fitnessraum", "11.03_Schwimmhalle", "12.01_Verkehrsfläche", "12.02_Verkehrsfläche 24 h", "12.03_Treppenhaus", "12.04_Nebenraum", "12.05_Küche, Teeküche", "12.06_WC, Bad, Dusche", "12.07_WC", "12.08_Garderobe, Dusche", "12.09_Parkhaus", "12.10_Wasch- und Trockenraum", "12.11_Kühlraum", "12.12_Serverraum"] | M11: ["1.01_Habitation immeuble collectif", "1.02_Habitation maison individuelle", "2.01_Chambre d’hôtel", "2.02_Réception, zone d’accueil", "3.01_Bureau individuel, collectif", "3.02_Bureau paysagé", "3.03_Salle de réunion", "3.04_Guichets, zone clientèle", "4.01_Salle d’école", "4.02_Salle des maîtres", "4.03_Bibliothèque", "4.04_Auditoire", "4.05_Local d’enseignement spécialisé", "5.01_Magasin d’alimentation", "5.02_Magasin spécialisé", "5.03_Magasin de meubles, bricolage et jardin", "6.01_Restaurant", "6.02_Restaurant self-service", "6.03_Cuisine de restaurant", "6.04_Cuisine de restaurant self-service", "7.01_Salle de spectacle", "7.02_Salle polyvalente", "11.03_Piscine couverte", "12.01_Surface de dégagement", "12.02_Surface de dégagement 24 h", "12.03_Cage d’escalier", "12.04_Local secondaire", "12.05_Cuisine, kitchenette", "12.06_WC, salle de bain, douche", "12.07_WC", "12.08_Vestiaire, douche", "12.09_Garage collectif", "12.10_Buanderie, séchoir", "12.11_Chambre froide", "12.12_Salle de serveurs"] | Q11: Preview | R11: 2026-07-09T10:30+02:00 | S11: IFMA
F12: IFMA_V_31030010 | G12: Area type d0165 code | H12: Flächenart d0165 Code | K12: ["1.1", "1.2", "1.3", "1.4", "1.5", "1.6", "2.1", "2.2", "2.3", "2.4", "2.5", "2.6", "2.7", "2.8", "3.1", "3.2", "3.3", "3.4", "3.5", "3.6", "3.7", "3.8", "4.1", "4.2", "4.3", "4.4", "4.5", "4.6"] | L12: ["1.1_Wohnräume", "1.2_Gemeinschaftsräume", "1.3_Pausenräume", "1.4_Warteräume", "1.5_Speiseräume", "1.6_Hafträume", "2.1_Büroräume", "2.2_Grossraumbüros", "2.3_Besprechungsräume", "2.4_Konstruktionsräume", "2.5_Schalterräume", "2.6_Bedienungsräume", "2.7_Aufsichtsräume", "2.8_Bürotechnikräume", "3.1_Werkhallen", "3.2_Werkstätten", "3.3_Technologische Labors", "3.4_Physikalische, physikalisch-technische, elektrotechnische Labors", "3.5_Chemische, bakteriologische morphologische Labors", "3.6_Räume für Tierhaltung", "3.7_Räume für Pflanzenzucht", "3.8_Küchen", "4.1_Lagerräume", "4.2_Archive, Sammlungsräume", "4.3_Kühlräume", "4.4_Annahme- und Ausgaberäume", "4.5_Verkaufsräume", "4.6_Ausstellungsräume"] | Q12: Preview | R12: 2026-07-09T10:30+02:00 | S12: IFMA
F13: IFMA_V_31030021 | G13: Energy reference area | H13: Energiebezugsfläche | K13: ["true", "false"] | L13: ["true", "false"] | M13: ["true", "false"] | Q13: Preview | R13: 2026-07-09T10:30+02:00 | S13: IFMA
F14: IFMA_V_31030023 | G14: Window openable | H14: Fenster öffenbar | K14: ["true", "false"] | L14: ["true", "false"] | M14: ["true", "false"] | Q14: Preview | R14: 2026-07-09T10:30+02:00 | S14: IFMA
F15: IFMA_V_31030025 | G15: Solar shading | H15: Sonnenschutz | K15: ["true", "false"] | L15: ["true", "false"] | M15: ["true", "false"] | Q15: Preview | R15: 2026-07-09T10:30+02:00 | S15: IFMA
F16: IFMA_V_31030026 | G16: Humidified | H16: Befeuchtet | K16: ["true", "false"] | L16: ["true", "false"] | M16: ["true", "false"] | Q16: Preview | R16: 2026-07-09T10:30+02:00 | S16: IFMA
F17: IFMA_V_31030027 | G17: Dehumidified | H17: Entfeuchtet | K17: ["true", "false"] | L17: ["true", "false"] | M17: ["true", "false"] | Q17: Preview | R17: 2026-07-09T10:30+02:00 | S17: IFMA
F18: IFMA_V_31030028 | G18: Rentable | H18: Vermietbarkeit | K18: ["true", "false"] | L18: ["true", "false"] | M18: ["true", "false"] | Q18: Preview | R18: 2026-07-09T10:30+02:00 | S18: IFMA
F19: IFMA_V_31030029 | G19: External space | H19: Aussenraum | K19: ["true", "false"] | L19: ["true", "false"] | M19: ["true", "false"] | Q19: Preview | R19: 2026-07-09T10:30+02:00 | S19: IFMA
F20: IFMA_V_31030037 | G20: Natural ventilation | H20: Natürliche Belüftung | K20: ["true", "false"] | L20: ["true", "false"] | M20: ["true", "false"] | Q20: Preview | R20: 2026-07-09T10:30+02:00 | S20: IFMA
F21: IFMA_V_31030039 | G21: Mechanical ventilation | H21: Mechanische Belüftung | K21: ["true", "false"] | L21: ["true", "false"] | M21: ["true", "false"] | Q21: Preview | R21: 2026-07-09T10:30+02:00 | S21: IFMA
F22: IFMA_V_31030041 | G22: Air conditioning | H22: Klimatisiert | K22: ["true", "false"] | L22: ["true", "false"] | M22: ["true", "false"] | Q22: Preview | R22: 2026-07-09T10:30+02:00 | S22: IFMA
F23: IFMA_V_31030044 | G23: Fire exit | H23: Fluchtweg | K23: ["true", "false"] | L23: ["true", "false"] | M23: ["true", "false"] | Q23: Preview | R23: 2026-07-09T10:30+02:00 | S23: IFMA

Sheet Documents
A1: Filter | B1: Hinweise zur Handhabung | C1: Documents | D1: GUID/URI | E1: Document-ID | F1: Document-Code | G1: DocumentName (EN) | H1: Bezeichnung (DE) | I1: Désignation (FR) | J1: Designazione (IT) | K1: DocumentItemReference | L1: DocumentItem (EN) | M1: DokumentElement (DE) | N1: DocumentÉlément (FR) | O1: DocumentoElemento (IT) | P1: Security level/Sicherheitsstufe/Niveau de sécurité/Livello di sicurezza | Q1: Accessibility/Zugänglichkeit/Accessibilité/Accessibilità | R1: Revision | S1: DocumentOwner | T1: Governance | U1: Status | V1: Version date | W1: Provenance (PROV) | Y1: User Defined (not part of HE Data Dictionary / not validated by Validator)
B2: Erforderlich für Excel | D2: no | E2: no | F2: optional | G2: optional | H2: optional | I2: optional | J2: optional | K2: optional | P2: optional | Q2: optional | R2: optional | S2: optional | U2: optional | V2: optional | W2: optional
B3: Sprachen | D3: multilingual | E3: multilingual | F3: multilingual | G3: EN | H3: DE | I3: FR | J3: IT | K3: multilingual | L3: EN | M3: DE | N3: FR | O3: IT | P3: multilingual | Q3: multilingual | R3: multilingual | S3: multilingual | U3: EN | V3: neutral | W3: EN
B4: Referenziert / System generiert | E4: system-generated | G4: referenced | R4: referenced | S4: referenced | U4: referenced | V4: referenced | W4: referenced
B5: Dropdown Liste | P5: Rules.ISG - Informationssicherheitsgesetz | Q5: Rules.FAIR Prinzipien | U5: Rules.Status
B6: Validierung | D6: not validated. Info: If available system-generated URI / user defined backend reference | E6: system-generated from DocumentName (EN) | F6: user defined | G6: user defined | H6: user defined | I6: user defined | J6: user defined | K6: user defined | L6: user defined | M6: user defined | N6: user defined | O6: user defined | P6: must match Rules.ISG - Informationssicherheitsgesetz | Q6: must match Rules.FAIR Prinzipien | R6: user defined | S6: user defined | U6: must match Rules.Status | V6: date format 2026-06-18T15:30+02:00 | W6: user defined
F30: SIA_416_2003 | G30: SIA 416 - Areas and volumes of buildings | H30: SIA 416:2003 - Flächen und Volumen von Gebäuden | P30: nicht klassifiziert | Q30: Zugänglich kostenpflichtig | R30: 2003 | S30: SIA | U30: Active | W30: SIA
F31: SIA_380_2015 | G31: SIA 380 - Basic principles for energy calculations for buildings | H31: SIA 380:2015 - Grundlagen für energetische Berechnungen von Gebäuden | P31: nicht klassifiziert | Q31: Zugänglich kostenpflichtig | R31: 2015 | S31: SIA | U31: Active | W31: SIA
F32: SIA_D_0165_2000 | G32: SIA D 1065 - Key performance indicators in property management | H32: SIA D 0165 - Kennzahlen im Immobilienmanagement | P32: nicht klassifiziert | Q32: Zugänglich kostenpflichtig | R32: 2000 | S32: SIA | U32: Active | W32: SIA
F33: SIA_2024_2021 | G33: SIA 2024 - Space utilisation for energy data and building technology | H33: SIA 2024 - Raumnutzungsdaten für die Energie- und Gebäudetechnik | P33: nicht klassifiziert | Q33: Zugänglich kostenpflichtig | R33: 2021 | S33: SIA | U33: Active | W33: SIA

Sheet GroupOfProperties
A1: Filter | B1: Hinweise zur Handhabung | C1: Group of Properties | D1: GUID/URI | E1: GoP-ID | F1: GoP-Code | G1: Designation (EN) | H1: Description (EN) | I1: Beschreibung (DE) | J1: Description (FR) | K1: Descrizione (IT) | L1: Governance | M1: Status | N1: Version date | O1: Provenance (PROV) | P1: RelatedDocuments | Q1: RelatedDocumentName (EN) | R1: RelatedDocumentItemReference | T1: User Defined (not part of HE Data Dictionary / not validated by Validator)
B2: Erforderlich für Excel | D2: no | E2: no | F2: no | G2: yes | H2: yes | I2: yes | J2: optional | K2: optional | M2: yes | N2: yes | O2: yes | Q2: optional | R2: optional
B3: Sprachen | D3: neutral | E3: EN | F3: neutral | G3: EN | H3: EN | I3: DE | J3: FR | K3: IT | M3: multilingual | N3: multilingual | O3: multilingual | Q3: EN | R3: multilingual
B4: Referenziert / System generiert | D4: referenced | E4: system-generated | M4: referenced | N4: referenced | O4: referenced | Q4: referenced | R4: referenced
B5: Dropdown Liste | M5: Rules.Status
B6: Validierung | D6: not validated. Info: If available system-generated URI / user defined backend reference | E6: system-generated from Designation (EN) | F6: user defined | G6: must start with <OrganizationCode>_; forbidden prefixes: Pset_, IFC_, CH_ | H6: user defined | I6: user defined | J6: user defined | K6: user defined | M6: must match Rules.Status | N6: date format 2026-06-18T15:30+02:00 | O6: user defined | Q6: must match a DocumentName (EN) entry from Documents.DocumentName (EN) | R6: must match a DocumentItemReference entry from Documents.DocumentItemReference
G7: IFMA_AreaMgmt | H7: Includes all space- and area-related parameters for Project Development and Asset and Facility Management, in accordance with the relevant SIA standards. | I7: Enthält alle raum- und flächenbezogenen Merkmale für Projektentwicklung, -planung sowie Asset und Facility Management, in Übereinstimmung mit den relevanten SIA Standards. | M7: Preview | N7: 2026-07-09T10:30+02:00 | O7: IFMA

Sheet Data_Template
D1: GoP | F1: Properties | BC1: DocumentName | BL1: DocumentItemReference
D2: GoP - Designation | F2: Property - Designation | G2: {=TRANSPOSE(Properties!K7:K53)} -> Name | H2: LongName | I2: SIA_416_2003 | J2: SIA_380_2015 | K2: SIA_2024_2021 | L2: SIA_d0165_2000 | M2: RoomUsage | N2: RoomType | O2: UnitType | P2: UnitID | Q2: CAFM_ID | R2: RoomSignalLabel | S2: CleaningGroup | T2: AreaLoad | U2: PointLoad | V2: EnergyReferenceArea | W2: WindowsCleaningArea | X2: WindowsOpenable | Y2: Occupant | Z2: Shading | AA2: IsHumidified | AB2: IsDehumidified | AC2: IsRentable | AD2: IsExternal | AE2: OccupancyType | AF2: MinimumHeadroom | AG2: OccupancyNumberPeak | AH2: OccupancyNumber | AI2: FloorCovering | AJ2: WallCovering | AK2: CeilingCovering | AL2: NaturalVentilation | AM2: NaturalVentilationRate | AN2: MechanicalVentilation | AO2: MechanicalVentilationRate | AP2: AirConditioning | AQ2: TemperatureSetPoint | AR2: HumiditySetPoint | AS2: FireExit | AT2: GrossFloorArea | AU2: GrossVolume | AV2: NetFloorArea | AW2: NetVolume | AX2: NetWallArea | AY2: Height | AZ2: AboveGround | BA2: CostZone | BC2: RelatedDocumentName (EN) | BL2: RelatedDocumentItemReference
F3: Property-Code | G3: {=TRANSPOSE(Properties!F7:F53)} -> IFMA_P_31020002 | H3: IFMA_P_31020003 | I3: IFMA_P_31020004 | J3: IFMA_P_31020007 | K3: IFMA_P_31020008 | L3: IFMA_P_31020010 | M3: IFMA_P_31020012 | N3: IFMA_P_31020013 | O3: IFMA_P_31020014 | P3: IFMA_P_31020015 | Q3: IFMA_P_31020016 | R3: IFMA_P_31020017 | S3: IFMA_P_31020018 | T3: IFMA_P_31020019 | U3: IFMA_P_31020020 | V3: IFMA_P_31020021 | W3: IFMA_P_31020022 | X3: IFMA_P_31020023 | Y3: IFMA_P_31020024 | Z3: IFMA_P_31020025 | AA3: IFMA_P_31020026 | AB3: IFMA_P_31020027 | AC3: IFMA_P_31020028 | AD3: IFMA_P_31020029 | AE3: IFMA_P_31020030 | AF3: IFMA_P_31020031 | AG3: IFMA_P_31020032 | AH3: IFMA_P_31020033 | AI3: IFMA_P_31020034 | AJ3: IFMA_P_31020035 | AK3: IFMA_P_31020036 | AL3: IFMA_P_31020037 | AM3: IFMA_P_31020038 | AN3: IFMA_P_31020039 | AO3: IFMA_P_31020040 | AP3: IFMA_P_31020041 | AQ3: IFMA_P_31020042 | AR3: IFMA_P_31020043 | AS3: IFMA_P_31020044 | AT3: IFMA_P_31020045 | AU3: IFMA_P_31020046 | AV3: IFMA_P_31020047 | AW3: IFMA_P_31020048 | AX3: IFMA_P_31020049 | AY3: IFMA_P_31020050 | AZ3: IFMA_P_31020051 | BA3: IFMA_P_31020052
A4: Classes
A5: Class-Coode | B5: Class - Designation/Bezeichnung/Désignation/Designazione
A6: =Classes!J7 -> IFMA_C_31010000 | B6: =Classes!P7 -> Geschoss | D6: IFMA_AreaMgmt | G6: x | H6: x | Q6: x
A7: =Classes!J8 -> IFMA_C_31010001 | B7: =Classes!P8 -> Grundstückfläche | D7: IFMA_AreaMgmt | I7: ["1_GSF", "1_ST", "1_SF"] | AT7: x
