Workbook
Name Affectation_de_classe: #REF!
Name Affectation_de_classe: Rules!$C$2:$C$50
Name Assegnazione_della_classe: #REF!
Name Assegnazione_della_classe: Rules!$D$2:$D$50
Name Assegnazione_della_proprieta: #REF!
Name Assegnazione_della_proprieta: Rules!$H$2:$H$50
Name Attribution_de_propriete: #REF!
Name Attribution_de_propriete: Rules!$G$2:$G$50
Name DataType: #REF!
Name DataType: Rules!$I$2:$I$50
Name FAIR_Prinzipien: #REF!
Name FAIR_Prinzipien: Rules!$M$2:$M$50
Name IFC_Data_Type: Rules!$J$2:$J$111
Name IFC_Data_Type: Rules!$J$2:$J$111
Name ISG___Informationssicherheitsgesetz: #REF!
Name ISG___Informationssicherheitsgesetz: Rules!$L$2:$L$50
Name Klassen_Zuordnung: #REF!
Name Klassen_Zuordnung: Rules!$B$2:$B$50
Name Klassifikation: #REF!
Name Klassifikation: Rules!$B$2:$B$50
Name LifecycleStatus: #REF!
Name LifecycleStatus: Rules!$N$2:$N$50
Name Markmals_Klassifikation: #REF!
Name Markmals_Klassifikation: Rules!$F$2:$F$50
Name Merkmals_Zuordnung: #REF!
Name Merkmals_Zuordnung: Rules!$F$2:$F$50
Name Objekt_Einordnung: #REF!
Name Objekt_Einordnung: Rules!$A$2:$A$50
Name Property_Classification: #REF!
Name Property_Classification: Rules!$E$2:$E$50
Name Status: #REF!
Name Status: Rules!$K$2:$K$50

Sheet Impressum
B1: Strukturvorlage Data Dictionaries
B3: Dokumenteninformationen
C4: Status | D4: Final
C5: Version | D5: v1.1.0
C6: Herausgeber | D6: Bauen digital Schweiz / buildingSMART Switzerland
D7: info@bauen-digital.ch
B9: Trägerschaft | D9: Bauen digital Schweiz / buildingSMART Switzerland
D10: IFMA Schweiz
D11: Infra Suisse
D12: Infrastruktur Hospital Schweiz (IHS)
D13: Koordinationskonferenz der Bau- und Liegenschaftsorgane der öffentlichen Bauherren (KBOB)
D14: Schweizerische Zentralstelle für Baurationalisierung (CRB)
D15: Schweizerischer Baumeisterverband (SBV)
D16: Schweizerischer Ingenieur- und Architektenverein (SIA)
B17: Mit freundlicher Unterstützung von
C18: B+S AG | D18: Marti Tunnel AG
C19: Basler & Hofmann AG | D19: Mensch und Maschine Schweiz AG
C20: Bauenschweiz | D20: open BIM Verband
C21: Baumschlager Eberle Zürich AG | D21: Penzel Valier AG
C22: Buildup AG | D22: POM+
C23: CADMEC AG | D23: Roundtable Gebäudetechnik
C24: Fachgruppe für Untertagbau (FGU) | D24: Schindler Aufzüge AG
C25: Fachverband für Gebäudeautomation (MeGA) | D25: Schweizerische Bundesbahnen (SBB AG)
C26: FHNW | D26: Schweizerische Eidgenossenschaft – Bundesamt für Rüstung (armasuisse)
C27: Frutiger AG | D27: Schweizerische Eidgenossenschaft – Bundesamt für Strassen (ASTRA)
C28: HKG | D28: Siemens AG
C29: IBG Engineering AG | D29: Stadt Luzern
... C36: Losinger Marazzi AG | D36: Walo AG
B38: Abgrenzung | D38: Fokus auf Austauschformat IFC 4.3.2.0 (IFC4X3_ADD2)
D39: Andere Formate (z. B. CityGML, gbXML, LandXML) sind kein Bestandteil
D40: Strukturvorlage ist eine methodische Grundlage, kein vollständiges Data Dictionaries
D41: Vollständige Data Dictionariess müssen in Datenbanken realsiert werden
D42: Die Handlungsempfehlung ist keine Implementierungsrichtlinie für Softwareentwicklung
D43: Die Strukturvorlage ist ein Best Practice Beispiel und kann jederzeit an neue Anforderungen angepasst werden. Es wird davon abgeraten, auf der Basis der Strukturvorlage Applikationen oder Tools zu entwickeln.
D44: Keine spezifischen Referenzen/Anbindungen an externe Data Dictionaries
B46: Copyright | D46: Dieses Dokument ist als Creative Commons Attribution-NonCommercial-ShareAlike 4.0 International Lizenz als Namensnennung – nichtkommerziell Weitergabe – unter gleichen Bedingungen lizenziert
D47: Weitere Informationen unter:
D48: Creative Commons
B50: Einschränkung und Handhabung | D50: Dieses Dokument erhebt keinen Anspruch auf Vollständigkeit. Es ist auch keine aus rechtlicher Sicht allgemeingültige Empfehlung oder Leitlinie, sondern soll alle Beteiligten in der Bau- und Immobilienbranche dabei unterstützen, die Abhängigkeit der einzelnen notwendigen Steuerungsinstrumente untereinander zu verstehen und richtig zuzuordnen.

Sheet Anleitung
A1: Anleitung Strukturvorlage Data Dictionaries
B3: Inhaltsverzeichnis
B5: 1 | C5: Handhabung
B6: 2 | C6: Governance
B7: 3 | C7: Header (Kopfzeile)
B8: 4 | C8: Classes (Objekte)
B9: 5 | C9: Properties (Merkmale)
B10: 6 | C10: Values (Werte)
B11: 7 | C11: Documents (Dokument) | G11: Data Template (Datenvorlage)
B12: 8 | C12: GroupOfProperties (Merkmalsgruppen)
B14: Hinweise zur Handhabung
B16: Farbcode zum ausfüllen der Strukturvorlage
B17: D | C17: Kein Farbcode: | H17: Diese Spalten müssen ausgefüllt werden.
H18: Bei sprachabhängigen Texten muss mind. EN und eine Landessprache ausgefüllt werden
C19: Grüner Farbcode: | H19: Dropdownliste: Automatische Übersetzung von EN in DE, FR, IT. Basiert auf der Übersetzung im Reiter "Rules"
C20: Grauer Farbcode: | H20: Zusätzliche Sprachen; falls erforderlich
C21: Blauer Farbcode: | H21: Diese Spalte ist system-generated, d.h. ist im Excl nicht auszufüllen, sondern wird vom Zielsystem (Datenbank) generiert
C22: Roter Farbcode: | H22: Wird automatisch durch das Validierungskript ausgefüllt
C24: A | D24: B | E24: C | F24: D | G24: E
B25: Hinweise zur Handhabung | C25: Erforderlich für Excel | D25: Sprachen | E25: Referenziert / System generiert | F25: Rules | G25: Erforderlich für Validierung
B26: A | C26: Erforderlich für Objektkatalog / Merkmalskatalog / Wertekatalog
C27: Definiert die Mindestanforderungen an einen Katalog. Unterscheidung zwischen yes = erforderlich / optional = bei Bedarf ergänzen / no = nicht notwendig
B28: B | C28: Sprachen
C29: Angabe zur Sprache: mehrsprachig = muss in der für den Katalog führenden Sprache enthalten sein
C30: EN, DE, FR, IT = gibt Sprache zwingend vor / neutral = nicht von Sprache abhängig
B31: C | C31: Regelt die Eingabe der Spalten
C32: Darf nicht vom Ersteller manuell ausgefüllt werden, sondern wird auf eine Quelle referenziert, resp. von eine Datenbank automatisch generiert
C33: referenced = Referenz auf anderen Katalog / system-generated = vom Zielsystem generiert
B34: D | C34: Vordefinierte Regeln
C35: Verweist auf die Dropdownliste in diesem Template
B36: E | C36: Erforderlich für eine automatische Validierung zur technischen Qualitätssicherung
C37: Gibt die Valdierungsregeln an, nach welchen die Spalteninhalte geprüft werden
A39: 2 | B39: Governance
B41: Vorgabe einer minimalen Governance für die verschiedenen Kataloge (gültig für alle Reiter)
B42: Optional können aller Regeln der SN EN ISO 23386 ergänzt werden
B44: A | C44: B | D44: C | E44: D | F44: E | G44: F | H44: G
B45: Governance | C45: Status | D45: Versionsdatum | E45: Herkunft (PROV) | F45: Regeln zur Festlegung von Merkmalen | G45: Regeln zur Festlegung von Merkmalsgruppen | H45: Management-Regeln für die Erstellung und Pflege
B46: B | C46: Vorgeschriebener Status des Merkmals während seines Lebenszyklus gemäss Liste (Enumeration)
B47: C | C47: Datum der Version. Format nach ISO 8601 = YYYY-MM-DDThh:mm:ssTDZ (T = festes Trennzeichen zwischen Datum und Uhrzeit / TDZ = Zeitzonenbezeichnung. Z = UTC, Abweichung zu UTC angeben)
C48: Beispiel: CET Zeit: 15:30 = UTC+2h > Korrekte Angabe: 2026-06-18T15:30+02:00
...

Sheet Header
A1: Data Dictionary — Core Metadata
A2: Field | B2: Value | C2: Requirement | D2: Notes / Maps to
A3: IDENTIFICATION
A4: OrganizationCode | C4: user defined name (small or capital letters), max 7 chars | D4: Short org code — lowercase, max 7 chars, appears in all derived IRIs
A5: DictionaryCode | C5: SYSTEM-GENERATED | D5: Generated from DictionaryName (EN)
A6: DictionaryName (EN) | C6: REQUIRED | D6: Required authoring title in English — source for DictionaryCode generation
A7: DictionaryName (DE) | C7: OPTIONAL | D7: Core authoring title in German — minimal DCAT
A8: DictionaryName (FR) | C8: OPTIONAL | D8: Optional multilingual title support
A9: DictionaryName (IT) | C9: DictionaryName (IT) | D9: Optional multilingual title support
A10: Description (EN) | C10: REQUIRED WHEN USED | D10: dct:description@en
A11: Beschreibung (DE) | C11: OPTIONAL | D11: dct:description@de
A12: Description (FR) | C12: OPTIONAL | D12: dct:description@fr
A13: Descrizione (IT) | C13: OPTIONAL | D13: dct:description@it
A14: DictionaryVersion | C14: REQUIRED | D14: Semantic versioning: MAJOR.MINOR.PATCH
A15: DictionaryUri | C15: SYSTEM-GENERATED | D15: Derived from OrganizationCode and DictionaryCode; canonical base pattern https://example.com/<OrganizationCode>/<DictionaryCode>
C16: Guide | D16: Private organisations may keep only this tab and delete Dictionary_public.
A17: GOVERNANCE
A18: LifecycleStatus | B18: Candidate | C18: REQUIRED | D18: Governance state used to derive i14y registration status
A20: LEGEND
A21: REQUIRED: | B21: Must be filled before validation/export
A22: OPTIONAL: | B22: Fill if available
A24: LICENSING
A25: License | C25: OPTIONAL | D25: Human-readable license name — dct:license
A26: LicenseUrl | C26: OPTIONAL | D26: Resolvable license URI/URL — dct:license
A28: TECHNICAL ENDPOINTS
A29: SPARQL_Endpoint | C29: OPTIONAL | D29: SPARQL endpoint URL for published graph access
A30: TTL_Download_URL | C30: OPTIONAL | D30: Download URL for Turtle/RDF serialization — dcat:distribution
A31: JSON_Download_URL | C31: OPTIONAL | D31: Download URL for JSON/JSON-LD serialization — dcat:distribution
A32: MoreInfoUrl | C32: OPTIONAL | D32: Landing page / homepage

Sheet Classes
A1: Filter | B1: Hinweise zur Handhabung | C1: Structural categorisation | D1: Domain/Domäne/Domaine/Dominio | E1: System/System/Système/Sistema | F1: Category/Kategorie/Catégorie/Categoria | G1: Classes | H1: GUID/URI | I1: Class-ID | J1: Class-Code | K1: Class-Assignment | L1: Klassen-Zuordnung (DE) | M1: Affectation de classe (FR) | N1: Assegnazione della classe (IT) | O1: Designation (EN) | P1: Bezeichnung (DE) | Q1: Désignation (FR) | R1: Designazione (IT) | S1: Description (EN) | T1: Beschreibung (DE) | U1: Description (FR) | V1: Descrizione (IT) | W1: IFC 4.3.2.0 (IFC4X3_ADD2) | X1: IFC_URI | Y1: IfcObject Entity | Z1: IfcTypeObject Entity | AA1: PredefinedType | AB1: ObjectType | AC1: Governance | AD1: Status | AE1: Version date | AF1: Provenance (PROV) | AG1: RelatedDocuments | AH1: RelatedDocumentName (EN) | AI1: RelatedDocumentItemReference | AK1: User Defined (not part of HE Data Dictionary / not validated by Validator)
B2: Erforderlich für Excel | D2: optional | E2: optional | F2: optional | H2: no | I2: no | J2: yes | K2: yes | O2: yes | P2: yes | Q2: optional | R2: optional | S2: ja | T2: ja | U2: optional | V2: optional | X2: yes | Y2: yes | Z2: yes | AA2: yes | AB2: yes | AD2: yes | AE2: yes | AF2: yes | AH2: optional | AI2: optional
B3: Sprachen | D3: multilingual | E3: multilingual | F3: multilingual | H3: neutral | I3: neutral | J3: neutral | K3: multilingual | L3: DE | M3: FR | N3: IT | O3: EN | P3: DE | Q3: FR | R3: IT | S3: EN | T3: DE | U3: FR | V3: IT | X3: multilingual | Y3: multilingual | Z3: multilingual | AA3: multilingual | AB3: multilingual | AD3: EN | AE3: neutral | AF3: EN | AH3: EN | AI3: multilingual
B4: Referenziert / System generiert | H4: referenced | I4: system-generated | L4: system-generated | M4: system-generated | N4: system-generated | X4: referenced | Y4: referenced | Z4: referenced | AA4: referenced | AB4: referenced | AD4: referenced | AE4: referenced | AF4: referenced | AH4: referenced | AI4: referenced
B5: Dropdown Liste | K5: Rules.Class-Assignment | L5: Rules.Klassen-Zuordnung | M5: Rules.Affectation de classe | N5: Rules.Assegnazione della classe | AD5: Rules.Status
B6: Validierung | D6: user defined | E6: user defined | F6: user defined | H6: not validated. Info: If available system-generated URI / user defined backend reference | I6: system-generated from Designation (EN) | J6: user defined | K6: must match Rules.Class-Assignment | L6: system-generated from Class-Assignment via Rules | M6: system-generated from Class-Assignment via Rules | N6: system-generated from Class-Assignment via Rules | O6: user defined | P6: user defined | Q6: user defined | R6: user defined | S6: user defined | T6: user defined | U6: user defined | V6: user defined | X6: validated against identifiers from https://search.bsdd.buildingsmart.org/uri/buildingsmart/ifc/4.3 | Y6: validated against IFC 4.3 entity identifiers | Z6: not validated; optional information whether the mapping also applies to an IFC TypeObject level | AA6: validated against IFC predefined types when applicable | AB6: validated against IFC 4.3 entity identifiers | AD6: must match Rules.Status | AE6: date format 2026-06-18T15:30+02:00 | AF6: user defined | AH6: must match a DocumentName (EN) entry from Documents.DocumentName (EN) | AI6: must match a DocumentItemReference entry from Documents.DocumentItemReference
M46: =IFERROR(INDEX(Rules!$C:$C,MATCH(K46,Rules!$A:$A,0)),"") | N46: =IFERROR(INDEX(Rules!$D:$D,MATCH(K46,Rules!$A:$A,0)),"")
L47: =IFERROR(INDEX(Rules!$B:$B,MATCH(K47,Rules!$A:$A,0)),"") | M47: =IFERROR(INDEX(Rules!$C:$C,MATCH(K47,Rules!$A:$A,0)),"") | N47: =IFERROR(INDEX(Rules!$D:$D,MATCH(K47,Rules!$A:$A,0)),"")
L48: =IFERROR(INDEX(Rules!$B:$B,MATCH(K48,Rules!$A:$A,0)),"") | M48: =IFERROR(INDEX(Rules!$C:$C,MATCH(K48,Rules!$A:$A,0)),"") | N48: =IFERROR(INDEX(Rules!$D:$D,MATCH(K48,Rules!$A:$A,0)),"")
L49: =IFERROR(INDEX(Rules!$B:$B,MATCH(K49,Rules!$A:$A,0)),"") | M49: =IFERROR(INDEX(Rules!$C:$C,MATCH(K49,Rules!$A:$A,0)),"") | N49: =IFERROR(INDEX(Rules!$D:$D,MATCH(K49,Rules!$A:$A,0)),"")

Sheet Properties
A1: Filter | B1: Hinweise zur Handhabung | C1: Properties | D1: GUID/URI | E1: Property-ID | F1: Property-Code | G1: Property-Assignment | H1: Merkmals-Zuordnung (DE) | I1: Attribution de propriété (FR) | J1: Assegnazione della proprietà (IT) | K1: Designation (EN) | L1: Bezeichnung (DE) | M1: Désignation (FR) | N1: Designazione (IT) | O1: Description (EN) | P1: Beschreibung (DE) | Q1: Description (FR) | R1: Descrizione (IT) | S1: DataType (Base Type) | T1: DataType (IFC) | U1: EnumerationDesignation (EN) | V1: IFC 4.3.2.0 (IFC4X3_ADD2) | W1: IFC_URI | X1: IfcPropertySet (Pset) IfcQuantitySet (Qto) | Y1: Units/Einheit/Unité/Unità | Z1: Governance | AA1: Status | AB1: Version date | AC1: Provenance (PROV) | AD1: RelatedDocuments | AE1: RelatedDocumentName (EN) | AF1: RelatedDocumentItemReference | AH1: User Defined (not part of HE Data Dictionary / not validated by Validator)
B2: Erforderlich für Excel | D2: no | E2: no | F2: yes | G2: yes | K2: yes | L2: yes | M2: optional | N2: optional | O2: yes | P2: yes | Q2: optional | R2: optional | S2: yes | T2: yes | U2: yes | W2: yes | X2: yes | Y2: yes | AA2: yes | AB2: yes | AC2: yes | AE2: optional | AF2: optional
B3: Sprachen | D3: neutral | E3: neutral | F3: neutral | G3: neutral | H3: DE | I3: FR | J3: IT | K3: EN | L3: DE | M3: FR | N3: IT | O3: EN | P3: DE | Q3: FR | R3: IT | S3: neutral | T3: neutral | U3: EN | W3: neutral | X3: EN | Y3: neutral | AA3: EN | AB3: neutral | AC3: EN | AE3: EN | AF3: multilingual
B4: Referenziert / System generiert | D4: referenced | E4: system-generated | H4: system-generated | I4: system-generated | J4: system-generated | S4: referenced | T4: referenced | U4: referenced | W4: referenced | X4: referenced | AA4: referenced | AB4: referenced | AC4: referenced | AE4: referenced | AF4: referenced
B5: Dropdown Liste | G5: Rules.Property-Assignment | H5: Rules.Merkmals-Zuordnung | I5: Rules.Attribution de propriété | J5: Rules.Assegnazione della proprietà | S5: Rules.DataType | T5: Rules.IFC Data Type | AA5: Rules.Status
B6: Validierung | D6: not validated. Info: If available system-generated URI / user defined backend reference | E6: system-generated from Designation (EN) | F6: user defined | G6: must match Rules.Property-Assignment | H6: system-generated from Property-Assignment via Rules | I6: system-generated from Property-Assignment via Rules | J6: system-generated from Property-Assignment via Rules | K6: user defined | L6: user defined | M6: user defined | N6: user defined | O6: user defined | P6: user defined | Q6: user defined | R6: user defined | S6: must match Rules.DataType | T6: must match Rules.IFC Data Type | U6: must match a Designation (EN) entry from Values.Designation (EN) | W6: validated against identifiers from https://search.bsdd.buildingsmart.org/uri/buildingsmart/ifc/4.3 | X6: validated against IFC 4.3 property/quantity set identifiers when IFC_URI is present | Y6: user defined | AA6: must match Rules.Status | AB6: date format 2026-06-18T15:30+02:00 | AC6: user defined | AE6: must match a DocumentName (EN) entry from Documents.DocumentName (EN) | AF6: must match a DocumentItemReference entry from Documents.DocumentItemReference

Sheet Values
A1: Filter | B1: Hinweise zur Handhabung | C1: Enumerations | D1: GUID/URI | E1: Enumeration-ID | F1: Enumeration-Code | G1: Designation (EN) | H1: Bezeichnung (DE) | I1: Désignation (FR) | J1: Designazione (IT) | K1: Enumeration (EN) | L1: Werteliste (DE) | M1: Liste de valeurs (FR) | N1: Lista valori (IT) | O1: Units/Einheit/Unité/Unità | P1: Governance | Q1: Status | R1: Version date | S1: Provenance (PROV) | T1: RelatedDocuments | U1: RelatedDocumentName (EN) | V1: RelatedDocumentItemReference | X1: User Defined (not part of HE Data Dictionary / not validated by Validator)
B2: Erforderlich für Excel | D2: no | E2: no | F2: yes | G2: yes | H2: yes | I2: optional | J2: optional | K2: yes | L2: yes | M2: optional | N2: optional | O2: yes | Q2: yes | R2: yes | S2: yes | U2: optional | V2: optional
B3: Sprachen | D3: neutral | E3: EN | F3: neutral | G3: EN | H3: DE | I3: FR | J3: IT | K3: EN | L3: DE | M3: FR | N3: IT | O3: multilingual | Q3: EN | R3: neutral | S3: EN | U3: EN | V3: multilingual
B4: Referenziert / System generiert | D4: system-generated | E4: system-generated | Q4: referenced | R4: referenced | S4: referenced | U4: referenced | V4: referenced
B5: Dropdown Liste | Q5: Rules.Status
B6: Validierung | D6: not validated. Info: If available system-generated URI / user defined backend reference | E6: system-generated from Designation (EN) | F6: user defined | G6: user defined; must be unique and is referenced by Properties.EnumerationDesignation (EN) | H6: user defined | I6: user defined | J6: user defined | K6: must use JSON-style list syntax, e.g. ["A", "B", "C"] or ["A", 1.5, "C"] for alphanumeric/numeric values | L6: must use JSON-style list syntax, e.g. ["A", "B", "C"] or ["A", 1.5, "C"] for alphanumeric/numeric values | M6: must use JSON-style list syntax, e.g. ["A", "B", "C"] or ["A", 1.5, "C"] for alphanumeric/numeric values | N6: must use JSON-style list syntax, e.g. ["A", "B", "C"] or ["A", 1.5, "C"] for alphanumeric/numeric values | O6: user defined | Q6: must match Rules.Status | R6: date format 2026-06-18T15:30+02:00 | S6: user defined | U6: must match a DocumentName (EN) entry from Documents.DocumentName (EN) | V6: must match a DocumentItemReference entry from Documents.DocumentItemReference

Sheet Documents
A1: Filter | B1: Hinweise zur Handhabung | C1: Documents | D1: GUID/URI | E1: Document-ID | F1: Document-Code | G1: DocumentName (EN) | H1: Bezeichnung (DE) | I1: Désignation (FR) | J1: Designazione (IT) | K1: DocumentItemReference | L1: DocumentItem (EN) | M1: DokumentElement (DE) | N1: DocumentÉlément (FR) | O1: DocumentoElemento (IT) | P1: Security level/Sicherheitsstufe/Niveau de sécurité/Livello di sicurezza | Q1: Accessibility/Zugänglichkeit/Accessibilité/Accessibilità | R1: Revision | S1: DocumentOwner | T1: Governance | U1: Status | V1: Version date | W1: Provenance (PROV) | Y1: User Defined (not part of HE Data Dictionary / not validated by Validator)
B2: Erforderlich für Excel | D2: no | E2: no | F2: optional | G2: optional | H2: optional | I2: optional | J2: optional | K2: optional | P2: optional | Q2: optional | R2: optional | S2: optional | U2: optional | V2: optional | W2: optional
B3: Sprachen | D3: multilingual | E3: multilingual | F3: multilingual | G3: EN | H3: DE | I3: FR | J3: IT | K3: multilingual | L3: EN | M3: DE | N3: FR | O3: IT | P3: multilingual | Q3: multilingual | R3: multilingual | S3: multilingual | U3: EN | V3: neutral | W3: EN
B4: Referenziert / System generiert | E4: system-generated | G4: referenced | R4: referenced | S4: referenced | U4: referenced | V4: referenced | W4: referenced
B5: Dropdown Liste | P5: Rules.ISG - Informationssicherheitsgesetz | Q5: Rules.FAIR Prinzipien | U5: Rules.Status
B6: Validierung | D6: not validated. Info: If available system-generated URI / user defined backend reference | E6: system-generated from DocumentName (EN) | F6: user defined | G6: user defined | H6: user defined | I6: user defined | J6: user defined | K6: user defined | L6: user defined | M6: user defined | N6: user defined | O6: user defined | P6: must match Rules.ISG - Informationssicherheitsgesetz | Q6: must match Rules.FAIR Prinzipien | R6: user defined | S6: user defined | U6: must match Rules.Status | V6: date format 2026-06-18T15:30+02:00 | W6: user defined

Sheet GroupOfProperties
A1: Filter | B1: Hinweise zur Handhabung | C1: Group of Properties | D1: GUID/URI | E1: GoP-ID | F1: GoP-Code | G1: Designation (EN) | H1: Description (EN) | I1: Beschreibung (DE) | J1: Description (FR) | K1: Descrizione (IT) | L1: Governance | M1: Status | N1: Version date | O1: Provenance (PROV) | P1: RelatedDocuments | Q1: RelatedDocumentName (EN) | R1: RelatedDocumentItemReference | T1: User Defined (not part of HE Data Dictionary / not validated by Validator)
B2: Erforderlich für Excel | D2: no | E2: no | F2: no | G2: yes | H2: yes | I2: yes | J2: optional | K2: optional | M2: yes | N2: yes | O2: yes | Q2: optional | R2: optional
B3: Sprachen | D3: neutral | E3: EN | F3: neutral | G3: EN | H3: EN | I3: DE | J3: FR | K3: IT | M3: multilingual | N3: multilingual | O3: multilingual | Q3: EN | R3: multilingual
B4: Referenziert / System generiert | D4: referenced | E4: system-generated | M4: referenced | N4: referenced | O4: referenced | Q4: referenced | R4: referenced
B5: Dropdown Liste | M5: Rules.Status
B6: Validierung | D6: not validated. Info: If available system-generated URI / user defined backend reference | E6: system-generated from Designation (EN) | F6: user defined | G6: must start with <OrganizationCode>_; forbidden prefixes: Pset_, IFC_, CH_ | H6: user defined | I6: user defined | J6: user defined | K6: user defined | M6: must match Rules.Status | N6: date format 2026-06-18T15:30+02:00 | O6: user defined | Q6: must match a DocumentName (EN) entry from Documents.DocumentName (EN) | R6: must match a DocumentItemReference entry from Documents.DocumentItemReference

Sheet Data_Template
C1: GoP | E1: Properties | BB1: DocumentName | BK1: DocumentItemReference | BY1: Documents | CE1: LOIN | CJ1: Governance
C2: GoP - Designation/Bezeichnung/Désignation/Designazione | E2: Property - Designation/Bezeichnung/Désignation/Designazione | F2: {=IF(TRANSPOSE(Properties!K7:K55)="","",TRANSPOSE(Properties!K7:K55))} | BB2: RelatedDocumentName (EN) | BK2: RelatedDocumentItemReference | BY2: Document - Designation/Bezeichnung/Désignation/Designazione | CE2: LOIN | CF2: LOIN_Milestone | CG2: LOIN_Role | CH2: LOIN_UseCase | CJ2: Governance | CK2: Status | CL2: Version date | CM2: Provenance (PROV)
A3: Validierung | C3: must match a Designation (EN) from GroupOfProperties.Designation (EN) | E3: must match a Designation (EN) from Properties.Designation (EN) | F3: Leer = Property nicht zugeordnet; x = zugeordnet ohne lokale Einschränkung; [] = gesamte globale Werteliste. Teilmenge: ["Wert 1"; "Wert 2"] oder [1.2; 2.2]. Werte müssen aus der über Properties.EnumerationDesignation (EN) verknüpften Values-Liste stammen. | BC3: must match a DocumentName (EN) entry from Documents.DocumentName (EN) | BD3: must match a DocumentName (EN) entry from Documents.DocumentName (EN) | BE3: must match a DocumentName (EN) entry from Documents.DocumentName (EN) | BF3: must match a DocumentName (EN) entry from Documents.DocumentName (EN) | BG3: must match a DocumentName (EN) entry from Documents.DocumentName (EN) | BH3: must match a DocumentName (EN) entry from Documents.DocumentName (EN) | BI3: must match a DocumentName (EN) entry from Documents.DocumentName (EN) | BL3: must match a DocumentItemReference entry from Documents.DocumentItemReference | BM3: must match a DocumentItemReference entry from Documents.DocumentItemReference | BN3: must match a DocumentItemReference entry from Documents.DocumentItemReference | BO3: must match a DocumentItemReference entry from Documents.DocumentItemReference | BP3: must match a DocumentItemReference entry from Documents.DocumentItemReference | BQ3: must match a DocumentItemReference entry from Documents.DocumentItemReference | BR3: must match a DocumentItemReference entry from Documents.DocumentItemReference | BS3: must match a DocumentItemReference entry from Documents.DocumentItemReference | BT3: must match a DocumentItemReference entry from Documents.DocumentItemReference | BU3: must match a DocumentItemReference entry from Documents.DocumentItemReference | BV3: must match a DocumentItemReference entry from Documents.DocumentItemReference | BW3: must match a DocumentItemReference entry from Documents.DocumentItemReference | BZ3: must match a DocumentName (EN) entry from Documents.DocumentName (EN) | CA3: must match a DocumentName (EN) entry from Documents.DocumentName (EN) | CB3: must match a DocumentName (EN) entry from Documents.DocumentName (EN) | CC3: must match a DocumentName (EN) entry from Documents.DocumentName (EN) | CF3: user defined | CG3: user defined | CH3: user defined | CK3: must match Rules.Status | CL3: date format 2026-06-18T15:30+02:00 | CM3: user defined
A4: Classes
A5: Class - Designation/Bezeichnung/Désignation/Designazione

Sheet Gelöschte Bauteile
B1: D | C1: 05 | D1: . | E1: 01 | F1: . | G1: 004 | H1: . | I1: nnn | L1: Schalldämpfer | N1: 242.2 | O1: - | P1: - | Q1: - | R1: x | U1: x | V1: Rohrzubehör | Y1: Apparat HLKS | Z1: IfcDuctSilencerType | AA1: ROUND/RECTANGULAR | AD1: 200 | AE1: 200 | AF1: 300 | AG1: 300 | AH1: 300 | AI1: 300 | AV1: x | BE1: =IF(COUNTIF(AJ1:BD1,"x")>0,"x","") -> x
B2: D | C2: 05 | D2: . | E2: 01 | F2: . | G2: 004 | H2: . | I2: nnn | L2: Dacheinfassung | N2: 242.2 | O2: - | P2: - | Q2: - | R2: x | U2: x | V2: Rohrzubehör | Y2: Installationszubehör | Z2: IfcCoveringType | AA2: ROOFING | AD2: 200 | AE2: 200 | AF2: 300 | AG2: 300 | AH2: 300 | AI2: 300 | AV2: x | BE2: =IF(COUNTIF(AJ2:BD2,"x")>0,"x","") -> x
B3: D | C3: 05 | D3: . | E3: 01 | F3: . | G3: 004 | H3: . | I3: nnn | L3: Revisionsstück | N3: 242.2 | O3: - | P3: - | Q3: - | R3: x | U3: x | V3: Rohrformteile | Z3: IfcPipeSegmentType | AA3: SPOOL | AD3: 200 | AE3: 200 | AF3: 300 | AG3: 300 | AH3: 300 | AI3: 300 | AV3: x | BE3: =IF(COUNTIF(AJ3:BD3,"x")>0,"x","") -> x
B4: D | C4: 05 | D4: . | E4: 01 | F4: . | G4: 004 | H4: . | I4: nnn | L4: Messstutzen | N4: 242.2 | O4: - | P4: - | Q4: - | R4: x | U4: x | V4: Rohrformteile | Z4: IfcPipeFittingType | AA4: ENTRY | AD4: 200 | AE4: 200 | AF4: 300 | AG4: 300 | AH4: 300 | AI4: 300 | AV4: x | BE4: =IF(COUNTIF(AJ4:BD4,"x")>0,"x","") -> x
B5: D | C5: 05 | D5: . | E5: 01 | F5: . | G5: 004 | H5: . | I5: nnn | L5: Abscheider | N5: 242.2 | O5: - | P5: - | Q5: - | R5: x | U5: x | V5: Rohrzubehör | Y5: Armatur HLKS | Z5: IfcValveType | AA5: DRAWOFFCOCK | AD5: 200 | AE5: 200 | AF5: 300 | AG5: 300 | AH5: 300 | AI5: 300 | AV5: x | BE5: =IF(COUNTIF(AJ5:BD5,"x")>0,"x","") -> x
B6: D | C6: 05 | D6: . | E6: 01 | F6: . | G6: 004 | H6: . | I6: nnn | L6: Isolierstück | N6: 242.2 | O6: - | P6: - | Q6: - | R6: x | U6: x | V6: Rohrformteile | Z6: IfcPipeSegmentType | AA6: SPOOL | AD6: 200 | AE6: 200 | AF6: 300 | AG6: 300 | AH6: 300 | AI6: 300 | AV6: x | BE6: =IF(COUNTIF(AJ6:BD6,"x")>0,"x","") -> x
B7: D | C7: 05 | D7: . | E7: 01 | F7: . | G7: 004 | H7: . | I7: nnn | L7: Kontrolldeckel | N7: 242.2 | O7: - | P7: - | Q7: - | R7: x | U7: x | V7: Rohrzubehör | AV7: x | BE7: =IF(COUNTIF(AJ7:BD7,"x")>0,"x","") -> x
B8: D | C8: 05 | D8: . | E8: 01 | F8: . | G8: 004 | H8: . | I8: nnn | L8: Schlammsammler | N8: 242.2 | O8: - | P8: - | Q8: - | R8: x | U8: x | V8: Rohrzubehör | Y8: Apparat HLKS | Z8: IfcFilterType | AA8: WATERFILTER | AD8: 200 | AE8: 200 | AF8: 300 | AG8: 300 | AH8: 300 | AI8: 300 | AV8: x | BE8: =IF(COUNTIF(AJ8:BD8,"x")>0,"x","") -> x
B9: D | C9: 05 | D9: . | E9: 01 | F9: . | G9: 004 | H9: . | I9: nnn | L9: Storzkupplung | N9: 242.2 | O9: - | P9: - | Q9: - | R9: x | U9: x | V9: Rohrformteile | Z9: IfcPipeFittingType | AA9: CONNECTOR | AD9: 200 | AE9: 200 | AF9: 300 | AG9: 300 | AH9: 300 | AI9: 300 | AV9: x | BE9: =IF(COUNTIF(AJ9:BD9,"x")>0,"x","") -> x
B10: D | C10: 05 | D10: . | E10: 02 | F10: . | G10: 009 | H10: . | I10: nnn | L10: Wärmeübertrager | N10: 242.0 | O10: - | P10: - | Q10: - | R10: x | U10: x | V10: HLS-Bauteile | Y10: Apparat HLKS | Z10: IfcHeatExchanger | AA10: - | AD10: 200 | AE10: 200 | AF10: 300 | AG10: 300 | AH10: 300 | AI10: 300 | AV10: x | BE10: =IF(COUNTIF(AJ10:BD10,"x")>0,"x","") -> x
B11: D | C11: 05 | D11: . | E11: 02 | F11: . | G11: 009 | H11: . | I11: nnn | L11: Wassermangelsicherung | N11: 242.2 | O11: - | P11: - | Q11: - | R11: x | U11: x | V11: HLS-Bauteile | Y11: Schaltung & Steuerung HLKSE | Z11: IfcFlowController | AA11: - | AD11: 200 | AE11: 200 | AF11: 300 | AG11: 300 | AH11: 300 | AI11: 300 | AV11: x | BE11: =IF(COUNTIF(AJ11:BD11,"x")>0,"x","") -> x

Sheet Rules
A1: Class-Assignment | B1: Klassen-Zuordnung | C1: Affectation de classe | D1: Assegnazione della classe | E1: Property-Assignment | F1: Merkmals-Zuordnung | G1: Attribution de propriété | H1: Assegnazione della proprietà | I1: DataType | J1: IFC Data Type | K1: Status | L1: ISG - Informationssicherheitsgesetz | M1: FAIR Prinzipien | N1: LifecycleStatus
A2: Systems / Installations | B2: Systeme / Anlagen | C2: Systèmes / installations | D2: Sistemi / installazioni | E2: not defined | F2: nicht definiert | G2: non défini | H2: non definito | I2: BOOLEAN | J2: nicht definiert | K2: Preview | L2: nicht klassifiziert | M2: Zugänglich kostenpflichtig | N2: Preview
A3: Physical elements | B3: Physische Bauteile | C3: Éléments physiques | D3: Elementi fisici | E3: Identification and classification | F3: Identifikation und Klassifikation | G3: Identification et classification | H3: Identificazione e classificazione | I3: CHARACTER | J3: IfcAbsorbedDoseMeasure | K3: Active | L3: intern | M3: Zugänglich unentgeltlich | N3: Active
A4: Spatial structure | B4: Räumliche Struktur | C4: Structure spatiale | D4: Struttura spaziale | E4: Manufacturer and product information | F4: Hersteller- und Produktinformationen | G4: Informations sur le fabricant et le produit | H4: Informazioni sul produttore e sul prodotto | I4: INTEGER | J4: IfcAccelerationMeasure | K4: Inactive | L4: sensitiv | M4: Nicht zugänglich - kostenpflichtig | N4: Inactive
A5: Logical zones & groups | B5: Logische Zonen & Gruppen | C5: Zones logiques et groupes | D5: Zone logiche e gruppi | E5: Geometric characteristics | F5: Geometrische Eigenschaften | G5: Caractéristiques géométriques | H5: Caratteristiche geometriche | I5: REAL | J5: IfcAmountOfSubstanceMeasure | K5: Deprecated | L5: geheim | M5: Nicht zugänglich - unentgeltlich | N5: Deprecated
A6: Geometric references & grids | B6: Geometrische Referenzen & Raster | C6: Références géométriques et grilles | D6: Riferimenti geometrici e griglie | E6: Physical characteristics | F6: Physikalische Eigenschaften | G6: Caractéristiques physiques | H6: Caratteristiche fisiche | I6: STRING | J6: IfcAngularVelocityMeasure | K6: Retired | N6: Retired
A7: Actors | B7: Akteure | C7: Acteurs | D7: Attori | E7: Material and construction | F7: Material und Aufbau | G7: Matériau et constitution | H7: Materiale e struttura | I7: TIME | J7: IfcAreaDensityMeasure | K7: Candidate | N7: Candidate
A8: Resources | B8: Ressourcen | C8: Ressources | D8: Risorse | E8: Operating conditions and limits | F8: Betriebsbedingungen und Grenzwerte | G8: Conditions de fonctionnement et limites | H8: Condizioni operative e limiti | I8: DATETIME | J8: IfcAreaMeasure | K8: Recorded | N8: Recorded
A9: Processes & tasks | B9: Prozesse & Aufgaben | C9: Processus et tâches | D9: Processi e compiti | E9: Performance characteristics | F9: Leistungs- und Funktionskennwerte | G9: Caractéristiques de performance et de fonctionnement | H9: Caratteristiche prestazionali e funzionali | J9: IfcBinary | K9: Superseded | N9: Superseded
E10: Hydraulic / flow characteristics | F10: Hydraulische / strömungstechnische Kennwerte | G10: Caractéristiques hydrauliques / d’écoulement | H10: Caratteristiche idrauliche / di flusso | J10: IfcBoolean | K10: Incomplete | N10: Incomplete
E11: Thermal characteristics | F11: Thermische Kennwerte | G11: Caractéristiques thermiques | H11: Caratteristiche termiche | J11: IfcComplexNumber
E12: Electrical characteristics | F12: Elektrische Kennwerte | G12: Caractéristiques électriques | H12: Caratteristiche elettriche | J12: IfcCompoundPlaneAngleMeasure
E13: Measurement, control and sensing | F13: Mess-, Steuer- und Regelungsdaten | G13: Caractéristiques de mesure, de commande et de détection | H13: Caratteristiche di misurazione, controllo e rilevamento | J13: IfcContextDependentMeasure
E14: Connection and interface characteristics | F14: Anschluss- und Schnittstelleninformationen | G14: Caractéristiques de raccordement et d’interface | H14: Caratteristiche di collegamento e interfaccia | J14: IfcCountMeasure
E15: Safety and protection characteristics | F15: Sicherheits- und Schutzmerkmale | G15: Caractéristiques de sécurité et de protection | H15: Caratteristiche di sicurezza e protezione | J15: IfcCurvatureMeasure
E16: Installation and delivery information | F16: Montage-, Einbau- und Lieferinformationen | G16: Informations de montage, d’installation et de livraison | H16: Informazioni di montaggio, installazione e fornitura | J16: IfcDate
E17: Reference and documentation information | F17: Referenz- und Dokumentationsinformationen | G17: Informations de référence et de documentation | H17: Informazioni di riferimento e documentazione | J17: IfcDateTime
J18: IfcDescriptiveMeasure
J19: IfcDoseEquivalentMeasure
J20: IfcDuration
J21: IfcDynamicViscosityMeasure
J22: IfcElectricCapacitanceMeasure
J23: IfcElectricChargeMeasure
J24: IfcElectricConductanceMeasure
J25: IfcElectricCurrentMeasure
J26: IfcElectricResistanceMeasure
J27: IfcElectricVoltageMeasure
J28: IfcEnergyMeasure
J29: IfcForceMeasure
... J111: IfcWarpingMomentMeasure
