Workbook
Name Affectation_de_classe: [1]Rules!$C$2:$C$50
Name Affectation_de_classe: #REF!
Name Affectation_de_classe: Rules!$C$2:$C$47
Name Assegnazione_della_classe: [1]Rules!$D$2:$D$50
Name Assegnazione_della_classe: #REF!
Name Assegnazione_della_classe: Rules!$D$2:$D$47
Name Assegnazione_della_proprieta: [1]Rules!$H$2:$H$50
Name Assegnazione_della_proprieta: #REF!
Name Assegnazione_della_proprieta: Rules!$H$2:$H$47
Name Attribution_de_propriete: [1]Rules!$G$2:$G$50
Name Attribution_de_propriete: #REF!
Name Attribution_de_propriete: Rules!$G$2:$G$47
Name Beschreibung: Rules!$F$2:$F$47
Name DataType: [1]Rules!$I$2:$I$50
Name DataType: Rules!$B$2:$B$47
Name DataType: #REF!
Name DataType: Rules!$I$2:$I$47
Name FAIR_Prinzipien: [1]Rules!$M$2:$M$50
Name FAIR_Prinzipien: Rules!$I$2:$I$47
Name FAIR_Prinzipien: #REF!
Name FAIR_Prinzipien: Rules!$M$2:$M$47
Name IFC_Data_Type: [1]Rules!$J$2:$J$50
Name IFC_Data_Type: Rules!$C$2:$C$47
Name IFC_Data_Type: #REF!
Name IFC_Data_Type: Rules!$J$2:$J$47
Name ISG___Informationssicherheitsgesetz: [1]Rules!$L$2:$L$50
Name ISG___Informationssicherheitsgesetz: Rules!$H$2:$H$47
Name ISG___Informationssicherheitsgesetz: #REF!
Name ISG___Informationssicherheitsgesetz: Rules!$L$2:$L$47
Name Klassen_Zuordnung: [1]Rules!$B$2:$B$50
Name Klassen_Zuordnung: #REF!
Name Klassen_Zuordnung: Rules!$B$2:$B$47
Name Klassifikation: #REF!
Name Klassifikation: Rules!$B$2:$B$47
Name LifecycleStatus: [1]Rules!$N$2:$N$50
Name LifecycleStatus: [1]Rules!$N$2:$N$50
Name LifecycleStatus: #REF!
Name LifecycleStatus: Rules!$N$2:$N$47
Name Markmals_Klassifikation: #REF!
Name Markmals_Klassifikation: Rules!$F$2:$F$47
Name Merkmals_Zuordnung: [1]Rules!$F$2:$F$50
Name Merkmals_Zuordnung: #REF!
Name Merkmals_Zuordnung: Rules!$F$2:$F$47
Name Objekt_Einordnung: [1]Rules!$A$2:$A$50
Name Objekt_Einordnung: Rules!$A$2:$A$47
Name Objekt_Einordnung: #REF!
Name Objekt_Einordnung: Rules!$A$2:$A$47
Name Property_Classification: [1]Rules!$E$2:$E$50
Name Property_Classification: Rules!$L$2:$L$47
Name Property_Classification: #REF!
Name Property_Classification: Rules!$E$2:$E$47
Name Status: [1]Rules!$K$2:$K$50
Name Status: Rules!$G$2:$G$47
Name Status: #REF!
Name Status: Rules!$K$2:$K$47

Sheet Impressum
B1: Strukturvorlage Data Dictionaries
B3: Dokumenteninformationen
C4: Status | D4: Entwurf
C5: Version | D5: 0.5.0
C6: Herausgeber | D6: Bauen digital Schweiz / buildingSMART Switzerland
D7: info@bauen-digital.ch
B9: Trägerschaft | D9: Bauen digital Schweiz / buildingSMART Switzerland
D10: IFMA Schweiz
D11: Infra Suisse
D12: Koordinationskonferenz der Bau- und Liegenschaftsorgane der öffentlichen Bauherren (KBOB)
D13: Schweizerische Zentralstelle für Baurationalisierung (CRB)
D14: Schweizerischer Baumeisterverband (SBV)
B15: Mit freundlicher Unterstützung von
C16: B+S AG | D16: Mensch und Maschine Schweiz AG
C17: Basler & Hofmann AG | D17: open BIM Verband
C18: Bauenschweiz | D18: Penzel Valier AG
C19: Baumschlager Eberle Zürich AG | D19: POM+
C20: Buildup AG | D20: Roundtable Gebäudetechnik
C21: CADMEC AG | D21: Schindler Aufzüge AG
C22: Fachgruppe für Untertagbau (FGU) | D22: Schweizerische Bundesbahnen (SBB AG)
C23: FHNW | D23: Schweizerische Eidgenossenschaft – Bundesamt für Rüstung (armasuisse)
C24: Frutiger AG | D24: Schweizerische Eidgenossenschaft – Bundesamt für Strassen (ASTRA)
C25: HKG | D25: Schweizerischer Ingenieur- und Architektenverein (SIA)
C26: IBG Engineering AG | D26: Siemens AG
C27: ILF beratende Ingenieure AG | D27: Stadt Luzern
... C34: Marti Tunnel AG | D34: Walo AG
C35: MEGA
B37: Abgrenzung | D37: Fokus auf Austauschformat IFC 4.3.2.0 (IFC4X3_ADD2)
D38: Andere Formate (z. B. CityGML, gbXML, LandXML) sind kein Bestandteil
D39: Strukturvorlage ist eine methodische Grundlage, kein vollständiges Data Dictionaries
D40: Vollständige Data Dictionariess müssen in Datenbanken realsiert werden
D41: Die Handlungsempfehlung ist keine Implementierungsrichtlinie für Softwareentwicklung
D42: Die Strukturvorlage ist ein Best Practice Beispiel und kann jederzeit an neue Anforderungen angepasst werden. Es wird davon abgeraten, auf der Basis der Strukturvorlage Applikationen oder Tools zu entwickeln.
D43: Keine spezifischen Referenzen/Anbindungen an externe Data Dictionaries
B45: Copyright | D45: Dieses Dokument ist als Creative Commons Attribution-NonCommercial-ShareAlike 4.0 International Lizenz als Namensnennung – nichtkommerziell Weitergabe – unter gleichen Bedingungen lizenziert
D46: Weitere Informationen unter:
D47: Creative Commons
B49: Einschränkung und Handhabung | D49: Dieses Dokument erhebt keinen Anspruch auf Vollständigkeit. Es ist auch keine aus rechtlicher Sicht allgemeingültige Empfehlung oder Leitlinie, sondern soll alle Beteiligten in der Bau- und Immobilienbranche dabei unterstützen, die Abhängigkeit der einzelnen notwendigen Steuerungsinstrumente untereinander zu verstehen und richtig zuzuordnen.

Sheet Anleitung
A1: Anleitung Strukturvorlage Data Dictionaries
B3: Inhaltsverzeichnis
B5: 1 | C5: Handhabung
B6: 2 | C6: Governance
B7: 3 | C7: Header (Kopfzeile)
B8: 4 | C8: Classes (Objekte)
B9: 5 | C9: Properties (Merkmale)
B10: 6 | C10: Values (Werte)
B11: 7 | C11: Documents (Dokument) | G11: Data Template (Datenvorlage)
B12: 8 | C12: GroupOfProperties (Merkmalsgruppen)
B14: Hinweise zur Handhabung
B16: Farbcode zum ausfüllen der Strukturvorlage
B17: D | C17: Kein Farbcode: | H17: Diese Spalten müssen ausgefüllt werden.
H18: Bei sprachabhängigen Texten muss mind. EN und eine Landessprache ausgefüllt werden
C19: Grüner Farbcode: | H19: Dropdownliste: Automatische Übersetzung von EN in DE, FR, IT. Basiert auf der Übersetzung im Reiter "Rules"
C20: Grauer Farbcode: | H20: Zusätzliche Sprachen; falls erforderlich
C21: Blauer Farbcode: | H21: Diese Spalte ist system-generated, d.h. ist im Excl nicht auszufüllen, sondern wird vom Zielsystem (Datenbank) generiert
C22: Roter Farbcode: | H22: Wird automatisch durch das Validierungskript ausgefüllt
C24: A | D24: B | E24: C | F24: D | G24: E
B25: Hinweise zur Handhabung | C25: Erforderlich für Excel | D25: Sprachen | E25: Referenziert / System generiert | F25: Rules | G25: Erforderlich für Validierung
B26: A | C26: Erforderlich für Objektkatalog / Merkmalskatalog / Wertekatalog
C27: Definiert die Mindestanforderungen an einen Katalog. Unterscheidung zwischen yes = erforderlich / optional = bei Bedarf ergänzen / no = nicht notwendig
B28: B | C28: Sprachen
C29: Angabe zur Sprache: mehrsprachig = muss in der für den Katalog führenden Sprache enthalten sein
C30: EN, DE, FR, IT = gibt Sprache zwingend vor / neutral = nicht von Sprache abhängig
B31: C | C31: Regelt die Eingabe der Spalten
C32: Darf nicht vom Ersteller manuell ausgefüllt werden, sondern wird auf eine Quelle referenziert, resp. von eine Datenbank automatisch generiert
C33: referenced = Referenz auf anderen Katalog / system-generated = vom Zielsystem generiert
B34: D | C34: Vordefinierte Regeln
C35: Verweist auf die Dropdownliste in diesem Template
B36: E | C36: Erforderlich für eine automatische Validierung zur technischen Qualitätssicherung
C37: Gibt die Valdierungsregeln an, nach welchen die Spalteninhalte geprüft werden
A39: 2 | B39: Governance
B41: Vorgabe einer minimalen Governance für die verschiedenen Kataloge
B42: Optional können aller Regeln der SN EN ISO 23386 ergänzt werden
B44: A | C44: B | D44: C | E44: D | F44: E | G44: F | H44: G
B45: Governance | C45: Status | D45: Versionsdatum | E45: Herkunft (PROV) | F45: Regeln zur Festlegung von Merkmalen | G45: Regeln zur Festlegung von Merkmalsgruppen | H45: Management-Regeln für die Erstellung und Pflege
B46: B | C46: Vorgeschriebener Status des Merkmals während seines Lebenszyklus gemäss Liste (Enumeration)
B47: C | C47: Datum der Version. Format nach ISO 8601 = YYYY-MM-DDThh:mm:ssTDZ (T = festes Trennzeichen zwischen Datum und Uhrzeit / TDZ = Zeitzonenbezeichnung. Z = UTC, Abweichung zu UTC angeben)
C48: Beispiel: CET Zeit: 15:30 = UTC+2h > Korrekte Angabe: 2026-06-18T15:30+02:00
...

Sheet Header
A1: Data Dictionary — Core Metadata
A2: Field | B2: Value | C2: Requirement | D2: Notes / Maps to
A3: IDENTIFICATION
A4: OrganizationCode | C4: REQUIRED | D4: Short org code — lowercase, max 7 chars, appears in all derived IRIs
A5: DictionaryCode | C5: SYSTEM-GENERATED | D5: Generated from DictionaryName (EN)
A6: DictionaryName (EN) | C6: REQUIRED | D6: Required authoring title in English — source for DictionaryCode generation
A7: DictionaryName (DE) | C7: Min. one language REQUIRED | D7: Optional multilingual title support
A8: DictionaryName (FR) | D8: Optional multilingual title support
A9: DictionaryName (IT) | D9: Optional multilingual title support
A10: DictionaryVersion | C10: REQUIRED | D10: Semantic versioning: MAJOR.MINOR.PATCH
A11: DictionaryUri | C11: SYSTEM-GENERATED | D11: Derived from OrganizationCode and DictionaryCode; canonical base pattern https://example.com/<OrganizationCode>/<DictionaryCode>
A13: GOVERNANCE
A14: LifecycleStatus | C14: REQUIRED | D14: Governance state used to derive i14y registration status
A16: LEGEND
A17: REQUIRED: | B17: Must be filled before validation/export
A18: OPTIONAL: | B18: Fill if available

Sheet Dictionary_public
A1: Data Dictionary — Additional Metadata
A2: Field | B2: Value | C2: Requirement | D2: Notes / Maps to
A3: GOVERNANCE / PUBLISHING
A4: Owner / Publisher | C4: REQUIRED WHEN USED | D4: dct:publisher / i14y publisher mapping
A5: ContactEmail | C5: REQUIRED WHEN USED | D5: dcat:contactPoint / i14y contact
A6: Description (DE) | C6: REQUIRED WHEN USED | D6: dct:description@de
A7: Description (FR) | C7: OPTIONAL | D7: dct:description@fr
A8: Description (EN) | C8: OPTIONAL | D8: dct:description@en
A9: PrimaryLanguage | C9: REQUIRED WHEN USED | D9: Primary metadata/content language
A10: MetadataLanguages | C10: OPTIONAL | D10: Additional metadata languages; delimited list allowed
A11: ReleaseDate | C11: OPTIONAL | D11: dct:issued — format YYYY-MM-DD
A12: ModifiedDate | C12: OPTIONAL
A13: QualityAssuranceProcedure | C13: OPTIONAL
A14: QualityAssuranceProcedureUrl | C14: OPTIONAL
A16: DISCOVERY / CATALOG METADATA
A17: Keywords (DE) | C17: OPTIONAL | D17: German keywords/tags — dcat:keyword@de
A18: Keywords (FR) | C18: OPTIONAL | D18: French keywords/tags — dcat:keyword@fr
A19: Keywords (EN) | C19: OPTIONAL | D19: English keywords/tags — dcat:keyword@en
A20: AccessRights | C20: OPTIONAL | D20: Access rights / visibility statement — dct:accessRights
A21: eCH_Theme | C21: OPTIONAL | D21: Swiss eCH thematic classification / topic category
A22: SpatialCoverage | C22: OPTIONAL | D22: Geographic scope or covered territory — dct:spatial
A23: TemporalCoverage | C23: OPTIONAL | D23: Covered time period / validity period — dct:temporal
A24: DocumentationURLs | C24: OPTIONAL | D24: Supporting documentation links; delimited list allowed
A25: RelatedResourceURLs | C25: OPTIONAL | D25: Related datasets/resources links — dct:relation
A26: ApplicableLegislation | C26: OPTIONAL | D26: Applicable legal basis / legislation references
A28: LICENSING
A29: License | C29: OPTIONAL | D29: Human-readable license name — dct:license
A30: LicenseUrl | C30: OPTIONAL | D30: Resolvable license URI/URL — dct:license
A32: TECHNICAL ENDPOINTS
A33: SPARQL_Endpoint | C33: OPTIONAL | D33: SPARQL endpoint URL for published graph access
A34: TTL_Download_URL | C34: OPTIONAL | D34: Download URL for Turtle/RDF serialization — dcat:distribution
A35: JSON_Download_URL | C35: OPTIONAL | D35: Download URL for JSON/JSON-LD serialization — dcat:distribution
A36: MoreInfoUrl | C36: OPTIONAL | D36: Landing page / homepage
A38: STANDARDS ALIGNMENT
A39: ConformsTo_ISO23386 | C39: OPTIONAL | D39: dct:conformsTo — property methodology
A40: ConformsTo_ISO12006_3 | C40: OPTIONAL
A41: ConformsTo_DCAT_AP_CH | C41: OPTIONAL
A42: VersionNotes (DE) | C42: OPTIONAL
A43: VersionNotes (FR) | C43: OPTIONAL
A44: VersionNotes (EN) | C44: OPTIONAL

Sheet Classes
A1: Filter | B1: Hinweise zur Handhabung | C1: Structural categorisation | D1: Domain/Domäne/Domaine/Dominio | E1: System/System/Système/Sistema | F1: Category/Kategorie/Catégorie/Categoria | G1: Classes | H1: GUID/URI | I1: Class-ID | J1: Class-Code | K1: Class-Assignment | L1: Klassen-Zuordnung (DE) | M1: Affectation de classe (FR) | N1: Assegnazione della classe (IT) | O1: Designation (EN) | P1: Bezeichnung (DE) | Q1: Désignation (FR) | R1: Designazione (IT) | S1: Description (EN) | T1: Beschreibung (DE) | U1: Description (FR) | V1: Descrizione (IT) | W1: IFC 4.3.2.0 (IFC4X3_ADD2) | X1: IFC_URI | Y1: IfcObject Entity | Z1: IfcTypeObject Entity | AA1: PredefinedType | AB1: ObjectType | AC1: RDS | AD1: Governance | AE1: Status | AF1: Version date | AG1: Provenance (PROV) | AH1: RelatedDocuments | AI1: RelatedDocumentName (EN)
B2: Erforderlich für Excel | D2: optional | E2: optional | F2: optional | H2: no | I2: no | J2: yes | K2: yes | O2: yes | P2: yes | Q2: optional | R2: optional | S2: ja | T2: ja | U2: optional | V2: optional | X2: yes | Y2: yes | Z2: yes | AA2: yes | AB2: yes | AE2: yes | AF2: yes | AG2: yes | AI2: optional
B3: Sprachen | D3: multilingual | E3: multilingual | F3: multilingual | H3: neutral | I3: neutral | J3: neutral | K3: multilingual | L3: DE | M3: FR | N3: IT | O3: EN | P3: DE | Q3: FR | R3: IT | S3: EN | T3: DE | U3: FR | V3: IT | X3: multilingual | Y3: multilingual | Z3: multilingual | AA3: multilingual | AB3: multilingual | AC3: multilingual | AE3: EN | AF3: neutral | AG3: EN | AI3: EN
B4: Referenziert / System generiert | H4: referenced | I4: system-generated | L4: system-generated | M4: system-generated | N4: system-generated | X4: referenced | Y4: referenced | Z4: referenced | AA4: referenced | AB4: referenced | AC4: referenced | AE4: referenced | AF4: referenced | AG4: referenced | AI4: referenced
B5: Dropdown Liste | K5: Rules.Class-Assignment | L5: Rules.Klassen-Zuordnung | M5: Rules.Affectation de classe | N5: Rules.Assegnazione della classe | AE5: Rules.Status
B6: Validierung | D6: user defined | E6: user defined | F6: user defined | H6: not validated. Info: If available system-generated URI / user defined backend reference | I6: system-generated from Designation (EN) | J6: user defined | K6: must match Rules.Class-Assignment | L6: system-generated from Class-Assignment via Rules | M6: system-generated from Class-Assignment via Rules | N6: system-generated from Class-Assignment via Rules | O6: user defined | P6: user defined | Q6: user defined | R6: user defined | S6: user defined | T6: user defined | U6: user defined | V6: user defined | X6: validated against identifiers from https://search.bsdd.buildingsmart.org/uri/buildingsmart/ifc/4.3 | Y6: validated against IFC 4.3 entity identifiers | Z6: validated against IFC 4.3 entity identifiers | AA6: validated against IFC predefined types when applicable | AB6: validated against IFC 4.3 entity identifiers | AE6: must match Rules.Status | AF6: date format 2026-06-18T15:30+02:00 | AG6: user defined | AI6: must match a DocumentName (EN) entry from Documents.DocumentName (EN)
L7: =IFERROR(INDEX(Rules!$B:$B,MATCH(K7,Rules!$A:$A,0)),"") | M7: =IFERROR(INDEX(Rules!$C:$C,MATCH(K7,Rules!$A:$A,0)),"") | N7: =IFERROR(INDEX(Rules!$D:$D,MATCH(K7,Rules!$A:$A,0)),"")
L8: =IFERROR(INDEX(Rules!$B:$B,MATCH(K8,Rules!$A:$A,0)),"") | M8: =IFERROR(INDEX(Rules!$C:$C,MATCH(K8,Rules!$A:$A,0)),"") | N8: =IFERROR(INDEX(Rules!$D:$D,MATCH(K8,Rules!$A:$A,0)),"")
L9: =IFERROR(INDEX(Rules!$B:$B,MATCH(K9,Rules!$A:$A,0)),"") | M9: =IFERROR(INDEX(Rules!$C:$C,MATCH(K9,Rules!$A:$A,0)),"") | N9: =IFERROR(INDEX(Rules!$D:$D,MATCH(K9,Rules!$A:$A,0)),"")
L10: =IFERROR(INDEX(Rules!$B:$B,MATCH(K10,Rules!$A:$A,0)),"") | M10: =IFERROR(INDEX(Rules!$C:$C,MATCH(K10,Rules!$A:$A,0)),"") | N10: =IFERROR(INDEX(Rules!$D:$D,MATCH(K10,Rules!$A:$A,0)),"")
L11: =IFERROR(INDEX(Rules!$B:$B,MATCH(K11,Rules!$A:$A,0)),"") | M11: =IFERROR(INDEX(Rules!$C:$C,MATCH(K11,Rules!$A:$A,0)),"") | N11: =IFERROR(INDEX(Rules!$D:$D,MATCH(K11,Rules!$A:$A,0)),"")
L12: =IFERROR(INDEX(Rules!$B:$B,MATCH(K12,Rules!$A:$A,0)),"") | M12: =IFERROR(INDEX(Rules!$C:$C,MATCH(K12,Rules!$A:$A,0)),"") | N12: =IFERROR(INDEX(Rules!$D:$D,MATCH(K12,Rules!$A:$A,0)),"")
L13: =IFERROR(INDEX(Rules!$B:$B,MATCH(K13,Rules!$A:$A,0)),"") | M13: =IFERROR(INDEX(Rules!$C:$C,MATCH(K13,Rules!$A:$A,0)),"") | N13: =IFERROR(INDEX(Rules!$D:$D,MATCH(K13,Rules!$A:$A,0)),"")
L14: =IFERROR(INDEX(Rules!$B:$B,MATCH(K14,Rules!$A:$A,0)),"") | M14: =IFERROR(INDEX(Rules!$C:$C,MATCH(K14,Rules!$A:$A,0)),"") | N14: =IFERROR(INDEX(Rules!$D:$D,MATCH(K14,Rules!$A:$A,0)),"")
L15: =IFERROR(INDEX(Rules!$B:$B,MATCH(K15,Rules!$A:$A,0)),"") | M15: =IFERROR(INDEX(Rules!$C:$C,MATCH(K15,Rules!$A:$A,0)),"") | N15: =IFERROR(INDEX(Rules!$D:$D,MATCH(K15,Rules!$A:$A,0)),"")
L16: =IFERROR(INDEX(Rules!$B:$B,MATCH(K16,Rules!$A:$A,0)),"") | M16: =IFERROR(INDEX(Rules!$C:$C,MATCH(K16,Rules!$A:$A,0)),"") | N16: =IFERROR(INDEX(Rules!$D:$D,MATCH(K16,Rules!$A:$A,0)),"")
L17: =IFERROR(INDEX(Rules!$B:$B,MATCH(K17,Rules!$A:$A,0)),"") | M17: =IFERROR(INDEX(Rules!$C:$C,MATCH(K17,Rules!$A:$A,0)),"") | N17: =IFERROR(INDEX(Rules!$D:$D,MATCH(K17,Rules!$A:$A,0)),"")
L18: =IFERROR(INDEX(Rules!$B:$B,MATCH(K18,Rules!$A:$A,0)),"") | M18: =IFERROR(INDEX(Rules!$C:$C,MATCH(K18,Rules!$A:$A,0)),"") | N18: =IFERROR(INDEX(Rules!$D:$D,MATCH(K18,Rules!$A:$A,0)),"")
... L24: =IFERROR(INDEX(Rules!$B:$B,MATCH(K24,Rules!$A:$A,0)),"") | M24: =IFERROR(INDEX(Rules!$C:$C,MATCH(K24,Rules!$A:$A,0)),"") | N24: =IFERROR(INDEX(Rules!$D:$D,MATCH(K24,Rules!$A:$A,0)),"")

Sheet Properties
A1: Filter | B1: Hinweise zur Handhabung | C1: Properties | D1: GUID/URI | E1: Property-ID | F1: Property-Code | G1: Property-Assignment | H1: Merkmals-Zuordnung (DE) | I1: Attribution de propriété (FR) | J1: Assegnazione della proprietà (IT) | K1: Designation (EN) | L1: Bezeichnung (DE) | M1: Désignation (FR) | N1: Designazione (IT) | O1: Description (EN) | P1: Beschreibung (DE) | Q1: Description (FR) | R1: Descrizione (IT) | S1: DataType (Base Type) | T1: DataType (IFC) | U1: EnumerationDesignation (EN) | V1: IFC 4.3.2.0 (IFC4X3_ADD2) | W1: IFC_URI | X1: IfcPropertySet (Pset) IfcQuantitySet (Qto) | Y1: Units/Einheit/Unité/Unità | Z1: QUDT URI | AA1: Unit Name (EN) | AB1: Einheit-Name (DE) | AC1: Nom de l’unité (FR) | AD1: Nome unità (IT) | AE1: Governance | AF1: Status | AG1: Version date | AH1: Provenance (PROV)
B2: Erforderlich für Excel | D2: no | E2: no | F2: yes | G2: yes | K2: yes | L2: yes | M2: optional | N2: optional | O2: yes | P2: yes | Q2: optional | R2: optional | S2: yes | T2: yes | U2: yes | W2: yes | X2: yes | Y2: yes | AF2: yes | AG2: yes | AH2: yes
B3: Sprachen | D3: neutral | E3: neutral | F3: neutral | G3: neutral | H3: DE | I3: FR | J3: IT | K3: EN | L3: DE | M3: FR | N3: IT | O3: EN | P3: DE | Q3: FR | R3: IT | S3: neutral | T3: neutral | U3: EN | W3: neutral | X3: EN | Y3: neutral | Z3: multilingual | AA3: EN | AB3: DE | AC3: FR | AD3: IT | AF3: EN | AG3: neutral | AH3: EN
B4: Referenziert / System generiert | D4: referenced | E4: system-generated | H4: system-generated | I4: system-generated | J4: system-generated | S4: referenced | T4: referenced | U4: referenced | W4: referenced | X4: referenced | Z4: referenced | AA4: system-generated | AB4: system-generated | AC4: system-generated | AD4: system-generated | AF4: referenced | AG4: referenced | AH4: referenced
B5: Dropdown Liste | G5: Rules.Property-Assignment | H5: Rules.Merkmals-Zuordnung | I5: Rules.Attribution de propriété | J5: Rules.Assegnazione della proprietà | S5: Rules.DataType | T5: Rules.IFC Data Type | AF5: Rules.Status
B6: Validierung | D6: not validated. Info: If available system-generated URI / user defined backend reference | E6: system-generated from Designation (EN) | F6: user defined | G6: must match Rules.Property-Assignment | H6: system-generated from Property-Assignment via Rules | I6: system-generated from Property-Assignment via Rules | J6: system-generated from Property-Assignment via Rules | K6: user defined | L6: user defined | M6: user defined | N6: user defined | O6: user defined | P6: user defined | Q6: user defined | R6: user defined | S6: must match Rules.DataType | T6: must match Rules.IFC Data Type | U6: must match a Designation (EN) entry from Values.Designation (EN) | W6: validated against identifiers from https://search.bsdd.buildingsmart.org/uri/buildingsmart/ifc/4.3 | X6: validated against IFC 4.3 property/quantity set identifiers when IFC_URI is present | Y6: user defined | AF6: must match Rules.Status | AG6: date format 2026-06-18T15:30+02:00 | AH6: user defined
H7: =IFERROR(INDEX(Rules!$F:$F,MATCH(G7,Rules!$E:$E,0)),"") | I7: =IFERROR(INDEX(Rules!$G:$G,MATCH(G7,Rules!$E:$E,0)),"") | J7: =IFERROR(INDEX(Rules!$H:$H,MATCH(G7,Rules!$E:$E,0)),"")
H8: =IFERROR(INDEX(Rules!$F:$F,MATCH(G8,Rules!$E:$E,0)),"") | I8: =IFERROR(INDEX(Rules!$G:$G,MATCH(G8,Rules!$E:$E,0)),"") | J8: =IFERROR(INDEX(Rules!$H:$H,MATCH(G8,Rules!$E:$E,0)),"")
H9: =IFERROR(INDEX(Rules!$F:$F,MATCH(G9,Rules!$E:$E,0)),"") | I9: =IFERROR(INDEX(Rules!$G:$G,MATCH(G9,Rules!$E:$E,0)),"") | J9: =IFERROR(INDEX(Rules!$H:$H,MATCH(G9,Rules!$E:$E,0)),"")
H10: =IFERROR(INDEX(Rules!$F:$F,MATCH(G10,Rules!$E:$E,0)),"") | I10: =IFERROR(INDEX(Rules!$G:$G,MATCH(G10,Rules!$E:$E,0)),"") | J10: =IFERROR(INDEX(Rules!$H:$H,MATCH(G10,Rules!$E:$E,0)),"")
H11: =IFERROR(INDEX(Rules!$F:$F,MATCH(G11,Rules!$E:$E,0)),"") | I11: =IFERROR(INDEX(Rules!$G:$G,MATCH(G11,Rules!$E:$E,0)),"") | J11: =IFERROR(INDEX(Rules!$H:$H,MATCH(G11,Rules!$E:$E,0)),"")
H12: =IFERROR(INDEX(Rules!$F:$F,MATCH(G12,Rules!$E:$E,0)),"") | I12: =IFERROR(INDEX(Rules!$G:$G,MATCH(G12,Rules!$E:$E,0)),"") | J12: =IFERROR(INDEX(Rules!$H:$H,MATCH(G12,Rules!$E:$E,0)),"")
H13: =IFERROR(INDEX(Rules!$F:$F,MATCH(G13,Rules!$E:$E,0)),"") | I13: =IFERROR(INDEX(Rules!$G:$G,MATCH(G13,Rules!$E:$E,0)),"") | J13: =IFERROR(INDEX(Rules!$H:$H,MATCH(G13,Rules!$E:$E,0)),"")
H14: =IFERROR(INDEX(Rules!$F:$F,MATCH(G14,Rules!$E:$E,0)),"") | I14: =IFERROR(INDEX(Rules!$G:$G,MATCH(G14,Rules!$E:$E,0)),"") | J14: =IFERROR(INDEX(Rules!$H:$H,MATCH(G14,Rules!$E:$E,0)),"")
H15: =IFERROR(INDEX(Rules!$F:$F,MATCH(G15,Rules!$E:$E,0)),"") | I15: =IFERROR(INDEX(Rules!$G:$G,MATCH(G15,Rules!$E:$E,0)),"") | J15: =IFERROR(INDEX(Rules!$H:$H,MATCH(G15,Rules!$E:$E,0)),"")
H16: =IFERROR(INDEX(Rules!$F:$F,MATCH(G16,Rules!$E:$E,0)),"") | I16: =IFERROR(INDEX(Rules!$G:$G,MATCH(G16,Rules!$E:$E,0)),"") | J16: =IFERROR(INDEX(Rules!$H:$H,MATCH(G16,Rules!$E:$E,0)),"")
H17: =IFERROR(INDEX(Rules!$F:$F,MATCH(G17,Rules!$E:$E,0)),"") | I17: =IFERROR(INDEX(Rules!$G:$G,MATCH(G17,Rules!$E:$E,0)),"") | J17: =IFERROR(INDEX(Rules!$H:$H,MATCH(G17,Rules!$E:$E,0)),"")
H18: =IFERROR(INDEX(Rules!$F:$F,MATCH(G18,Rules!$E:$E,0)),"") | I18: =IFERROR(INDEX(Rules!$G:$G,MATCH(G18,Rules!$E:$E,0)),"") | J18: =IFERROR(INDEX(Rules!$H:$H,MATCH(G18,Rules!$E:$E,0)),"")
... H59: =IFERROR(INDEX(Rules!$F:$F,MATCH(G59,Rules!$E:$E,0)),"") | I59: =IFERROR(INDEX(Rules!$G:$G,MATCH(G59,Rules!$E:$E,0)),"") | J59: =IFERROR(INDEX(Rules!$H:$H,MATCH(G59,Rules!$E:$E,0)),"")
H60: =IFERROR(INDEX(Rules!$F:$F,MATCH(G61,Rules!$E:$E,0)),"") | I60: =IFERROR(INDEX(Rules!$G:$G,MATCH(G61,Rules!$E:$E,0)),"") | J60: =IFERROR(INDEX(Rules!$H:$H,MATCH(G61,Rules!$E:$E,0)),"")
H61: =IFERROR(INDEX(Rules!$F:$F,MATCH(G62,Rules!$E:$E,0)),"") | I61: =IFERROR(INDEX(Rules!$G:$G,MATCH(G62,Rules!$E:$E,0)),"") | J61: =IFERROR(INDEX(Rules!$H:$H,MATCH(G62,Rules!$E:$E,0)),"")
H62: =IFERROR(INDEX(Rules!$F:$F,MATCH(G63,Rules!$E:$E,0)),"") | I62: =IFERROR(INDEX(Rules!$G:$G,MATCH(G63,Rules!$E:$E,0)),"") | J62: =IFERROR(INDEX(Rules!$H:$H,MATCH(G63,Rules!$E:$E,0)),"")
H63: =IFERROR(INDEX(Rules!$F:$F,MATCH(G64,Rules!$E:$E,0)),"") | I63: =IFERROR(INDEX(Rules!$G:$G,MATCH(G64,Rules!$E:$E,0)),"") | J63: =IFERROR(INDEX(Rules!$H:$H,MATCH(G64,Rules!$E:$E,0)),"")
H64: =IFERROR(INDEX(Rules!$F:$F,MATCH(G65,Rules!$E:$E,0)),"") | I64: =IFERROR(INDEX(Rules!$G:$G,MATCH(G65,Rules!$E:$E,0)),"") | J64: =IFERROR(INDEX(Rules!$H:$H,MATCH(G65,Rules!$E:$E,0)),"")
H65: =IFERROR(INDEX(Rules!$F:$F,MATCH(G66,Rules!$E:$E,0)),"") | I65: =IFERROR(INDEX(Rules!$G:$G,MATCH(G66,Rules!$E:$E,0)),"") | J65: =IFERROR(INDEX(Rules!$H:$H,MATCH(G66,Rules!$E:$E,0)),"")
H66: =IFERROR(INDEX(Rules!$F:$F,MATCH(G67,Rules!$E:$E,0)),"") | I66: =IFERROR(INDEX(Rules!$G:$G,MATCH(G67,Rules!$E:$E,0)),"") | J66: =IFERROR(INDEX(Rules!$H:$H,MATCH(G67,Rules!$E:$E,0)),"")
H67: =IFERROR(INDEX(Rules!$F:$F,MATCH(G68,Rules!$E:$E,0)),"") | I67: =IFERROR(INDEX(Rules!$G:$G,MATCH(G68,Rules!$E:$E,0)),"") | J67: =IFERROR(INDEX(Rules!$H:$H,MATCH(G68,Rules!$E:$E,0)),"")
H68: =IFERROR(INDEX(Rules!$F:$F,MATCH(G69,Rules!$E:$E,0)),"") | I68: =IFERROR(INDEX(Rules!$G:$G,MATCH(G69,Rules!$E:$E,0)),"") | J68: =IFERROR(INDEX(Rules!$H:$H,MATCH(G69,Rules!$E:$E,0)),"")
H69: =IFERROR(INDEX(Rules!$F:$F,MATCH(G70,Rules!$E:$E,0)),"") | I69: =IFERROR(INDEX(Rules!$G:$G,MATCH(G70,Rules!$E:$E,0)),"") | J69: =IFERROR(INDEX(Rules!$H:$H,MATCH(G70,Rules!$E:$E,0)),"")
H70: =IFERROR(INDEX(Rules!$F:$F,MATCH(G71,Rules!$E:$E,0)),"") | I70: =IFERROR(INDEX(Rules!$G:$G,MATCH(G71,Rules!$E:$E,0)),"") | J70: =IFERROR(INDEX(Rules!$H:$H,MATCH(G71,Rules!$E:$E,0)),"")
H71: =IFERROR(INDEX(Rules!$F:$F,MATCH(G72,Rules!$E:$E,0)),"") | I71: =IFERROR(INDEX(Rules!$G:$G,MATCH(G72,Rules!$E:$E,0)),"") | J71: =IFERROR(INDEX(Rules!$H:$H,MATCH(G72,Rules!$E:$E,0)),"")
... H187: =IFERROR(INDEX(Rules!$F:$F,MATCH(G188,Rules!$E:$E,0)),"") | I187: =IFERROR(INDEX(Rules!$G:$G,MATCH(G188,Rules!$E:$E,0)),"") | J187: =IFERROR(INDEX(Rules!$H:$H,MATCH(G188,Rules!$E:$E,0)),"")

Sheet Values
A1: Filter | B1: Hinweise zur Handhabung | C1: Enumerations | D1: GUID/URI | E1: Enumeration-ID | F1: Enumeration-Code | G1: Designation (EN) | H1: Bezeichnung (DE) | I1: Désignation (FR) | J1: Designazione (IT) | K1: Enumeration (EN) | L1: Werteliste (DE) | M1: Liste de valeurs (FR) | N1: Lista valori (IT) | O1: Units/Einheit/Unité/Unità | P1: Governance | Q1: Status | R1: Version date | S1: Provenance (PROV)
B2: Erforderlich für Excel | D2: no | E2: no | F2: yes | G2: yes | H2: yes | I2: optional | J2: optional | K2: yes | L2: yes | M2: optional | N2: optional | O2: yes | Q2: yes | R2: yes | S2: yes
B3: Sprachen | D3: neutral | E3: EN | F3: neutral | G3: EN | H3: DE | I3: FR | J3: IT | K3: EN | L3: DE | M3: FR | N3: IT | O3: multilingual | Q3: EN | R3: neutral | S3: EN
B4: Referenziert / System generiert | D4: system-generated | E4: system-generated | Q4: referenced | R4: referenced | S4: referenced
B5: Dropdown Liste | Q5: Rules.Status
B6: Validierung | D6: not validated. Info: If available system-generated URI / user defined backend reference | E6: system-generated from Designation (EN) | F6: user defined | G6: user defined | H6: user defined | I6: user defined | J6: user defined | K6: must use JSON-style list syntax, e.g. ["A", "B", "C"] or ["A", 1.5, "C"] for alphanumeric/numeric values | L6: must use JSON-style list syntax, e.g. ["A", "B", "C"] or ["A", 1.5, "C"] for alphanumeric/numeric values | M6: must use JSON-style list syntax, e.g. ["A", "B", "C"] or ["A", 1.5, "C"] for alphanumeric/numeric values | N6: must use JSON-style list syntax, e.g. ["A", "B", "C"] or ["A", 1.5, "C"] for alphanumeric/numeric values | O6: user defined | Q6: must match Rules.Status | R6: date format 2026-06-18T15:30+02:00 | S6: user defined

Sheet Documents
A1: Filter | B1: Hinweise zur Handhabung | C1: Documents | D1: GUID/URI | E1: Document-ID | F1: Document-Code | G1: DocumentName (EN) | H1: Bezeichnung (DE) | I1: Désignation (FR) | J1: Designazione (IT) | K1: Security level/Sicherheitsstufe/Niveau de sécurité/Livello di sicurezza | L1: Accessibility/Zugänglichkeit/Accessibilité/Accessibilità | M1: Revision | N1: DocumentOwner | O1: Governance | P1: Status | Q1: Version date | R1: Provenance (PROV)
B2: Erforderlich für Excel | D2: no | E2: no | F2: optional | G2: optional | H2: optional | I2: optional | J2: optional | K2: optional | L2: optional | M2: optional | N2: optional | P2: optional | Q2: optional | R2: optional
B3: Sprachen | D3: multilingual | E3: multilingual | F3: multilingual | G3: EN | H3: DE | I3: FR | J3: IT | K3: multilingual | L3: multilingual | M3: multilingual | N3: multilingual | P3: EN | Q3: neutral | R3: EN
B4: Referenziert / System generiert | E4: system-generated | G4: referenced | M4: referenced | N4: referenced | P4: referenced | Q4: referenced | R4: referenced
B5: Dropdown Liste | K5: Rules.ISG - Informationssicherheitsgesetz | L5: Rules.FAIR Prinzipien | P5: Rules.Status
B6: Validierung | D6: not validated. Info: If available system-generated URI / user defined backend reference | E6: system-generated from DocumentName (EN) | F6: user defined | G6: user defined | H6: user defined | I6: user defined | J6: user defined | K6: must match Rules.ISG - Informationssicherheitsgesetz | L6: must match Rules.FAIR Prinzipien | M6: user defined | N6: user defined | P6: must match Rules.Status | Q6: date format 2026-06-18T15:30+02:00 | R6: user defined

Sheet GroupOfProperties
A1: Filter | B1: Hinweise zur Handhabung | C1: Group of Properties | D1: GoP-ID | E1: GoP-Code | F1: Designation (EN) | G1: Description (EN) | H1: Beschreibung (DE) | I1: Description (FR) | J1: Descrizione (IT) | K1: Governance | L1: Status | M1: Version date | N1: Provenance (PROV)
B2: Erforderlich für Excel | D2: no | E2: no | F2: yes | G2: yes | H2: yes | I2: optional | J2: optional | L2: yes | M2: yes | N2: yes
B3: Sprachen | D3: EN | E3: neutral | F3: EN | G3: EN | H3: DE | I3: FR | J3: IT | L3: multilingual | M3: multilingual | N3: multilingual
B4: Referenziert / System generiert | D4: system-generated | L4: referenced | M4: referenced | N4: referenced
B5: Dropdown Liste | L5: Rules.Status
B6: Validierung | D6: system-generated from Designation (EN) | E6: user defined | F6: must start with <OrganizationCode>_; forbidden prefixes: Pset_, IFC_, CH_ | G6: user defined | H6: user defined | I6: user defined | J6: user defined | L6: must match Rules.Status | M6: date format 2026-06-18T15:30+02:00 | N6: user defined

Sheet Data_Template
C1: GoP | E1: Properties | DM1: Documents | DS1: LOIN | DX1: Governance
C2: GoP - Designation/Bezeichnung/Désignation/Designazione | E2: Property - Designation/Bezeichnung/Désignation/Designazione | DM2: Document - Designation/Bezeichnung/Désignation/Designazione | DS2: LOIN | DT2: LOIN_Milestone | DU2: LOIN_Role | DV2: LOIN_UseCase | DX2: Governance | DY2: Status | DZ2: Version date | EA2: Provenance (PROV)
A3: Classes
A4: Class - Designation/Bezeichnung/Désignation/Designazione

Sheet Gelöschte Bauteile
B1: D | C1: 05 | D1: . | E1: 01 | F1: . | G1: 004 | H1: . | I1: nnn | L1: Schalldämpfer | N1: 242.2 | O1: - | P1: - | Q1: - | R1: x | U1: x | V1: Rohrzubehör | Y1: Apparat HLKS | Z1: IfcDuctSilencerType | AA1: ROUND/RECTANGULAR | AD1: 200 | AE1: 200 | AF1: 300 | AG1: 300 | AH1: 300 | AI1: 300 | AV1: x | BE1: =IF(COUNTIF(AJ1:BD1,"x")>0,"x","") -> x
B2: D | C2: 05 | D2: . | E2: 01 | F2: . | G2: 004 | H2: . | I2: nnn | L2: Dacheinfassung | N2: 242.2 | O2: - | P2: - | Q2: - | R2: x | U2: x | V2: Rohrzubehör | Y2: Installationszubehör | Z2: IfcCoveringType | AA2: ROOFING | AD2: 200 | AE2: 200 | AF2: 300 | AG2: 300 | AH2: 300 | AI2: 300 | AV2: x | BE2: =IF(COUNTIF(AJ2:BD2,"x")>0,"x","") -> x
B3: D | C3: 05 | D3: . | E3: 01 | F3: . | G3: 004 | H3: . | I3: nnn | L3: Revisionsstück | N3: 242.2 | O3: - | P3: - | Q3: - | R3: x | U3: x | V3: Rohrformteile | Z3: IfcPipeSegmentType | AA3: SPOOL | AD3: 200 | AE3: 200 | AF3: 300 | AG3: 300 | AH3: 300 | AI3: 300 | AV3: x | BE3: =IF(COUNTIF(AJ3:BD3,"x")>0,"x","") -> x
B4: D | C4: 05 | D4: . | E4: 01 | F4: . | G4: 004 | H4: . | I4: nnn | L4: Messstutzen | N4: 242.2 | O4: - | P4: - | Q4: - | R4: x | U4: x | V4: Rohrformteile | Z4: IfcPipeFittingType | AA4: ENTRY | AD4: 200 | AE4: 200 | AF4: 300 | AG4: 300 | AH4: 300 | AI4: 300 | AV4: x | BE4: =IF(COUNTIF(AJ4:BD4,"x")>0,"x","") -> x
B5: D | C5: 05 | D5: . | E5: 01 | F5: . | G5: 004 | H5: . | I5: nnn | L5: Abscheider | N5: 242.2 | O5: - | P5: - | Q5: - | R5: x | U5: x | V5: Rohrzubehör | Y5: Armatur HLKS | Z5: IfcValveType | AA5: DRAWOFFCOCK | AD5: 200 | AE5: 200 | AF5: 300 | AG5: 300 | AH5: 300 | AI5: 300 | AV5: x | BE5: =IF(COUNTIF(AJ5:BD5,"x")>0,"x","") -> x
B6: D | C6: 05 | D6: . | E6: 01 | F6: . | G6: 004 | H6: . | I6: nnn | L6: Isolierstück | N6: 242.2 | O6: - | P6: - | Q6: - | R6: x | U6: x | V6: Rohrformteile | Z6: IfcPipeSegmentType | AA6: SPOOL | AD6: 200 | AE6: 200 | AF6: 300 | AG6: 300 | AH6: 300 | AI6: 300 | AV6: x | BE6: =IF(COUNTIF(AJ6:BD6,"x")>0,"x","") -> x
B7: D | C7: 05 | D7: . | E7: 01 | F7: . | G7: 004 | H7: . | I7: nnn | L7: Kontrolldeckel | N7: 242.2 | O7: - | P7: - | Q7: - | R7: x | U7: x | V7: Rohrzubehör | AV7: x | BE7: =IF(COUNTIF(AJ7:BD7,"x")>0,"x","") -> x
B8: D | C8: 05 | D8: . | E8: 01 | F8: . | G8: 004 | H8: . | I8: nnn | L8: Schlammsammler | N8: 242.2 | O8: - | P8: - | Q8: - | R8: x | U8: x | V8: Rohrzubehör | Y8: Apparat HLKS | Z8: IfcFilterType | AA8: WATERFILTER | AD8: 200 | AE8: 200 | AF8: 300 | AG8: 300 | AH8: 300 | AI8: 300 | AV8: x | BE8: =IF(COUNTIF(AJ8:BD8,"x")>0,"x","") -> x
B9: D | C9: 05 | D9: . | E9: 01 | F9: . | G9: 004 | H9: . | I9: nnn | L9: Storzkupplung | N9: 242.2 | O9: - | P9: - | Q9: - | R9: x | U9: x | V9: Rohrformteile | Z9: IfcPipeFittingType | AA9: CONNECTOR | AD9: 200 | AE9: 200 | AF9: 300 | AG9: 300 | AH9: 300 | AI9: 300 | AV9: x | BE9: =IF(COUNTIF(AJ9:BD9,"x")>0,"x","") -> x
B10: D | C10: 05 | D10: . | E10: 02 | F10: . | G10: 009 | H10: . | I10: nnn | L10: Wärmeübertrager | N10: 242.0 | O10: - | P10: - | Q10: - | R10: x | U10: x | V10: HLS-Bauteile | Y10: Apparat HLKS | Z10: IfcHeatExchanger | AA10: - | AD10: 200 | AE10: 200 | AF10: 300 | AG10: 300 | AH10: 300 | AI10: 300 | AV10: x | BE10: =IF(COUNTIF(AJ10:BD10,"x")>0,"x","") -> x
B11: D | C11: 05 | D11: . | E11: 02 | F11: . | G11: 009 | H11: . | I11: nnn | L11: Wassermangelsicherung | N11: 242.2 | O11: - | P11: - | Q11: - | R11: x | U11: x | V11: HLS-Bauteile | Y11: Schaltung & Steuerung HLKSE | Z11: IfcFlowController | AA11: - | AD11: 200 | AE11: 200 | AF11: 300 | AG11: 300 | AH11: 300 | AI11: 300 | AV11: x | BE11: =IF(COUNTIF(AJ11:BD11,"x")>0,"x","") -> x

Sheet Rules
A1: Class-Assignment | B1: Klassen-Zuordnung | C1: Affectation de classe | D1: Assegnazione della classe | E1: Property-Assignment | F1: Merkmals-Zuordnung | G1: Attribution de propriété | H1: Assegnazione della proprietà | I1: DataType | J1: IFC Data Type | K1: Status | L1: ISG - Informationssicherheitsgesetz | M1: FAIR Prinzipien | N1: LifecycleStatus
A2: Systems / Installations | B2: Systeme / Anlagen | C2: Systèmes / installations | D2: Sistemi / installazioni | E2: not defined | F2: nicht definiert | G2: non défini | H2: non definito | I2: BOOLEAN | J2: nicht definiert | K2: Preview | L2: nicht klassifiziert | M2: Zugänglich kostenpflichtig | N2: Preview
A3: Physical elements | B3: Physische Bauteile | C3: Éléments physiques | D3: Elementi fisici | E3: Identification and classification | F3: Identifikation und Klassifikation | G3: Identification et classification | H3: Identificazione e classificazione | I3: CHARACTER | J3: IfcBoolean | K3: Active | L3: intern | M3: Zugänglich unentgeltlich | N3: Active
A4: Spatial structure | B4: Räumliche Struktur | C4: Structure spatiale | D4: Struttura spaziale | E4: Manufacturer and product information | F4: Hersteller- und Produktinformationen | G4: Informations sur le fabricant et le produit | H4: Informazioni sul produttore e sul prodotto | I4: INTEGER | J4: IfcDate | K4: Inactive | L4: sensitiv | M4: Nicht zugänglich - kostenpflichtig | N4: Inactive
A5: Logical zones & groups | B5: Logische Zonen & Gruppen | C5: Zones logiques et groupes | D5: Zone logiche e gruppi | E5: Geometric characteristics | F5: Geometrische Eigenschaften | G5: Caractéristiques géométriques | H5: Caratteristiche geometriche | I5: REAL | J5: IfcDateTime | K5: Deprecated | L5: geheim | M5: Nicht zugänglich - unentgeltlich | N5: Deprecated
A6: Geometric references & grids | B6: Geometrische Referenzen & Raster | C6: Références géométriques et grilles | D6: Riferimenti geometrici e griglie | E6: Physical characteristics | F6: Physikalische Eigenschaften | G6: Caractéristiques physiques | H6: Caratteristiche fisiche | I6: STRING | J6: IfcDuration | K6: Retired | N6: Retired
A7: Actors | B7: Akteure | C7: Acteurs | D7: Attori | E7: Material and construction | F7: Material und Aufbau | G7: Matériau et constitution | H7: Materiale e struttura | I7: TIME | J7: IfcGloballyUniqueId | K7: Candidate | N7: Candidate
A8: Resources | B8: Ressourcen | C8: Ressources | D8: Risorse | E8: Operating conditions and limits | F8: Betriebsbedingungen und Grenzwerte | G8: Conditions de fonctionnement et limites | H8: Condizioni operative e limiti | I8: DATETIME | J8: IfcIdentifier | K8: Recorded | N8: Recorded
A9: Processes & tasks | B9: Prozesse & Aufgaben | C9: Processus et tâches | D9: Processi e compiti | E9: Performance characteristics | F9: Leistungs- und Funktionskennwerte | G9: Caractéristiques de performance et de fonctionnement | H9: Caratteristiche prestazionali e funzionali | J9: IfcInteger | K9: Superseded | N9: Superseded
E10: Hydraulic / flow characteristics | F10: Hydraulische / strömungstechnische Kennwerte | G10: Caractéristiques hydrauliques / d’écoulement | H10: Caratteristiche idrauliche / di flusso | J10: IfcLabel | K10: Incomplete | N10: Incomplete
E11: Thermal characteristics | F11: Thermische Kennwerte | G11: Caractéristiques thermiques | H11: Caratteristiche termiche | J11: IfcLengthMeasure
E12: Electrical characteristics | F12: Elektrische Kennwerte | G12: Caractéristiques électriques | H12: Caratteristiche elettriche | J12: IfcLocalTime
E13: Measurement, control and sensing | F13: Mess-, Steuer- und Regelungsdaten | G13: Caractéristiques de mesure, de commande et de détection | H13: Caratteristiche di misurazione, controllo e rilevamento | J13: IfcLogical
E14: Connection and interface characteristics | F14: Anschluss- und Schnittstelleninformationen | G14: Caractéristiques de raccordement et d’interface | H14: Caratteristiche di collegamento e interfaccia | J14: IfcNormalisedRatioMeasure
E15: Safety and protection characteristics | F15: Sicherheits- und Schutzmerkmale | G15: Caractéristiques de sécurité et de protection | H15: Caratteristiche di sicurezza e protezione | J15: IfcPositiveInteger
E16: Installation and delivery information | F16: Montage-, Einbau- und Lieferinformationen | G16: Informations de montage, d’installation et de livraison | H16: Informazioni di montaggio, installazione e fornitura | J16: IfcPositiveLengthMeasure
E17: Reference and documentation information | F17: Referenz- und Dokumentationsinformationen | G17: Informations de référence et de documentation | H17: Informazioni di riferimento e documentazione | J17: IfcPositiveRatioMeasure
J18: IfcPositiveTimeMeasure
J19: IfcRatioMeasure
J20: IfcReal
J21: IfcText
J22: IfcThermalTransmittanceMeasure
J23: IfcTime
J24: IfcURIReference
