Workbook
Name Affectation_de_classe: Rules!$C$2:$C$50
Name Assegnazione_della_classe: Rules!$D$2:$D$50
Name Assegnazione_della_proprieta: Rules!$H$2:$H$50
Name Attribution_de_propriete: Rules!$G$2:$G$50
Name DataType: Rules!$I$2:$I$50
Name FAIR_Prinzipien: Rules!$M$2:$M$50
Name IFC_Data_Type: Rules!$J$2:$J$50
Name ISG___Informationssicherheitsgesetz: Rules!$L$2:$L$50
Name Klassen_Zuordnung: Rules!$B$2:$B$50
Name Klassifikation: Rules!$B$2:$B$50
Name LifecycleStatus: Rules!$N$2:$N$50
Name Markmals_Klassifikation: Rules!$F$2:$F$50
Name Merkmals_Zuordnung: Rules!$F$2:$F$50
Name Objekt_Einordnung: Rules!$A$2:$A$50
Name Property_Classification: Rules!$E$2:$E$50
Name Status: Rules!$K$2:$K$50

Sheet Impressum
B1: Data Dictionary - Flächenmanagement
B3: Dokumenteninformationen
C4: Status | D4: Entwurf
C5: Version | D5: 0.5.0
C6: Letzte Änderung | D6: 46272
C7: Autor | D7: Bauen digital Schweiz / buildingSMART Switzerland
B9: Trägerschaft
B11: Mit freundlicher Unterstützung von
C12: B+S AG | D12: MEGA
C13: Basler & Hofmann AG | D13: Mensch und Maschine Schweiz AG
C14: Bauenschweiz | D14: open BIM Verband
C15: Baumschlager Eberle Zürich AG | D15: Penzel Valier AG
C16: Buildup AG | D16: POM+
C17: CADMEC AG | D17: Roundtable Gebäudetechnik
C18: CRB | D18: Schindler Aufzüge AG
C19: Fachgruppe für Untertagbau (FGU) | D19: Schweizerische Bundesbahnen (SBB AG)
C20: FHNW | D20: Schweizerische Eidgenossenschaft – Bundesamt für Rüstung (armasuisse)
C21: Frutiger AG | D21: Schweizerische Eidgenossenschaft – Bundesamt für Strassen (ASTRA)
C22: HKG | D22: Schweizerischer Ingenieur- und Architektenverein (SIA)
C23: IBG Engineering AG | D23: Siemens AG
... C31: Marti Tunnel AG | D31: Walo AG
B33: Abgrenzung | D33: Fokus auf Austauschformat IFC 4.3.2.0 (IFC4X3_ADD2)
D34: Andere Formate (z. B. CityGML, gbXML, LandXML) sind kein Bestandteil
D35: Strukturvorlage ist eine methodische Grundlage, kein vollständiges Data Dictionaries
D36: Vollständige Data Dictionariess müssen in Datenbanken realsiert werden
D37: Die Handlungsempfehlung ist keine Implementierungsrichtlinie für Softwareentwicklung
D38: Die Strukturvorlage ist ein Best Practice Beispiel und kann jederzeit an neue Anforderungen angepasst werden. Es wird davon abgeraten, auf der Basis der Strukturvorlage Applikationen oder Tools zu entwickeln.
D39: Keine spezifischen Referenzen/Anbindungen an externe Data Dictionaries
B41: Copyright | D41: Dieses Dokument ist als Creative Commons Attribution-NonCommercial-ShareAlike 4.0 International Lizenz als Namensnennung – nichtkommerziell Weitergabe – unter gleichen Bedingungen lizenziert
D42: Weitere Informationen unter:
D43: Creative Commons
B45: Einschränkung und Handhabung | D45: Dieses Dokument erhebt keinen Anspruch auf Vollständigkeit. Es ist auch keine aus rechtlicher Sicht allgemeingültige Empfehlung oder Leitlinie, sondern soll alle Beteiligten in der Bau- und Immobilienbranche dabei unterstützen, die Abhängigkeit der einzelnen notwendigen Steuerungsinstrumente untereinander zu verstehen und richtig zuzuordnen.
B47: Herausgeber | D47: Bauen digital Schweiz / buildingSMART Switzerland
D48: info@bauen-digital.ch

Sheet Anleitung
A1: Anleitung Strukturvorlage Data Dictionaries
B3: Inhaltsverzeichnis
B5: 1 | C5: Handhabung
B6: 2 | C6: Governance
B7: 3 | C7: Header (Kopfzeile)
B8: 4 | C8: Classes (Objekte)
B9: 5 | C9: Properties (Merkmale)
B10: 6 | C10: Values (Werte)
B11: 7 | C11: Documents (Dokument) | G11: Data Template (Datenvorlage)
B12: 8 | C12: GroupOfProperties (Merkmalsgruppen)
B14: Hinweise zur Handhabung
B16: Farbcode zum ausfüllen der Strukturvorlage
B17: D | C17: Kein Farbcode: | H17: Diese Spalten müssen ausgefüllt werden.
H18: Bei sprachabhängigen Texten muss mind. EN und eine Landessprache ausgefüllt werden
C19: Grüner Farbcode: | H19: Dropdownliste: Automatische Übersetzung von EN in DE, FR, IT. Basiert auf der Übersetzung im Reiter "Rules"
C20: Grauer Farbcode: | H20: Zusätzliche Sprachen; falls erforderlich
C21: Blauer Farbcode: | H21: Diese Spalte ist system-generated, d.h. ist im Excl nicht auszufüllen, sondern wird vom Zielsystem (Datenbank) generiert
C22: Roter Farbcode: | H22: Wird automatisch durch das Validierungskript ausgefüllt
C24: A | D24: B | E24: C | F24: D | G24: E
B25: Hinweise zur Handhabung | C25: Erforderlich für Excel | D25: Sprachen | E25: Referenziert / System generiert | F25: Rules | G25: Erforderlich für Validierung
B26: A | C26: Erforderlich für Objektkatalog / Merkmalskatalog / Wertekatalog
C27: Definiert die Mindestanforderungen an einen Katalog. Unterscheidung zwischen yes = erforderlich / optional = bei Bedarf ergänzen / no = nicht notwendig
B28: B | C28: Sprachen
C29: Angabe zur Sprache: mehrsprachig = muss in der für den Katalog führenden Sprache enthalten sein
C30: EN, DE, FR, IT = gibt Sprache zwingend vor / neutral = nicht von Sprache abhängig
B31: C | C31: Regelt die Eingabe der Spalten
C32: Darf nicht vom Ersteller manuell ausgefüllt werden, sondern wird auf eine Quelle referenziert, resp. von eine Datenbank automatisch generiert
C33: referenced = Referenz auf anderen Katalog / system-generated = vom Zielsystem generiert
B34: D | C34: Vordefinierte Regeln
C35: Verweist auf die Dropdownliste in diesem Template
B36: E | C36: Erforderlich für eine automatische Validierung zur technischen Qualitätssicherung
C37: Gibt die Valdierungsregeln an, nach welchen die Spalteninhalte geprüft werden
A39: 2 | B39: Governance
B41: Vorgabe einer minimalen Governance für die verschiedenen Kataloge
B42: Optional können aller Regeln der SN EN ISO 23386 ergänzt werden
B44: A | C44: B | D44: C | E44: D | F44: E | G44: F | H44: G
B45: Governance | C45: Status | D45: Versionsdatum | E45: Herkunft (PROV) | F45: Regeln zur Festlegung von Merkmalen | G45: Regeln zur Festlegung von Merkmalsgruppen | H45: Management-Regeln für die Erstellung und Pflege
B46: B | C46: Vorgeschriebener Status des Merkmals während seines Lebenszyklus gemäss Liste (Enumeration)
B47: C | C47: Datum der Version. Format nach ISO 8601 = YYYY-MM-DDThh:mm:ssTDZ (T = festes Trennzeichen zwischen Datum und Uhrzeit / TDZ = Zeitzonenbezeichnung. Z = UTC, Abweichung zu UTC angeben)
C48: Beispiel: CET Zeit: 15:30 = UTC+2h > Korrekte Angabe: 2026-06-18T15:30+02:00
...

Sheet Header
A1: Data Dictionary — Core Metadata
A2: Field | B2: Value | C2: Requirement | D2: Notes / Maps to
A3: IDENTIFICATION
A4: OrganizationCode | B4: IFMA | C4: user defined name (small or capital letters), max 7 chars | D4: Short org code — lowercase, max 7 chars, appears in all derived IRIs
A5: DictionaryCode | B5: data_dictionary_area_management | C5: SYSTEM-GENERATED | D5: Generated from DictionaryName (EN)
A6: DictionaryName (EN) | B6: Data Dictionary Area Management | C6: REQUIRED | D6: Required authoring title in English — source for DictionaryCode generation
A7: DictionaryName (DE) | B7: Data Dictionary Flächenmanagement | C7: OPTIONAL | D7: Core authoring title in German — minimal DCAT
A8: DictionaryName (FR) | B8: Data Dictionary Gestion des zones | C8: OPTIONAL | D8: Optional multilingual title support
A9: DictionaryName (IT) | B9: Data Dictionary Gestione dell'area | C9: DictionaryName (IT) | D9: Optional multilingual title support
A10: DictionaryVersion | B10: 0.5.0 | C10: REQUIRED | D10: Semantic versioning: MAJOR.MINOR.PATCH
A11: DictionaryUri | B11: https://example.com/BdCH/data_dictionary_area_management | C11: SYSTEM-GENERATED | D11: Derived from OrganizationCode and DictionaryCode; canonical base pattern https://example.com/<OrganizationCode>/<DictionaryCode>
C12: Guide | D12: Private organisations may keep only this tab and delete Dictionary_public.
A13: GOVERNANCE
A14: LifecycleStatus | B14: Candidate | C14: REQUIRED | D14: Governance state used to derive i14y registration status
A16: LEGEND
A17: REQUIRED: | B17: Must be filled before validation/export
A18: OPTIONAL: | B18: Fill if available

Sheet Classes
A1: Filter | B1: Hinweise zur Handhabung | C1: Structural categorisation | D1: Domain/Domäne/Domaine/Dominio | E1: System/System/Système/Sistema | F1: Category/Kategorie/Catégorie/Categoria | G1: Classes | H1: GUID/URI | I1: Class-ID | J1: Class-Code | K1: Class-Assignment | L1: Klassen-Zuordnung (DE) | M1: Affectation de classe (FR) | N1: Assegnazione della classe (IT) | O1: Designation (EN) | P1: Bezeichnung (DE) | Q1: Désignation (FR) | R1: Designazione (IT) | S1: Description (EN) | T1: Beschreibung (DE) | U1: Description (FR) | V1: Descrizione (IT) | W1: IFC 4.3.2.0 (IFC4X3_ADD2) | X1: IFC_URI | Y1: IfcObject Entity | Z1: IfcTypeObject Entity | AA1: PredefinedType | AB1: ObjectType | AC1: Governance | AD1: Status | AE1: Version date | AF1: Provenance (PROV) | AG1: RelatedDocuments | AH1: RelatedDocumentName (EN) | AJ1: User Defined (not part of HE Data Dictionary / not validated by Validator)
B2: Erforderlich für Excel | D2: optional | E2: optional | F2: optional | H2: no | I2: no | J2: yes | K2: yes | O2: yes | P2: yes | Q2: optional | R2: optional | S2: ja | T2: ja | U2: optional | V2: optional | X2: yes | Y2: yes | Z2: yes | AA2: yes | AB2: yes | AD2: yes | AE2: yes | AF2: yes | AH2: optional
B3: Sprachen | D3: multilingual | E3: multilingual | F3: multilingual | H3: neutral | I3: neutral | J3: neutral | K3: multilingual | L3: DE | M3: FR | N3: IT | O3: EN | P3: DE | Q3: FR | R3: IT | S3: EN | T3: DE | U3: FR | V3: IT | X3: multilingual | Y3: multilingual | Z3: multilingual | AA3: multilingual | AB3: multilingual | AD3: EN | AE3: neutral | AF3: EN | AH3: EN
B4: Referenziert / System generiert | H4: referenced | I4: system-generated | L4: system-generated | M4: system-generated | N4: system-generated | X4: referenced | Y4: referenced | Z4: referenced | AA4: referenced | AB4: referenced | AD4: referenced | AE4: referenced | AF4: referenced | AH4: referenced
B5: Dropdown Liste | K5: Rules.Class-Assignment | L5: Rules.Klassen-Zuordnung | M5: Rules.Affectation de classe | N5: Rules.Assegnazione della classe | AD5: Rules.Status
B6: Validierung | D6: user defined | E6: user defined | F6: user defined | H6: not validated. Info: If available system-generated URI / user defined backend reference | I6: system-generated from Designation (EN) | J6: user defined | K6: must match Rules.Class-Assignment | L6: system-generated from Class-Assignment via Rules | M6: system-generated from Class-Assignment via Rules | N6: system-generated from Class-Assignment via Rules | O6: user defined | P6: user defined | Q6: user defined | R6: user defined | S6: user defined | T6: user defined | U6: user defined | V6: user defined | X6: validated against identifiers from https://search.bsdd.buildingsmart.org/uri/buildingsmart/ifc/4.3 | Y6: validated against IFC 4.3 entity identifiers | Z6: validated against IFC 4.3 entity identifiers | AA6: validated against IFC predefined types when applicable | AB6: validated against IFC 4.3 entity identifiers | AD6: must match Rules.Status | AE6: date format 2026-06-18T15:30+02:00 | AF6: user defined | AH6: must match a DocumentName (EN) entry from Documents.DocumentName (EN)
J7: IFMA_C_31010000 | K7: Spatial structure | L7: Logische Zonen & Gruppen | M7: =IFERROR(INDEX(Rules!$C:$C,MATCH(K7,Rules!$A:$A,0)),"") -> Structure spatiale | N7: =IFERROR(INDEX(Rules!$D:$D,MATCH(K7,Rules!$A:$A,0)),"") -> Struttura spaziale | O7: Elevation | P7: Geschossebene | S7: The physical floor level or storey level of a building. | T7: Die physische Geschossebene bzw. Etage eines Gebäudes. | X7: https://identifier.buildingsmart.org/uri/buildingsmart/ifc/4.3/class/IfcBuildingStorey | Y7: IfcBuildingStorey | Z7: IfcBuildingStorey | AD7: Preview | AE7: 2026-07-09T10:30+02:00 | AF7: IFMA | AH7: Document type catalogue
J8: IFMA_C_31010001 | K8: Spatial structure | L8: =IFERROR(INDEX(Rules!$B:$B,MATCH(K8,Rules!$A:$A,0)),"") -> Räumliche Struktur | M8: =IFERROR(INDEX(Rules!$C:$C,MATCH(K8,Rules!$A:$A,0)),"") -> Structure spatiale | N8: =IFERROR(INDEX(Rules!$D:$D,MATCH(K8,Rules!$A:$A,0)),"") -> Struttura spaziale | O8: Site area | P8: Grundstückfläche | S8: Site area (plot area according to SIA 416) | T8: Parzellenfläche (Grundstückfläche gemäss SIA 416) | X8: https://identifier.buildingsmart.org/uri/buildingsmart/ifc/4.3/class/IfcSite | Y8: IfcSite | Z8: IfcSite | AD8: Preview | AE8: 2026-07-09T10:30+02:00 | AF8: IFMA | AH8: Document type catalogue
J9: IFMA_C_31010002 | K9: Spatial structure | L9: =IFERROR(INDEX(Rules!$B:$B,MATCH(K9,Rules!$A:$A,0)),"") -> Räumliche Struktur | M9: =IFERROR(INDEX(Rules!$C:$C,MATCH(K9,Rules!$A:$A,0)),"") -> Structure spatiale | N9: =IFERROR(INDEX(Rules!$D:$D,MATCH(K9,Rules!$A:$A,0)),"") -> Struttura spaziale | O9: Surrounding area | P9: Umgebungsfläche | S9: Surrounding area according to SIA 416 | T9: Umgebungsfläche gemäss SIA 416 | X9: https://identifier.buildingsmart.org/uri/buildingsmart/ifc/4.3/class/IfcSpace | Y9: IfcSpace | Z9: IfcSpace | AA9: USERDEFINED | AB9: SITE_AREA | AD9: Preview | AE9: 2026-07-09T10:30+02:00 | AF9: IFMA | AH9: Document type catalogue
J10: IFMA_C_31010003 | K10: Spatial structure | L10: =IFERROR(INDEX(Rules!$B:$B,MATCH(K10,Rules!$A:$A,0)),"") -> Räumliche Struktur | M10: =IFERROR(INDEX(Rules!$C:$C,MATCH(K10,Rules!$A:$A,0)),"") -> Structure spatiale | N10: =IFERROR(INDEX(Rules!$D:$D,MATCH(K10,Rules!$A:$A,0)),"") -> Struttura spaziale | O10: Gross floor area | P10: Geschossvolumen | S10: Volumetric representation of gross floor areas and storey volumes according to SIA 416 | T10: Volumetrische Darstellung der Geschossflächen (brutto) und Geschossvolumen gemäss SIA 416 | X10: https://identifier.buildingsmart.org/uri/buildingsmart/ifc/4.3/class/IfcSpace | Y10: IfcSpace | Z10: IfcSpace | AA10: USERDEFINED | AB10: SURROUNDING_AREA | AD10: Preview | AE10: 2026-07-09T10:30+02:00 | AF10: IFMA | AH10: Document type catalogue
J11: IFMA_C_31010004 | K11: Spatial structure | L11: =IFERROR(INDEX(Rules!$B:$B,MATCH(K11,Rules!$A:$A,0)),"") -> Räumliche Struktur | M11: =IFERROR(INDEX(Rules!$C:$C,MATCH(K11,Rules!$A:$A,0)),"") -> Structure spatiale | N11: =IFERROR(INDEX(Rules!$D:$D,MATCH(K11,Rules!$A:$A,0)),"") -> Struttura spaziale | O11: Room | P11: Nettogeschossfläche | S11: Internal spaces (net floor areas according to SIA 416) | T11: Innenräume (Nettogeschossflächen gemäss SIA 416) | X11: https://identifier.buildingsmart.org/uri/buildingsmart/ifc/4.3/class/IfcSpaceGFA | Y11: IfcSpace | Z11: IfcSpace | AA11: GFA | AD11: Preview | AE11: 2026-07-09T10:30+02:00 | AF11: IFMA | AH11: Document type catalogue
J12: IFMA_C_31010005 | K12: Spatial structure | L12: =IFERROR(INDEX(Rules!$B:$B,MATCH(K12,Rules!$A:$A,0)),"") -> Räumliche Struktur | M12: =IFERROR(INDEX(Rules!$C:$C,MATCH(K12,Rules!$A:$A,0)),"") -> Structure spatiale | N12: =IFERROR(INDEX(Rules!$D:$D,MATCH(K12,Rules!$A:$A,0)),"") -> Struttura spaziale | O12: External room | P12: Aussen-Nettogeschossfläche | S12: External spaces (external net floor areas according to SIA 416) | T12: Aussenräume (Aussen-Nettogeschossflächen gemäss SIA 416) | X12: https://identifier.buildingsmart.org/uri/buildingsmart/ifc/4.3/class/IfcSpace | Y12: IfcSpace | Z12: IfcSpace | AA12: USERDEFINED | AB12: ROOM | AD12: Preview | AE12: 2026-07-09T10:30+02:00 | AF12: IFMA | AH12: Document type catalogue
J13: IFMA_C_31010006 | K13: Spatial structure | L13: =IFERROR(INDEX(Rules!$B:$B,MATCH(K13,Rules!$A:$A,0)),"") -> Räumliche Struktur | M13: =IFERROR(INDEX(Rules!$C:$C,MATCH(K13,Rules!$A:$A,0)),"") -> Structure spatiale | N13: =IFERROR(INDEX(Rules!$D:$D,MATCH(K13,Rules!$A:$A,0)),"") -> Struttura spaziale | O13: Parking space | P13: Stellplatz | S13: Parking spaces such as car parking spaces, moped parking, bicycle parking, fire service access/parking bays | T13: Stellplätze wie z.B. Autoparkplatz, Mofa-Parkplatz, Velostellplatz, Feuerwehrstellplatz | X13: https://identifier.buildingsmart.org/uri/buildingsmart/ifc/4.3/class/IfcSpace | Y13: IfcSpace | Z13: IfcSpace | AA13: USERDEFINED | AB13: EXTERNAL_ROOM | AD13: Preview | AE13: 2026-07-09T10:30+02:00 | AF13: IFMA | AH13: Document type catalogue
J14: IFMA_C_31010007 | K14: Spatial structure | L14: =IFERROR(INDEX(Rules!$B:$B,MATCH(K14,Rules!$A:$A,0)),"") -> Räumliche Struktur | M14: =IFERROR(INDEX(Rules!$C:$C,MATCH(K14,Rules!$A:$A,0)),"") -> Structure spatiale | N14: =IFERROR(INDEX(Rules!$D:$D,MATCH(K14,Rules!$A:$A,0)),"") -> Struttura spaziale | O14: Rentable area | P14: Vermietbare Fläche | S14: Representation of lettable area where this differs from net floor areas | T14: Darstellung der vermietbaren Fläche, insofern diese von den Nettoraumflächen differiert | X14: https://identifier.buildingsmart.org/uri/buildingsmart/ifc/4.3/class/IfcSpacePARKING | Y14: IfcSpace | Z14: IfcSpace | AA14: PARKING | AD14: Preview | AE14: 2026-07-09T10:30+02:00 | AF14: IFMA | AH14: Document type catalogue
M16: =IFERROR(INDEX(Rules!$C:$C,MATCH(K16,Rules!$A:$A,0)),"") | N16: =IFERROR(INDEX(Rules!$D:$D,MATCH(K16,Rules!$A:$A,0)),"")
L17: =IFERROR(INDEX(Rules!$B:$B,MATCH(K17,Rules!$A:$A,0)),"") | M17: =IFERROR(INDEX(Rules!$C:$C,MATCH(K17,Rules!$A:$A,0)),"") | N17: =IFERROR(INDEX(Rules!$D:$D,MATCH(K17,Rules!$A:$A,0)),"")
L18: =IFERROR(INDEX(Rules!$B:$B,MATCH(K18,Rules!$A:$A,0)),"") | M18: =IFERROR(INDEX(Rules!$C:$C,MATCH(K18,Rules!$A:$A,0)),"") | N18: =IFERROR(INDEX(Rules!$D:$D,MATCH(K18,Rules!$A:$A,0)),"")
L19: =IFERROR(INDEX(Rules!$B:$B,MATCH(K19,Rules!$A:$A,0)),"") | M19: =IFERROR(INDEX(Rules!$C:$C,MATCH(K19,Rules!$A:$A,0)),"") | N19: =IFERROR(INDEX(Rules!$D:$D,MATCH(K19,Rules!$A:$A,0)),"")
L20: =IFERROR(INDEX(Rules!$B:$B,MATCH(K20,Rules!$A:$A,0)),"") | M20: =IFERROR(INDEX(Rules!$C:$C,MATCH(K20,Rules!$A:$A,0)),"") | N20: =IFERROR(INDEX(Rules!$D:$D,MATCH(K20,Rules!$A:$A,0)),"")
L21: =IFERROR(INDEX(Rules!$B:$B,MATCH(K21,Rules!$A:$A,0)),"") | M21: =IFERROR(INDEX(Rules!$C:$C,MATCH(K21,Rules!$A:$A,0)),"") | N21: =IFERROR(INDEX(Rules!$D:$D,MATCH(K21,Rules!$A:$A,0)),"")
L22: =IFERROR(INDEX(Rules!$B:$B,MATCH(K22,Rules!$A:$A,0)),"") | M22: =IFERROR(INDEX(Rules!$C:$C,MATCH(K22,Rules!$A:$A,0)),"") | N22: =IFERROR(INDEX(Rules!$D:$D,MATCH(K22,Rules!$A:$A,0)),"")
L23: =IFERROR(INDEX(Rules!$B:$B,MATCH(K23,Rules!$A:$A,0)),"") | M23: =IFERROR(INDEX(Rules!$C:$C,MATCH(K23,Rules!$A:$A,0)),"") | N23: =IFERROR(INDEX(Rules!$D:$D,MATCH(K23,Rules!$A:$A,0)),"")
L24: =IFERROR(INDEX(Rules!$B:$B,MATCH(K24,Rules!$A:$A,0)),"") | M24: =IFERROR(INDEX(Rules!$C:$C,MATCH(K24,Rules!$A:$A,0)),"") | N24: =IFERROR(INDEX(Rules!$D:$D,MATCH(K24,Rules!$A:$A,0)),"")

Sheet Properties
A1: Filter | B1: Hinweise zur Handhabung | C1: Properties | D1: GUID/URI | E1: Property-ID | F1: Property-Code | G1: Property-Assignment | H1: Merkmals-Zuordnung (DE) | I1: Attribution de propriété (FR) | J1: Assegnazione della proprietà (IT) | K1: Designation (EN) | L1: Bezeichnung (DE) | M1: Désignation (FR) | N1: Designazione (IT) | O1: Description (EN) | P1: Beschreibung (DE) | Q1: Description (FR) | R1: Descrizione (IT) | S1: DataType (Base Type) | T1: DataType (IFC) | U1: EnumerationDesignation (EN) | V1: IFC 4.3.2.0 (IFC4X3_ADD2) | W1: IFC_URI | X1: IfcPropertySet (Pset) IfcQuantitySet (Qto) | Y1: Units/Einheit/Unité/Unità | Z1: Governance | AA1: Status | AB1: Version date | AC1: Provenance (PROV) | AE1: User Defined (not part of HE Data Dictionary / not validated by Validator)
B2: Erforderlich für Excel | D2: no | E2: no | F2: yes | G2: yes | K2: yes | L2: yes | M2: optional | N2: optional | O2: yes | P2: yes | Q2: optional | R2: optional | S2: yes | T2: yes | U2: yes | W2: yes | X2: yes | Y2: yes | AA2: yes | AB2: yes | AC2: yes
B3: Sprachen | D3: neutral | E3: neutral | F3: neutral | G3: neutral | H3: DE | I3: FR | J3: IT | K3: EN | L3: DE | M3: FR | N3: IT | O3: EN | P3: DE | Q3: FR | R3: IT | S3: neutral | T3: neutral | U3: EN | W3: neutral | X3: EN | Y3: neutral | AA3: EN | AB3: neutral | AC3: EN
B4: Referenziert / System generiert | D4: referenced | E4: system-generated | H4: system-generated | I4: system-generated | J4: system-generated | S4: referenced | T4: referenced | U4: referenced | W4: referenced | X4: referenced | AA4: referenced | AB4: referenced | AC4: referenced
B5: Dropdown Liste | G5: Rules.Property-Assignment | H5: Rules.Merkmals-Zuordnung | I5: Rules.Attribution de propriété | J5: Rules.Assegnazione della proprietà | S5: Rules.DataType | T5: Rules.IFC Data Type | AA5: Rules.Status
B6: Validierung | D6: not validated. Info: If available system-generated URI / user defined backend reference | E6: system-generated from Designation (EN) | F6: user defined | G6: must match Rules.Property-Assignment | H6: system-generated from Property-Assignment via Rules | I6: system-generated from Property-Assignment via Rules | J6: system-generated from Property-Assignment via Rules | K6: user defined | L6: user defined | M6: user defined | N6: user defined | O6: user defined | P6: user defined | Q6: user defined | R6: user defined | S6: must match Rules.DataType | T6: must match Rules.IFC Data Type | U6: must match a Designation (EN) entry from Values.Designation (EN) | W6: validated against identifiers from https://search.bsdd.buildingsmart.org/uri/buildingsmart/ifc/4.3 | X6: validated against IFC 4.3 property/quantity set identifiers when IFC_URI is present | Y6: user defined | AA6: must match Rules.Status | AB6: date format 2026-06-18T15:30+02:00 | AC6: user defined
F7: IFMA_P_31020002 | G7: Identification and classification | H7: =IFERROR(INDEX(Rules!$F:$F,MATCH(G7,Rules!$E:$E,0)),"") -> Identifikation und Klassifikation | I7: =IFERROR(INDEX(Rules!$G:$G,MATCH(G7,Rules!$E:$E,0)),"") -> Identification et classification | J7: =IFERROR(INDEX(Rules!$H:$H,MATCH(G7,Rules!$E:$E,0)),"") -> Identificazione e classificazione | K7: Name | L7: ID | O7: Unique room number or floor number according to numbering scheme | P7: Eindeutige Raumnummer bzw. Geschossnummer gemäss Nummerierungskonzept | S7: STRING | T7: IfcLabel | AA7: Preview | AB7: 2026-07-09T10:30+02:00 | AC7: IFMA
F8: IFMA_P_31020003 | G8: Identification and classification | H8: =IFERROR(INDEX(Rules!$F:$F,MATCH(G8,Rules!$E:$E,0)),"") -> Identifikation und Klassifikation | I8: =IFERROR(INDEX(Rules!$G:$G,MATCH(G8,Rules!$E:$E,0)),"") -> Identification et classification | J8: =IFERROR(INDEX(Rules!$H:$H,MATCH(G8,Rules!$E:$E,0)),"") -> Identificazione e classificazione | K8: LongName | L8: Raumbezeichnung | O8: Designation | P8: Bezeichnung | S8: STRING | T8: IfcLabel | AA8: Preview | AB8: 2026-07-09T10:30+02:00 | AC8: IFMA
F9: IFMA_P_31020004 | G9: Identification and classification | H9: =IFERROR(INDEX(Rules!$F:$F,MATCH(G9,Rules!$E:$E,0)),"") -> Identifikation und Klassifikation | I9: =IFERROR(INDEX(Rules!$G:$G,MATCH(G9,Rules!$E:$E,0)),"") -> Identification et classification | J9: =IFERROR(INDEX(Rules!$H:$H,MATCH(G9,Rules!$E:$E,0)),"") -> Identificazione e classificazione | K9: SIA_416_2003 | L9: SIA 416:2003 Flächenart | O9: Classification according to SIA 416 / 2003 | P9: Klassifizierung gemäss SIA 416 / 2003 | S9: STRING | T9: IfcLabel | U9: Area type SIA 416 code | AA9: Preview | AB9: 2026-07-09T10:30+02:00 | AC9: IFMA
F10: IFMA_P_31020007 | G10: Identification and classification | H10: =IFERROR(INDEX(Rules!$F:$F,MATCH(G10,Rules!$E:$E,0)),"") -> Identifikation und Klassifikation | I10: =IFERROR(INDEX(Rules!$G:$G,MATCH(G10,Rules!$E:$E,0)),"") -> Identification et classification | J10: =IFERROR(INDEX(Rules!$H:$H,MATCH(G10,Rules!$E:$E,0)),"") -> Identificazione e classificazione | K10: SIA_380_2015 | L10: SIA 380:2015 Raumbezeichnung | O10: Classification according to SIA 380 / 2015 | P10: Klassifizierung gemäss SIA 380 / 2015 | S10: STRING | T10: IfcLabel | U10: Room designation SIA 380 label | AA10: Preview | AB10: 2026-07-09T10:30+02:00 | AC10: IFMA
F11: IFMA_P_31020008 | G11: Identification and classification | H11: =IFERROR(INDEX(Rules!$F:$F,MATCH(G11,Rules!$E:$E,0)),"") -> Identifikation und Klassifikation | I11: =IFERROR(INDEX(Rules!$G:$G,MATCH(G11,Rules!$E:$E,0)),"") -> Identification et classification | J11: =IFERROR(INDEX(Rules!$H:$H,MATCH(G11,Rules!$E:$E,0)),"") -> Identificazione e classificazione | K11: SIA_2024_2021 | L11: SIA 2024:2001 Raumnutzung | O11: Classification according to SIA 2024 / 2021 | P11: Klassifizierung gemäss SIA 2024 / 2021 | S11: STRING | T11: IfcLabel | U11: Room usage SIA 2024 code | AA11: Preview | AB11: 2026-07-09T10:30+02:00 | AC11: IFMA
F12: IFMA_P_31020010 | G12: Identification and classification | H12: =IFERROR(INDEX(Rules!$F:$F,MATCH(G12,Rules!$E:$E,0)),"") -> Identifikation und Klassifikation | I12: =IFERROR(INDEX(Rules!$G:$G,MATCH(G12,Rules!$E:$E,0)),"") -> Identification et classification | J12: =IFERROR(INDEX(Rules!$H:$H,MATCH(G12,Rules!$E:$E,0)),"") -> Identificazione e classificazione | K12: SIA_d0615_2000 | L12: SIA d0165:2000 Nutzungsart | O12: Classification according to SIA D 0165 / 2000 | P12: Klassifizierung gemäss SIA D 0165 / 2000 | S12: STRING | T12: IfcLabel | U12: Area type d0165 code | AA12: Preview | AB12: 2026-07-09T10:30+02:00 | AC12: IFMA
F13: IFMA_P_31020012 | G13: Operating conditions and limits | H13: =IFERROR(INDEX(Rules!$F:$F,MATCH(G13,Rules!$E:$E,0)),"") -> Betriebsbedingungen und Grenzwerte | I13: =IFERROR(INDEX(Rules!$G:$G,MATCH(G13,Rules!$E:$E,0)),"") -> Conditions de fonctionnement et limites | J13: =IFERROR(INDEX(Rules!$H:$H,MATCH(G13,Rules!$E:$E,0)),"") -> Condizioni operative e limiti | K13: ProgramUse | L13: Raumnutzung | O13: Room usage according to room programme | P13: Raumnutzung gemäss Raumprogramm | S13: STRING | T13: IfcLabel | U13: Program use | AA13: Preview | AB13: 2026-07-09T10:30+02:00 | AC13: IFMA
F14: IFMA_P_31020013 | G14: Operating conditions and limits | H14: =IFERROR(INDEX(Rules!$F:$F,MATCH(G14,Rules!$E:$E,0)),"") -> Betriebsbedingungen und Grenzwerte | I14: =IFERROR(INDEX(Rules!$G:$G,MATCH(G14,Rules!$E:$E,0)),"") -> Conditions de fonctionnement et limites | J14: =IFERROR(INDEX(Rules!$H:$H,MATCH(G14,Rules!$E:$E,0)),"") -> Condizioni operative e limiti | K14: RoomType | L14: Raumtyp | O14: Room type (functional type) according to room catalogue (room data sheets) | P14: Raumtyp (Funktionstyp) gemäss Raumkatalog (Raumdatenblätter) | S14: STRING | T14: IfcLabel | U14: Room type | AA14: Preview | AB14: 2026-07-09T10:30+02:00 | AC14: IFMA
F15: IFMA_P_31020014 | G15: Identification and classification | H15: =IFERROR(INDEX(Rules!$F:$F,MATCH(G15,Rules!$E:$E,0)),"") -> Identifikation und Klassifikation | I15: =IFERROR(INDEX(Rules!$G:$G,MATCH(G15,Rules!$E:$E,0)),"") -> Identification et classification | J15: =IFERROR(INDEX(Rules!$H:$H,MATCH(G15,Rules!$E:$E,0)),"") -> Identificazione e classificazione | K15: UnitType | L15: Einheitstyp | O15: Unit type, in particular dwelling type (e.g. 3.5-room flat) | P15: Einheitstyp, insb. Wohnungstyp z.B. 3,5-Zi | S15: STRING | T15: IfcLabel | U15: Unit type | AA15: Preview | AB15: 2026-07-09T10:30+02:00 | AC15: IFMA
F16: IFMA_P_31020015 | G16: Identification and classification | H16: =IFERROR(INDEX(Rules!$F:$F,MATCH(G16,Rules!$E:$E,0)),"") -> Identifikation und Klassifikation | I16: =IFERROR(INDEX(Rules!$G:$G,MATCH(G16,Rules!$E:$E,0)),"") -> Identification et classification | J16: =IFERROR(INDEX(Rules!$H:$H,MATCH(G16,Rules!$E:$E,0)),"") -> Identificazione e classificazione | K16: Unit_ID | L16: Einheitsnummer | O16: Unique unit number (ID) according to numbering scheme for sale or rental units (e.g. apartment number) | P16: Eindeutige Einheitsnummer (ID) gemäss Nummerierungskonzept für Verkaufs- bzw. Mieteinheiten, z.B. Wohnungsnummer | S16: STRING | T16: IfcLabel | U16: Unit ID | AA16: Preview | AB16: 2026-07-09T10:30+02:00 | AC16: IFMA
F17: IFMA_P_31020016 | G17: Identification and classification | H17: =IFERROR(INDEX(Rules!$F:$F,MATCH(G17,Rules!$E:$E,0)),"") -> Identifikation und Klassifikation | I17: =IFERROR(INDEX(Rules!$G:$G,MATCH(G17,Rules!$E:$E,0)),"") -> Identification et classification | J17: =IFERROR(INDEX(Rules!$H:$H,MATCH(G17,Rules!$E:$E,0)),"") -> Identificazione e classificazione | K17: RoomNumberFM | L17: Raumnummer_Betrieb | O17: Operational room number | P17: Raumnummer Betrieb | S17: STRING | T17: IfcLabel | U17: Operational room number | AA17: Preview | AB17: 2026-07-09T10:30+02:00 | AC17: IFMA
F18: IFMA_P_31020017 | G18: Identification and classification | H18: =IFERROR(INDEX(Rules!$F:$F,MATCH(G18,Rules!$E:$E,0)),"") -> Identifikation und Klassifikation | I18: =IFERROR(INDEX(Rules!$G:$G,MATCH(G18,Rules!$E:$E,0)),"") -> Identification et classification | J18: =IFERROR(INDEX(Rules!$H:$H,MATCH(G18,Rules!$E:$E,0)),"") -> Identificazione e classificazione | K18: RoomSignalLabel | L18: Raumbeschriftung | O18: Room labelled | P18: Raum beschriftet | S18: STRING | T18: IfcLabel | U18: Room signal label | AA18: Preview | AB18: 2026-07-09T10:30+02:00 | AC18: IFMA
F19: IFMA_P_31020018 | G19: Operating conditions and limits | H19: =IFERROR(INDEX(Rules!$F:$F,MATCH(G19,Rules!$E:$E,0)),"") -> Betriebsbedingungen und Grenzwerte | I19: =IFERROR(INDEX(Rules!$G:$G,MATCH(G19,Rules!$E:$E,0)),"") -> Conditions de fonctionnement et limites | J19: =IFERROR(INDEX(Rules!$H:$H,MATCH(G19,Rules!$E:$E,0)),"") -> Condizioni operative e limiti | K19: CleaningGroup | L19: Reinigungsgruppe | O19: Cleaning group | P19: Reinigungsgruppe | S19: STRING | T19: IfcLabel | U19: Cleaning group | AA19: Preview | AB19: 2026-07-09T10:30+02:00 | AC19: IFMA
F20: IFMA_P_31020019 | G20: Physical characteristics | H20: =IFERROR(INDEX(Rules!$F:$F,MATCH(G20,Rules!$E:$E,0)),"") -> Physikalische Eigenschaften | I20: =IFERROR(INDEX(Rules!$G:$G,MATCH(G20,Rules!$E:$E,0)),"") -> Caractéristiques physiques | J20: =IFERROR(INDEX(Rules!$H:$H,MATCH(G20,Rules!$E:$E,0)),"") -> Caratteristiche fisiche | K20: AreaLoad | L20: Flächenlast | O20: Area load | P20: Flächenlast | S20: REAL | T20: IfcPlanarForceMeasure | U20: Area load | AA20: Preview | AB20: 2026-07-09T10:30+02:00 | AC20: IFMA
... F29: IFMA_P_31020028 | G29: Operating conditions and limits | H29: =IFERROR(INDEX(Rules!$F:$F,MATCH(G29,Rules!$E:$E,0)),"") -> Betriebsbedingungen und Grenzwerte | I29: =IFERROR(INDEX(Rules!$G:$G,MATCH(G29,Rules!$E:$E,0)),"") -> Conditions de fonctionnement et limites | J29: =IFERROR(INDEX(Rules!$H:$H,MATCH(G29,Rules!$E:$E,0)),"") -> Condizioni operative e limiti | K29: IsRentable | L29: Vermietbarkeit | O29: Letting suitability | P29: Vermietbarkeit | S29: BOOLEAN | T29: IfcBoolean | U29: Rentable | AA29: Preview | AB29: 2026-07-09T10:30+02:00 | AC29: IFMA
D30: https://identifier.buildingsmart.org/uri/buildingsmart/ifc/4.3/prop/IsExternal | F30: IFMA_P_31020029 | G30: Identification and classification | H30: =IFERROR(INDEX(Rules!$F:$F,MATCH(G30,Rules!$E:$E,0)),"") -> Identifikation und Klassifikation | I30: =IFERROR(INDEX(Rules!$G:$G,MATCH(G30,Rules!$E:$E,0)),"") -> Identification et classification | J30: =IFERROR(INDEX(Rules!$H:$H,MATCH(G30,Rules!$E:$E,0)),"") -> Identificazione e classificazione | K30: IsExternal | L30: Aussenraum | O30: Indicates whether the element is intended for outdoor use (TRUE) or not (FALSE). If set to (TRUE), the element is an external element that forms the outer boundary of a building. | P30: Angabe, ob das Element für die Verwendung im Aussenbereich vorgesehen ist (TRUE) oder nicht (FALSE). Bei (TRUE) handelt es sich um ein Aussenelement, das ein Gebäude nach außen abschliesst. | S30: BOOLEAN | T30: IfcBoolean | U30: External space | W30: https://identifier.buildingsmart.org/uri/buildingsmart/ifc/4.3/prop/IsExternal | X30: Pset_SpaceCommon | AA30: Preview | AB30: 2026-07-09T10:30+02:00 | AC30: IFMA
D31: https://identifier.buildingsmart.org/uri/buildingsmart/ifc/4.3/prop/OccupancyType | F31: IFMA_P_31020030 | G31: Operating conditions and limits | H31: =IFERROR(INDEX(Rules!$F:$F,MATCH(G31,Rules!$E:$E,0)),"") -> Betriebsbedingungen und Grenzwerte | I31: =IFERROR(INDEX(Rules!$G:$G,MATCH(G31,Rules!$E:$E,0)),"") -> Conditions de fonctionnement et limites | J31: =IFERROR(INDEX(Rules!$H:$H,MATCH(G31,Rules!$E:$E,0)),"") -> Condizioni operative e limiti | K31: OccupancyType | L31: Nutzungsart | O31: Occupancy type for this object.; It is defined according to the presiding national building code. | P31: Nutzungsart dieses Objekts; sie wird gemäss den geltenden nationalen Bauvorschriften definiert. | S31: STRING | T31: IfcLabel | U31: Occupancy type | W31: https://identifier.buildingsmart.org/uri/buildingsmart/ifc/4.3/prop/OccupancyType | X31: Pset_SpaceOccupancyRequirements | AA31: Preview | AB31: 2026-07-09T10:30+02:00 | AC31: IFMA
F32: IFMA_P_31020031 | G32: Geometric characteristics | H32: =IFERROR(INDEX(Rules!$F:$F,MATCH(G32,Rules!$E:$E,0)),"") -> Geometrische Eigenschaften | I32: =IFERROR(INDEX(Rules!$G:$G,MATCH(G32,Rules!$E:$E,0)),"") -> Caractéristiques géométriques | J32: =IFERROR(INDEX(Rules!$H:$H,MATCH(G32,Rules!$E:$E,0)),"") -> Caratteristiche geometriche | K32: MinimumHeadroom | L32: Raumnutzhöhe | O32: Effective clear height | P32: Lichte Höhe | S32: REAL | T32: IfcLengthMeasure | U32: Headroom | X32: Pset_SpaceOccupancyRequirements | AA32: Preview | AB32: 2026-07-09T10:30+02:00 | AC32: IFMA
D33: https://identifier.buildingsmart.org/uri/buildingsmart/ifc/4.3/prop/OccupancyNumberPeak | F33: IFMA_P_31020032 | G33: Operating conditions and limits | H33: =IFERROR(INDEX(Rules!$F:$F,MATCH(G33,Rules!$E:$E,0)),"") -> Betriebsbedingungen und Grenzwerte | I33: =IFERROR(INDEX(Rules!$G:$G,MATCH(G33,Rules!$E:$E,0)),"") -> Conditions de fonctionnement et limites | J33: =IFERROR(INDEX(Rules!$H:$H,MATCH(G33,Rules!$E:$E,0)),"") -> Condizioni operative e limiti | K33: OccupancyNumberPeak | L33: Personenbelegung geplant | O33: Maximal number of people required for the activity assigned to this space in peak time. | P33: Maximale Anzahl Personen für die zugewiesene Nutzung dieses Raums in Spitzenzeiten. | S33: INTEGER | T33: IfcInteger | U33: Planned occupancy | W33: https://identifier.buildingsmart.org/uri/buildingsmart/ifc/4.3/prop/OccupancyNumberPeak | X33: Pset_SpaceOccupancyRequirements | AA33: Preview | AB33: 2026-07-09T10:30+02:00 | AC33: IFMA
D34: https://identifier.buildingsmart.org/uri/buildingsmart/ifc/4.3/prop/OccupancyNumber | F34: IFMA_P_31020033 | G34: Operating conditions and limits | H34: =IFERROR(INDEX(Rules!$F:$F,MATCH(G34,Rules!$E:$E,0)),"") -> Betriebsbedingungen und Grenzwerte | I34: =IFERROR(INDEX(Rules!$G:$G,MATCH(G34,Rules!$E:$E,0)),"") -> Conditions de fonctionnement et limites | J34: =IFERROR(INDEX(Rules!$H:$H,MATCH(G34,Rules!$E:$E,0)),"") -> Condizioni operative e limiti | K34: OccupancyNumber | L34: Personenbelegung ist | O34: Number of people required for the activity assigned to this space. | P34: Anzahl Personen für die zugewiesene Nutzung dieses Raums. | S34: INTEGER | T34: IfcInteger | U34: Actual occupancy | W34: https://identifier.buildingsmart.org/uri/buildingsmart/ifc/4.3/prop/OccupancyNumber | X34: Pset_SpaceOccupancyRequirements | AA34: Preview | AB34: 2026-07-09T10:30+02:00 | AC34: IFMA
D35: https://identifier.buildingsmart.org/uri/buildingsmart/ifc/4.3/prop/FloorCovering | F35: IFMA_P_31020034 | G35: Material and construction | H35: =IFERROR(INDEX(Rules!$F:$F,MATCH(G35,Rules!$E:$E,0)),"") -> Material und Aufbau | I35: =IFERROR(INDEX(Rules!$G:$G,MATCH(G35,Rules!$E:$E,0)),"") -> Matériau et constitution | J35: =IFERROR(INDEX(Rules!$H:$H,MATCH(G35,Rules!$E:$E,0)),"") -> Materiale e struttura | K35: FloorCovering | L35: Bodenbelag | O35: Label to indicate the material or finish of the space flooring. The label is used for room book information and often displayed in room stamp.The material information is provided in absence of an Covering (type=FLOORING) object with own shape representation and material assignment. In case of inconsistency the material assigned to Covering elements takes precedence. | P35: Kennzeichnung des Materials bzw. der Oberfläche des Bodenbelags im Raum. Die Kennzeichnung wird für Raumbuchinformationen verwendet und häufig im Raumstempel angezeigt. Die Materialinformation wird bereitgestellt, sofern kein Covering-Objekt (Typ=FLOORING) mit eigener Geometrie und Materialzuweisung vorhanden ist. Bei Inkonsistenzen hat die Materialzuweisung der Covering-Elemente Vorrang. | S35: STRING | T35: IfcLabel | U35: Floor covering | W35: https://identifier.buildingsmart.org/uri/buildingsmart/ifc/4.3/prop/FloorCovering | X35: Pset_SpaceCoveringRequirements | AA35: Preview | AB35: 2026-07-09T10:30+02:00 | AC35: IFMA
D36: https://identifier.buildingsmart.org/uri/buildingsmart/ifc/4.3/prop/WallCovering | F36: IFMA_P_31020035 | G36: Manufacturer and product information | H36: =IFERROR(INDEX(Rules!$F:$F,MATCH(G36,Rules!$E:$E,0)),"") -> Hersteller- und Produktinformationen | I36: =IFERROR(INDEX(Rules!$G:$G,MATCH(G36,Rules!$E:$E,0)),"") -> Informations sur le fabricant et le produit | J36: =IFERROR(INDEX(Rules!$H:$H,MATCH(G36,Rules!$E:$E,0)),"") -> Informazioni sul produttore e sul prodotto | K36: WallCovering | L36: Wandbelag | O36: Label to indicate the material or finish of the space cladding. The label is used for room book information and often displayed in room stamp.The material information is provided in absence of an Covering (type=CLADDING) object with own shape representation and material assignment. In case of inconsistency the material assigned to Covering elements takes precedence | P36: Kennzeichnung des Materials bzw. der Oberfläche der Wandbekleidung im Raum. Die Kennzeichnung wird für Raumbuchinformationen verwendet und häufig im Raumstempel angezeigt. Die Materialinformation wird bereitgestellt, sofern kein Covering-Objekt (Typ=CLADDING) mit eigener Geometrie und Materialzuweisung vorhanden ist. Bei Inkonsistenzen hat die Materialzuweisung der Covering-Elemente Vorrang. | S36: STRING | T36: IfcLabel | U36: Wall covering | W36: https://identifier.buildingsmart.org/uri/buildingsmart/ifc/4.3/prop/WallCovering | X36: Pset_SpaceCoveringRequirements | AA36: Preview | AB36: 2026-07-09T10:30+02:00 | AC36: IFMA
D37: https://identifier.buildingsmart.org/uri/buildingsmart/ifc/4.3/prop/CeilingCovering | F37: IFMA_P_31020036 | G37: Material and construction | H37: =IFERROR(INDEX(Rules!$F:$F,MATCH(G37,Rules!$E:$E,0)),"") -> Material und Aufbau | I37: =IFERROR(INDEX(Rules!$G:$G,MATCH(G37,Rules!$E:$E,0)),"") -> Matériau et constitution | J37: =IFERROR(INDEX(Rules!$H:$H,MATCH(G37,Rules!$E:$E,0)),"") -> Materiale e struttura | K37: CeilingCovering | L37: Deckenmaterial | O37: Label to indicate the material or finish of the space ceiling. The label is used for room book information and often displayed in room stamp.The material information is provided in absence of an Covering (type=[[CEILING]]) object with own shape representation and material assignment. In case of inconsistency the material assigned to Covering elements takes precedence. | P37: Kennzeichnung des Materials bzw. der Oberfläche der Raumdecke. Die Kennzeichnung wird für Raumbuchinformationen verwendet und häufig im Raumstempel angezeigt. Die Materialinformation wird bereitgestellt, sofern kein Covering-Objekt (Typ=CEILING) mit eigener Geometrie und Materialzuweisung vorhanden ist. Bei Inkonsistenzen hat die Materialzuweisung der Covering-Elemente Vorrang. | S37: STRING | T37: IfcLabel | U37: Ceiling covering | W37: https://identifier.buildingsmart.org/uri/buildingsmart/ifc/4.3/prop/CeilingCovering | X37: Pset_SpaceCoveringRequirements | AA37: Preview | AB37: 2026-07-09T10:30+02:00 | AC37: IFMA
D38: https://identifier.buildingsmart.org/uri/buildingsmart/ifc/4.3/prop/NaturalVentilation | F38: IFMA_P_31020037 | G38: Thermal characteristics | H38: =IFERROR(INDEX(Rules!$F:$F,MATCH(G38,Rules!$E:$E,0)),"") -> Thermische Kennwerte | I38: =IFERROR(INDEX(Rules!$G:$G,MATCH(G38,Rules!$E:$E,0)),"") -> Caractéristiques thermiques | J38: =IFERROR(INDEX(Rules!$H:$H,MATCH(G38,Rules!$E:$E,0)),"") -> Caratteristiche termiche | K38: NaturalVentilation | L38: Natürliche Belüftung | O38: Indication whether the space is required to have natural ventilation (TRUE), or not (FALSE). | P38: Angabe, ob für den Raum natürliche Lüftung erforderlich ist (TRUE) oder nicht (FALSE). | S38: BOOLEAN | T38: IfcBoolean | U38: Natural ventilation | W38: https://identifier.buildingsmart.org/uri/buildingsmart/ifc/4.3/prop/NaturalVentilation | AA38: Preview | AB38: 2026-07-09T10:30+02:00 | AC38: IFMA
D39: https://identifier.buildingsmart.org/uri/buildingsmart/ifc/4.3/prop/NaturalVentilationRate | F39: IFMA_P_31020038 | G39: Hydraulic / flow characteristics | H39: =IFERROR(INDEX(Rules!$F:$F,MATCH(G39,Rules!$E:$E,0)),"") -> Hydraulische / strömungstechnische Kennwerte | I39: =IFERROR(INDEX(Rules!$G:$G,MATCH(G39,Rules!$E:$E,0)),"") -> Caractéristiques hydrauliques / d’écoulement | J39: =IFERROR(INDEX(Rules!$H:$H,MATCH(G39,Rules!$E:$E,0)),"") -> Caratteristiche idrauliche / di flusso | K39: NaturalVentilationRate | L39: Natürliche Luftwechselrate | O39: Indication of the requirement of a particular natural air ventilation rate, given in air changes per hour. | P39: Angabe der erforderlichen natürlichen Luftwechselrate (in Luftwechseln pro Stunde). | S39: REAL | T39: IfcVolumetricFlowRateMeasure | U39: Natural ventilation rate | W39: https://identifier.buildingsmart.org/uri/buildingsmart/ifc/4.3/prop/NaturalVentilationRate | AA39: Preview | AB39: 2026-07-09T10:30+02:00 | AC39: IFMA
D40: https://identifier.buildingsmart.org/uri/buildingsmart/ifc/4.3/prop/MechanicalVentilation | F40: IFMA_P_31020039 | G40: Performance characteristics | H40: =IFERROR(INDEX(Rules!$F:$F,MATCH(G40,Rules!$E:$E,0)),"") -> Leistungs- und Funktionskennwerte | I40: =IFERROR(INDEX(Rules!$G:$G,MATCH(G40,Rules!$E:$E,0)),"") -> Caractéristiques de performance et de fonctionnement | J40: =IFERROR(INDEX(Rules!$H:$H,MATCH(G40,Rules!$E:$E,0)),"") -> Caratteristiche prestazionali e funzionali | K40: MechanicalVentilation | L40: Mechanische Belüftung | O40: Indication whether the space is required to have mechanical ventilation (TRUE), or not (FALSE). | P40: Angabe, ob für den Raum mechanische Lüftung erforderlich ist (TRUE) oder nicht (FALSE). | S40: BOOLEAN | T40: IfcBoolean | U40: Mechanical ventilation | W40: https://identifier.buildingsmart.org/uri/buildingsmart/ifc/4.3/prop/MechanicalVentilation | AA40: Preview | AB40: 2026-07-09T10:30+02:00 | AC40: IFMA
D41: https://identifier.buildingsmart.org/uri/buildingsmart/ifc/4.3/prop/MechanicalVentilationRate | F41: IFMA_P_31020040 | G41: Hydraulic / flow characteristics | H41: =IFERROR(INDEX(Rules!$F:$F,MATCH(G41,Rules!$E:$E,0)),"") -> Hydraulische / strömungstechnische Kennwerte | I41: =IFERROR(INDEX(Rules!$G:$G,MATCH(G41,Rules!$E:$E,0)),"") -> Caractéristiques hydrauliques / d’écoulement | J41: =IFERROR(INDEX(Rules!$H:$H,MATCH(G41,Rules!$E:$E,0)),"") -> Caratteristiche idrauliche / di flusso | K41: MechanicalVentilationRate | L41: Mechanische Luftwechselrate | O41: Indication of the requirement of a particular mechanical air ventilation rate, given in air changes per hour. | P41: Angabe der erforderlichen mechanischen Luftwechselrate (in Luftwechseln pro Stunde). | S41: REAL | T41: IfcVolumetricFlowRateMeasure | U41: Mechanical ventilation rate | W41: https://identifier.buildingsmart.org/uri/buildingsmart/ifc/4.3/prop/MechanicalVentilationRate | AA41: Preview | AB41: 2026-07-09T10:30+02:00 | AC41: IFMA
D42: https://identifier.buildingsmart.org/uri/buildingsmart/ifc/4.3/prop/AirConditioning | F42: IFMA_P_31020041 | G42: Thermal characteristics | H42: =IFERROR(INDEX(Rules!$F:$F,MATCH(G42,Rules!$E:$E,0)),"") -> Thermische Kennwerte | I42: =IFERROR(INDEX(Rules!$G:$G,MATCH(G42,Rules!$E:$E,0)),"") -> Caractéristiques thermiques | J42: =IFERROR(INDEX(Rules!$H:$H,MATCH(G42,Rules!$E:$E,0)),"") -> Caratteristiche termiche | K42: AirConditioning | L42: Klimatisiert | O42: Indication whether this space requires air conditioning provided (TRUE) or not (FALSE). | P42: Angabe, ob für diesen Raum eine Klimatisierung erforderlich ist (TRUE) oder nicht (FALSE). | S42: BOOLEAN | T42: IfcBoolean | U42: Air conditioning | W42: https://identifier.buildingsmart.org/uri/buildingsmart/ifc/4.3/prop/AirConditioning | AA42: Preview | AB42: 2026-07-09T10:30+02:00 | AC42: IFMA
D43: https://identifier.buildingsmart.org/uri/buildingsmart/ifc/4.3/prop/TemperatureSetPoint | F43: IFMA_P_31020042 | G43: Thermal characteristics | H43: =IFERROR(INDEX(Rules!$F:$F,MATCH(G43,Rules!$E:$E,0)),"") -> Thermische Kennwerte | I43: =IFERROR(INDEX(Rules!$G:$G,MATCH(G43,Rules!$E:$E,0)),"") -> Caractéristiques thermiques | J43: =IFERROR(INDEX(Rules!$H:$H,MATCH(G43,Rules!$E:$E,0)),"") -> Caratteristiche termiche | K43: TemperatureSetPoint | L43: Temperatur Ziel | O43: The temperature setpoint range and default setpoint. | P43: Temperatur-Sollwertbereich und Standard-Sollwert. | S43: REAL | T43: IfcThermodynamicTemperatureMeasure | U43: Temperature set point | W43: https://identifier.buildingsmart.org/uri/buildingsmart/ifc/4.3/prop/TemperatureSetPoint | AA43: Preview | AB43: 2026-07-09T10:30+02:00 | AC43: IFMA
D44: https://identifier.buildingsmart.org/uri/buildingsmart/ifc/4.3/prop/HumiditySetPoint | F44: IFMA_P_31020043 | G44: Thermal characteristics | H44: =IFERROR(INDEX(Rules!$F:$F,MATCH(G44,Rules!$E:$E,0)),"") -> Thermische Kennwerte | I44: =IFERROR(INDEX(Rules!$G:$G,MATCH(G44,Rules!$E:$E,0)),"") -> Caractéristiques thermiques | J44: =IFERROR(INDEX(Rules!$H:$H,MATCH(G44,Rules!$E:$E,0)),"") -> Caratteristiche termiche | K44: HumiditySetPoint | L44: Luftfeuchtigkeit Ziel | O44: Humidity of the space or zone that is required from user/designer view point. If no summer or winter space humidity requirements are given, it applies all year, otherwise for the intermediate period. Provide this property, if no humidity range (Min-Max) is available. | P44: Geforderte Luftfeuchtigkeit des Raums bzw. der Zone aus Sicht Nutzer/Planer. Falls keine sommer- oder winterbezogenen Anforderungen angegeben sind, gilt der Wert ganzjährig, ansonsten für die Übergangszeit. Diese Eigenschaft ist anzugeben, sofern kein Feuchtebereich (Min–Max) verfügbar ist. | S44: REAL | T44: IfcReal | U44: Humidity set point | W44: https://identifier.buildingsmart.org/uri/buildingsmart/ifc/4.3/prop/HumiditySetPoint | AA44: Preview | AB44: 2026-07-09T10:30+02:00 | AC44: IFMA
D45: https://identifier.buildingsmart.org/uri/buildingsmart/ifc/4.3/prop/FireExit | F45: IFMA_P_31020044 | G45: Safety and protection characteristics | H45: =IFERROR(INDEX(Rules!$F:$F,MATCH(G45,Rules!$E:$E,0)),"") -> Sicherheits- und Schutzmerkmale | I45: =IFERROR(INDEX(Rules!$G:$G,MATCH(G45,Rules!$E:$E,0)),"") -> Caractéristiques de sécurité et de protection | J45: =IFERROR(INDEX(Rules!$H:$H,MATCH(G45,Rules!$E:$E,0)),"") -> Caratteristiche di sicurezza e protezione | K45: FireExit | L45: Fluchtweg | O45: Indication whether this object is designed to serve as an exit in the case of fire (TRUE) or not (FALSE). | P45: Angabe, ob dieses Objekt im Brandfall als Ausgang dient (TRUE) oder nicht (FALSE). | S45: BOOLEAN | T45: IfcBoolean | U45: Fire exit | W45: https://identifier.buildingsmart.org/uri/buildingsmart/ifc/4.3/prop/FireExit | X45: Pset_SpaceFireSafetyRequirements | AA45: Preview | AB45: 2026-07-09T10:30+02:00 | AC45: IFMA
D46: https://identifier.buildingsmart.org/uri/buildingsmart/ifc/4.3/prop/GrossFloorArea | F46: IFMA_P_31020045 | G46: Geometric characteristics | H46: =IFERROR(INDEX(Rules!$F:$F,MATCH(G46,Rules!$E:$E,0)),"") -> Geometrische Eigenschaften | I46: =IFERROR(INDEX(Rules!$G:$G,MATCH(G46,Rules!$E:$E,0)),"") -> Caractéristiques géométriques | J46: =IFERROR(INDEX(Rules!$H:$H,MATCH(G46,Rules!$E:$E,0)),"") -> Caratteristiche geometriche | K46: GrossFloorArea | L46: Bruttofläche | O46: Sum of all gross floor areas within the spatial structure element | P46: Summe aller Bruttogrundflächen innerhalb des räumlichen Strukturelements. | S46: REAL | T46: IfcAreaMeasure | U46: Gross floor area | W46: https://identifier.buildingsmart.org/uri/buildingsmart/ifc/4.3/prop/GrossFloorArea | X46: Qto_SpaceBaseQuantities | AA46: Preview | AB46: 2026-07-09T10:30+02:00 | AC46: IFMA
D47: https://identifier.buildingsmart.org/uri/buildingsmart/ifc/4.3/prop/GrossVolume | F47: IFMA_P_31020046 | G47: Geometric characteristics | H47: =IFERROR(INDEX(Rules!$F:$F,MATCH(G47,Rules!$E:$E,0)),"") -> Geometrische Eigenschaften | I47: =IFERROR(INDEX(Rules!$G:$G,MATCH(G47,Rules!$E:$E,0)),"") -> Caractéristiques géométriques | J47: =IFERROR(INDEX(Rules!$H:$H,MATCH(G47,Rules!$E:$E,0)),"") -> Caratteristiche geometriche | K47: GrossVolume | L47: Bruttovolumen | O47: Total gross volume of the object. Openings, recesses, enclosed objects and projections are not taken into account. | P47: Gesamtes Bruttovolumen des Objekts. Öffnungen, Aussparungen, eingeschlossene Objekte und Vorsprünge werden nicht berücksichtigt. | S47: REAL | T47: IfcVolumeMeasure | U47: Gross volume | W47: https://identifier.buildingsmart.org/uri/buildingsmart/ifc/4.3/prop/GrossVolume | X47: Qto_SpaceBaseQuantities | AA47: Preview | AB47: 2026-07-09T10:30+02:00 | AC47: IFMA
D48: https://identifier.buildingsmart.org/uri/buildingsmart/ifc/4.3/prop/NetFloorArea | F48: IFMA_P_31020047 | G48: Geometric characteristics | H48: =IFERROR(INDEX(Rules!$F:$F,MATCH(G48,Rules!$E:$E,0)),"") -> Geometrische Eigenschaften | I48: =IFERROR(INDEX(Rules!$G:$G,MATCH(G48,Rules!$E:$E,0)),"") -> Caractéristiques géométriques | J48: =IFERROR(INDEX(Rules!$H:$H,MATCH(G48,Rules!$E:$E,0)),"") -> Caratteristiche geometriche | K48: NetFloorArea | L48: Nettofläche | O48: Sum of all net usable floor areas. | P48: Summe aller Nettogrundflächen. | S48: REAL | T48: IfcAreaMeasure | U48: Net floor area | W48: https://identifier.buildingsmart.org/uri/buildingsmart/ifc/4.3/prop/NetFloorArea | X48: Qto_SpaceBaseQuantities | AA48: Preview | AB48: 2026-07-09T10:30+02:00 | AC48: IFMA
...

Sheet Values
A1: Filter | B1: Hinweise zur Handhabung | C1: Enumerations | D1: GUID/URI | E1: Enumeration-ID | F1: Enumeration-Code | G1: Designation (EN) | H1: Bezeichnung (DE) | I1: Désignation (FR) | J1: Designazione (IT) | K1: Enumeration (EN) | L1: Werteliste (DE) | M1: Liste de valeurs (FR) | N1: Lista valori (IT) | O1: Units/Einheit/Unité/Unità | P1: Governance | Q1: Status | R1: Version date | S1: Provenance (PROV) | U1: User Defined (not part of HE Data Dictionary / not validated by Validator)
B2: Erforderlich für Excel | D2: no | E2: no | F2: yes | G2: yes | H2: yes | I2: optional | J2: optional | K2: yes | L2: yes | M2: optional | N2: optional | O2: yes | Q2: yes | R2: yes | S2: yes
B3: Sprachen | D3: neutral | E3: EN | F3: neutral | G3: EN | H3: DE | I3: FR | J3: IT | K3: EN | L3: DE | M3: FR | N3: IT | O3: multilingual | Q3: EN | R3: neutral | S3: EN
B4: Referenziert / System generiert | D4: system-generated | E4: system-generated | Q4: referenced | R4: referenced | S4: referenced
B5: Dropdown Liste | Q5: Rules.Status
B6: Validierung | D6: not validated. Info: If available system-generated URI / user defined backend reference | E6: system-generated from Designation (EN) | F6: user defined | G6: user defined | H6: user defined | I6: user defined | J6: user defined | K6: must use JSON-style list syntax, e.g. ["A", "B", "C"] or ["A", 1.5, "C"] for alphanumeric/numeric values | L6: must use JSON-style list syntax, e.g. ["A", "B", "C"] or ["A", 1.5, "C"] for alphanumeric/numeric values | M6: must use JSON-style list syntax, e.g. ["A", "B", "C"] or ["A", 1.5, "C"] for alphanumeric/numeric values | N6: must use JSON-style list syntax, e.g. ["A", "B", "C"] or ["A", 1.5, "C"] for alphanumeric/numeric values | O6: user defined | Q6: must match Rules.Status | R6: date format 2026-06-18T15:30+02:00 | S6: user defined
F7: IFMA_V_31030000 | G7: PredefinedType | H7: Vordefinierter Typ | K7: ["GFA", "PARKING", "USERDEFINED"] | L7: ["GFA", "PARKING", "USERDEFINED"] | M7: ["GFA", "PARKING", "USERDEFINED"] | Q7: Preview | R7: 2026-07-09T10:30+02:00 | S7: IFMA
F8: IFMA_V_31030001 | G8: ObjectType | H8: Objekttyp | K8: ["SITE_AREA", "LANDSCAPE_AREA", "ROOM,EXTERNAL_ROOM", "RENTABLE_AREA"] | L8: ["SITE_AREA", "LANDSCAPE_AREA", "ROOM,EXTERNAL_ROOM", "RENTABLE_AREA"] | M8: ["SITE_AREA", "LANDSCAPE_AREA", "ROOM,EXTERNAL_ROOM", "RENTABLE_AREA"] | Q8: Preview | R8: 2026-07-09T10:30+02:00 | S8: IFMA
F9: IFMA_V_31030002 | G9: ID | H9: ID | Q9: Preview | R9: 2026-07-09T10:30+02:00 | S9: IFMA
F10: IFMA_V_31030003 | G10: Room designation | H10: Raumbezeichnung | Q10: Preview | R10: 2026-07-09T10:30+02:00 | S10: IFMA
F11: IFMA_V_31030004 | G11: Area type SIA 416 code | H11: Flächenart SIA 416 Code | K11: ["1.2", "1.2.1", "1.2.2", 2, "2.1.1.1", "2.1.1.2", "2.1.2", "2.1.3", 3, "3.1.1", "3.1.2", "3.1.3", "AIRSPACE", "ROOF"] | L11: ["1_GSF", "1.1_GGF", "1.2_UF", "1.2.1_BUF", "1.2.2_UUF", "2_GF", "2.1.1.1_HNF", "2.1.1.2_NNF", "2.1.2_VF", "2.1.3_FF", "3_AGF", "3.1_ANGF", "3.1.1_ANF", "3.1.2_AVF", "3.1.3_AFF", "5_GV", "AIRSPACE_LUFTRAUM", "ROOF_DACH"] | M11: ["1_ST", "1.1_SB", "1.2_SA", "1.2.1_SAA", "1.2.2_SAN", "2_SP", "2.1.1.1_SUP", "2.1.1.2_SUS", "2.1.2_SD", "2.1.3_SI", "3_SEP", "3.1_SEN", "3.1.1_SEU", "3.1.2_SED", "3.1.3_SEI", "5_VB", "AIRSPACE_VIDE", "ROOF_TOIT"] | Q11: Preview | R11: 2026-07-09T10:30+02:00 | S11: IFMA
F12: IFMA_V_31030007 | G12: Room designation SIA 380 label | H12: Raumbezeichnung SIA 380 Bezeichnung | K12: ["1", "2", "3", "4", "5", "6", "1", "8", "9", "10"] | L12: ["HNF1", "HNF2", "HNF3", "HNF4", "HNF5", "HNF6", "NNF7", "FF8", "VF9", "BUF10"] | M12: ["SUP1", "SUP2", "SUP3", "SUP4", "SUP5", "SUP6", "SUS7", "SI8", "SD9", "SAA10"] | Q12: Preview | R12: 2026-07-09T10:30+02:00 | S12: IFMA
F13: IFMA_V_31030008 | G13: Room usage SIA 2024 code | H13: Raumnutzung SIA 2024 Code | K13: [1.01, 1.02, 2.01, 2.02, 3.01, 3.02, 3.03, 3.04, 4.01, 4.02, 4.03, 4.04, 4.05, 5.01, 5.02, 5.03, 6.01, 6.02, 6.03, 6.04, 7.01, 7.02, 7.03, 8.01, 8.02, 8.03, 9.01, 9.02, 9.03, 10.01, 11.01, 11.02, 11.03, 12.01, 12.02, 12.03, 12.04, 12.05, 12.06, 12.07, 12.08, 12.09, 12.1, 12.11, 12.12] | L13: ["1.01_Wohnen Mehrfamilienhaus", "1.02_Wohnen Einfamilienhaus", "2.01_Hotelzimmer", "2.02_Empfang oder Lobby", "3.01_Einzel- oder Gruppenbüro", "3.02_Grossraumbüro", "3.03_Sitzungszimmer", "3.04_Schalterhalle oder Empfang", "4.01_Schulzimmer", "4.02_Lehrerzimmer", "4.03_Bibliothek", "4.04_Hörsaal", "4.05_Schulfachraum", "5.01_Lebensmittelverkauf", "5.02_Fachgeschäft", "5.03_Verkauf Möbel-Bau-Garten", "6.01_Restaurant", "6.02_Selbstbedienungsrestaurant", "6.03_Küche zu Restaurant", "6.04_Küche zu Selbstbedienungsrestaurant", "7.01_Vorstellungsraum", "7.02_Mehrzweckhalle", "7.03_Ausstellungshalle", "8.01_Bettenzimmer", "8.02_Stationszimmer", "8.03_Behandlungsraum", "9.01_Produktion (grobe Arbeit)", "9.02_Produktion (feine Arbeit)", "9.03_Laborraum", "10.01_Lagerhalle", "11.01_Turnhalle", "11.02_Fitnessraum", "11.03_Schwimmhalle", "12.01_Verkehrsfläche", "12.02_Verkehrsfläche 24 h", "12.03_Treppenhaus", "12.04_Nebenraum", "12.05_Küche oder Teeküche", "12.06_WC-Bad-Dusche zu Hotel oder Spital", "12.07_WC alle Nutzungen", "12.08_Garderobe oder Dusche", "12.09_Parkhaus", "12.10_Wasch- oder Trockenraum", "12.11_Kühlraum", "12.12_Serverraum"] | Q13: Preview | R13: 2026-07-09T10:30+02:00 | S13: IFMA
F14: IFMA_V_31030010 | G14: Area type d0165 code | H14: Flächenart d0165 Code | K14: [1.1, 1.2, 1.3, 1.4, 1.5, 1.6, 2.1, 2.2, 2.3, 2.4, 2.5, 2.6, 2.7, 2.8, 3.1, 3.2, 3.3, 3.4, 3.5, 3.6, 3.7, 3.8, 3.9, 4.1, 4.2, 4.3, 4.4, 4.5, 4.6, 5.1, 5.2, 5.3, 5.4, 5.5, 5.6, 5.7, 5.8, 5.9, 6.1, 6.2, 6.3, 6.4, 6.5, 6.6, 6.7, 6.8, 7.1, 7.2, 7.3, 7.4, 7.5, 7.6, 7.7, 8.1, 8.2, 8.3, 8.4, 8.5, 8.6, 8.7, 8.8, 8.9, 9.1, 9.2, 9.3, 9.4, 10.1] | L14: ["1.1_Wohnräume", "1.2_Gemeinschaftsräume", "1.3_Pausenräume", "1.4_Warteräume", "1.5_Speiseräume", "1.6_Hafträume", "2.1_Büroräume", "2.2_Grossraumbüros", "2.3_Besprechungsräume", "2.4_Konstruktionsräume", "2.5_Schalterräume", "2.6_Bedienungsräume", "2.7_Aufsichtsräume", "2.8_Bürotechnikräume", "3.1_Werkhallen", "3.2_Werkstätten", "3.3_Technologische Labors", "3.4_Physikalische/physikaltechnische/elektrotechnische Labors", "3.5_Chemische/bakteriologische/morphologische Labors", "3.6_Räume für Tierhaltung", "3.7_Räume für Pflanzenzucht", "3.8_Küchen", "3.9_Sonderarbeitsräume", "4.1_Lagerräume", "4.2_Archive/Sammlungsräume", "4.3_Kühlräume", "4.4_Annahme- und Ausgaberäume", "4.5_Verkaufsräume", "4.6_Ausstellungsräume", "5.1_Unterrichtsräume mit festem Gestühl", "5.2_Allgemein Unterrichts- und Übungsräume ohne festes Gestühl", "5.3_Besondere Unterrichts- und Übungsräume ohne festes Gestühl", "5.4_Bibliotheksräume", "5.5_Sporträume", "5.6_Versammlungsräume", "5.7_Bühnen-/Studioräume", "5.8_Schauräume", "5.9_Sakralräume", "6.1_Räume mit allgemeiner medizinischen Ausstattung", "6.2_Räume mit besonderer medizinischen Ausstattung", "6.3_Räume für operative Eingriffe/Endoskopien/Entbindungen", "6.4_Räume für Strahlendiagnostik", "6.5_Räume für Strahlentherapie", "6.6_Räume für Physiotherapie und Rehabilitation", "6.7_Bettenräume mit allgemeiner Ausstattung", "6.8_Bettenräume mit besonderer Ausstattung", "7.1_Sanitärräume", "7.2_Garderoben", "7.3_Abstellräume", "7.4_Fahrzeugabstellflächen", "7.5_Fahrgastflächen", "7.6_Räume für zentrale Technik", "7.7_Schutzräum", "8.1_Abwasseraufbereitung u. -beseitigung", "8.2_Wasserversorgung", "8.3_Heizung und Brauchwassererwärmung", "8.4_Gase und Flüssigkeiten", "8.5_Elektrische Stromversorgung", "8.6_Fernmeldetechnik", "8.7_Raumlufttechnische Anlagen", "8.8_Aufzugs- und Förderanlagen", "8.9_Sonstige betriebstechnische Anlagen", "9.1_Flure/Hallen", "9.2_Treppen", "9.3_Schächte für Förderanlagen", "9.4_Fahrzeugsverkehrsflächen", "10.1_aussenliegende Fahrzeugabstellflächen"] | Q14: Preview | R14: 2026-07-09T10:30+02:00 | S14: IFMA
F15: IFMA_V_31030012 | G15: Program use | H15: Raumnutzung | Q15: Preview | R15: 2026-07-09T10:30+02:00 | S15: IFMA
F16: IFMA_V_31030013 | G16: Room type | H16: Raumtyp | Q16: Preview | R16: 2026-07-09T10:30+02:00 | S16: IFMA
F17: IFMA_V_31030014 | G17: Unit type | H17: Einheitstyp | Q17: Preview | R17: 2026-07-09T10:30+02:00 | S17: IFMA
F18: IFMA_V_31030015 | G18: Unit ID | H18: Einheitsnummer | Q18: Preview | R18: 2026-07-09T10:30+02:00 | S18: IFMA
F19: IFMA_V_31030016 | G19: Operational room number | H19: Raumnummer Betrieb | Q19: Preview | R19: 2026-07-09T10:30+02:00 | S19: IFMA
F20: IFMA_V_31030017 | G20: Room signal label | H20: Raumbeschriftung | Q20: Preview | R20: 2026-07-09T10:30+02:00 | S20: IFMA
F21: IFMA_V_31030018 | G21: Cleaning group | H21: Reinigungsgruppe | Q21: Preview | R21: 2026-07-09T10:30+02:00 | S21: IFMA
F22: IFMA_V_31030019 | G22: Area load | H22: Flächenlast | Q22: Preview | R22: 2026-07-09T10:30+02:00 | S22: IFMA
F23: IFMA_V_31030020 | G23: Point load | H23: Punktlast | Q23: Preview | R23: 2026-07-09T10:30+02:00 | S23: IFMA
F24: IFMA_V_31030021 | G24: Energy reference area | H24: Energiebezugsfläche | K24: ["true", "false"] | L24: ["true", "false"] | M24: ["true", "false"] | Q24: Preview | R24: 2026-07-09T10:30+02:00 | S24: IFMA
F25: IFMA_V_31030022 | G25: Window area | H25: Fensterfläche | Q25: Preview | R25: 2026-07-09T10:30+02:00 | S25: IFMA
F26: IFMA_V_31030023 | G26: Window openable | H26: Fenster öffenbar | K26: ["true", "false"] | L26: ["true", "false"] | M26: ["true", "false"] | Q26: Preview | R26: 2026-07-09T10:30+02:00 | S26: IFMA
F27: IFMA_V_31030024 | G27: Occupant | H27: Raumnutzer | Q27: Preview | R27: 2026-07-09T10:30+02:00 | S27: IFMA
F28: IFMA_V_31030025 | G28: Solar shading | H28: Sonnenschutz | K28: ["true", "false"] | L28: ["true", "false"] | M28: ["true", "false"] | Q28: Preview | R28: 2026-07-09T10:30+02:00 | S28: IFMA
F29: IFMA_V_31030026 | G29: Humidified | H29: Befeuchtet | K29: ["true", "false"] | L29: ["true", "false"] | M29: ["true", "false"] | Q29: Preview | R29: 2026-07-09T10:30+02:00 | S29: IFMA
F30: IFMA_V_31030027 | G30: Dehumidified | H30: Entfeuchtet | K30: ["true", "false"] | L30: ["true", "false"] | M30: ["true", "false"] | Q30: Preview | R30: 2026-07-09T10:30+02:00 | S30: IFMA
F31: IFMA_V_31030028 | G31: Rentable | H31: Vermietbarkeit | K31: ["true", "false"] | L31: ["true", "false"] | M31: ["true", "false"] | Q31: Preview | R31: 2026-07-09T10:30+02:00 | S31: IFMA
