Workbook
Name Affectation_de_classe: Rules!$C$2:$C$47
Name Assegnazione_della_classe: Rules!$D$2:$D$47
Name Assegnazione_della_proprieta: Rules!$H$2:$H$47
Name Attribution_de_propriete: Rules!$G$2:$G$47
Name DataType: Rules!$I$2:$I$47
Name FAIR_Prinzipien: Rules!$M$2:$M$47
Name IFC_Data_Type: Rules!$J$2:$J$47
Name ISG___Informationssicherheitsgesetz: Rules!$L$2:$L$47
Name Klassen_Zuordnung: Rules!$B$2:$B$47
Name Klassifikation: Rules!$B$2:$B$47
Name LifecycleStatus: Rules!$N$2:$N$47
Name Markmals_Klassifikation: Rules!$F$2:$F$47
Name Merkmals_Zuordnung: Rules!$F$2:$F$47
Name Objekt_Einordnung: Rules!$A$2:$A$47
Name Property_Classification: Rules!$E$2:$E$47
Name Status: Rules!$K$2:$K$47

Sheet Impressum
B1: Data Dictionary - Flächenmanagement
B3: Dokumenteninformationen
C4: Status | D4: Entwurf
C5: Version | D5: v20260701
C6: Letzte Änderung | D6: 46204
C7: Autor | D7: Truong, Wendy / Joslyn, Alexander
C9: Trägerschaft
D10: IFMA
D11: Bauen digital Schweiz / buildingSMART Switzerland
B12: Projektteam
C13: Truong, Wendy | D13: IFMA
C14: Pick. Patrick | D14: IFMA
C15: Joslyn, Alexander | D15: Losinger Marazzi AG
B17: Abgrenzung | D17: Fokus auf Austauschformat IFC 4.3.2.0 (IFC4X3_ADD2)
D18: Andere Formate (z. B. CityGML, gbXML, LandXML) sind kein Bestandteil
D19: Keine Abbildung von Geodaten (Geologie, Topographie, Bewuchs, Gewässer)
D20: Strukturvorlage ist eine methodische Grundlage, kein vollständiger Data Dictionary
D21: Vollständige Datenkataloge müssen in Datenbanken realsiert werden
D22: Die Handlungsempfehlung ist keine Implementierungsrichtlinie für Softwareentwicklung
D23: Die Strukturvorlage ist ein Best Practice Beispiel und kann jederzeit an neue Anforderungen angepasst werden. Es wird davon abgeraten, auf der Basis der Strukturvorlage Applikationen oder Tools zu entwickeln.
D24: Keine konkrete Implementierung oder Vernetzung von Data Dictionaries
B27: Copyright | D27: https://creativecommons.org/licenses/by-nc-sa/4.0/

Sheet Anleitung
A1: Anleitung Strukturvorlage Data Dictionaries
B3: Inhaltsverzeichnis
B5: 1 | C5: Handhabung
B6: 2 | C6: Governance
B7: 3 | C7: Header (Kopfzeile)
B8: 4 | C8: Classes (Objekte)
B9: 5 | C9: Properties (Merkmale)
B10: 6 | C10: Values (Werte)
B11: 7 | C11: Documents (Dokument) | G11: Data Template (Datenvorlage)
B12: 8 | C12: GroupOfProperties (Merkmalsgruppen)
B14: Hinweise zur Handhabung
C16: A | D16: B | E16: C | F16: D | G16: E
B17: Hinweise zur Handhabung | C17: Erforderlich für Excel | D17: Sprachen | E17: Referenziert / System generiert | F17: Rules | G17: Erforderlich für Validierung
B18: A | C18: Erforderlich für Objektkatalog / Merkmalskatalog / Wertekatalog
C19: Definiert die Mindestanforderungen an einen Katalog. Unterscheidung zwischen yes = erforderlich / optional = bei Bedarf ergänzen / no = nicht notwendig
B20: B | C20: Sprachen
C21: Angabe zur Sprache: mehrsprachig = muss in der für den Katalog führenden Sprache enthalten sein
C22: EN, DE, FR, IT = gibt Sprache zwingend vor / neutral = nicht von Sprache abhängig
B23: C | C23: Regelt die Eingabe der Spalten
C24: Darf nicht vom Ersteller manuell ausgefüllt werden, sondern wird auf eine Quelle referenziert, resp. von eine Datenbank automatisch generiert
C25: referenced = Referenz auf anderen Katalog / system-generated = vom Zielsystem generiert
B26: D | C26: Vordefinierte Regeln
C27: Verweist auf die Dropdownliste in diesem Template
B28: E | C28: Erforderlich für eine automatische Validierung zur technischen Qualitätssicherung
C29: Gibt die Valdierungsregeln an, nach welchen die Spalteninhalte geprüft werden
A31: 2 | B31: Governance
B33: Vorgabe einer minimalen Governance für die verschiedenen Kataloge
B34: Optional können aller Regeln der SN EN ISO 23386 ergänzt werden
B36: A | C36: B | D36: C | E36: D | F36: E | G36: F | H36: G
B37: Governance | C37: Status | D37: Versionsdatum | E37: Herkunft (PROV) | F37: Regeln zur Festlegung von Merkmalen | G37: Regeln zur Festlegung von Merkmalsgruppen | H37: Management-Regeln für die Erstellung und Pflege
B38: B | C38: Vorgeschriebener Status des Merkmals während seines Lebenszyklus gemäss Liste (Enumeration)
B39: C | C39: Datum der Version. Format nach ISO 8601 = YYYY-MM-DDThh:mm:ssTDZ (T = festes Trennzeichen zwischen Datum und Uhrzeit / TDZ = Zeitzonenbezeichnung. Z = UTC, Abweichung zu UTC angeben)
C40: Beispiel: CET Zeit: 15:30 = UTC+2h > Korrekte Angabe: 2026-06-18T15:30+02:00
B41: D | C41: EN: PROV = Provenance, DE = Herkunft, Entstehungsgeschichte oder Nachweis der Datenherkunft
B42: E | C42: Um eindeutig, maschinenlesbar und für den Menschen verständlich zu sein, müssen Merkmale als Liste von Attributen festgelegt werden. Einige Attribute sind zwingend erforderlich und andere sind freigestellt.
C43: Hinweis: Entspricht PA002 bis PA040 - Attribute eines Merkmals
C44: Anwendung: Die Regeln zur Festlegung von Merkmalen müssen erst für über Datenbanken publizierte Data Dictionaries angewandt werden
B45: F | C45: Um eindeutig, maschinenlesbar und für den Menschen verständlich zu sein, müssen Merkmalsgruppen als Liste von Attributen festgelegt werden. Einige Attribute sind zwingend erforderlich und andere sind freigestellt.
C46: Hinweis: Entspricht GA001 bis GA02 - Attribute eines Merkmalsgruppe
C47: Anwendung: Die Regeln zur Festlegung von Merkmalsgruppen müssen erst für über Datenbanken publizierte Data Dictionaries angewandt werden
...

Sheet Header
A1: Data Dictionary — Core Metadata
A2: Field | B2: Value | C2: Requirement | D2: Notes / Maps to
A3: IDENTIFICATION
A4: OrganizationCode | B4: BdCH | C4: user defined name (small or capital letters), max 7 chars | D4: Short org code — lowercase, max 7 chars, appears in all derived IRIs
A5: DictionaryCode | B5: data_dictionary_area_management | C5: SYSTEM-GENERATED | D5: Generated from DictionaryName (EN)
A6: DictionaryName (EN) | B6: Data Dictionary Area Management | C6: REQUIRED | D6: Required authoring title in English — source for DictionaryCode generation
A7: DictionaryName (DE) | B7: Data Dictionary Flächenmanagement | C7: OPTIONAL | D7: Core authoring title in German — minimal DCAT
A8: DictionaryName (FR) | B8: Data Dictionary Gestion des zones | C8: OPTIONAL | D8: Optional multilingual title support
A9: DictionaryName (IT) | B9: Data Dictionary Gestione dell'area | C9: DictionaryName (IT) | D9: Optional multilingual title support
A10: DictionaryVersion | B10: 0.9.0 | C10: REQUIRED | D10: Semantic versioning: MAJOR.MINOR.PATCH
A11: DictionaryUri | B11: https://example.com/BdCH/data_dictionary_area_management | C11: SYSTEM-GENERATED | D11: Derived from OrganizationCode and DictionaryCode; canonical base pattern https://example.com/<OrganizationCode>/<DictionaryCode>
C12: Guide | D12: Private organisations may keep only this tab and delete Dictionary_public.
A13: GOVERNANCE
A14: LifecycleStatus | B14: Candidate | C14: REQUIRED | D14: Governance state used to derive i14y registration status
A16: LEGEND
A17: REQUIRED: | B17: Must be filled before validation/export
A18: OPTIONAL: | B18: Fill if available

Sheet Classes
A1: Filter | B1: Hinweise zur Handhabung | C1: Structural categorisation | D1: Domain/Domäne/Domaine/Dominio | E1: System/System/Système/Sistema | F1: Category/Kategorie/Catégorie/Categoria | G1: Classes | H1: GUID/URI | I1: Class-ID | J1: Class-Code | K1: Class-Assignment | L1: Klassen-Zuordnung (DE) | M1: Affectation de classe (FR) | N1: Assegnazione della classe (IT) | O1: Designation (EN) | P1: Bezeichnung (DE) | Q1: Désignation (FR) | R1: Designazione (IT) | S1: Description (EN) | T1: Beschreibung (DE) | U1: Description (FR) | V1: Descrizione (IT) | W1: IFC 4.3.2.0 (IFC4X3_ADD2) | X1: IFC_URI | Y1: IfcObject Entity | Z1: IfcTypeObject Entity | AA1: PredefinedType | AB1: ObjectType | AC1: Governance | AD1: Status | AE1: Version date | AF1: Provenance (PROV) | AG1: RelatedDocuments | AH1: RelatedDocumentName (EN) | AJ1: User Defined (not part of HE Data Dictionary / not validated by Validator)
B2: Erforderlich für Excel | D2: optional | E2: optional | F2: optional | H2: no | I2: no | J2: yes | K2: yes | O2: yes | P2: yes | Q2: optional | R2: optional | S2: ja | T2: ja | U2: optional | V2: optional | X2: yes | Y2: yes | Z2: yes | AA2: yes | AB2: yes | AD2: yes | AE2: yes | AF2: yes | AH2: optional
B3: Sprachen | D3: multilingual | E3: multilingual | F3: multilingual | H3: neutral | I3: neutral | J3: neutral | K3: multilingual | L3: DE | M3: FR | N3: IT | O3: EN | P3: DE | Q3: FR | R3: IT | S3: EN | T3: DE | U3: FR | V3: IT | X3: multilingual | Y3: multilingual | Z3: multilingual | AA3: multilingual | AB3: multilingual | AD3: EN | AE3: neutral | AF3: EN | AH3: EN
B4: Referenziert / System generiert | H4: referenced | I4: system-generated | L4: system-generated | M4: system-generated | N4: system-generated | X4: referenced | Y4: referenced | Z4: referenced | AA4: referenced | AB4: referenced | AD4: referenced | AE4: referenced | AF4: referenced | AH4: referenced
B5: Dropdown Liste | K5: Rules.Class-Assignment | L5: Rules.Klassen-Zuordnung | M5: Rules.Affectation de classe | N5: Rules.Assegnazione della classe | AD5: Rules.Status
B6: Validierung | D6: user defined | E6: user defined | F6: user defined | H6: not validated. Info: If available system-generated URI / user defined backend reference | I6: system-generated from Designation (EN) | J6: user defined | K6: must match Rules.Class-Assignment | L6: system-generated from Class-Assignment via Rules | M6: system-generated from Class-Assignment via Rules | N6: system-generated from Class-Assignment via Rules | O6: user defined | P6: user defined | Q6: user defined | R6: user defined | S6: user defined | T6: user defined | U6: user defined | V6: user defined | X6: validated against identifiers from https://search.bsdd.buildingsmart.org/uri/buildingsmart/ifc/4.3 | Y6: validated against IFC 4.3 entity identifiers | Z6: validated against IFC 4.3 entity identifiers | AA6: validated against IFC predefined types when applicable | AB6: validated against IFC 4.3 entity identifiers | AD6: must match Rules.Status | AE6: date format 2026-06-18T15:30+02:00 | AF6: user defined | AH6: must match a DocumentName (EN) entry from Documents.DocumentName (EN)
J7: BdCH_O_31010000 | K7: Spatial structure | L7: =IFERROR(INDEX(Rules!$B:$B,MATCH(K7,Rules!$A:$A,0)),"") | M7: =IFERROR(INDEX(Rules!$C:$C,MATCH(K7,Rules!$A:$A,0)),"") | N7: =IFERROR(INDEX(Rules!$D:$D,MATCH(K7,Rules!$A:$A,0)),"") | O7: Elevation | P7: Geschossebene | S7: The physical floor level or storey level of a building. | T7: Die physische Geschossebene bzw. Etage eines Gebäudes. | X7: https://identifier.buildingsmart.org/uri/buildingsmart/ifc/4.3/class/IfcBuildingStorey | Y7: IfcBuildingStorey | Z7: IfcBuildingStorey | AD7: Candidate | AE7: 2026-06-18T15:30+02:00 | AF7: BdCH | AH7: Document type catalogue
J8: BdCH_O_31010001 | K8: Spatial structure | L8: =IFERROR(INDEX(Rules!$B:$B,MATCH(K8,Rules!$A:$A,0)),"") | M8: =IFERROR(INDEX(Rules!$C:$C,MATCH(K8,Rules!$A:$A,0)),"") | N8: =IFERROR(INDEX(Rules!$D:$D,MATCH(K8,Rules!$A:$A,0)),"") | O8: Site area | P8: Grundstückfläche | S8: Site area (plot area according to SIA 416) | T8: Parzellenfläche (Grundstückfläche gemäss SIA 416) | X8: https://identifier.buildingsmart.org/uri/buildingsmart/ifc/4.3/class/IfcSite | Y8: IfcSite | Z8: IfcSite | AD8: Candidate | AE8: 2026-06-18T15:30+02:00 | AF8: BdCH | AH8: Document type catalogue
J9: BdCH_O_31010002 | K9: Spatial structure | L9: =IFERROR(INDEX(Rules!$B:$B,MATCH(K9,Rules!$A:$A,0)),"") | M9: =IFERROR(INDEX(Rules!$C:$C,MATCH(K9,Rules!$A:$A,0)),"") | N9: =IFERROR(INDEX(Rules!$D:$D,MATCH(K9,Rules!$A:$A,0)),"") | O9: Surrounding area | P9: Umgebungsfläche | S9: Surrounding area according to SIA 416 | T9: Umgebungsfläche gemäss SIA 416 | X9: https://identifier.buildingsmart.org/uri/buildingsmart/ifc/4.3/class/IfcSpace | Y9: IfcSpace | Z9: IfcSpace | AA9: USERDEFINED | AB9: SITE_AREA | AD9: Candidate | AE9: 2026-06-18T15:30+02:00 | AF9: BdCH | AH9: Document type catalogue
J10: BdCH_O_31010003 | K10: Spatial structure | L10: =IFERROR(INDEX(Rules!$B:$B,MATCH(K10,Rules!$A:$A,0)),"") | M10: =IFERROR(INDEX(Rules!$C:$C,MATCH(K10,Rules!$A:$A,0)),"") | N10: =IFERROR(INDEX(Rules!$D:$D,MATCH(K10,Rules!$A:$A,0)),"") | O10: Gross floor area | P10: Geschossvolumen | S10: Volumetric representation of gross floor areas and storey volumes according to SIA 416 | T10: Volumetrische Darstellung der Geschossflächen (brutto) und Geschossvolumen gemäss SIA 416 | X10: https://identifier.buildingsmart.org/uri/buildingsmart/ifc/4.3/class/IfcSpace | Y10: IfcSpace | Z10: IfcSpace | AA10: USERDEFINED | AB10: SURROUNDING_AREA | AD10: Candidate | AE10: 2026-06-18T15:30+02:00 | AF10: BdCH | AH10: Document type catalogue
J11: BdCH_O_31010004 | K11: Spatial structure | L11: =IFERROR(INDEX(Rules!$B:$B,MATCH(K11,Rules!$A:$A,0)),"") | M11: =IFERROR(INDEX(Rules!$C:$C,MATCH(K11,Rules!$A:$A,0)),"") | N11: =IFERROR(INDEX(Rules!$D:$D,MATCH(K11,Rules!$A:$A,0)),"") | O11: Room | P11: Nettogeschossfläche | S11: Internal spaces (net floor areas according to SIA 416) | T11: Innenräume (Nettogeschossflächen gemäss SIA 416) | U11: https://identifier.buildingsmart.org/uri/buildingsmart/ifc/4.3/class/IfcSpaceGFA | X11: https://identifier.buildingsmart.org/uri/buildingsmart/ifc/4.3/class/IfcSpaceGFA | Y11: IfcSpace | Z11: IfcSpace | AA11: GFA | AD11: Candidate | AE11: 2026-06-18T15:30+02:00 | AF11: BdCH | AH11: Document type catalogue
J12: BdCH_O_31010005 | K12: Spatial structure | L12: =IFERROR(INDEX(Rules!$B:$B,MATCH(K12,Rules!$A:$A,0)),"") | M12: =IFERROR(INDEX(Rules!$C:$C,MATCH(K12,Rules!$A:$A,0)),"") | N12: =IFERROR(INDEX(Rules!$D:$D,MATCH(K12,Rules!$A:$A,0)),"") | O12: External room | P12: Aussen-Nettogeschossfläche | S12: External spaces (external net floor areas according to SIA 416) | T12: Aussenräume (Aussen-Nettogeschossflächen gemäss SIA 416) | X12: https://identifier.buildingsmart.org/uri/buildingsmart/ifc/4.3/class/IfcSpace | Y12: IfcSpace | Z12: IfcSpace | AA12: USERDEFINED | AB12: ROOM | AD12: Candidate | AE12: 2026-06-18T15:30+02:00 | AF12: BdCH | AH12: Document type catalogue
J13: BdCH_O_31010006 | K13: Spatial structure | L13: =IFERROR(INDEX(Rules!$B:$B,MATCH(K13,Rules!$A:$A,0)),"") | M13: =IFERROR(INDEX(Rules!$C:$C,MATCH(K13,Rules!$A:$A,0)),"") | N13: =IFERROR(INDEX(Rules!$D:$D,MATCH(K13,Rules!$A:$A,0)),"") | O13: Parking space | P13: Stellplatz | S13: Parking spaces such as car parking spaces, moped parking, bicycle parking, fire service access/parking bays | T13: Stellplätze wie z.B. Autoparkplatz, Mofa-Parkplatz, Velostellplatz, Feuerwehrstellplatz | X13: https://identifier.buildingsmart.org/uri/buildingsmart/ifc/4.3/class/IfcSpace | Y13: IfcSpace | Z13: IfcSpace | AA13: USERDEFINED | AB13: EXTERNAL_ROOM | AD13: Candidate | AE13: 2026-06-18T15:30+02:00 | AF13: BdCH | AH13: Document type catalogue
J14: BdCH_O_31010007 | K14: Spatial structure | L14: =IFERROR(INDEX(Rules!$B:$B,MATCH(K14,Rules!$A:$A,0)),"") | M14: =IFERROR(INDEX(Rules!$C:$C,MATCH(K14,Rules!$A:$A,0)),"") | N14: =IFERROR(INDEX(Rules!$D:$D,MATCH(K14,Rules!$A:$A,0)),"") | O14: Rentable area | P14: Vermietbare Fläche | S14: Representation of lettable area where this differs from net floor areas | T14: Darstellung der vermietbaren Fläche, insofern diese von den Nettoraumflächen differiert | X14: https://identifier.buildingsmart.org/uri/buildingsmart/ifc/4.3/class/IfcSpacePARKING | Y14: IfcSpace | Z14: IfcSpace | AA14: PARKING | AD14: Candidate | AE14: 2026-06-18T15:30+02:00 | AF14: BdCH | AH14: Document type catalogue
M16: =IFERROR(INDEX(Rules!$C:$C,MATCH(K16,Rules!$A:$A,0)),"") | N16: =IFERROR(INDEX(Rules!$D:$D,MATCH(K16,Rules!$A:$A,0)),"")
L17: =IFERROR(INDEX(Rules!$B:$B,MATCH(K17,Rules!$A:$A,0)),"") | M17: =IFERROR(INDEX(Rules!$C:$C,MATCH(K17,Rules!$A:$A,0)),"") | N17: =IFERROR(INDEX(Rules!$D:$D,MATCH(K17,Rules!$A:$A,0)),"")
L18: =IFERROR(INDEX(Rules!$B:$B,MATCH(K18,Rules!$A:$A,0)),"") | M18: =IFERROR(INDEX(Rules!$C:$C,MATCH(K18,Rules!$A:$A,0)),"") | N18: =IFERROR(INDEX(Rules!$D:$D,MATCH(K18,Rules!$A:$A,0)),"")
L19: =IFERROR(INDEX(Rules!$B:$B,MATCH(K19,Rules!$A:$A,0)),"") | M19: =IFERROR(INDEX(Rules!$C:$C,MATCH(K19,Rules!$A:$A,0)),"") | N19: =IFERROR(INDEX(Rules!$D:$D,MATCH(K19,Rules!$A:$A,0)),"")
L20: =IFERROR(INDEX(Rules!$B:$B,MATCH(K20,Rules!$A:$A,0)),"") | M20: =IFERROR(INDEX(Rules!$C:$C,MATCH(K20,Rules!$A:$A,0)),"") | N20: =IFERROR(INDEX(Rules!$D:$D,MATCH(K20,Rules!$A:$A,0)),"")
L21: =IFERROR(INDEX(Rules!$B:$B,MATCH(K21,Rules!$A:$A,0)),"") | M21: =IFERROR(INDEX(Rules!$C:$C,MATCH(K21,Rules!$A:$A,0)),"") | N21: =IFERROR(INDEX(Rules!$D:$D,MATCH(K21,Rules!$A:$A,0)),"")
L22: =IFERROR(INDEX(Rules!$B:$B,MATCH(K22,Rules!$A:$A,0)),"") | M22: =IFERROR(INDEX(Rules!$C:$C,MATCH(K22,Rules!$A:$A,0)),"") | N22: =IFERROR(INDEX(Rules!$D:$D,MATCH(K22,Rules!$A:$A,0)),"")
L23: =IFERROR(INDEX(Rules!$B:$B,MATCH(K23,Rules!$A:$A,0)),"") | M23: =IFERROR(INDEX(Rules!$C:$C,MATCH(K23,Rules!$A:$A,0)),"") | N23: =IFERROR(INDEX(Rules!$D:$D,MATCH(K23,Rules!$A:$A,0)),"")
L24: =IFERROR(INDEX(Rules!$B:$B,MATCH(K24,Rules!$A:$A,0)),"") | M24: =IFERROR(INDEX(Rules!$C:$C,MATCH(K24,Rules!$A:$A,0)),"") | N24: =IFERROR(INDEX(Rules!$D:$D,MATCH(K24,Rules!$A:$A,0)),"")

Sheet Properties
A1: Filter | B1: Hinweise zur Handhabung | C1: Properties | D1: GUID/URI | E1: Property-ID | F1: Property-Code | G1: Property-Assignment | H1: Merkmals-Zuordnung (DE) | I1: Attribution de propriété (FR) | J1: Assegnazione della proprietà (IT) | K1: Designation (EN) | L1: Bezeichnung (DE) | M1: Désignation (FR) | N1: Designazione (IT) | O1: Description (EN) | P1: Beschreibung (DE) | Q1: Description (FR) | R1: Descrizione (IT) | S1: DataType (Base Type) | T1: DataType (IFC) | U1: EnumerationDesignation (EN) | V1: IFC 4.3.2.0 (IFC4X3_ADD2) | W1: IFC_URI | X1: IfcPropertySet (Pset) IfcQuantitySet (Qto) | Y1: Units/Einheit/Unité/Unità | Z1: Governance | AA1: Status | AB1: Version date | AC1: Provenance (PROV) | AE1: User Defined (not part of HE Data Dictionary / not validated by Validator)
B2: Erforderlich für Excel | D2: no | E2: no | F2: yes | G2: yes | K2: yes | L2: yes | M2: optional | N2: optional | O2: yes | P2: yes | Q2: optional | R2: optional | S2: yes | T2: yes | U2: yes | W2: yes | X2: yes | Y2: yes | AA2: yes | AB2: yes | AC2: yes
B3: Sprachen | D3: neutral | E3: neutral | F3: neutral | G3: neutral | H3: DE | I3: FR | J3: IT | K3: EN | L3: DE | M3: FR | N3: IT | O3: EN | P3: DE | Q3: FR | R3: IT | S3: neutral | T3: neutral | U3: EN | W3: neutral | X3: EN | Y3: neutral | AA3: EN | AB3: neutral | AC3: EN
B4: Referenziert / System generiert | D4: referenced | E4: system-generated | H4: system-generated | I4: system-generated | J4: system-generated | S4: referenced | T4: referenced | U4: referenced | W4: referenced | X4: referenced | AA4: referenced | AB4: referenced | AC4: referenced
B5: Dropdown Liste | G5: Rules.Property-Assignment | H5: Rules.Merkmals-Zuordnung | I5: Rules.Attribution de propriété | J5: Rules.Assegnazione della proprietà | S5: Rules.DataType | T5: Rules.IFC Data Type | AA5: Rules.Status
B6: Validierung | D6: not validated. Info: If available system-generated URI / user defined backend reference | E6: system-generated from Designation (EN) | F6: user defined | G6: must match Rules.Property-Assignment | H6: system-generated from Property-Assignment via Rules | I6: system-generated from Property-Assignment via Rules | J6: system-generated from Property-Assignment via Rules | K6: user defined | L6: user defined | M6: user defined | N6: user defined | O6: user defined | P6: user defined | Q6: user defined | R6: user defined | S6: must match Rules.DataType | T6: must match Rules.IFC Data Type | U6: must match a Designation (EN) entry from Values.Designation (EN) | W6: validated against identifiers from https://search.bsdd.buildingsmart.org/uri/buildingsmart/ifc/4.3 | X6: validated against IFC 4.3 property/quantity set identifiers when IFC_URI is present | Y6: user defined | AA6: must match Rules.Status | AB6: date format 2026-06-18T15:30+02:00 | AC6: user defined
F7: BdCH_P_31020002 | H7: =IFERROR(INDEX(Rules!$F:$F,MATCH(G7,Rules!$E:$E,0)),"") | I7: =IFERROR(INDEX(Rules!$G:$G,MATCH(G7,Rules!$E:$E,0)),"") | J7: =IFERROR(INDEX(Rules!$H:$H,MATCH(G7,Rules!$E:$E,0)),"") | K7: Name | L7: ID | O7: Unique room number or floor number according to numbering scheme | P7: Eindeutige Raumnummer bzw. Geschossnummer gemäss Nummerierungskonzept | S7: STRING | T7: IfcLabel | AA7: Candidate | AB7: 2026-06-18T15:30+02:00 | AC7: BdCH
F8: BdCH_P_31020003 | H8: =IFERROR(INDEX(Rules!$F:$F,MATCH(G8,Rules!$E:$E,0)),"") | I8: =IFERROR(INDEX(Rules!$G:$G,MATCH(G8,Rules!$E:$E,0)),"") | J8: =IFERROR(INDEX(Rules!$H:$H,MATCH(G8,Rules!$E:$E,0)),"") | K8: LongName | L8: Raumbezeichnung | O8: Designation | P8: Bezeichnung | S8: STRING | T8: IfcLabel | AA8: Candidate | AB8: 2026-06-18T15:30+02:00 | AC8: BdCH
F9: BdCH_P_31020004 | H9: =IFERROR(INDEX(Rules!$F:$F,MATCH(G9,Rules!$E:$E,0)),"") | I9: =IFERROR(INDEX(Rules!$G:$G,MATCH(G9,Rules!$E:$E,0)),"") | J9: =IFERROR(INDEX(Rules!$H:$H,MATCH(G9,Rules!$E:$E,0)),"") | K9: SIA_416_2003_Code | L9: Flächenart SIA 416 Code | O9: Classification according to SIA 416 / 2003 | P9: Klassifizierung gemäss SIA 416 / 2003 | S9: STRING | T9: IfcLabel | U9: Area type SIA 416 code | AA9: Candidate | AB9: 2026-06-18T15:30+02:00 | AC9: BdCH
F10: BdCH_P_31020005 | H10: =IFERROR(INDEX(Rules!$F:$F,MATCH(G10,Rules!$E:$E,0)),"") | I10: =IFERROR(INDEX(Rules!$G:$G,MATCH(G10,Rules!$E:$E,0)),"") | J10: =IFERROR(INDEX(Rules!$H:$H,MATCH(G10,Rules!$E:$E,0)),"") | K10: SIA_416_2003_Label | L10: Flächenart SIA 416 Label | O10: Classification according to SIA 416 / 2003 | P10: Klassifizierung gemäss SIA 416 / 2003 | S10: STRING | T10: IfcLabel | U10: Area type SIA 416 label | AA10: Candidate | AB10: 2026-06-18T15:30+02:00 | AC10: BdCH
F11: BdCH_P_31020006 | H11: =IFERROR(INDEX(Rules!$F:$F,MATCH(G11,Rules!$E:$E,0)),"") | I11: =IFERROR(INDEX(Rules!$G:$G,MATCH(G11,Rules!$E:$E,0)),"") | J11: =IFERROR(INDEX(Rules!$H:$H,MATCH(G11,Rules!$E:$E,0)),"") | K11: SIA_380_2015_Code | L11: Raumbezeichnung SIA 380 Code | O11: Classification according to SIA 380 / 2015 | P11: Klassifizierung gemäss SIA 380 / 2015 | S11: STRING | T11: IfcLabel | U11: Room designation SIA 380 code | AA11: Candidate | AB11: 2026-06-18T15:30+02:00 | AC11: BdCH
F12: BdCH_P_31020007 | H12: =IFERROR(INDEX(Rules!$F:$F,MATCH(G12,Rules!$E:$E,0)),"") | I12: =IFERROR(INDEX(Rules!$G:$G,MATCH(G12,Rules!$E:$E,0)),"") | J12: =IFERROR(INDEX(Rules!$H:$H,MATCH(G12,Rules!$E:$E,0)),"") | K12: SIA_380_2015_Label | L12: Raumbezeichnung SIA 380 Label | O12: Classification according to SIA 380 / 2015 | P12: Klassifizierung gemäss SIA 380 / 2015 | S12: STRING | T12: IfcLabel | U12: Room designation SIA 380 label | AA12: Candidate | AB12: 2026-06-18T15:30+02:00 | AC12: BdCH
F13: BdCH_P_31020008 | H13: =IFERROR(INDEX(Rules!$F:$F,MATCH(G13,Rules!$E:$E,0)),"") | I13: =IFERROR(INDEX(Rules!$G:$G,MATCH(G13,Rules!$E:$E,0)),"") | J13: =IFERROR(INDEX(Rules!$H:$H,MATCH(G13,Rules!$E:$E,0)),"") | K13: SIA_2024_2021_Code | L13: Raumnutzung SIA 2024 Code | O13: Classification according to SIA 2024 / 2021 | P13: Klassifizierung gemäss SIA 2024 / 2021 | S13: STRING | T13: IfcLabel | U13: Room usage SIA 2024 code | AA13: Candidate | AB13: 2026-06-18T15:30+02:00 | AC13: BdCH
F14: BdCH_P_31020009 | H14: =IFERROR(INDEX(Rules!$F:$F,MATCH(G14,Rules!$E:$E,0)),"") | I14: =IFERROR(INDEX(Rules!$G:$G,MATCH(G14,Rules!$E:$E,0)),"") | J14: =IFERROR(INDEX(Rules!$H:$H,MATCH(G14,Rules!$E:$E,0)),"") | K14: SIA_2024_2021_Label | L14: Raumnutzung SIA 2024 Label | O14: Classification according to SIA 2024 / 2021 | P14: Klassifizierung gemäss SIA 2024 / 2021 | S14: STRING | T14: IfcLabel | U14: Room usage SIA 2024 label | AA14: Candidate | AB14: 2026-06-18T15:30+02:00 | AC14: BdCH
F15: BdCH_P_31020010 | H15: =IFERROR(INDEX(Rules!$F:$F,MATCH(G15,Rules!$E:$E,0)),"") | I15: =IFERROR(INDEX(Rules!$G:$G,MATCH(G15,Rules!$E:$E,0)),"") | J15: =IFERROR(INDEX(Rules!$H:$H,MATCH(G15,Rules!$E:$E,0)),"") | K15: SIA_d0615_2000_Code | L15: Flächenart d0165 Code | O15: Classification according to SIA D 0165 / 2000 | P15: Klassifizierung gemäss SIA D 0165 / 2000 | S15: STRING | T15: IfcLabel | U15: Area type d0165 code | AA15: Candidate | AB15: 2026-06-18T15:30+02:00 | AC15: BdCH
F16: BdCH_P_31020011 | H16: =IFERROR(INDEX(Rules!$F:$F,MATCH(G16,Rules!$E:$E,0)),"") | I16: =IFERROR(INDEX(Rules!$G:$G,MATCH(G16,Rules!$E:$E,0)),"") | J16: =IFERROR(INDEX(Rules!$H:$H,MATCH(G16,Rules!$E:$E,0)),"") | K16: SIA_d0615_2000_Label | L16: Flächenart d0165 Label | O16: Classification according to SIA D 0165 / 2000 | P16: Klassifizierung gemäss SIA D 0165 / 2000 | S16: STRING | T16: IfcLabel | U16: Area type d0165 label | AA16: Candidate | AB16: 2026-06-18T15:30+02:00 | AC16: BdCH
F17: BdCH_P_31020012 | H17: =IFERROR(INDEX(Rules!$F:$F,MATCH(G17,Rules!$E:$E,0)),"") | I17: =IFERROR(INDEX(Rules!$G:$G,MATCH(G17,Rules!$E:$E,0)),"") | J17: =IFERROR(INDEX(Rules!$H:$H,MATCH(G17,Rules!$E:$E,0)),"") | K17: ProgramUse | L17: Raumnutzung | O17: Room usage according to room programme | P17: Raumnutzung gemäss Raumprogramm | S17: STRING | T17: IfcLabel | U17: Program use | AA17: Candidate | AB17: 2026-06-18T15:30+02:00 | AC17: BdCH
F18: BdCH_P_31020013 | H18: =IFERROR(INDEX(Rules!$F:$F,MATCH(G18,Rules!$E:$E,0)),"") | I18: =IFERROR(INDEX(Rules!$G:$G,MATCH(G18,Rules!$E:$E,0)),"") | J18: =IFERROR(INDEX(Rules!$H:$H,MATCH(G18,Rules!$E:$E,0)),"") | K18: RoomType | L18: Raumtyp | O18: Room type (functional type) according to room catalogue (room data sheets) | P18: Raumtyp (Funktionstyp) gemäss Raumkatalog (Raumdatenblätter) | S18: STRING | T18: IfcLabel | U18: Room type | AA18: Candidate | AB18: 2026-06-18T15:30+02:00 | AC18: BdCH
F19: BdCH_P_31020014 | H19: =IFERROR(INDEX(Rules!$F:$F,MATCH(G19,Rules!$E:$E,0)),"") | I19: =IFERROR(INDEX(Rules!$G:$G,MATCH(G19,Rules!$E:$E,0)),"") | J19: =IFERROR(INDEX(Rules!$H:$H,MATCH(G19,Rules!$E:$E,0)),"") | K19: UnitType | L19: Einheitstyp | O19: Unit type, in particular dwelling type (e.g. 3.5-room flat) | P19: Einheitstyp, insb. Wohnungstyp z.B. 3,5-Zi | S19: STRING | T19: IfcLabel | U19: Unit type | AA19: Candidate | AB19: 2026-06-18T15:30+02:00 | AC19: BdCH
F20: BdCH_P_31020015 | H20: =IFERROR(INDEX(Rules!$F:$F,MATCH(G20,Rules!$E:$E,0)),"") | I20: =IFERROR(INDEX(Rules!$G:$G,MATCH(G20,Rules!$E:$E,0)),"") | J20: =IFERROR(INDEX(Rules!$H:$H,MATCH(G20,Rules!$E:$E,0)),"") | K20: Unit_ID | L20: Einheitsnummer | O20: Unique unit number (ID) according to numbering scheme for sale or rental units (e.g. apartment number) | P20: Eindeutige Einheitsnummer (ID) gemäss Nummerierungskonzept für Verkaufs- bzw. Mieteinheiten, z.B. Wohnungsnummer | S20: STRING | T20: IfcLabel | U20: Unit ID | AA20: Candidate | AB20: 2026-06-18T15:30+02:00 | AC20: BdCH
... F33: BdCH_P_31020028 | H33: =IFERROR(INDEX(Rules!$F:$F,MATCH(G33,Rules!$E:$E,0)),"") | I33: =IFERROR(INDEX(Rules!$G:$G,MATCH(G33,Rules!$E:$E,0)),"") | J33: =IFERROR(INDEX(Rules!$H:$H,MATCH(G33,Rules!$E:$E,0)),"") | K33: IsRentable | L33: Vermietbarkeit | O33: Letting suitability | P33: Vermietbarkeit | S33: BOOLEAN | T33: IfcBoolean | U33: Rentable | AA33: Candidate | AB33: 2026-06-18T15:30+02:00 | AC33: BdCH
F34: BdCH_P_31020029 | H34: =IFERROR(INDEX(Rules!$F:$F,MATCH(G34,Rules!$E:$E,0)),"") | I34: =IFERROR(INDEX(Rules!$G:$G,MATCH(G34,Rules!$E:$E,0)),"") | J34: =IFERROR(INDEX(Rules!$H:$H,MATCH(G34,Rules!$E:$E,0)),"") | K34: IsExternal | L34: Aussenraum | O34: Indicates whether the element is intended for outdoor use (TRUE) or not (FALSE). If set to (TRUE), the element is an external element that forms the outer boundary of a building. | P34: Angabe, ob das Element für die Verwendung im Aussenbereich vorgesehen ist (TRUE) oder nicht (FALSE). Bei (TRUE) handelt es sich um ein Aussenelement, das ein Gebäude nach außen abschliesst. | S34: BOOLEAN | T34: IfcBoolean | U34: External space | W34: https://identifier.buildingsmart.org/uri/buildingsmart/ifc/4.3/prop/IsExternal | X34: Pset_SpaceCommon | AA34: Candidate | AB34: 2026-06-18T15:30+02:00 | AC34: BdCH
F35: BdCH_P_31020030 | H35: =IFERROR(INDEX(Rules!$F:$F,MATCH(G35,Rules!$E:$E,0)),"") | I35: =IFERROR(INDEX(Rules!$G:$G,MATCH(G35,Rules!$E:$E,0)),"") | J35: =IFERROR(INDEX(Rules!$H:$H,MATCH(G35,Rules!$E:$E,0)),"") | K35: OccupancyType | L35: Nutzungsart | O35: Occupancy type for this object.; It is defined according to the presiding national building code. | P35: Nutzungsart dieses Objekts; sie wird gemäss den geltenden nationalen Bauvorschriften definiert. | S35: STRING | T35: IfcLabel | U35: Occupancy type | W35: https://identifier.buildingsmart.org/uri/buildingsmart/ifc/4.3/prop/OccupancyType | X35: Pset_SpaceOccupancyRequirements | AA35: Candidate | AB35: 2026-06-18T15:30+02:00 | AC35: BdCH
F36: BdCH_P_31020031 | H36: =IFERROR(INDEX(Rules!$F:$F,MATCH(G36,Rules!$E:$E,0)),"") | I36: =IFERROR(INDEX(Rules!$G:$G,MATCH(G36,Rules!$E:$E,0)),"") | J36: =IFERROR(INDEX(Rules!$H:$H,MATCH(G36,Rules!$E:$E,0)),"") | K36: MinimumHeadroom | L36: Raumnutzhöhe | O36: Effective clear height | P36: Lichte Höhe | S36: REAL | T36: IfcLengthMeasure | U36: Headroom | X36: Pset_SpaceOccupancyRequirements | AA36: Candidate | AB36: 2026-06-18T15:30+02:00 | AC36: BdCH
F37: BdCH_P_31020032 | H37: =IFERROR(INDEX(Rules!$F:$F,MATCH(G37,Rules!$E:$E,0)),"") | I37: =IFERROR(INDEX(Rules!$G:$G,MATCH(G37,Rules!$E:$E,0)),"") | J37: =IFERROR(INDEX(Rules!$H:$H,MATCH(G37,Rules!$E:$E,0)),"") | K37: OccupancyNumberPeak | L37: Personenbelegung geplant | O37: Maximal number of people required for the activity assigned to this space in peak time. | P37: Maximale Anzahl Personen für die zugewiesene Nutzung dieses Raums in Spitzenzeiten. | S37: INTEGER | T37: IfcInteger | U37: Planned occupancy | W37: https://identifier.buildingsmart.org/uri/buildingsmart/ifc/4.3/prop/OccupancyNumberPeak | X37: Pset_SpaceOccupancyRequirements | AA37: Candidate | AB37: 2026-06-18T15:30+02:00 | AC37: BdCH
F38: BdCH_P_31020033 | H38: =IFERROR(INDEX(Rules!$F:$F,MATCH(G38,Rules!$E:$E,0)),"") | I38: =IFERROR(INDEX(Rules!$G:$G,MATCH(G38,Rules!$E:$E,0)),"") | J38: =IFERROR(INDEX(Rules!$H:$H,MATCH(G38,Rules!$E:$E,0)),"") | K38: OccupancyNumber | L38: Personenbelegung ist | O38: Number of people required for the activity assigned to this space. | P38: Anzahl Personen für die zugewiesene Nutzung dieses Raums. | S38: INTEGER | T38: IfcInteger | U38: Actual occupancy | W38: https://identifier.buildingsmart.org/uri/buildingsmart/ifc/4.3/prop/OccupancyNumber | X38: Pset_SpaceOccupancyRequirements | AA38: Candidate | AB38: 2026-06-18T15:30+02:00 | AC38: BdCH
F39: BdCH_P_31020034 | H39: =IFERROR(INDEX(Rules!$F:$F,MATCH(G39,Rules!$E:$E,0)),"") | I39: =IFERROR(INDEX(Rules!$G:$G,MATCH(G39,Rules!$E:$E,0)),"") | J39: =IFERROR(INDEX(Rules!$H:$H,MATCH(G39,Rules!$E:$E,0)),"") | K39: FloorCovering | L39: Bodenbelag | O39: Label to indicate the material or finish of the space flooring. The label is used for room book information and often displayed in room stamp.The material information is provided in absence of an Covering (type=FLOORING) object with own shape representation and material assignment. In case of inconsistency the material assigned to Covering elements takes precedence. | P39: Kennzeichnung des Materials bzw. der Oberfläche des Bodenbelags im Raum. Die Kennzeichnung wird für Raumbuchinformationen verwendet und häufig im Raumstempel angezeigt. Die Materialinformation wird bereitgestellt, sofern kein Covering-Objekt (Typ=FLOORING) mit eigener Geometrie und Materialzuweisung vorhanden ist. Bei Inkonsistenzen hat die Materialzuweisung der Covering-Elemente Vorrang. | S39: STRING | T39: IfcLabel | U39: Floor covering | W39: https://identifier.buildingsmart.org/uri/buildingsmart/ifc/4.3/prop/FloorCovering | X39: Pset_SpaceCoveringRequirements | AA39: Candidate | AB39: 2026-06-18T15:30+02:00 | AC39: BdCH
F40: BdCH_P_31020035 | H40: =IFERROR(INDEX(Rules!$F:$F,MATCH(G40,Rules!$E:$E,0)),"") | I40: =IFERROR(INDEX(Rules!$G:$G,MATCH(G40,Rules!$E:$E,0)),"") | J40: =IFERROR(INDEX(Rules!$H:$H,MATCH(G40,Rules!$E:$E,0)),"") | K40: WallCovering | L40: Wandbelag | O40: Label to indicate the material or finish of the space cladding. The label is used for room book information and often displayed in room stamp.The material information is provided in absence of an Covering (type=CLADDING) object with own shape representation and material assignment. In case of inconsistency the material assigned to Covering elements takes precedence | P40: Kennzeichnung des Materials bzw. der Oberfläche der Wandbekleidung im Raum. Die Kennzeichnung wird für Raumbuchinformationen verwendet und häufig im Raumstempel angezeigt. Die Materialinformation wird bereitgestellt, sofern kein Covering-Objekt (Typ=CLADDING) mit eigener Geometrie und Materialzuweisung vorhanden ist. Bei Inkonsistenzen hat die Materialzuweisung der Covering-Elemente Vorrang. | S40: STRING | T40: IfcLabel | U40: Wall covering | W40: https://identifier.buildingsmart.org/uri/buildingsmart/ifc/4.3/prop/WallCovering | X40: Pset_SpaceCoveringRequirements | AA40: Candidate | AB40: 2026-06-18T15:30+02:00 | AC40: BdCH
F41: BdCH_P_31020036 | H41: =IFERROR(INDEX(Rules!$F:$F,MATCH(G41,Rules!$E:$E,0)),"") | I41: =IFERROR(INDEX(Rules!$G:$G,MATCH(G41,Rules!$E:$E,0)),"") | J41: =IFERROR(INDEX(Rules!$H:$H,MATCH(G41,Rules!$E:$E,0)),"") | K41: CeilingCovering | L41: Deckenmaterial | O41: Label to indicate the material or finish of the space ceiling. The label is used for room book information and often displayed in room stamp.The material information is provided in absence of an Covering (type=[[CEILING]]) object with own shape representation and material assignment. In case of inconsistency the material assigned to Covering elements takes precedence. | P41: Kennzeichnung des Materials bzw. der Oberfläche der Raumdecke. Die Kennzeichnung wird für Raumbuchinformationen verwendet und häufig im Raumstempel angezeigt. Die Materialinformation wird bereitgestellt, sofern kein Covering-Objekt (Typ=CEILING) mit eigener Geometrie und Materialzuweisung vorhanden ist. Bei Inkonsistenzen hat die Materialzuweisung der Covering-Elemente Vorrang. | S41: STRING | T41: IfcLabel | U41: Ceiling covering | W41: https://identifier.buildingsmart.org/uri/buildingsmart/ifc/4.3/prop/CeilingCovering | X41: Pset_SpaceCoveringRequirements | AA41: Candidate | AB41: 2026-06-18T15:30+02:00 | AC41: BdCH
F42: BdCH_P_31020037 | H42: =IFERROR(INDEX(Rules!$F:$F,MATCH(G42,Rules!$E:$E,0)),"") | I42: =IFERROR(INDEX(Rules!$G:$G,MATCH(G42,Rules!$E:$E,0)),"") | J42: =IFERROR(INDEX(Rules!$H:$H,MATCH(G42,Rules!$E:$E,0)),"") | K42: NaturalVentilation | L42: Natürliche Belüftung | O42: Indication whether the space is required to have natural ventilation (TRUE), or not (FALSE). | P42: Angabe, ob für den Raum natürliche Lüftung erforderlich ist (TRUE) oder nicht (FALSE). | S42: BOOLEAN | T42: IfcBoolean | U42: Natural ventilation | W42: https://identifier.buildingsmart.org/uri/buildingsmart/ifc/4.3/prop/NaturalVentilation | AA42: Candidate | AB42: 2026-06-18T15:30+02:00 | AC42: BdCH
F43: BdCH_P_31020038 | H43: =IFERROR(INDEX(Rules!$F:$F,MATCH(G43,Rules!$E:$E,0)),"") | I43: =IFERROR(INDEX(Rules!$G:$G,MATCH(G43,Rules!$E:$E,0)),"") | J43: =IFERROR(INDEX(Rules!$H:$H,MATCH(G43,Rules!$E:$E,0)),"") | K43: NaturalVentilationRate | L43: Natürliche Luftwechselrate | O43: Indication of the requirement of a particular natural air ventilation rate, given in air changes per hour. | P43: Angabe der erforderlichen natürlichen Luftwechselrate (in Luftwechseln pro Stunde). | S43: REAL | T43: IfcVolumetricFlowRateMeasure | U43: Natural ventilation rate | W43: https://identifier.buildingsmart.org/uri/buildingsmart/ifc/4.3/prop/NaturalVentilationRate | AA43: Candidate | AB43: 2026-06-18T15:30+02:00 | AC43: BdCH
F44: BdCH_P_31020039 | H44: =IFERROR(INDEX(Rules!$F:$F,MATCH(G44,Rules!$E:$E,0)),"") | I44: =IFERROR(INDEX(Rules!$G:$G,MATCH(G44,Rules!$E:$E,0)),"") | J44: =IFERROR(INDEX(Rules!$H:$H,MATCH(G44,Rules!$E:$E,0)),"") | K44: MechanicalVentilation | L44: Mechanische Belüftung | O44: Indication whether the space is required to have mechanical ventilation (TRUE), or not (FALSE). | P44: Angabe, ob für den Raum mechanische Lüftung erforderlich ist (TRUE) oder nicht (FALSE). | S44: BOOLEAN | T44: IfcBoolean | U44: Mechanical ventilation | W44: https://identifier.buildingsmart.org/uri/buildingsmart/ifc/4.3/prop/MechanicalVentilation | AA44: Candidate | AB44: 2026-06-18T15:30+02:00 | AC44: BdCH
F45: BdCH_P_31020040 | H45: =IFERROR(INDEX(Rules!$F:$F,MATCH(G45,Rules!$E:$E,0)),"") | I45: =IFERROR(INDEX(Rules!$G:$G,MATCH(G45,Rules!$E:$E,0)),"") | J45: =IFERROR(INDEX(Rules!$H:$H,MATCH(G45,Rules!$E:$E,0)),"") | K45: MechanicalVentilationRate | L45: Mechanische Luftwechselrate | O45: Indication of the requirement of a particular mechanical air ventilation rate, given in air changes per hour. | P45: Angabe der erforderlichen mechanischen Luftwechselrate (in Luftwechseln pro Stunde). | S45: REAL | T45: IfcVolumetricFlowRateMeasure | U45: Mechanical ventilation rate | W45: https://identifier.buildingsmart.org/uri/buildingsmart/ifc/4.3/prop/MechanicalVentilationRate | AA45: Candidate | AB45: 2026-06-18T15:30+02:00 | AC45: BdCH
F46: BdCH_P_31020041 | H46: =IFERROR(INDEX(Rules!$F:$F,MATCH(G46,Rules!$E:$E,0)),"") | I46: =IFERROR(INDEX(Rules!$G:$G,MATCH(G46,Rules!$E:$E,0)),"") | J46: =IFERROR(INDEX(Rules!$H:$H,MATCH(G46,Rules!$E:$E,0)),"") | K46: AirConditioning | L46: Klimatisiert | O46: Indication whether this space requires air conditioning provided (TRUE) or not (FALSE). | P46: Angabe, ob für diesen Raum eine Klimatisierung erforderlich ist (TRUE) oder nicht (FALSE). | S46: BOOLEAN | T46: IfcBoolean | U46: Air conditioning | W46: https://identifier.buildingsmart.org/uri/buildingsmart/ifc/4.3/prop/AirConditioning | AA46: Candidate | AB46: 2026-06-18T15:30+02:00 | AC46: BdCH
F47: BdCH_P_31020042 | H47: =IFERROR(INDEX(Rules!$F:$F,MATCH(G47,Rules!$E:$E,0)),"") | I47: =IFERROR(INDEX(Rules!$G:$G,MATCH(G47,Rules!$E:$E,0)),"") | J47: =IFERROR(INDEX(Rules!$H:$H,MATCH(G47,Rules!$E:$E,0)),"") | K47: TemperatureSetPoint | L47: Temperatur Ziel | O47: The temperature setpoint range and default setpoint. | P47: Temperatur-Sollwertbereich und Standard-Sollwert. | S47: REAL | T47: IfcThermodynamicTemperatureMeasure | U47: Temperature set point | W47: https://identifier.buildingsmart.org/uri/buildingsmart/ifc/4.3/prop/TemperatureSetPoint | AA47: Candidate | AB47: 2026-06-18T15:30+02:00 | AC47: BdCH
F48: BdCH_P_31020043 | H48: =IFERROR(INDEX(Rules!$F:$F,MATCH(G48,Rules!$E:$E,0)),"") | I48: =IFERROR(INDEX(Rules!$G:$G,MATCH(G48,Rules!$E:$E,0)),"") | J48: =IFERROR(INDEX(Rules!$H:$H,MATCH(G48,Rules!$E:$E,0)),"") | K48: HumiditySetPoint | L48: Luftfeuchtigkeit Ziel | O48: Humidity of the space or zone that is required from user/designer view point. If no summer or winter space humidity requirements are given, it applies all year, otherwise for the intermediate period. Provide this property, if no humidity range (Min-Max) is available. | P48: Geforderte Luftfeuchtigkeit des Raums bzw. der Zone aus Sicht Nutzer/Planer. Falls keine sommer- oder winterbezogenen Anforderungen angegeben sind, gilt der Wert ganzjährig, ansonsten für die Übergangszeit. Diese Eigenschaft ist anzugeben, sofern kein Feuchtebereich (Min–Max) verfügbar ist. | S48: REAL | T48: IfcReal | U48: Humidity set point | W48: https://identifier.buildingsmart.org/uri/buildingsmart/ifc/4.3/prop/HumiditySetPoint | AA48: Candidate | AB48: 2026-06-18T15:30+02:00 | AC48: BdCH
F49: BdCH_P_31020044 | H49: =IFERROR(INDEX(Rules!$F:$F,MATCH(G49,Rules!$E:$E,0)),"") | I49: =IFERROR(INDEX(Rules!$G:$G,MATCH(G49,Rules!$E:$E,0)),"") | J49: =IFERROR(INDEX(Rules!$H:$H,MATCH(G49,Rules!$E:$E,0)),"") | K49: FireExit | L49: Fluchtweg | O49: Indication whether this object is designed to serve as an exit in the case of fire (TRUE) or not (FALSE). | P49: Angabe, ob dieses Objekt im Brandfall als Ausgang dient (TRUE) oder nicht (FALSE). | S49: BOOLEAN | T49: IfcBoolean | U49: Fire exit | W49: https://identifier.buildingsmart.org/uri/buildingsmart/ifc/4.3/prop/FireExit | X49: Pset_SpaceFireSafetyRequirements | AA49: Candidate | AB49: 2026-06-18T15:30+02:00 | AC49: BdCH
F50: BdCH_P_31020045 | H50: =IFERROR(INDEX(Rules!$F:$F,MATCH(G50,Rules!$E:$E,0)),"") | I50: =IFERROR(INDEX(Rules!$G:$G,MATCH(G50,Rules!$E:$E,0)),"") | J50: =IFERROR(INDEX(Rules!$H:$H,MATCH(G50,Rules!$E:$E,0)),"") | K50: GrossFloorArea | L50: Bruttofläche | O50: Sum of all gross floor areas within the spatial structure element | P50: Summe aller Bruttogrundflächen innerhalb des räumlichen Strukturelements. | S50: REAL | T50: IfcAreaMeasure | U50: Gross floor area | W50: https://identifier.buildingsmart.org/uri/buildingsmart/ifc/4.3/prop/GrossFloorArea | X50: Qto_SpaceBaseQuantities | AA50: Candidate | AB50: 2026-06-18T15:30+02:00 | AC50: BdCH
F51: BdCH_P_31020046 | H51: =IFERROR(INDEX(Rules!$F:$F,MATCH(G51,Rules!$E:$E,0)),"") | I51: =IFERROR(INDEX(Rules!$G:$G,MATCH(G51,Rules!$E:$E,0)),"") | J51: =IFERROR(INDEX(Rules!$H:$H,MATCH(G51,Rules!$E:$E,0)),"") | K51: GrossVolume | L51: Bruttovolumen | O51: Total gross volume of the object. Openings, recesses, enclosed objects and projections are not taken into account. | P51: Gesamtes Bruttovolumen des Objekts. Öffnungen, Aussparungen, eingeschlossene Objekte und Vorsprünge werden nicht berücksichtigt. | S51: REAL | T51: IfcVolumeMeasure | U51: Gross volume | W51: https://identifier.buildingsmart.org/uri/buildingsmart/ifc/4.3/prop/GrossVolume | X51: Qto_SpaceBaseQuantities | AA51: Candidate | AB51: 2026-06-18T15:30+02:00 | AC51: BdCH
F52: BdCH_P_31020047 | H52: =IFERROR(INDEX(Rules!$F:$F,MATCH(G52,Rules!$E:$E,0)),"") | I52: =IFERROR(INDEX(Rules!$G:$G,MATCH(G52,Rules!$E:$E,0)),"") | J52: =IFERROR(INDEX(Rules!$H:$H,MATCH(G52,Rules!$E:$E,0)),"") | K52: NetFloorArea | L52: Nettofläche | O52: Sum of all net usable floor areas. | P52: Summe aller Nettogrundflächen. | S52: REAL | T52: IfcAreaMeasure | U52: Net floor area | W52: https://identifier.buildingsmart.org/uri/buildingsmart/ifc/4.3/prop/NetFloorArea | X52: Qto_SpaceBaseQuantities | AA52: Candidate | AB52: 2026-06-18T15:30+02:00 | AC52: BdCH
...

Sheet Values
A1: Filter | B1: Hinweise zur Handhabung | C1: Enumerations | D1: GUID/URI | E1: Enumeration-ID | F1: Enumeration-Code | G1: Designation (EN) | H1: Bezeichnung (DE) | I1: Désignation (FR) | J1: Designazione (IT) | K1: Enumeration (EN) | L1: Werteliste (DE) | M1: Liste de valeurs (FR) | N1: Lista valori (IT) | O1: Units/Einheit/Unité/Unità | P1: Governance | Q1: Status | R1: Version date | S1: Provenance (PROV) | U1: User Defined (not part of HE Data Dictionary / not validated by Validator)
B2: Erforderlich für Excel | D2: no | E2: no | F2: yes | G2: yes | H2: yes | I2: optional | J2: optional | K2: yes | L2: yes | M2: optional | N2: optional | O2: yes | Q2: yes | R2: yes | S2: yes
B3: Sprachen | D3: neutral | E3: EN | F3: neutral | G3: EN | H3: DE | I3: FR | J3: IT | K3: EN | L3: DE | M3: FR | N3: IT | O3: multilingual | Q3: EN | R3: neutral | S3: EN
B4: Referenziert / System generiert | D4: system-generated | E4: system-generated | Q4: referenced | R4: referenced | S4: referenced
B5: Dropdown Liste | Q5: Rules.Status
B6: Validierung | D6: not validated. Info: If available system-generated URI / user defined backend reference | E6: system-generated from Designation (EN) | F6: user defined | G6: user defined | H6: user defined | I6: user defined | J6: user defined | K6: must use JSON-style list syntax, e.g. ["A", "B", "C"] or ["A", 1.5, "C"] for alphanumeric/numeric values | L6: must use JSON-style list syntax, e.g. ["A", "B", "C"] or ["A", 1.5, "C"] for alphanumeric/numeric values | M6: must use JSON-style list syntax, e.g. ["A", "B", "C"] or ["A", 1.5, "C"] for alphanumeric/numeric values | N6: must use JSON-style list syntax, e.g. ["A", "B", "C"] or ["A", 1.5, "C"] for alphanumeric/numeric values | O6: user defined | Q6: must match Rules.Status | R6: date format 2026-06-18T15:30+02:00 | S6: user defined
E7: predefinedtype_enum | F7: BDCH_V_31030000 | G7: PredefinedType | H7: Vordefinierter Typ | K7: ["GFA", "PARKING", "USERDEFINED"] | L7: ["GFA", "PARKING", "USERDEFINED"] | M7: ["GFA", "PARKING", "USERDEFINED"] | Q7: Candidate | R7: 2026-06-18T15:30+02:00 | S7: client-migration
E8: objecttype_enum | F8: BDCH_V_31030001 | G8: ObjectType | H8: Objekttyp | K8: ["SITE_AREA", "LANDSCAPE_AREA", "ROOM,EXTERNAL_ROOM", "RENTABLE_AREA"] | L8: ["SITE_AREA", "LANDSCAPE_AREA", "ROOM,EXTERNAL_ROOM", "RENTABLE_AREA"] | M8: ["SITE_AREA", "LANDSCAPE_AREA", "ROOM,EXTERNAL_ROOM", "RENTABLE_AREA"] | Q8: Candidate | R8: 2026-06-18T15:30+02:00 | S8: client-migration
E9: id_enum | F9: BDCH_V_31030002 | G9: ID | H9: ID | Q9: Candidate | R9: 2026-06-18T15:30+02:00 | S9: client-migration
E10: room_designation_enum | F10: BDCH_V_31030003 | G10: Room designation | H10: Raumbezeichnung | Q10: Candidate | R10: 2026-06-18T15:30+02:00 | S10: client-migration
E11: area_type_sia_416_code_enum | F11: BDCH_V_31030004 | G11: Area type SIA 416 code | H11: Flächenart SIA 416 Code | K11: [1.2, "1.2.1", "1.2.2", 2, "2.1.1.1", "2.1.1.2", "2.1.2", "2.1.3", 3, "3.1.1", "3.1.2", "3.1.3", "AIRSPACE", "ROOF"] | L11: [1.2, "1.2.1", "1.2.2", 2, "2.1.1.1", "2.1.1.2", "2.1.2", "2.1.3", 3, "3.1.1", "3.1.2", "3.1.3", "AIRSPACE", "ROOF"] | M11: [1.2, "1.2.1", "1.2.2", 2, "2.1.1.1", "2.1.1.2", "2.1.2", "2.1.3", 3, "3.1.1", "3.1.2", "3.1.3", "AIRSPACE", "ROOF"] | Q11: Candidate | R11: 2026-06-18T15:30+02:00 | S11: client-migration
E12: area_type_sia_416_label_enum | F12: BDCH_V_31030005 | G12: Area type SIA 416 label | H12: Flächenart SIA 416 Bezeichnung | K12: ["GSF", "UF", "BUF", "UUF", "GF", "HNF", "NNF", "VF", "FF", "AGF", "ANF", "AVF", "AFF", "GV"] | L12: ["GSF", "UF", "BUF", "UUF", "GF", "HNF", "NNF", "VF", "FF", "AGF", "ANF", "AVF", "AFF", "GV"] | M12: ["ST", "SA", "SAA", "SAN", "SP", "SUP", "SUS", "SD", "SI", "SEP", "SEU", "SED", "SEI", "VB"] | Q12: Candidate | R12: 2026-06-18T15:30+02:00 | S12: client-migration
E13: room_designation_sia_380_code_enum | F13: BDCH_V_31030006 | G13: Room designation SIA 380 code | H13: Raumbezeichnung SIA 380 Code | K13: [1, 2, 3, 4, 5, 6, 7, 8, 9, 10] | L13: [1, 2, 3, 4, 5, 6, 7, 8, 9, 10] | M13: [1, 2, 3, 4, 5, 6, 7, 8, 9, 10] | Q13: Candidate | R13: 2026-06-18T15:30+02:00 | S13: client-migration
E14: room_designation_sia_380_label_enum | F14: BDCH_V_31030007 | G14: Room designation SIA 380 label | H14: Raumbezeichnung SIA 380 Bezeichnung | K14: ["HNF1", "HNF2", "HNF3", "HNF4", "HNF5", "HNF6", "NNF7", "FF8", "VF9", "BUF10"] | L14: ["HNF1", "HNF2", "HNF3", "HNF4", "HNF5", "HNF6", "NNF7", "FF8", "VF9", "BUF10"] | M14: ["SUP1", "SUP2", "SUP3", "SUP4", "SUP5", "SUP6", "SUS7", "SI8", "SD9", "SAA10"] | Q14: Candidate | R14: 2026-06-18T15:30+02:00 | S14: client-migration
E15: room_usage_sia_2024_code_enum | F15: BDCH_V_31030008 | G15: Room usage SIA 2024 code | H15: Raumnutzung SIA 2024 Code | K15: [1.01, 1.02, 2.01, 2.02, 3.01, 3.02, 3.03, 3.04, 4.01, 4.02, 4.03, 4.04, 4.05, 5.01, 5.02, 5.03, 6.01, 6.02, 6.03, 6.04, 7.01, 7.02, 7.03, 8.01, 8.02, 8.03, 9.01, 9.02, 9.03, 10.01, 11.01, 11.02, 11.03, 12.01, 12.02, 12.03, 12.04, 12.05, 12.06, 12.07, 12.08, 12.09, 12.1, 12.11, 12.12] | L15: [1.01, 1.02, 2.01, 2.02, 3.01, 3.02, 3.03, 3.04, 4.01, 4.02, 4.03, 4.04, 4.05, 5.01, 5.02, 5.03, 6.01, 6.02, 6.03, 6.04, 7.01, 7.02, 7.03, 8.01, 8.02, 8.03, 9.01, 9.02, 9.03, 10.01, 11.01, 11.02, 11.03, 12.01, 12.02, 12.03, 12.04, 12.05, 12.06, 12.07, 12.08, 12.09, 12.1, 12.11, 12.12] | M15: [1.01, 1.02, 2.01, 2.02, 3.01, 3.02, 3.03, 3.04, 4.01, 4.02, 4.03, 4.04, 4.05, 5.01, 5.02, 5.03, 6.01, 6.02, 6.03, 6.04, 7.01, 7.02, 7.03, 8.01, 8.02, 8.03, 9.01, 9.02, 9.03, 10.01, 11.01, 11.02, 11.03, 12.01, 12.02, 12.03, 12.04, 12.05, 12.06, 12.07, 12.08, 12.09, 12.1, 12.11, 12.12] | Q15: Candidate | R15: 2026-06-18T15:30+02:00 | S15: client-migration
E16: room_usage_sia_2024_label_enum | F16: BDCH_V_31030009 | G16: Room usage SIA 2024 label | H16: Raumnutzung SIA 2024 Bezeichnung | K16: ["Wohnen Mehrfamilienhaus", "Wohnen Einfamilienhaus", "Hotelzimmer", "Empfang, Lobby", "Einzel-, Gruppenbüro", "Grossraumbüro", "Sitzungszimmer", "Schalterhalle, Empfang", "Schulzimmer", "Lehrerzimmer", "Bibliothek", "Hörsaal", "Schulfachraum", "Lebensmittelverkauf", "Fachgeschäft", "Verkauf Möbel, Bau, Garten", "Restaurant", "Selbstbedienungsrestaurant", "Küche zu Restaurant", "Küche zu Selbstbedienungsrestaurant", "Vorstellungsraum", "Mehrzweckhalle", "Ausstellungshalle", "Bettenzimmer", "Stationszimmer", "Behandlungsraum", "Produktion (grobe Arbeit)", "Produktion (feine Arbeit)", "Laborraum", "Lagerhalle", "Turnhalle", "Fitnessraum", "Schwimmhalle", "Verkehrsfläche", "Verkehrsfläche 24 h", "Treppenhaus", "Nebenraum", "Küche, Teeküche", "WC, Bad, Dusche", "WC", "Garderobe, Dusche", "Parkhaus", "Wasch- und Trockenraum", "Kühlraum", "Serverraum"] | L16: ["Wohnen Mehrfamilienhaus", "Wohnen Einfamilienhaus", "Hotelzimmer", "Empfang, Lobby", "Einzel-, Gruppenbüro", "Grossraumbüro", "Sitzungszimmer", "Schalterhalle, Empfang", "Schulzimmer", "Lehrerzimmer", "Bibliothek", "Hörsaal", "Schulfachraum", "Lebensmittelverkauf", "Fachgeschäft", "Verkauf Möbel, Bau, Garten", "Restaurant", "Selbstbedienungsrestaurant", "Küche zu Restaurant", "Küche zu Selbstbedienungsrestaurant", "Vorstellungsraum", "Mehrzweckhalle", "Ausstellungshalle", "Bettenzimmer", "Stationszimmer", "Behandlungsraum", "Produktion (grobe Arbeit)", "Produktion (feine Arbeit)", "Laborraum", "Lagerhalle", "Turnhalle", "Fitnessraum", "Schwimmhalle", "Verkehrsfläche", "Verkehrsfläche 24 h", "Treppenhaus", "Nebenraum", "Küche, Teeküche", "WC, Bad, Dusche", "WC", "Garderobe, Dusche", "Parkhaus", "Wasch- und Trockenraum", "Kühlraum", "Serverraum"] | Q16: Candidate | R16: 2026-06-18T15:30+02:00 | S16: client-migration
E17: area_type_d0165_code_enum | F17: BDCH_V_31030010 | G17: Area type d0165 code | H17: Flächenart d0165 Code | K17: [1.1, 1.2, 1.3, 1.4, 1.5, 1.6, 2.1, 2.2, 2.3, 2.4, 2.5, 2.6, 2.7, 2.8, 3.1, 3.2, 3.3, 3.4, 3.5, 3.6, 3.7, 3.8, 3.9, 4.1, 4.2, 4.3, 4.4, 4.5, 4.6, 5.1, 5.2, 5.3, 5.4, 5.5, 5.6, 5.7, 5.8, 5.9, 6.1, 6.2, 6.3, 6.4, 6.5, 6.6, 6.7, 6.8, 7.1, 7.2, 7.3, 7.4, 7.5, 7.6, 7.7, 8.1, 8.2, 8.3, 8.4, 8.5, 8.6, 8.7, 8.8, 8.9, 9.1, 9.2, 9.3, 9.4, 10.1] | L17: [1.1, 1.2, 1.3, 1.4, 1.5, 1.6, 2.1, 2.2, 2.3, 2.4, 2.5, 2.6, 2.7, 2.8, 3.1, 3.2, 3.3, 3.4, 3.5, 3.6, 3.7, 3.8, 3.9, 4.1, 4.2, 4.3, 4.4, 4.5, 4.6, 5.1, 5.2, 5.3, 5.4, 5.5, 5.6, 5.7, 5.8, 5.9, 6.1, 6.2, 6.3, 6.4, 6.5, 6.6, 6.7, 6.8, 7.1, 7.2, 7.3, 7.4, 7.5, 7.6, 7.7, 8.1, 8.2, 8.3, 8.4, 8.5, 8.6, 8.7, 8.8, 8.9, 9.1, 9.2, 9.3, 9.4, 10.1] | Q17: Candidate | R17: 2026-06-18T15:30+02:00 | S17: client-migration
E18: area_type_d0165_label_enum | F18: BDCH_V_31030011 | G18: Area type d0165 label | H18: Flächenart d0165 Bezeichnung | K18: ["Wohnräume", "Gemeinschaftsräume", "Pausenräume", "Warteräume", "Speiseräume", "Hafträume", "Büroräume", "Grossraumbüros", "Besprechungsräume", "Konstruktionsräume", "Schalterräume", "Bedienungsräume", "Aufsichtsräume", "Bürotechnikräume", "Werkhallen", "Werkstätten", "Technologische Labors", "Physikalische, physikaltechnische, elektrotechnische Labors", "Chemische, bekteriologische, morphologische Labors", "Räume für Tierhaltung", "Räume für Pflanzenzucht", "Küchen", "Sonderarbeitsräume", "Lagerräume", "Archive, Sammlungsräume", "Kühlräume", "Annahme- und Ausgaberäume", "Verkaufsräume", "Ausstellungsräume", "Unterrichtsräume mit festem Gestühl", "Allgemein Unterrichts- und Übungsräume ohne festes Gestühl", "Besondere Unterrichts- und Übungsräume ohne festes Gestühl", "Bibliotheksräume", "Sporträume", "Versammlungsräume", "Bühnen-, Studioräume", "Schauräume", "Sakralräume", "Räume mit allgemeiner medizinischen Ausstattung", "Räume mit besonderer medizinischen Ausstattung", "Räume für operative Eingriffe, Endoskopien und Entbindungen", "Räume für Strahlendiagnostik", "Räume für Strahlentherapie", "Räume für Physiotherapie und Rehabilitation", "Bettenräume mit allgemeiner Ausstattung", "Bettenräume mit besonderer Ausstattung", "Sanitärräume", "Garderoben", "Abstellräume", "Fahrzeugabstellflächen", "Fahrgastflächen", "Räume für zentrale Technik", "Schutzräum", "Abwasseraufbereitung u. -beseitigung", "Wasserversorgung", "Heizung und Brauchwassererwärmung", "Gase und Flüssigkeiten", "Elektrische Stromversorgung", "Fernmeldetechnik", "Raumlufttechnische Anlagen", "Aufzugs- und Förderanlagen", "Sonstige betriebstechnische Anlagen", "Flure, Hallen", "Treppen", "Schächte für Förderanlagen", "Fahrzeugverkehrsflächen", "aussenliegende Fahrzeugabstellflächen"] | L18: ["Wohnräume", "Gemeinschaftsräume", "Pausenräume", "Warteräume", "Speiseräume", "Hafträume", "Büroräume", "Grossraumbüros", "Besprechungsräume", "Konstruktionsräume", "Schalterräume", "Bedienungsräume", "Aufsichtsräume", "Bürotechnikräume", "Werkhallen", "Werkstätten", "Technologische Labors", "Physikalische, physikaltechnische, elektrotechnische Labors", "Chemische, bekteriologische, morphologische Labors", "Räume für Tierhaltung", "Räume für Pflanzenzucht", "Küchen", "Sonderarbeitsräume", "Lagerräume", "Archive, Sammlungsräume", "Kühlräume", "Annahme- und Ausgaberäume", "Verkaufsräume", "Ausstellungsräume", "Unterrichtsräume mit festem Gestühl", "Allgemein Unterrichts- und Übungsräume ohne festes Gestühl", "Besondere Unterrichts- und Übungsräume ohne festes Gestühl", "Bibliotheksräume", "Sporträume", "Versammlungsräume", "Bühnen-, Studioräume", "Schauräume", "Sakralräume", "Räume mit allgemeiner medizinischen Ausstattung", "Räume mit besonderer medizinischen Ausstattung", "Räume für operative Eingriffe, Endoskopien und Entbindungen", "Räume für Strahlendiagnostik", "Räume für Strahlentherapie", "Räume für Physiotherapie und Rehabilitation", "Bettenräume mit allgemeiner Ausstattung", "Bettenräume mit besonderer Ausstattung", "Sanitärräume", "Garderoben", "Abstellräume", "Fahrzeugabstellflächen", "Fahrgastflächen", "Räume für zentrale Technik", "Schutzräum", "Abwasseraufbereitung u. -beseitigung", "Wasserversorgung", "Heizung und Brauchwassererwärmung", "Gase und Flüssigkeiten", "Elektrische Stromversorgung", "Fernmeldetechnik", "Raumlufttechnische Anlagen", "Aufzugs- und Förderanlagen", "Sonstige betriebstechnische Anlagen", "Flure, Hallen", "Treppen", "Schächte für Förderanlagen", "Fahrzeugverkehrsflächen", "aussenliegende Fahrzeugabstellflächen"] | Q18: Candidate | R18: 2026-06-18T15:30+02:00 | S18: client-migration
E19: program_use_enum | F19: BDCH_V_31030012 | G19: Program use | H19: Raumnutzung | Q19: Candidate | R19: 2026-06-18T15:30+02:00 | S19: client-migration
E20: room_type_enum | F20: BDCH_V_31030013 | G20: Room type | H20: Raumtyp | Q20: Candidate | R20: 2026-06-18T15:30+02:00 | S20: client-migration
E21: unit_type_enum | F21: BDCH_V_31030014 | G21: Unit type | H21: Einheitstyp | Q21: Candidate | R21: 2026-06-18T15:30+02:00 | S21: client-migration
E22: unit_id_enum | F22: BDCH_V_31030015 | G22: Unit ID | H22: Einheitsnummer | Q22: Candidate | R22: 2026-06-18T15:30+02:00 | S22: client-migration
E23: operational_room_number_enum | F23: BDCH_V_31030016 | G23: Operational room number | H23: Raumnummer Betrieb | Q23: Candidate | R23: 2026-06-18T15:30+02:00 | S23: client-migration
E24: room_signal_label_enum | F24: BDCH_V_31030017 | G24: Room signal label | H24: Raumbeschriftung | Q24: Candidate | R24: 2026-06-18T15:30+02:00 | S24: BdCH
E25: cleaning_group_enum | F25: BDCH_V_31030018 | G25: Cleaning group | H25: Reinigungsgruppe | Q25: Candidate | R25: 2026-06-18T15:30+02:00 | S25: BdCH
E26: area_load_enum | F26: BDCH_V_31030019 | G26: Area load | H26: Flächenlast | Q26: Candidate | R26: 2026-06-18T15:30+02:00 | S26: BdCH
E27: point_load_enum | F27: BDCH_V_31030020 | G27: Point load | H27: Punktlast | Q27: Candidate | R27: 2026-06-18T15:30+02:00 | S27: BdCH
E28: energy_reference_area_enum | F28: BDCH_V_31030021 | G28: Energy reference area | H28: Energiebezugsfläche | K28: ["true", "false"] | L28: ["true", "false"] | M28: ["true", "false"] | Q28: Candidate | R28: 2026-06-18T15:30+02:00 | S28: BdCH
E29: window_area_enum | F29: BDCH_V_31030022 | G29: Window area | H29: Fensterfläche | Q29: Candidate | R29: 2026-06-18T15:30+02:00 | S29: BdCH
E30: window_openable_enum | F30: BDCH_V_31030023 | G30: Window openable | H30: Fenster öffenbar | K30: ["true", "false"] | L30: ["true", "false"] | M30: ["true", "false"] | Q30: Candidate | R30: 2026-06-18T15:30+02:00 | S30: BdCH
E31: occupant_enum | F31: BDCH_V_31030024 | G31: Occupant | H31: Raumnutzer | Q31: Candidate | R31: 2026-06-18T15:30+02:00 | S31: BdCH
E32: solar_shading_enum | F32: BDCH_V_31030025 | G32: Solar shading | H32: Sonnenschutz | K32: ["true", "false"] | L32: ["true", "false"] | M32: ["true", "false"] | Q32: Candidate | R32: 2026-06-18T15:30+02:00 | S32: BdCH
E33: humidified_enum | F33: BDCH_V_31030026 | G33: Humidified | H33: Befeuchtet | K33: ["true", "false"] | L33: ["true", "false"] | M33: ["true", "false"] | Q33: Candidate | R33: 2026-06-18T15:30+02:00 | S33: BdCH
E34: dehumidified_enum | F34: BDCH_V_31030027 | G34: Dehumidified | H34: Entfeuchtet | K34: ["true", "false"] | L34: ["true", "false"] | M34: ["true", "false"] | Q34: Candidate | R34: 2026-06-18T15:30+02:00 | S34: BdCH
E35: rentable_enum | F35: BDCH_V_31030028 | G35: Rentable | H35: Vermietbarkeit | K35: ["true", "false"] | L35: ["true", "false"] | M35: ["true", "false"] | Q35: Candidate | R35: 2026-06-18T15:30+02:00 | S35: BdCH
E36: external_space_enum | F36: BDCH_V_31030029 | G36: External space | H36: Aussenraum | K36: ["true", "false"] | L36: ["true", "false"] | M36: ["true", "false"] | Q36: Candidate | R36: 2026-06-18T15:30+02:00 | S36: BdCH
E37: occupancy_type_enum | F37: BDCH_V_31030030 | G37: Occupancy type | H37: Nutzungsart | Q37: Candidate | R37: 2026-06-18T15:30+02:00 | S37: BdCH
E38: headroom_enum | F38: BDCH_V_31030031 | G38: Headroom | H38: Raumnutzhöhe | Q38: Candidate | R38: 2026-06-18T15:30+02:00 | S38: BdCH
E39: planned_occupancy_enum | F39: BDCH_V_31030032 | G39: Planned occupancy | H39: Personenbelegung geplant | Q39: Candidate | R39: 2026-06-18T15:30+02:00 | S39: BdCH
E40: actual_occupancy_enum | F40: BDCH_V_31030033 | G40: Actual occupancy | H40: Personenbelegung ist | Q40: Candidate | R40: 2026-06-18T15:30+02:00 | S40: BdCH
...

Sheet Documents
A1: Filter | B1: Hinweise zur Handhabung | C1: Documents | D1: GUID/URI | E1: Document-ID | F1: Document-Code | G1: DocumentName (EN) | H1: Bezeichnung (DE) | I1: Désignation (FR) | J1: Designazione (IT) | K1: Security level/Sicherheitsstufe/Niveau de sécurité/Livello di sicurezza | L1: Accessibility/Zugänglichkeit/Accessibilité/Accessibilità | M1: Revision | N1: DocumentOwner | O1: Governance | P1: Status | Q1: Version date | R1: Provenance (PROV) | T1: User Defined (not part of HE Data Dictionary / not validated by Validator)
B2: Erforderlich für Excel | D2: no | E2: no | F2: optional | G2: optional | H2: optional | I2: optional | J2: optional | K2: optional | L2: optional | M2: optional | N2: optional | P2: optional | Q2: optional | R2: optional
B3: Sprachen | D3: multilingual | E3: multilingual | F3: multilingual | G3: EN | H3: DE | I3: FR | J3: IT | K3: multilingual | L3: multilingual | M3: multilingual | N3: multilingual | P3: EN | Q3: neutral | R3: EN
B4: Referenziert / System generiert | E4: system-generated | G4: referenced | M4: referenced | N4: referenced | P4: referenced | Q4: referenced | R4: referenced
B5: Dropdown Liste | K5: Rules.ISG - Informationssicherheitsgesetz | L5: Rules.FAIR Prinzipien | P5: Rules.Status
