Workbook
Name Affectation_de_classe: Rules!$C$2:$C$47
Name Assegnazione_della_classe: Rules!$D$2:$D$47
Name Assegnazione_della_proprieta: Rules!$H$2:$H$47
Name Attribution_de_propriete: Rules!$G$2:$G$47
Name DataType: Rules!$I$2:$I$47
Name FAIR_Prinzipien: Rules!$M$2:$M$47
Name IFC_Data_Type: Rules!$J$2:$J$47
Name ISG___Informationssicherheitsgesetz: Rules!$L$2:$L$47
Name Klassen_Zuordnung: Rules!$B$2:$B$47
Name Klassifikation: Rules!$B$2:$B$47
Name LifecycleStatus: Rules!$N$2:$N$47
Name Markmals_Klassifikation: Rules!$F$2:$F$47
Name Merkmals_Zuordnung: Rules!$F$2:$F$47
Name Objekt_Einordnung: Rules!$A$2:$A$47
Name Property_Classification: Rules!$E$2:$E$47
Name Status: Rules!$K$2:$K$47

Sheet Impressum
B1: Strukturvorlage Handlungsempfehlung Data Dictionaries
B3: Dokumenteninformationen
C4: Status | D4: Entwurf
C5: Version | D5: v20260510
C6: Letzte Änderung | D6: 46152
C7: Autor | D7: Bauen digital Schweiz / buildingSMART Switzerland (BdCH/bSCH)
B9: Trägerschaft
B12: Mit freundlicher Unterstützung von
C13: Armasuisse | E13: Schweizerische Bundesbahnen (SBB AG)
C14: B+S AG | E14: Schweizerischer Baumeisterverband (SBV)
C15: Basler & Hofmann AG | D15: Lignum Holzwirtschaft Schweiz | E15: Schweizerischer Ingenieur- und Architektenverein (SIA)
C16: Baumschlager Eberle Zürich AG | D16: Lombardi AG | E16: Stadt Luzern
C17: Buildup AG | D17: Losinger Marazzi AG | E17: Stadt Zürich
C18: Bundesamt für Strassen (ASTRA) | D18: Marti Tunnel AG | E18: Steinmann Ingenieure und Planer AG
C19: CRB | D19: MEGA | E19: Suissetec
C20: Fachgruppe für Untertagbau (FGU) | D20: Mensch und Maschine Schweiz AG | E20: Swissgee
C21: FHNW | D21: Open BIM Verband | E21: SWKI / die Planer
C22: Frutiger AG | D22: Penzel Valier AG | E22: Terradata AG
C23: HKG | D23: Rhomberg Sersa Rail Group Schweiz | E23: Walo AG
C24: IBG Engineering AG | D24: Roundtable Gebäudetechnik
C25: ILF BERATENDE INGENIEURE AG | D25: Schindler Aufzüge AG
C26: Implenia Schweiz AG | D26: Siemens AG
B28: Abgrenzung | D28: Fokus auf Austauschformat IFC 4.3.2.0 (IFC4X3_ADD2)
D29: Andere Formate (z. B. CityGML, gbXML, LandXML) sind kein Bestandteil
D30: Keine Abbildung von Geodaten (Geologie, Topographie, Bewuchs, Gewässer)
D31: Strukturvorlage ist eine methodische Grundlage, kein vollständiger Datenkatalog
D32: Vollständige Datenkataloge müssen in Datenbanken realsiert werden
D33: Die Handlungsempfehlung ist keine Implementierungsrichtlinie für Softwareentwicklung
D34: Die Strukturvorlage ist ein Best Practice Beispiel und kann jederzeit an neue Anforderungen angepasst werden. Es wird davon abgeraten, auf der Basis der Strukturvorlage Applikationen oder Tools zu entwickeln.
D35: Keine konkrete Implementierung oder Vernetzung von Datenkatalogen
B38: Copyright
D41: https://creativecommons.org/licenses/by-nc-sa/4.0/
D49: mailto:info@bauen-digital.ch

Sheet Anleitung
A1: Anleitung Strukturvorlage Data Dictionaries
B3: Inhaltsverzeichnis
B5: 1 | C5: Handhabung
B6: 2 | C6: Governance
B7: 3 | C7: Objekte
B8: 4 | C8: Klassifikationen
B9: 5 | C9: Merkmale
B10: 6 | C10: Werteliste
B11: 7 | C11: Dokumente
B13: Hinweise zur Handhabung
C15: A | D15: B | E15: C | F15: D | G15: E
B16: Hinweise zur Handhabung | C16: Erforderlich | D16: Erforderlich für Data Dictionary | E16: Sprachen | F16: Referenziert / System generiert | G16: Dropdown Liste
B17: A | C17: Erforderlich für Objektkatalog
C18: Definiert die Mindestandorderugen an einen Katalog. Unterscheidung zwischen ja = erforderlich / empfohlen / <leer> = nicht notwendig
B19: B | C19: Erforderlich für Data Dictionary
C20: Definiert die Mindestandorderugen an ein in einer Datenbank eingepfegtes Data Dictionaries. Unterscheidung zwischen ja = erforderlich / empfohlen / <leer> = nicht notwendig
B21: C | C21: Sprachen
C22: Angabe zur Sprache: mehrsprachig = muss in der für den Katalog führenden Sprache enthalten sein / EN, DE, FR, IT = gibt Sprache zwingend vor / Sprachneutral = nicht von Sprache abängig
B23: D | C23: Referenziert / System generiert
C24: Darf nicht vom Ersteller manuell ausgefüllt werden, sondern wird auf eine Quelle referenziert, resp. von eine Datenbank automatisch generiert
B25: E | C25: Dropdown Liste
C26: Verweist auf die Dropdownliste in diesem Template
A28: 2 | B28: Governance
B30: Vorgabe einer minimalen Governance für die verschiedenen Kataloge
B31: Optional können aller Regeln der SN EN ISO 23386 ergänzt werden
B33: A | C33: B | D33: C | E33: D | F33: E | G33: F | H33: G
B34: Governance | C34: Status | D34: Versionsdatum | E34: Herkunft (PROV) | F34: Regeln zur Festlegung von Merkmalen | G34: Regeln zur Festlegung von Merkmalsgruppen | H34: Management-Regeln für die Erstellung und Pflege
B35: B | C35: Vorgeschriebner Status des Merkmals während seines Lebenszyklus (Enumeration: active / inactive)
B36: C | C36: Datum der Version. Format nach ISO 8601 = YYYY-MM-DDThh:mm:ssTDZ (T = festes Trennzeichen zwischen Datum und Uhrzeit / TDZ = Zeitzonenbezeichnung. Z = UTC, Abweichung zu UTC angeben)
C38: EN: PROV = Provenance, DE = Herkunft, Entstehungsgeschichte oder Nachweis der Datenherkunft
C39: Um eindeutig, maschinenlesbar und für den Menschen verständlich zu sein, müssen Merkmale als Liste von Attributen festgelegt werden. Einige Attribute sind zwingend erforderlich und andere sind freigestellt.
C42: Um eindeutig, maschinenlesbar und für den Menschen verständlich zu sein, müssen Merkmalsgruppen als Liste von Attributen festgelegt werden. Einige Attribute sind zwingend erforderlich und andere sind freigestellt.
C45: Verbindliche Regeln zur Erstellung, Pflege und Versionierung von Merkmalen und Merkmaslgruppen sowie zur koordinierten Abstimmung und Freigabe zwischen Akteuren zur Sicherstellung von Qualität, Konsistenz und Interoperabilität.
B50: Objekte
C52: B | E52: D | F52: E | G52: F | H52: G | I52: H | J52: I | K52: J | L52: K | M52: L | N52: M | O52: N | P52: O | R52: Q | S52: R
B53: Strukturelle Einordnung | C53: Domäne | E53: Kategorie | F53: Objekte | G53: GUID/URI | H53: Objekt-ID | I53: Objekt-Einordnung | J53: Bezeichnung | K53: Designation | L53: Beschreibung | M53: Description | N53: IFC 4.3.2.0 (IFC4X3_ADD2) | O53: GUID/URI | P53: IfcObject Entity | R53: PredefinedType | S53: ObjectType
B55: Strukturelle Einordnung
C57: B | E57: D
B58: Strukturelle Einordnung | C58: Domäne | E58: Kategorie
C59: Fachlicher Gesamtbereich, oberste Gliederung nach Disziplin Biespiele: Architektur, Tragwerk, HVAC, Verkehrswegebau, Bahntechnik, Werkleitungen
...

Sheet Header
A1: Data Dictionary — Core Metadata
A2: Field | B2: Value | C2: Requirement | D2: Notes / Maps to
A3: IDENTIFICATION
A4: OrganizationCode | B4: KBOB | C4: user defined name (small or capital letters), max 7 chars | D4: Short org code — lowercase, max 7 chars, appears in all derived IRIs
A5: DictionaryCode | C5: SYSTEM-GENERATED | D5: Generated from DictionaryName (EN)
A6: DictionaryName (EN) | B6: KBOB FM Data Dictionary | C6: REQUIRED | D6: Required authoring title in English — source for DictionaryCode generation
A7: DictionaryName (DE) | B7: KBOB Datenkatalog FM | C7: OPTIONAL | D7: Core authoring title in German — minimal DCAT/i14y anchor
A8: DictionaryName (FR) | B8: Catalogue de données KBOB FM | C8: OPTIONAL | D8: Optional multilingual title support
A9: DictionaryName (IT)
A10: DictionaryVersion | B10: 0.3.0 | C10: REQUIRED | D10: Semantic versioning: MAJOR.MINOR.PATCH
A11: DictionaryUri | C11: SYSTEM-GENERATED | D11: Derived from OrganizationCode and DictionaryCode; canonical base pattern https://example.com/<OrganizationCode>/<DictionaryCode>
A13: GOVERNANCE
A14: LifecycleStatus | B14: Candidate | C14: REQUIRED | D14: Governance state used to derive i14y registration status
A16: LEGEND
A17: REQUIRED: | B17: Must be filled before validation/export
A18: OPTIONAL: | B18: Fill if available

Sheet Dictionary_public
A1: Data Dictionary — Additional Metadata
A2: Field | B2: Value | C2: Requirement | D2: Notes / Maps to
A3: GOVERNANCE / PUBLISHING
A4: Owner / Publisher | C4: REQUIRED WHEN USED | D4: dct:publisher / i14y publisher mapping
A5: ContactEmail | C5: REQUIRED WHEN USED | D5: dcat:contactPoint / i14y contact
A6: Description (DE) | C6: REQUIRED WHEN USED | D6: dct:description@de
A7: Description (FR) | C7: OPTIONAL | D7: dct:description@fr
A8: Description (EN) | C8: OPTIONAL | D8: dct:description@en
A9: PrimaryLanguage | C9: REQUIRED WHEN USED | D9: Primary metadata/content language
A10: MetadataLanguages | C10: OPTIONAL | D10: Additional metadata languages; delimited list allowed
A11: ReleaseDate | C11: OPTIONAL | D11: dct:issued — format YYYY-MM-DD
A12: ModifiedDate | C12: OPTIONAL
A13: QualityAssuranceProcedure | C13: OPTIONAL
A14: QualityAssuranceProcedureUrl | C14: OPTIONAL
A16: DISCOVERY / CATALOG METADATA
A17: Keywords (DE) | C17: OPTIONAL | D17: German keywords/tags — dcat:keyword@de
A18: Keywords (FR) | C18: OPTIONAL | D18: French keywords/tags — dcat:keyword@fr
A19: Keywords (EN) | C19: OPTIONAL | D19: English keywords/tags — dcat:keyword@en
A20: AccessRights | C20: OPTIONAL | D20: Access rights / visibility statement — dct:accessRights
A21: eCH_Theme | C21: OPTIONAL | D21: Swiss eCH thematic classification / topic category
A22: SpatialCoverage | C22: OPTIONAL | D22: Geographic scope or covered territory — dct:spatial
A23: TemporalCoverage | C23: OPTIONAL | D23: Covered time period / validity period — dct:temporal
A24: DocumentationURLs | C24: OPTIONAL | D24: Supporting documentation links; delimited list allowed
A25: RelatedResourceURLs | C25: OPTIONAL | D25: Related datasets/resources links — dct:relation
A26: ApplicableLegislation | C26: OPTIONAL | D26: Applicable legal basis / legislation references
A28: LICENSING
A29: License | C29: OPTIONAL | D29: Human-readable license name — dct:license
A30: LicenseUrl | C30: OPTIONAL | D30: Resolvable license URI/URL — dct:license
A32: TECHNICAL ENDPOINTS
A33: SPARQL_Endpoint | C33: OPTIONAL | D33: SPARQL endpoint URL for published graph access
A34: TTL_Download_URL | C34: OPTIONAL | D34: Download URL for Turtle/RDF serialization — dcat:distribution
A35: JSON_Download_URL | C35: OPTIONAL | D35: Download URL for JSON/JSON-LD serialization — dcat:distribution
A36: MoreInfoUrl | C36: OPTIONAL | D36: Landing page / homepage
A38: STANDARDS ALIGNMENT
A39: ConformsTo_ISO23386 | C39: OPTIONAL | D39: dct:conformsTo — property methodology
A40: ConformsTo_ISO12006_3 | C40: OPTIONAL
A41: ConformsTo_DCAT_AP_CH | C41: OPTIONAL
A42: VersionNotes (DE) | C42: OPTIONAL
A43: VersionNotes (FR) | C43: OPTIONAL
A44: VersionNotes (EN) | C44: OPTIONAL

Sheet Classes
A1: Filter | B1: Hinweise zur Handhabung | C1: Structural categorisation | D1: Domain/Domäne/Domaine/Dominio | E1: System/System/Système/Sistema | F1: Category/Kategorie/Catégorie/Categoria | G1: Classes | H1: GUID/URI | I1: Class-ID | J1: Class-Code | K1: Class-Assignment | L1: Klassen-Zuordnung (DE) | M1: Affectation de classe (FR) | N1: Assegnazione della classe (IT) | O1: Designation (EN) | P1: Bezeichnung (DE) | Q1: Désignation (FR) | R1: Designazione (IT) | S1: Description (EN) | T1: Beschreibung (DE) | U1: Description (FR) | V1: Descrizione (IT) | W1: IFC 4.3.2.0 (IFC4X3_ADD2) | X1: IFC_URI | Y1: IfcObject Entity | Z1: IfcTypeObject Entity | AA1: PredefinedType | AB1: ObjectType | AC1: RDS | AD1: Governance | AE1: Status | AF1: Version date | AG1: Provenance (PROV) | AH1: RelatedDocuments | AI1: RelatedDocumentName (EN)
B2: Erforderlich für Excel
B3: Sprachen
B4: Referenziert / System generiert | D4: multilingual | E4: multilingual | F4: multilingual | H4: multilingual | I4: multilingual | J4: multilingual | K4: multilingual | L4: DE | M4: FR | N4: IT | O4: EN | P4: DE | Q4: FR | R4: IT | S4: EN | T4: DE | U4: FR | V4: IT | X4: multilingual | Y4: multilingual | Z4: multilingual | AA4: multilingual | AB4: multilingual | AC4: multilingual | AE4: multilingual | AF4: multilingual | AG4: multilingual | AI4: multilingual
B5: Dropdown Liste | H5: referenced | I5: system-generated | L5: system-generated | M5: system-generated | N5: system-generated | X5: referenced | Y5: referenced | Z5: referenced | AA5: referenced | AB5: referenced | AC5: referenced | AE5: referenced | AF5: referenced | AG5: referenced | AI5: referenced
B6: Validierung | K6: Rules.Class-Assignment | L6: Rules.Klassen-Zuordnung | M6: Rules.Affectation de classe | N6: Rules.Assegnazione della classe | AE6: Rules.Status
H7: https://www.kbob.admin.ch/class/grundstuck | J7: grundstuck | K7: Spatial structure | L7: =IFERROR(INDEX(Rules!$B:$B,MATCH(K8,Rules!$A:$A,0)),"") -> Räumliche Struktur | M7: =IFERROR(INDEX(Rules!$C:$C,MATCH(K8,Rules!$A:$A,0)),"") -> Structure spatiale | N7: =IFERROR(INDEX(Rules!$D:$D,MATCH(K8,Rules!$A:$A,0)),"") -> Struttura spaziale | O7: Site | P7: Grundstück | S7: KBOB FM object class for a site as a spatial unit of a developed or undeveloped plot. | T7: KBOB-FM-Objektklasse für ein Grundstück als räumliche Einheit des bebauten oder unbebauten Areals. | X7: https://identifier.buildingsmart.org/uri/buildingsmart/ifc/4.3/class/IfcSite | Y7: IfcSite | Z7: IfcSite | AE7: Candidate | AF7: 2026-06-30T12:00:00Z | AG7: KBOB | AI7: KBOB DK FM_i14y.csv
H8: https://www.kbob.admin.ch/class/gebaude | J8: gebaude | K8: Spatial structure | L8: =IFERROR(INDEX(Rules!$B:$B,MATCH(K9,Rules!$A:$A,0)),"") -> Räumliche Struktur | M8: =IFERROR(INDEX(Rules!$C:$C,MATCH(K9,Rules!$A:$A,0)),"") -> Structure spatiale | N8: =IFERROR(INDEX(Rules!$D:$D,MATCH(K9,Rules!$A:$A,0)),"") -> Struttura spaziale | O8: Building | P8: Gebäude | S8: KBOB FM object class for a building as an independent built asset. | T8: KBOB-FM-Objektklasse für ein Gebäude als eigenständiges Bauwerk. | X8: https://identifier.buildingsmart.org/uri/buildingsmart/ifc/4.3/class/IfcBuilding | Y8: IfcBuilding | Z8: IfcBuilding | AE8: Candidate | AF8: 2026-06-30T12:00:00Z | AG8: KBOB | AI8: KBOB DK FM_i14y.csv
H9: https://www.kbob.admin.ch/class/geschoss | J9: geschoss | K9: Spatial structure | L9: =IFERROR(INDEX(Rules!$B:$B,MATCH(K10,Rules!$A:$A,0)),"") -> Räumliche Struktur | M9: =IFERROR(INDEX(Rules!$C:$C,MATCH(K10,Rules!$A:$A,0)),"") -> Structure spatiale | N9: =IFERROR(INDEX(Rules!$D:$D,MATCH(K10,Rules!$A:$A,0)),"") -> Struttura spaziale | O9: Building storey | P9: Geschoss | S9: KBOB FM object class for a storey as a spatial level within a building. | T9: KBOB-FM-Objektklasse für ein Geschoss als räumliche Ebene innerhalb eines Gebäudes. | X9: https://identifier.buildingsmart.org/uri/buildingsmart/ifc/4.3/class/IfcBuildingStorey | Y9: IfcBuildingStorey | Z9: IfcBuildingStorey | AE9: Candidate | AF9: 2026-06-30T12:00:00Z | AG9: KBOB | AI9: KBOB DK FM_i14y.csv
H10: https://www.kbob.admin.ch/class/raum | J10: raum | K10: Spatial structure | L10: Räumliche Struktur | M10: Structure spatiale | N10: Struttura spaziale | O10: Room | P10: Raum | S10: KBOB FM object class for a room as a usable spatial unit within a storey. | T10: KBOB-FM-Objektklasse für einen Raum als nutzbare räumliche Einheit innerhalb eines Geschosses. | X10: https://identifier.buildingsmart.org/uri/buildingsmart/ifc/4.3/class/IfcSpace | Y10: IfcSpace | Z10: IfcSpace | AE10: Candidate | AF10: 2026-06-30T12:00:00Z | AG10: KBOB | AI10: KBOB DK FM_i14y.csv
H11: https://www.kbob.admin.ch/class/bauteil | J11: bauteil | K11: Physical elements | L11: Physische Bauteile | M11: Éléments physiques | N11: Elementi fisici | O11: Component | P11: Bauteil | S11: KBOB FM object class for a component as an identifiable element of a building or facility. | T11: KBOB-FM-Objektklasse für ein Bauteil als identifizierbares Element eines Bauwerks oder einer Anlage. | X11: https://identifier.buildingsmart.org/uri/buildingsmart/ifc/4.3/class/IfcElement | Y11: IfcElement | Z11: IfcElement | AE11: Candidate | AF11: 2026-06-30T12:00:00Z | AG11: KBOB | AI11: KBOB DK FM_i14y.csv
L12: =IFERROR(INDEX(Rules!$B:$B,MATCH(K13,Rules!$A:$A,0)),"") | M12: =IFERROR(INDEX(Rules!$C:$C,MATCH(K13,Rules!$A:$A,0)),"") | N12: =IFERROR(INDEX(Rules!$D:$D,MATCH(K13,Rules!$A:$A,0)),"")
L13: =IFERROR(INDEX(Rules!$B:$B,MATCH(K14,Rules!$A:$A,0)),"") | M13: =IFERROR(INDEX(Rules!$C:$C,MATCH(K14,Rules!$A:$A,0)),"") | N13: =IFERROR(INDEX(Rules!$D:$D,MATCH(K14,Rules!$A:$A,0)),"")
L14: =IFERROR(INDEX(Rules!$B:$B,MATCH(K15,Rules!$A:$A,0)),"") | M14: =IFERROR(INDEX(Rules!$C:$C,MATCH(K15,Rules!$A:$A,0)),"") | N14: =IFERROR(INDEX(Rules!$D:$D,MATCH(K15,Rules!$A:$A,0)),"")
L15: =IFERROR(INDEX(Rules!$B:$B,MATCH(K16,Rules!$A:$A,0)),"") | M15: =IFERROR(INDEX(Rules!$C:$C,MATCH(K16,Rules!$A:$A,0)),"") | N15: =IFERROR(INDEX(Rules!$D:$D,MATCH(K16,Rules!$A:$A,0)),"")
L16: =IFERROR(INDEX(Rules!$B:$B,MATCH(K17,Rules!$A:$A,0)),"") | M16: =IFERROR(INDEX(Rules!$C:$C,MATCH(K17,Rules!$A:$A,0)),"") | N16: =IFERROR(INDEX(Rules!$D:$D,MATCH(K17,Rules!$A:$A,0)),"")
L17: =IFERROR(INDEX(Rules!$B:$B,MATCH(K18,Rules!$A:$A,0)),"") | M17: =IFERROR(INDEX(Rules!$C:$C,MATCH(K18,Rules!$A:$A,0)),"") | N17: =IFERROR(INDEX(Rules!$D:$D,MATCH(K18,Rules!$A:$A,0)),"")
L18: =IFERROR(INDEX(Rules!$B:$B,MATCH(K19,Rules!$A:$A,0)),"") | M18: =IFERROR(INDEX(Rules!$C:$C,MATCH(K19,Rules!$A:$A,0)),"") | N18: =IFERROR(INDEX(Rules!$D:$D,MATCH(K19,Rules!$A:$A,0)),"")
L19: =IFERROR(INDEX(Rules!$B:$B,MATCH(K20,Rules!$A:$A,0)),"") | M19: =IFERROR(INDEX(Rules!$C:$C,MATCH(K20,Rules!$A:$A,0)),"") | N19: =IFERROR(INDEX(Rules!$D:$D,MATCH(K20,Rules!$A:$A,0)),"")
L20: =IFERROR(INDEX(Rules!$B:$B,MATCH(K21,Rules!$A:$A,0)),"") | M20: =IFERROR(INDEX(Rules!$C:$C,MATCH(K21,Rules!$A:$A,0)),"") | N20: =IFERROR(INDEX(Rules!$D:$D,MATCH(K21,Rules!$A:$A,0)),"")
L21: =IFERROR(INDEX(Rules!$B:$B,MATCH(K22,Rules!$A:$A,0)),"") | M21: =IFERROR(INDEX(Rules!$C:$C,MATCH(K22,Rules!$A:$A,0)),"") | N21: =IFERROR(INDEX(Rules!$D:$D,MATCH(K22,Rules!$A:$A,0)),"")
L22: =IFERROR(INDEX(Rules!$B:$B,MATCH(K23,Rules!$A:$A,0)),"") | M22: =IFERROR(INDEX(Rules!$C:$C,MATCH(K23,Rules!$A:$A,0)),"") | N22: =IFERROR(INDEX(Rules!$D:$D,MATCH(K23,Rules!$A:$A,0)),"")
L23: =IFERROR(INDEX(Rules!$B:$B,MATCH(K24,Rules!$A:$A,0)),"") | M23: =IFERROR(INDEX(Rules!$C:$C,MATCH(K24,Rules!$A:$A,0)),"") | N23: =IFERROR(INDEX(Rules!$D:$D,MATCH(K24,Rules!$A:$A,0)),"")
L24: =IFERROR(INDEX(Rules!$B:$B,MATCH(K25,Rules!$A:$A,0)),"") | M24: =IFERROR(INDEX(Rules!$C:$C,MATCH(K25,Rules!$A:$A,0)),"") | N24: =IFERROR(INDEX(Rules!$D:$D,MATCH(K25,Rules!$A:$A,0)),"")

Sheet Properties
A1: Filter | B1: Hinweise zur Handhabung | C1: Properties | D1: GUID/URI | E1: Property-ID | F1: Property-Code | G1: Property-Assignment | H1: Merkmals-Zuordnung (DE) | I1: Attribution de propriété (FR) | J1: Assegnazione della proprietà (IT) | K1: Designation (EN) | L1: Bezeichnung (DE) | M1: Désignation (FR) | N1: Designazione (IT) | O1: Description (EN) | P1: Beschreibung (DE) | Q1: Description (FR) | R1: Descrizione (IT) | S1: DataType (Base Type) | T1: DataType (IFC) | U1: EnumerationDesignation (EN) | V1: IFC 4.3.2.0 (IFC4X3_ADD2) | W1: IFC_URI | X1: IfcPropertySet (Pset) IfcQuantitySet (Qto) | Y1: Units/Einheit/Unité/Unità | Z1: QUDT URI | AA1: Unit Name (EN) | AB1: Einheit-Name (DE) | AC1: Nom de l’unité (FR) | AD1: Nome unità (IT) | AE1: Governance | AF1: Status | AG1: Version date | AH1: Provenance (PROV)
B2: Erforderlich für Excel | G2: yes
B3: Sprachen
B4: Referenziert / System generiert | D4: multilingual | E4: multilingual | F4: multilingual | H4: DE | I4: FR | J4: IT | K4: EN | L4: DE | M4: FR | N4: IT | O4: EN | P4: DE | Q4: FR | R4: IT | S4: multilingual | T4: multilingual | U4: multilingual | W4: multilingual | X4: multilingual | Y4: multilingual | Z4: multilingual | AA4: EN | AB4: DE | AC4: FR | AD4: IT | AF4: multilingual | AG4: multilingual | AH4: multilingual
B5: Dropdown Liste | D5: referenced | E5: system-generated | H5: system-generated | I5: system-generated | J5: system-generated | S5: referenced | T5: referenced | U5: referenced | W5: referenced | X5: referenced | Z5: referenced | AA5: system-generated | AB5: system-generated | AC5: system-generated | AD5: system-generated | AF5: referenced | AG5: referenced | AH5: referenced
B6: Validierung | G6: Rules.Property-Assignment | H6: Rules.Merkmals-Zuordnung | I6: Rules.Attribution de propriété | J6: Rules.Assegnazione della proprietà | S6: Rules.DataType | T6: Rules.IFC Data Type | AF6: Rules.Status
F7: guid | H7: =IFERROR(INDEX(Rules!$F:$F,MATCH(G8,Rules!$E:$E,0)),"") | I7: =IFERROR(INDEX(Rules!$G:$G,MATCH(G8,Rules!$E:$E,0)),"") | J7: =IFERROR(INDEX(Rules!$H:$H,MATCH(G8,Rules!$E:$E,0)),"") | K7: GUID | L7: GUID | O7: Property for uniquely identifying the object by means of a global unique identifier (GUID). | P7: Merkmal zur eindeutigen Identifikation des Objekts mittels Global Unique Identifier (GUID). | S7: STRING | T7: IfcLabel | W7: https://identifier.buildingsmart.org/uri/buildingsmart/ifc/4.3/prop/GlobalId | AF7: Candidate | AG7: 2026-07-31T12:00:00Z | AH7: KBOB
F8: grundstueck-id | H8: =IFERROR(INDEX(Rules!$F:$F,MATCH(G9,Rules!$E:$E,0)),"") | I8: =IFERROR(INDEX(Rules!$G:$G,MATCH(G9,Rules!$E:$E,0)),"") | J8: =IFERROR(INDEX(Rules!$H:$H,MATCH(G9,Rules!$E:$E,0)),"") | K8: Site ID | L8: Grundstück ID | O8: Property for uniquely identifying sites. | P8: Merkmal zur eindeutigen Identifikation von Grundstücken. | S8: STRING | T8: IfcLabel | W8: https://identifier.buildingsmart.org/uri/buildingsmart/ifc/4.3/prop/LandID | X8: https://identifier.buildingsmart.org/uri/buildingsmart/ifc/4.3/class/Pset_LandRegistration | AF8: Candidate | AG8: 2026-07-31T12:00:00Z | AH8: KBOB
F9: wirtschaftseinheit-id | H9: =IFERROR(INDEX(Rules!$F:$F,MATCH(G10,Rules!$E:$E,0)),"") | I9: =IFERROR(INDEX(Rules!$G:$G,MATCH(G10,Rules!$E:$E,0)),"") | J9: =IFERROR(INDEX(Rules!$H:$H,MATCH(G10,Rules!$E:$E,0)),"") | K9: Business unit ID | L9: Wirtschaftseinheit ID | O9: Property for uniquely identifying economic units. | P9: Merkmal zur eindeutigen Identifikation von Wirtschaftseinheiten. | S9: STRING | T9: IfcLabel | W9: https://identifier.buildingsmart.org/uri/buildingsmart/ifc/4.3/prop/LandTitleID | X9: https://identifier.buildingsmart.org/uri/buildingsmart/ifc/4.3/class/Pset_LandRegistration | AF9: Candidate | AG9: 2026-07-31T12:00:00Z | AH9: KBOB
F10: ort | H10: =IFERROR(INDEX(Rules!$F:$F,MATCH(G11,Rules!$E:$E,0)),"") | I10: =IFERROR(INDEX(Rules!$G:$G,MATCH(G11,Rules!$E:$E,0)),"") | J10: =IFERROR(INDEX(Rules!$H:$H,MATCH(G11,Rules!$E:$E,0)),"") | K10: City | L10: Ort | O10: Property for specifying the location. | P10: Merkmal zur Angabe von dem Ort. | S10: STRING | T10: IfcLabel | W10: https://identifier.buildingsmart.org/uri/buildingsmart/ifc/4.3/prop/Town | X10: https://identifier.buildingsmart.org/uri/buildingsmart/ifc/4.3/class/Pset_Address | AF10: Candidate | AG10: 2026-07-31T12:00:00Z | AH10: KBOB
F11: grundstueckbezeichnung | H11: =IFERROR(INDEX(Rules!$F:$F,MATCH(G12,Rules!$E:$E,0)),"") | I11: =IFERROR(INDEX(Rules!$G:$G,MATCH(G12,Rules!$E:$E,0)),"") | J11: =IFERROR(INDEX(Rules!$H:$H,MATCH(G12,Rules!$E:$E,0)),"") | K11: Site designation | L11: Grundstückbezeichnung | O11: Property for specifying the site designation. | P11: Merkmal zur Angabe von der Grundstückbezeichnung. | S11: STRING | T11: IfcLabel | W11: https://identifier.buildingsmart.org/uri/buildingsmart/ifc/4.3/prop/Name | AF11: Candidate | AG11: 2026-07-31T12:00:00Z | AH11: KBOB
F12: landeskurzel | H12: =IFERROR(INDEX(Rules!$F:$F,MATCH(G13,Rules!$E:$E,0)),"") | I12: =IFERROR(INDEX(Rules!$G:$G,MATCH(G13,Rules!$E:$E,0)),"") | J12: =IFERROR(INDEX(Rules!$H:$H,MATCH(G13,Rules!$E:$E,0)),"") | K12: Country code | L12: Landeskürzel | O12: Property for specifying the country code. | P12: Merkmal zur Angabe von dem Landeskürzel. | S12: STRING | T12: IfcLabel | W12: https://identifier.buildingsmart.org/uri/buildingsmart/ifc/4.3/prop/Country | X12: https://identifier.buildingsmart.org/uri/buildingsmart/ifc/4.3/class/Pset_Address | AF12: Candidate | AG12: 2026-07-31T12:00:00Z | AH12: KBOB
F13: kanton | H13: =IFERROR(INDEX(Rules!$F:$F,MATCH(G14,Rules!$E:$E,0)),"") | I13: =IFERROR(INDEX(Rules!$G:$G,MATCH(G14,Rules!$E:$E,0)),"") | J13: =IFERROR(INDEX(Rules!$H:$H,MATCH(G14,Rules!$E:$E,0)),"") | K13: Canton | L13: Kanton | O13: Property for specifying the canton. | P13: Merkmal zur Angabe von dem Kanton. | S13: STRING | T13: IfcLabel | W13: https://identifier.buildingsmart.org/uri/buildingsmart/ifc/4.3/prop/Region | X13: https://identifier.buildingsmart.org/uri/buildingsmart/ifc/4.3/class/Pset_Address | AF13: Candidate | AG13: 2026-07-31T12:00:00Z | AH13: KBOB
F14: postleitzahl | H14: =IFERROR(INDEX(Rules!$F:$F,MATCH(G15,Rules!$E:$E,0)),"") | I14: =IFERROR(INDEX(Rules!$G:$G,MATCH(G15,Rules!$E:$E,0)),"") | J14: =IFERROR(INDEX(Rules!$H:$H,MATCH(G15,Rules!$E:$E,0)),"") | K14: Postcode | L14: Postleitzahl | O14: Property for specifying the postcode. | P14: Merkmal zur Angabe von der Postleitzahl. | S14: INTEGER | T14: IfcInteger | W14: https://identifier.buildingsmart.org/uri/buildingsmart/ifc/4.3/prop/PostalCode | X14: https://identifier.buildingsmart.org/uri/buildingsmart/ifc/4.3/class/Pset_Address | AF14: Candidate | AG14: 2026-07-31T12:00:00Z | AH14: KBOB
F15: politische-gemeinde | H15: =IFERROR(INDEX(Rules!$F:$F,MATCH(G16,Rules!$E:$E,0)),"") | I15: =IFERROR(INDEX(Rules!$G:$G,MATCH(G16,Rules!$E:$E,0)),"") | J15: =IFERROR(INDEX(Rules!$H:$H,MATCH(G16,Rules!$E:$E,0)),"") | K15: Political municipality | L15: Politische Gemeinde | O15: Property for specifying the political municipality | P15: Merkmal zur Angabe von der politischen Gemeinde. | S15: STRING | T15: IfcLabel | X15: https://identifier.buildingsmart.org/uri/buildingsmart/ifc/4.3/class/Pset_Address | AF15: Candidate | AG15: 2026-07-31T12:00:00Z | AH15: KBOB
F16: gis-parzellennummer | H16: =IFERROR(INDEX(Rules!$F:$F,MATCH(G17,Rules!$E:$E,0)),"") | I16: =IFERROR(INDEX(Rules!$G:$G,MATCH(G17,Rules!$E:$E,0)),"") | J16: =IFERROR(INDEX(Rules!$H:$H,MATCH(G17,Rules!$E:$E,0)),"") | K16: GIS parcel number | L16: GIS-Parzellennummer | O16: Property for specifying the GIS parcel number. | P16: Merkmal zur Angabe von der GIS-Parzellennummer. | S16: STRING | T16: IfcLabel | X16: https://identifier.buildingsmart.org/uri/buildingsmart/ifc/4.3/class/Pset_LandRegistration | AF16: Candidate | AG16: 2026-07-31T12:00:00Z | AH16: KBOB
F17: grundstucksflache | H17: =IFERROR(INDEX(Rules!$F:$F,MATCH(G19,Rules!$E:$E,0)),"") | I17: =IFERROR(INDEX(Rules!$G:$G,MATCH(G19,Rules!$E:$E,0)),"") | J17: =IFERROR(INDEX(Rules!$H:$H,MATCH(G19,Rules!$E:$E,0)),"") | K17: Site area | L17: Grundstücksfläche | O17: Property for specifying the site area. | P17: Merkmal zur Angabe der Grundstücksfläche. | S17: REAL | T17: IfcAreaMeasure | W17: https://identifier.buildingsmart.org/uri/buildingsmart/ifc/4.3/prop/GrossArea | X17: https://identifier.buildingsmart.org/uri/buildingsmart/ifc/4.3/class/Qto_SiteBaseQuantities | Y17: m² | Z17: http://qudt.org/vocab/unit/M2 | AF17: Candidate | AG17: 2026-07-31T12:00:00Z | AH17: KBOB
F18: eigentumer | H18: =IFERROR(INDEX(Rules!$F:$F,MATCH(G32,Rules!$E:$E,0)),"") | I18: =IFERROR(INDEX(Rules!$G:$G,MATCH(G32,Rules!$E:$E,0)),"") | J18: =IFERROR(INDEX(Rules!$H:$H,MATCH(G32,Rules!$E:$E,0)),"") | K18: Owner | L18: Eigentümer | O18: Property for specifying the owner. | P18: Merkmal zur Angabe von dem Eigentümer. | S18: STRING | T18: IfcLabel | W18: https://identifier.buildingsmart.org/uri/buildingsmart/ifc/4.3/class/IfcOccupantOWNER | X18: https://identifier.buildingsmart.org/uri/buildingsmart/ifc/4.3/class/Pset_Address | AF18: Candidate | AG18: 2026-07-31T12:00:00Z | AH18: KBOB
F19: dienstbarkeiten-id | H19: =IFERROR(INDEX(Rules!$F:$F,MATCH(G20,Rules!$E:$E,0)),"") | I19: =IFERROR(INDEX(Rules!$G:$G,MATCH(G20,Rules!$E:$E,0)),"") | J19: =IFERROR(INDEX(Rules!$H:$H,MATCH(G20,Rules!$E:$E,0)),"") | K19: Easement ID | L19: Dienstbarkeiten ID | O19: Property for uniquely identifying easements. | P19: Merkmal zur eindeutigen Identifikation von Dienstbarkeiten. | S19: STRING | T19: IfcLabel | X19: https://identifier.buildingsmart.org/uri/buildingsmart/ifc/4.3/class/Pset_LandRegistration | AF19: Candidate | AG19: 2026-07-31T12:00:00Z | AH19: KBOB
F20: dienstbarkeitenname | H20: =IFERROR(INDEX(Rules!$F:$F,MATCH(G21,Rules!$E:$E,0)),"") | I20: =IFERROR(INDEX(Rules!$G:$G,MATCH(G21,Rules!$E:$E,0)),"") | J20: =IFERROR(INDEX(Rules!$H:$H,MATCH(G21,Rules!$E:$E,0)),"") | K20: Easement name | L20: Dienstbarkeitenname | O20: Property for specifying the easement name. | P20: Merkmal zur Angabe von dem Namen der Dienstbarkeit. | S20: STRING | T20: IfcLabel | X20: https://identifier.buildingsmart.org/uri/buildingsmart/ifc/4.3/class/Pset_LandRegistration | AF20: Candidate | AG20: 2026-07-31T12:00:00Z | AH20: KBOB
F21: gebaude-id | H21: =IFERROR(INDEX(Rules!$F:$F,MATCH(G22,Rules!$E:$E,0)),"") | I21: =IFERROR(INDEX(Rules!$G:$G,MATCH(G22,Rules!$E:$E,0)),"") | J21: =IFERROR(INDEX(Rules!$H:$H,MATCH(G22,Rules!$E:$E,0)),"") | K21: Building ID | L21: Gebäude ID | O21: Property for uniquely identifying the building. | P21: Merkmal zur eindeutigen Identifikation des Gebäudes. | S21: STRING | T21: IfcLabel | W21: https://identifier.buildingsmart.org/uri/buildingsmart/ifc/4.3/prop/BuildingID | X21: https://identifier.buildingsmart.org/uri/buildingsmart/ifc/4.3/class/Pset_BuildingCommon | AF21: Candidate | AG21: 2026-07-31T12:00:00Z | AH21: KBOB
F22: objekt-id | H22: =IFERROR(INDEX(Rules!$F:$F,MATCH(G23,Rules!$E:$E,0)),"") | I22: =IFERROR(INDEX(Rules!$G:$G,MATCH(G23,Rules!$E:$E,0)),"") | J22: =IFERROR(INDEX(Rules!$H:$H,MATCH(G23,Rules!$E:$E,0)),"") | K22: Property ID | L22: Objekt ID | O22: Property for uniquely identifying the property. | P22: Merkmal zur eindeutigen Identifikation von Objekten. | S22: STRING | T22: IfcLabel | W22: https://identifier.buildingsmart.org/uri/buildingsmart/ifc/4.3/prop/BuildingID | X22: https://identifier.buildingsmart.org/uri/buildingsmart/ifc/4.3/class/Pset_BuildingCommon | AF22: Candidate | AG22: 2026-07-31T12:00:00Z | AH22: KBOB
F23: gebaudebezeichnung | H23: =IFERROR(INDEX(Rules!$F:$F,MATCH(G24,Rules!$E:$E,0)),"") | I23: =IFERROR(INDEX(Rules!$G:$G,MATCH(G24,Rules!$E:$E,0)),"") | J23: =IFERROR(INDEX(Rules!$H:$H,MATCH(G24,Rules!$E:$E,0)),"") | K23: Building designation | L23: Gebäudebezeichnung | O23: Property for specifying the building designation. | P23: Merkmal zur Angabe von der Gebäudebezeichnung. | S23: STRING | T23: IfcLabel | W23: https://identifier.buildingsmart.org/uri/buildingsmart/ifc/4.3/prop/Name | AF23: Candidate | AG23: 2026-07-31T12:00:00Z | AH23: KBOB
F24: objekttyp | H24: =IFERROR(INDEX(Rules!$F:$F,MATCH(G25,Rules!$E:$E,0)),"") | I24: =IFERROR(INDEX(Rules!$G:$G,MATCH(G25,Rules!$E:$E,0)),"") | J24: =IFERROR(INDEX(Rules!$H:$H,MATCH(G25,Rules!$E:$E,0)),"") | K24: Property type | L24: Objekttyp | O24: Property for specifying the property type. | P24: Merkmal zur Angabe von dem Objekttyp. | S24: STRING | T24: IfcLabel | AF24: Candidate | AG24: 2026-07-31T12:00:00Z | AH24: KBOB
F25: strasse-hausnummer | H25: =IFERROR(INDEX(Rules!$F:$F,MATCH(G26,Rules!$E:$E,0)),"") | I25: =IFERROR(INDEX(Rules!$G:$G,MATCH(G26,Rules!$E:$E,0)),"") | J25: =IFERROR(INDEX(Rules!$H:$H,MATCH(G26,Rules!$E:$E,0)),"") | K25: Address line | L25: Strasse Hausnummer | O25: Property for specifying the address line. | P25: Merkmal zur Angabe von Strasse und Hausnummer. | S25: STRING | T25: IfcLabel | W25: https://identifier.buildingsmart.org/uri/buildingsmart/ifc/4.3/prop/AddressLines | X25: https://identifier.buildingsmart.org/uri/buildingsmart/ifc/4.3/class/Pset_Address | AF25: Candidate | AG25: 2026-07-31T12:00:00Z | AH25: KBOB
F26: gefahrdungsstufe | H26: =IFERROR(INDEX(Rules!$F:$F,MATCH(G27,Rules!$E:$E,0)),"") | I26: =IFERROR(INDEX(Rules!$G:$G,MATCH(G27,Rules!$E:$E,0)),"") | J26: =IFERROR(INDEX(Rules!$H:$H,MATCH(G27,Rules!$E:$E,0)),"") | K26: Hazard level | L26: Gefährdungsstufe | O26: Property for specifying the hazard level. | P26: Merkmal zur Angabe von der Gefährdungsstufe. | S26: STRING | T26: IfcLabel | W26: https://identifier.buildingsmart.org/uri/buildingsmart/ifc/4.3/prop/RiskType | X26: https://identifier.buildingsmart.org/uri/buildingsmart/ifc/4.3/class/Pset_Risk | AF26: Candidate | AG26: 2026-07-31T12:00:00Z | AH26: KBOB
F27: kostentrager | H27: =IFERROR(INDEX(Rules!$F:$F,MATCH(#REF!,Rules!$E:$E,0)),"") | I27: =IFERROR(INDEX(Rules!$G:$G,MATCH(#REF!,Rules!$E:$E,0)),"") | J27: =IFERROR(INDEX(Rules!$H:$H,MATCH(#REF!,Rules!$E:$E,0)),"") | K27: Cost centre | L27: Kostenträger | O27: Property for specifying the cost centre. | P27: Merkmal zur Angabe von dem Kostenträger. | S27: STRING | T27: IfcLabel | AF27: Candidate | AG27: 2026-07-31T12:00:00Z | AH27: KBOB
F28: gebaudegrundflache | H28: =IFERROR(INDEX(Rules!$F:$F,MATCH(G29,Rules!$E:$E,0)),"") | I28: =IFERROR(INDEX(Rules!$G:$G,MATCH(G29,Rules!$E:$E,0)),"") | J28: =IFERROR(INDEX(Rules!$H:$H,MATCH(G29,Rules!$E:$E,0)),"") | K28: Building footprint area | L28: Gebäudegrundfläche | O28: Property for specifying the building footprint area. | P28: Merkmal zur Angabe der Gebäudegrundfläche. | S28: REAL | T28: IfcAreaMeasure | W28: https://identifier.buildingsmart.org/uri/buildingsmart/ifc/4.3/prop/GrossFloorArea | X28: https://identifier.buildingsmart.org/uri/buildingsmart/ifc/4.3/class/Qto_BuildingBaseQuantities | Y28: m² | Z28: http://qudt.org/vocab/unit/M2 | AF28: Candidate | AG28: 2026-07-31T12:00:00Z | AH28: KBOB
F29: gebaudevolumen | H29: =IFERROR(INDEX(Rules!$F:$F,MATCH(G30,Rules!$E:$E,0)),"") | I29: =IFERROR(INDEX(Rules!$G:$G,MATCH(G30,Rules!$E:$E,0)),"") | J29: =IFERROR(INDEX(Rules!$H:$H,MATCH(G30,Rules!$E:$E,0)),"") | K29: Gross building volume | L29: Gebäudevolumen | O29: Property for specifying the the gross building volume. | P29: Merkmal zur Angabe der dem Gebäudevolumen. | S29: REAL | T29: IfcReal | W29: https://identifier.buildingsmart.org/uri/buildingsmart/ifc/4.3/prop/GrossVolume | X29: https://identifier.buildingsmart.org/uri/buildingsmart/ifc/4.3/class/Qto_BodyGeometryValidation | Y29: m³ | Z29: http://qudt.org/vocab/unit/M3 | AF29: Candidate | AG29: 2026-07-31T12:00:00Z | AH29: KBOB
F30: nummer-gebaudeversicherung | H30: =IFERROR(INDEX(Rules!$F:$F,MATCH(G31,Rules!$E:$E,0)),"") | I30: =IFERROR(INDEX(Rules!$G:$G,MATCH(G31,Rules!$E:$E,0)),"") | J30: =IFERROR(INDEX(Rules!$H:$H,MATCH(G31,Rules!$E:$E,0)),"") | K30: Building insurance reference | L30: Nummer Gebäudeversicherung | O30: Property for specifying the building insurance reference. | P30: Merkmal zur Angabe von der Nummer der Gebäudeversicherung. | S30: STRING | T30: IfcLabel | W30: https://identifier.buildingsmart.org/uri/buildingsmart/ifc/4.3/prop/AssetInsuranceType | X30: https://identifier.buildingsmart.org/uri/buildingsmart/ifc/4.3/class/Pset_Asset | AF30: Candidate | AG30: 2026-07-31T12:00:00Z | AH30: KBOB
F31: baujahr | H31: =IFERROR(INDEX(Rules!$F:$F,MATCH(G18,Rules!$E:$E,0)),"") | I31: =IFERROR(INDEX(Rules!$G:$G,MATCH(G18,Rules!$E:$E,0)),"") | J31: =IFERROR(INDEX(Rules!$H:$H,MATCH(G18,Rules!$E:$E,0)),"") | K31: Year of construction | L31: Baujahr | O31: Property for specifying the year of construction. | P31: Merkmal zur Angabe von dem Baujahr. | S31: INTEGER | T31: IfcInteger | W31: https://identifier.buildingsmart.org/uri/buildingsmart/ifc/4.3/prop/YearOfConstruction | X31: https://identifier.buildingsmart.org/uri/buildingsmart/ifc/4.3/class/Pset_BuildingCommon | AF31: Candidate | AG31: 2026-07-31T12:00:00Z | AH31: KBOB
F32: medienbezug-elektrisch | H32: =IFERROR(INDEX(Rules!$F:$F,MATCH(G33,Rules!$E:$E,0)),"") | I32: =IFERROR(INDEX(Rules!$G:$G,MATCH(G33,Rules!$E:$E,0)),"") | J32: =IFERROR(INDEX(Rules!$H:$H,MATCH(G33,Rules!$E:$E,0)),"") | K32: Electricity supply connection | L32: Medienbezug Elektrisch | O32: Property for specifying the electrical supply connection. | P32: Merkmal zur Angabe von dem elektrischen Medienbezug. | S32: BOOLEAN | T32: IfcLabel | AF32: Candidate | AG32: 2026-07-31T12:00:00Z | AH32: KBOB
F33: medienbezug-wasser | H33: =IFERROR(INDEX(Rules!$F:$F,MATCH(G34,Rules!$E:$E,0)),"") | I33: =IFERROR(INDEX(Rules!$G:$G,MATCH(G34,Rules!$E:$E,0)),"") | J33: =IFERROR(INDEX(Rules!$H:$H,MATCH(G34,Rules!$E:$E,0)),"") | K33: Water supply connection | L33: Medienbezug Wasser | O33: Property for specifying the water supply connection. | P33: Merkmal zur Angabe von dem Wasserbezug. | S33: BOOLEAN | T33: IfcLabel | AF33: Candidate | AG33: 2026-07-31T12:00:00Z | AH33: KBOB
F34: medienbezug-heizwaerme | H34: =IFERROR(INDEX(Rules!$F:$F,MATCH(G35,Rules!$E:$E,0)),"") | I34: =IFERROR(INDEX(Rules!$G:$G,MATCH(G35,Rules!$E:$E,0)),"") | J34: =IFERROR(INDEX(Rules!$H:$H,MATCH(G35,Rules!$E:$E,0)),"") | K34: Heating supply connection | L34: Medienbezug Heizwärme | O34: Property for specifying the heating supply connection. | P34: Merkmal zur Angabe von dem Heizungsbezug. | S34: BOOLEAN | T34: IfcLabel | AF34: Candidate | AG34: 2026-07-31T12:00:00Z | AH34: KBOB
F35: nutzungsart-aussen | H35: =IFERROR(INDEX(Rules!$F:$F,MATCH(G36,Rules!$E:$E,0)),"") | I35: =IFERROR(INDEX(Rules!$G:$G,MATCH(G36,Rules!$E:$E,0)),"") | J35: =IFERROR(INDEX(Rules!$H:$H,MATCH(G36,Rules!$E:$E,0)),"") | K35: External area use | L35: Nutzungsart aussen | O35: Property for specifying the external area use. | P35: Merkmal zur Angabe von der Nutzungsart im Aussenbereich. | S35: STRING | T35: IfcLabel | W35: https://identifier.buildingsmart.org/uri/buildingsmart/ifc/4.3/prop/MarketCategory | X35: https://identifier.buildingsmart.org/uri/buildingsmart/ifc/4.3/class/Pset_BuildingUse | AF35: Candidate | AG35: 2026-07-31T12:00:00Z | AH35: KBOB
F36: gebaudeklasse | H36: =IFERROR(INDEX(Rules!$F:$F,MATCH(G37,Rules!$E:$E,0)),"") | I36: =IFERROR(INDEX(Rules!$G:$G,MATCH(G37,Rules!$E:$E,0)),"") | J36: =IFERROR(INDEX(Rules!$H:$H,MATCH(G37,Rules!$E:$E,0)),"") | K36: Building use class | L36: Gebäudeklasse | O36: Property for specifying the building use class. | P36: Merkmal zur Angabe von der Gebäudeklasse. | S36: STRING | T36: IfcLabel | W36: https://identifier.buildingsmart.org/uri/buildingsmart/ifc/4.3/prop/OccupancyType | X36: https://identifier.buildingsmart.org/uri/buildingsmart/ifc/4.3/class/Pset_SpaceOccupancyRequirements | AF36: Candidate | AG36: 2026-07-31T12:00:00Z | AH36: KBOB
F37: gebaudelabel | H37: =IFERROR(INDEX(Rules!$F:$F,MATCH(#REF!,Rules!$E:$E,0)),"") | I37: =IFERROR(INDEX(Rules!$G:$G,MATCH(#REF!,Rules!$E:$E,0)),"") | J37: =IFERROR(INDEX(Rules!$H:$H,MATCH(#REF!,Rules!$E:$E,0)),"") | K37: Building label | L37: Gebäudelabel | O37: Property for specifying the building label. | P37: Merkmal zur Angabe von dem Gebäudelabel. | S37: STRING | T37: IfcLabel | AF37: Candidate | AG37: 2026-07-31T12:00:00Z | AH37: KBOB
F38: denkmalstatus | H38: =IFERROR(INDEX(Rules!$F:$F,MATCH(G39,Rules!$E:$E,0)),"") | I38: =IFERROR(INDEX(Rules!$G:$G,MATCH(G39,Rules!$E:$E,0)),"") | J38: =IFERROR(INDEX(Rules!$H:$H,MATCH(G39,Rules!$E:$E,0)),"") | K38: Heritage status | L38: Denkmalstatus | O38: Property for specifying the heritage status. | P38: Merkmal zur Angabe von dem Denkmalstatus. | S38: BOOLEAN | T38: IfcBoolean | W38: https://identifier.buildingsmart.org/uri/buildingsmart/ifc/4.3/prop/IsLandmarked | X38: https://identifier.buildingsmart.org/uri/buildingsmart/ifc/4.3/class/Pset_BuildingCommon | AF38: Candidate | AG38: 2026-07-31T12:00:00Z | AH38: KBOB
F39: erdbebenbauwerksklasse | H39: =IFERROR(INDEX(Rules!$F:$F,MATCH(G40,Rules!$E:$E,0)),"") | I39: =IFERROR(INDEX(Rules!$G:$G,MATCH(G40,Rules!$E:$E,0)),"") | J39: =IFERROR(INDEX(Rules!$H:$H,MATCH(G40,Rules!$E:$E,0)),"") | K39: Seismic risk class | L39: Erdbebenbauwerksklasse | O39: Property for specifying the seismic risk class. | P39: Merkmal zur Angabe von der Erdbebenbauwerksklasse. | S39: STRING | T39: IfcLabel | X39: https://identifier.buildingsmart.org/uri/buildingsmart/ifc/4.3/class/Pset_EnvironmentalCondition | AF39: Candidate | AG39: 2026-07-31T12:00:00Z | AH39: KBOB
F40: schutzzone | H40: =IFERROR(INDEX(Rules!$F:$F,MATCH(G41,Rules!$E:$E,0)),"") | I40: =IFERROR(INDEX(Rules!$G:$G,MATCH(G41,Rules!$E:$E,0)),"") | J40: =IFERROR(INDEX(Rules!$H:$H,MATCH(G41,Rules!$E:$E,0)),"") | K40: Protection zone | L40: Schutzzone | O40: Property for specifying the protection zone. | P40: Merkmal zur Angabe von der Schutzzone. | S40: BOOLEAN | T40: IfcBoolean | X40: https://identifier.buildingsmart.org/uri/buildingsmart/ifc/4.3/class/Pset_SpatialZoneCommon | AF40: Candidate | AG40: 2026-07-31T12:00:00Z | AH40: KBOB
...

Sheet Values
A1: Filter | B1: Hinweise zur Handhabung | C1: Enumerations | D1: GUID/URI | E1: Enumeration-ID | F1: Enumeration-Code | G1: Designation (EN) | H1: Bezeichnung (DE) | I1: Désignation (FR) | J1: Designazione (IT) | K1: Enumeration (EN) | L1: Werteliste (DE) | M1: Liste de valeurs (FR) | N1: Lista valori (IT) | O1: Units/Einheit/Unité/Unità | P1: Governance | Q1: Status | R1: Version date | S1: Provenance (PROV)
B2: Erforderlich für Excel
B3: Sprachen
B4: Referenziert / System generiert | D4: multilingual | E4: multilingual | F4: multilingual | G4: EN | H4: DE | I4: FR | J4: IT | K4: EN | L4: DE | M4: FR | N4: IT | O4: multilingual | Q4: multilingual | R4: multilingual | S4: multilingual
B5: Dropdown Liste | D5: system-generated | E5: system-generated | Q5: referenced | R5: referenced | S5: referenced
B6: Validierung | Q6: Rules.Status
G7: Canton | H7: Kanton | K7: ["Zürich", "Bern", "Luzern", "Uri", "Schwyz", "Obwalden", "Nidwalden", "Glarus", "Zug", "Freiburg", "Solothurn", "Basel-Stadt", "Basel-Landschaft", "Schaffhausen", "Appenzell Ausserrhoden", "Appenzell Innerrhoden", "St. Gallen", "Graubünden", "Aargau", "Thurgau", "Tessin", "Waadt", "Wallis", "Neuenburg", "Genf", "Jura"] | L7: ["Zürich", "Bern", "Luzern", "Uri", "Schwyz", "Obwalden", "Nidwalden", "Glarus", "Zug", "Freiburg", "Solothurn", "Basel-Stadt", "Basel-Landschaft", "Schaffhausen", "Appenzell Ausserrhoden", "Appenzell Innerrhoden", "St. Gallen", "Graubünden", "Aargau", "Thurgau", "Tessin", "Waadt", "Wallis", "Neuenburg", "Genf", "Jura"] | Q7: Preview | R7: 2026-07-31T12:00:00Z | S7: KBOB
G8: SIA 416 area category | H8: Flächenart SIA 416 | K8: ["1.2", "1.2.1", "1.2.2", 2, "2.1.1.1", "2.1.1.2", "2.1.2", "2.1.3", 3, "3.1.1", "3.1.2", "3.1.3", "AIRSPACE", "ROOF", 1, 2, 3, 4] | L8: ["1_GSF", "1.1_GGF", "1.2_UF", "1.2.1_BUF", "1.2.2_UUF", "2_GF", "2.1.1.1_HNF", "2.1.1.2_NNF", "2.1.2_VF", "2.1.3_FF", "3_AGF", "3.1_ANGF", "3.1.1_ANF", "3.1.2_AVF", "3.1.3_AFF", "5_GV", "AIRSPACE_LUFTRAUM", "ROOF_DACH"] | Q8: Preview | R8: 2026-07-31T12:00:00Z | S8: KBOB
G9: d0165 area category | H9: Flächenart d0165 | K9: [1.1, 1.2, 1.3, 1.4, 1.5, 1.6, 2.1, 2.2, 2.3, 2.4, 2.5, 2.6, 2.7, 2.8, 3.1, 3.2, 3.3, 3.4, 3.5, 3.6, 3.7, 3.8, 3.9, 4.1, 4.2, 4.3, 4.4, 4.5, 4.6, 5.1, 5.2, 5.3, 5.4, 5.5, 5.6, 5.7, 5.8, 5.9, 6.1, 6.2, 6.3, 6.4, 6.5, 6.6, 6.7, 6.8, 7.1, 7.2, 7.3, 7.4, 7.5, 7.6, 7.7, 8.1, 8.2, 8.3, 8.4, 8.5, 8.6, 8.7, 8.8, 8.9, 9.1, 9.2, 9.3, 9.4, 10.1] | L9: ["1.1_Wohnräume", "1.2_Gemeinschaftsräume", "1.3_Pausenräume", "1.4_Warteräume", "1.5_Speiseräume", "1.6_Hafträume", "2.1_Büroräume", "2.2_Grossraumbüros", "2.3_Besprechungsräume", "2.4_Konstruktionsräume", "2.5_Schalterräume", "2.6_Bedienungsräume", "2.7_Aufsichtsräume", "2.8_Bürotechnikräume", "3.1_Werkhallen", "3.2_Werkstätten", "3.3_Technologische Labors", "3.4_Physikalische/physikaltechnische/elektrotechnische Labors", "3.5_Chemische/bakteriologische/morphologische Labors", "3.6_Räume für Tierhaltung", "3.7_Räume für Pflanzenzucht", "3.8_Küchen", "3.9_Sonderarbeitsräume", "4.1_Lagerräume", "4.2_Archive/Sammlungsräume", "4.3_Kühlräume", "4.4_Annahme- und Ausgaberäume", "4.5_Verkaufsräume", "4.6_Ausstellungsräume", "5.1_Unterrichtsräume mit festem Gestühl", "5.2_Allgemein Unterrichts- und Übungsräume ohne festes Gestühl", "5.3_Besondere Unterrichts- und Übungsräume ohne festes Gestühl", "5.4_Bibliotheksräume", "5.5_Sporträume", "5.6_Versammlungsräume", "5.7_Bühnen-/Studioräume", "5.8_Schauräume", "5.9_Sakralräume", "6.1_Räume mit allgemeiner medizinischen Ausstattung", "6.2_Räume mit besonderer medizinischen Ausstattung", "6.3_Räume für operative Eingriffe/Endoskopien/Entbindungen", "6.4_Räume für Strahlendiagnostik", "6.5_Räume für Strahlentherapie", "6.6_Räume für Physiotherapie und Rehabilitation", "6.7_Bettenräume mit allgemeiner Ausstattung", "6.8_Bettenräume mit besonderer Ausstattung", "7.1_Sanitärräume", "7.2_Garderoben", "7.3_Abstellräume", "7.4_Fahrzeugabstellflächen", "7.5_Fahrgastflächen", "7.6_Räume für zentrale Technik", "7.7_Schutzräum", "8.1_Abwasseraufbereitung u. -beseitigung", "8.2_Wasserversorgung", "8.3_Heizung und Brauchwassererwärmung", "8.4_Gase und Flüssigkeiten", "8.5_Elektrische Stromversorgung", "8.6_Fernmeldetechnik", "8.7_Raumlufttechnische Anlagen", "8.8_Aufzugs- und Förderanlagen", "8.9_Sonstige betriebstechnische Anlagen", "9.1_Flure/Hallen", "9.2_Treppen", "9.3_Schächte für Förderanlagen", "9.4_Fahrzeugsverkehrsflächen", "10.1_aussenliegende Fahrzeugabstellflächen"] | Q9: Preview | R9: 2026-07-31T12:00:00Z | S9: KBOB
G10: eBKP-H code | H10: eBKP-H | K10: ["A01.01", "A01.02", "A01.03", "A01.04", "A02.01", "A02.02", "A02.03", "A02.04", "A02.05", "A02.06", "A02.07", "B01.01", "B01.02", "B01.03", "B01.04", "B02.01", "B02.02", "B02.03", "B02.04", "B02.05", "B02.06", "B02.07", "B02.08", "B03.01", "B03.02", "B03.03", "B03.04", "B03.05", "B04.01", "B04.02", "B04.03", "B04.04", "B04.05", "B04.06", "B04.07", "B04.08", "B05.01", "B05.02", "B05.03", "B06.01", "B06.02", "B06.03", "B06.04", "B06.05", "B06.06", "B07.01", "B07.02", "B07.03", "B07.04", "B08.01", "B08.02", "B08.03", "B08.04", "B09.01", "B09.02", "B09.03", "C01.01", "C01.02", "C01.03", "C01.04", "C01.05", "C02.01", "C02.02", "C03.01", "C03.02", "C04.01", "C04.02", "C04.03", "C04.04", "C04.05", "C04.06", "C04.07", "C04.08", "C05.01", "C05.02", "D01.01", "D01.02", "D01.03", "D01.04", "D01.05", "D01.06", "D01.07", "D01.08", "D01.09", "D01.10", "D01.11", "D02.01", "D02.02", "D02.03", "D02.04", "D02.05", "D02.06", "D02.07", "D03.01", "D03.02", "D03.03", "D03.04", "D04.01", "D04.02", "D04.03", "D04.04", "D04.05", "D04.06", "D04.07", "D05.01", "D05.02", "D05.03", "D05.04", "D05.05", "D05.06", "D06.01", "D06.02", "D06.03", "D06.04", "D06.05", "D06.06", "D07.01", "D07.02", "D07.03", "D07.04", "D07.05", "D07.06", "D08.01", "D08.02", "D08.03", "D08.04", "D08.05", "D08.06", "D09.01", "D09.02", "D09.03", "D09.04", "D09.05", "D10.01", "D10.02", "D10.03", "D10.04", "D10.05", "D11.01", "D11.02", "D11.03", "D11.04", "D11.05", "D12.01", "D12.02", "D12.03", "D12.04", "D12.05", "D12.06", "E01.01", "E01.02", "E01.03", "E02.01", "E02.02", "E02.03", "E02.04", "E02.05", "E02.06", "E03.01", "E03.02", "E03.03", "E03.04", "E03.05", "F01.01", "F01.02", "F01.03", "F01.04", "F02.01", "F02.02", "F02.03", "G01.01", "G01.02", "G01.03", "G01.04", "G01.05", "G01.06", "G02.01", "G02.02", "G03.01", "G03.02", "G04.01", "G04.02", "G05.01", "G05.02", "G05.03", "G05.04", "G05.05", "G05.06", "G05.07", "G06.01", "G06.02", "G06.03", "G06.04", "H01.01", "H01.02", "H01.03", "H01.04", "H01.05", "H02.01", "H02.02", "H02.03", "H02.04", "H02.05", "H03.01", "H03.02", "H03.03", "H03.04", "H03.05", "H04.01", "H04.02", "H04.03", "H04.04", "H04.05", "H05.01", "H05.02", "H05.03", "H05.04", "H05.05", "H05.06", "H05.07", "H05.08", "H05.09", "H05.10", "H05.11", "H05.12", "H06.01", "H06.02", "H06.03", "H06.04", "H07.01", "H07.02", "H07.03", "H07.04", "H08.01", "H08.02", "H08.03", "H08.04", "H09.01", "H09.02", "H09.03", "H09.04", "H09.05", "H09.06", "H09.07", "H09.08", "H09.09", "I01.01", "I01.02", "I02.01", "I02.02", "I02.03", "I02.04", "I02.05", "I02.06", "I02.07", "I02.08", "I03.01", "I03.02", "I03.03", "I03.04", "I03.05", "I03.06", "I03.07", "I03.08", "I03.09", "I04.01", "I04.02", "I04.03", "I04.04", "I05.01", "I05.02", "I05.03", "I05.04", "I05.05", "I05.06", "I05.07", "I05.08", "I06.01", "I06.02", "I06.03", "I06.04", "J01.01", "J01.02", "J01.03", "J01.04", "J02.01", "J02.02", "J02.03", "J03.01", "J03.02", "J04.01", "J04.02", "V01.01", "V01.02", "V01.03", "V01.04", "V01.05", "V01.06", "V01.07", "V02.01", "V02.02", "V03.01", "V03.02", "V03.03", "V03.04", "V03.05", "V03.06", "V03.07", "W01.01", "W01.02", "W02.01", "W02.02", "W02.03", "W03.01", "W03.02", "W04.01", "W04.02", "W04.03", "W05.01", "W06.01", "W06.02", "W06.03", "W06.04", "W07.01", "W07.02", "Y01.01", "Y02.01", "Z01.01"] | L10: ["A01.01", "A01.02", "A01.03", "A01.04", "A02.01", "A02.02", "A02.03", "A02.04", "A02.05", "A02.06", "A02.07", "B01.01", "B01.02", "B01.03", "B01.04", "B02.01", "B02.02", "B02.03", "B02.04", "B02.05", "B02.06", "B02.07", "B02.08", "B03.01", "B03.02", "B03.03", "B03.04", "B03.05", "B04.01", "B04.02", "B04.03", "B04.04", "B04.05", "B04.06", "B04.07", "B04.08", "B05.01", "B05.02", "B05.03", "B06.01", "B06.02", "B06.03", "B06.04", "B06.05", "B06.06", "B07.01", "B07.02", "B07.03", "B07.04", "B08.01", "B08.02", "B08.03", "B08.04", "B09.01", "B09.02", "B09.03", "C01.01", "C01.02", "C01.03", "C01.04", "C01.05", "C02.01", "C02.02", "C03.01", "C03.02", "C04.01", "C04.02", "C04.03", "C04.04", "C04.05", "C04.06", "C04.07", "C04.08", "C05.01", "C05.02", "D01.01", "D01.02", "D01.03", "D01.04", "D01.05", "D01.06", "D01.07", "D01.08", "D01.09", "D01.10", "D01.11", "D02.01", "D02.02", "D02.03", "D02.04", "D02.05", "D02.06", "D02.07", "D03.01", "D03.02", "D03.03", "D03.04", "D04.01", "D04.02", "D04.03", "D04.04", "D04.05", "D04.06", "D04.07", "D05.01", "D05.02", "D05.03", "D05.04", "D05.05", "D05.06", "D06.01", "D06.02", "D06.03", "D06.04", "D06.05", "D06.06", "D07.01", "D07.02", "D07.03", "D07.04", "D07.05", "D07.06", "D08.01", "D08.02", "D08.03", "D08.04", "D08.05", "D08.06", "D09.01", "D09.02", "D09.03", "D09.04", "D09.05", "D10.01", "D10.02", "D10.03", "D10.04", "D10.05", "D11.01", "D11.02", "D11.03", "D11.04", "D11.05", "D12.01", "D12.02", "D12.03", "D12.04", "D12.05", "D12.06", "E01.01", "E01.02", "E01.03", "E02.01", "E02.02", "E02.03", "E02.04", "E02.05", "E02.06", "E03.01", "E03.02", "E03.03", "E03.04", "E03.05", "F01.01", "F01.02", "F01.03", "F01.04", "F02.01", "F02.02", "F02.03", "G01.01", "G01.02", "G01.03", "G01.04", "G01.05", "G01.06", "G02.01", "G02.02", "G03.01", "G03.02", "G04.01", "G04.02", "G05.01", "G05.02", "G05.03", "G05.04", "G05.05", "G05.06", "G05.07", "G06.01", "G06.02", "G06.03", "G06.04", "H01.01", "H01.02", "H01.03", "H01.04", "H01.05", "H02.01", "H02.02", "H02.03", "H02.04", "H02.05", "H03.01", "H03.02", "H03.03", "H03.04", "H03.05", "H04.01", "H04.02", "H04.03", "H04.04", "H04.05", "H05.01", "H05.02", "H05.03", "H05.04", "H05.05", "H05.06", "H05.07", "H05.08", "H05.09", "H05.10", "H05.11", "H05.12", "H06.01", "H06.02", "H06.03", "H06.04", "H07.01", "H07.02", "H07.03", "H07.04", "H08.01", "H08.02", "H08.03", "H08.04", "H09.01", "H09.02", "H09.03", "H09.04", "H09.05", "H09.06", "H09.07", "H09.08", "H09.09", "I01.01", "I01.02", "I02.01", "I02.02", "I02.03", "I02.04", "I02.05", "I02.06", "I02.07", "I02.08", "I03.01", "I03.02", "I03.03", "I03.04", "I03.05", "I03.06", "I03.07", "I03.08", "I03.09", "I04.01", "I04.02", "I04.03", "I04.04", "I05.01", "I05.02", "I05.03", "I05.04", "I05.05", "I05.06", "I05.07", "I05.08", "I06.01", "I06.02", "I06.03", "I06.04", "J01.01", "J01.02", "J01.03", "J01.04", "J02.01", "J02.02", "J02.03", "J03.01", "J03.02", "J04.01", "J04.02", "V01.01", "V01.02", "V01.03", "V01.04", "V01.05", "V01.06", "V01.07", "V02.01", "V02.02", "V03.01", "V03.02", "V03.03", "V03.04", "V03.05", "V03.06", "V03.07", "W01.01", "W01.02", "W02.01", "W02.02", "W02.03", "W03.01", "W03.02", "W04.01", "W04.02", "W04.03", "W05.01", "W06.01", "W06.02", "W06.03", "W06.04", "W07.01", "W07.02", "Y01.01", "Y02.01", "Z01.01"] | Q10: Preview | R10: 2026-07-31T12:00:00Z | S10: KBOB
G11: Electricity supply connection | H11: Medienbezug Elektrisch | K11: ["true", "false"] | L11: ["true", "false"] | Q11: Preview | R11: 2026-07-31T12:00:00Z | S11: KBOB
G12: Water supply connection | H12: Medienbezug Wasser | K12: ["true", "false"] | L12: ["true", "false"] | Q12: Preview | R12: 2026-07-31T12:00:00Z | S12: KBOB
G13: Heating supply connection | H13: Medienbezug Heizwärme | K13: ["true", "false"] | L13: ["true", "false"] | Q13: Preview | R13: 2026-07-31T12:00:00Z | S13: KBOB
G14: Heritage status | H14: Denkmalstatus | K14: ["true", "false"] | L14: ["true", "false"] | Q14: Preview | R14: 2026-07-31T12:00:00Z | S14: KBOB
G15: Protection zone | H15: Schutzzone | K15: ["true", "false"] | L15: ["true", "false"] | Q15: Preview | R15: 2026-07-31T12:00:00Z | S15: KBOB
G16: Above ground | H16: Oberirdisch | K16: ["true", "false"] | L16: ["true", "false"] | Q16: Preview | R16: 2026-07-31T12:00:00Z | S16: KBOB
G17: Escape route | H17: Fluchtweg | K17: ["true", "false"] | L17: ["true", "false"] | Q17: Preview | R17: 2026-07-31T12:00:00Z | S17: KBOB
G18: Openable window | H18: Fenster Öffenbar | K18: ["true", "false"] | L18: ["true", "false"] | Q18: Preview | R18: 2026-07-31T12:00:00Z | S18: KBOB
G19: Solar shading | H19: Sonnenschutz | K19: ["true", "false"] | L19: ["true", "false"] | Q19: Preview | R19: 2026-07-31T12:00:00Z | S19: KBOB
G20: Ventilation | H20: Belüftet | K20: ["true", "false"] | L20: ["true", "false"]
G21: Heated | H21: Beheizt | K21: ["true", "false"] | L21: ["true", "false"] | Q21: Preview | R21: 2026-07-31T12:00:00Z | S21: KBOB
G22: Humidified | H22: Befeuchtet | K22: ["true", "false"] | L22: ["true", "false"] | Q22: Preview | R22: 2026-07-31T12:00:00Z | S22: KBOB
G23: Dehumidified | H23: Entfeuchtet | K23: ["true", "false"] | L23: ["true", "false"] | Q23: Preview | R23: 2026-07-31T12:00:00Z | S23: KBOB
G24: Cooled | H24: Gekühlt | K24: ["true", "false"] | L24: ["true", "false"] | Q24: Preview | R24: 2026-07-31T12:00:00Z | S24: KBOB
G25: Air-conditioned | H25: Klimatisiert | K25: ["true", "false"] | L25: ["true", "false"] | Q25: Preview | R25: 2026-07-31T12:00:00Z | S25: KBOB
G26: Sanitary facilities | H26: Sanitäre Anlagen | K26: ["true", "false"] | L26: ["true", "false"] | Q26: Preview | R26: 2026-07-31T12:00:00Z | S26: KBOB
G27: Lettable status | H27: Vermietbarkeit | K27: ["true", "false"] | L27: ["true", "false"] | Q27: Preview | R27: 2026-07-31T12:00:00Z | S27: KBOB
G28: Raised access floor | H28: Doppelboden | K28: ["true", "false"] | L28: ["true", "false"] | Q28: Preview | R28: 2026-07-31T12:00:00Z | S28: KBOB
G29: Escape route function | H29: Fluchtwegfunktion | K29: ["true", "false"] | L29: ["true", "false"] | Q29: Preview | R29: 2026-07-31T12:00:00Z | S29: KBOB
G30: Drive | H30: Antrieb | K30: ["true", "false"] | L30: ["true", "false"] | Q30: Preview | R30: 2026-07-31T12:00:00Z | S30: KBOB

Sheet Documents
A1: Filter | B1: Hinweise zur Handhabung | C1: Documents | D1: GUID/URI | E1: Document-ID | F1: Document-Code | G1: DocumentName (EN) | H1: Bezeichnung (DE) | I1: Désignation (FR) | J1: Designazione (IT) | K1: Security level/Sicherheitsstufe/Niveau de sécurité/Livello di sicurezza | L1: Accessibility/Zugänglichkeit/Accessibilité/Accessibilità | M1: Revision | N1: DocumentOwner | O1: Governance | P1: Status | Q1: Version date | R1: Provenance (PROV)
B2: Erforderlich für Excel
B3: Sprachen
B4: Referenziert / System generiert | D4: multilingual | E4: multilingual | F4: multilingual | G4: EN | H4: DE | I4: FR | J4: IT | K4: multilingual | L4: multilingual | M4: multilingual | N4: multilingual | P4: multilingual | Q4: multilingual | R4: multilingual
B5: Dropdown Liste | E5: system-generated | G5: referenced | M5: referenced | N5: referenced | P5: referenced | Q5: referenced | R5: referenced
B6: Validierung | K6: Rules.ISG - Informationssicherheitsgesetz | L6: Rules.FAIR Prinzipien | P6: Rules.Status
G7: SN 504 416 - Areas and volumes of buildings | H7: SN 504 416 -Flächen und Volumen von Gebäuden | K7: nicht klassifiziert | L7: Zugänglich kostenpflichtig | M7: 2003 | N7: SIA | P7: Candidate | Q7: 2026-07-31T12:00:00Z | R7: KBOB

Sheet GroupOfProperties
A1: Filter | B1: Hinweise zur Handhabung | C1: Group of Properties | D1: GoP-ID | E1: GoP-Code | F1: Designation (EN) | G1: Description (EN) | H1: Beschreibung (DE) | I1: Description (FR) | J1: Descrizione (IT) | K1: Governance | L1: Status | M1: Version date | N1: Provenance (PROV)
B2: Erforderlich für Excel
B3: Sprachen
B4: Referenziert / System generiert | D4: multilingual | E4: multilingual | F4: EN | G4: EN | H4: DE | I4: FR | J4: IT | L4: multilingual | M4: multilingual | N4: multilingual
B5: Dropdown Liste | D5: system-generated | L5: referenced | M5: referenced | N5: referenced
B6: Validierung | L6: Rules.Status
E7: KBOB_Identifikation | F7: KBOB_Identification | G7: PropertySetName KBOB_Identifikation | H7: PropertySetName KBOB_Identification | L7: Candidate | M7: 2026-07-31T12:00:00Z | N7: KBOB
E8: KBOB_Verortung | F8: KBOB_Location | G8: PropertySetName KBOB_Verortung | H8: PropertySetName KBOB_Location | L8: Candidate | M8: 2026-07-31T12:00:00Z | N8: KBOB
E9: KBOB_Klassifikation | F9: KBOB_Classification | G9: PropertySetName KBOB_Klassifikation | H9: PropertySetName KBOB_Classification | L9: Candidate | M9: 2026-07-31T12:00:00Z | N9: KBOB
E10: KBOB_Nutzung | F10: KBOB_Usage | G10: PropertySetName KBOB_Nutzung | H10: PropertySetName KBOB_Usage | L10: Candidate | M10: 2026-07-31T12:00:00Z | N10: KBOB
E11: KBOB_Compliance | F11: KBOB_Compliance | G11: PropertySetName KBOB_Compliance | H11: PropertySetName KBOB_Compliance | L11: Candidate | M11: 2026-07-31T12:00:00Z | N11: KBOB
E12: KBOB_Geometrie | F12: KBOB_Geometry | G12: PropertySetName KBOB_Geometrie | H12: PropertySetName KBOB_Geometry | L12: Candidate | M12: 2026-07-31T12:00:00Z | N12: KBOB
E13: KBOB_Betrieb | F13: KBOB_Operations | G13: PropertySetName KBOB_Betrieb | H13: PropertySetName KBOB_Operations | L13: Candidate | M13: 2026-07-31T12:00:00Z | N13: KBOB
E14: KBOB_Technik | F14: KBOB_Technical | G14: PropertySetName KBOB_Technik | H14: PropertySetName KBOB_Technical | L14: Candidate | M14: 2026-07-31T12:00:00Z | N14: KBOB
E15: KBOB_Wartung | F15: KBOB_Maintenance | G15: PropertySetName KBOB_Wartung | H15: PropertySetName KBOB_Maintenance | L15: Candidate | M15: 2026-07-31T12:00:00Z | N15: KBOB
E16: KBOB_Material | F16: KBOB_Material | G16: PropertySetName KBOB_Material | H16: PropertySetName KBOB_Material | L16: Candidate | M16: 2026-07-31T12:00:00Z | N16: KBOB

Sheet Data_Template
C1: GoP | E1: Properties | DH1: Documents | DN1: LOIN | DS1: Governance
